Workbook

Sheet MRS
A1: ■ Purchase Requisition of Material / Manpower / Equipment Rental / ETC. | J1: DAESHIN PLANT
A2: PJT : SACE2 | D2: Division (In charge Name) : ADMIN MANAGER (Dong Chang Kim) | J2: Subcontract name (SAC2-SC-IK-SMP-01)
A3: MRS No : SAC2-DS-MRS-0501 | E3: =+L3+3 -> 46322 | L3: 46319
A4: No | B4: Item | D4: Specification (Model / Manufacturer / Size) | G4: Unit | H4: Qty | I4: Unit Price (SAR) (Exclude VAT) | J4: Total Price (SAR) (Exclude VAT) | K4: Vendor Name | L4: Remarks
A6: =ROW(A1) -> 1 | B6: SCAFFOLDING STEEL BOARD | D6: 225mm X 38mm x 4.0 mtr | E6: 225mm X 38mm x 4.0 mtr | F6: 225mm X 38mm x 4.0 mtr | G6: EA | H6: 200 | I6: 112 | J6: =H6*I6 -> 22400 | K6: YATCO | L6: One time
A7: =ROW(A2) -> 2 | B7: SCAFFOLDING STEEL BOARD | D7: 225mm X 38mm x 3.0 mtr | E7: 225mm X 38mm x 3.0 mtr | F7: 225mm X 38mm x 3.0 mtr | G7: EA | H7: 300 | I7: 85 | J7: =H7*I7 -> 25500 | K7: - | L7: -
A8: =ROW(A3) -> 3 | B8: SCAFFOLDING STEEL BOARD | D8: 225mm X 38mm x 2.5 mtr | E8: 225mm X 38mm x 2.5 mtr | F8: 225mm X 38mm x 2.5 mtr | G8: EA | H8: 200 | I8: 73 | J8: =H8*I8 -> 14600 | K8: - | L8: -
A9: =ROW(A4) -> 4 | B9: SCAFFOLDING STEEL BOARD | D9: 225mm X 38mm x 2.0 mtr | E9: 225mm X 38mm x 2.0 mtr | F9: 225mm X 38mm x 2.0 mtr | G9: EA | H9: 400 | I9: 60 | J9: =H9*I9 -> 24000 | K9: - | L9: -
A10: =ROW(A5) -> 5 | B10: SCAFFOLDING STEEL BOARD | D10: 225mm X 38mm x 1.5 mtr | E10: 225mm X 38mm x 1.5 mtr | F10: 225mm X 38mm x 1.5 mtr | G10: EA | H10: 400 | I10: 46 | J10: =H10*I10 -> 18400 | K10: - | L10: -
A11: =ROW(A6) -> 6 | B11: SCAFFOLDING STEEL BOARD | D11: 225mm X 38mm x 1.0 mtr | E11: 225mm X 38mm x 1.0 mtr | F11: 225mm X 38mm x 1.0 mtr | G11: EA | H11: 500 | I11: 31 | J11: =H11*I11 -> 15500 | K11: - | L11: -
A12: Purpose | I12: Sum | J12: =SUM(J6:J11) -> 120400
A13: * There will be an additional administration expense and financial expense (Depend on contract) deduction of total provision cost price.
O16: SUB-CON | T16: HDEC
O17: In Charge | P17: ADM | Q17: PCM | R17: PM | T17: Construction | U17: Subcon(PC) | V17: Account | Y17: ADM
V18: In Charge | W18: Manager
X20: HEC | Y20: ADM
O42: PROJECT MANAGER | P42: PROJECT MANAGER | S42: ADM
O46: PROJECT MANAGER | P46: PROJECT MANAGER | S46: PCM

Sheet MRS LIST
A1: ■ Purchase Requisition of Equipment Rental | J1: =+MRS!J1 -> DAESHIN PLANT
A2: =+MRS!A2 -> PJT : SACE2 | D2: =+MRS!D2 -> Division (In charge Name) : ADMIN MANAGER (Dong Chang Kim) | J2: =+MRS!J2 -> Subcontract name (SAC2-SC-IK-SMP-01)
A3: =+MRS!A3 -> MRS No : SAC2-DS-MRS-0501 | K3: =+MRS!L3 -> 46319
A4: No | B4: Item | D4: Specification (Model / Manufacturer / Size) | G4: Unit | H4: Q'ty | I4: Unit Price | J4: Total Price | K4: Remarks
A6: =+MRS!A6 -> 1 | B6: =MRS!B6 -> SCAFFOLDING STEEL BOARD | D6: =MRS!D6 -> 225mm X 38mm x 4.0 mtr | G6: =MRS!G6 -> EA | H6: =MRS!H6 -> 200 | I6: =MRS!I6 -> 112 | J6: =MRS!J6 -> 22400
A7: =+MRS!A7 -> 2 | B7: =MRS!B7 -> SCAFFOLDING STEEL BOARD | D7: =MRS!D7 -> 225mm X 38mm x 3.0 mtr | G7: =MRS!G7 -> EA | H7: =MRS!H7 -> 300 | I7: =MRS!I7 -> 85 | J7: =MRS!J7 -> 25500
A8: =+MRS!A8 -> 3 | B8: =MRS!B8 -> SCAFFOLDING STEEL BOARD | D8: =MRS!D8 -> 225mm X 38mm x 2.5 mtr | G8: =MRS!G8 -> EA | H8: =MRS!H8 -> 200 | I8: =MRS!I8 -> 73 | J8: =MRS!J8 -> 14600
A9: =+MRS!A9 -> 4 | B9: =MRS!B9 -> SCAFFOLDING STEEL BOARD | D9: =MRS!D9 -> 225mm X 38mm x 2.0 mtr | G9: =MRS!G9 -> EA | H9: =MRS!H9 -> 400 | I9: =MRS!I9 -> 60 | J9: =MRS!J9 -> 24000
A10: =+MRS!A10 -> 5 | B10: =MRS!B10 -> SCAFFOLDING STEEL BOARD | D10: =MRS!D10 -> 225mm X 38mm x 1.5 mtr | G10: =MRS!G10 -> EA | H10: =MRS!H10 -> 400 | I10: =MRS!I10 -> 46 | J10: =MRS!J10 -> 18400
A11: =+MRS!A11 -> 6 | B11: =MRS!B11 -> SCAFFOLDING STEEL BOARD | D11: =MRS!D11 -> 225mm X 38mm x 1.0 mtr | G11: =MRS!G11 -> EA | H11: =MRS!H11 -> 500 | I11: =MRS!I11 -> 31 | J11: =MRS!J11 -> 15500

Sheet PO 1st page
M2: BRANCH OF HYUNDAI ENG. & CONST. CO., LTD.
M3: P. O. Box 77249, Al Khobar 31952
M4: kingdom of Saudi Arabia
B5: C.R. 2051041774 & VAT No.: 300000504500003 | M5: Tel: +966-13-845-1088
M6: Fax: +966-13-845-1099
B9: TO: | C9: YATCO(Yaqoot Arabia Trading Company)
C10: CR No. : | D10: 2050187866 | J10: P/O Date: | K10: =MRS!L3 -> 46319
C11: VAT No. : | D11: 312249720500003 | J11: P/O No.: | K11: =SUBSTITUTE(SUBSTITUTE(+MRS!A3," MRS No : ",""),"-MRS","-PO") -> SAC2-DS-PO-0501
C12: In Charge : | D12: Haris | J12: (Please mention this No. in
D13: Mobile No. +966 565731662 | J13: All future correspondence)
C14: Abu Bakr Al-Razi Street Near Dharhan - Jubail Highway, Dammam 34223 | J14: Quote Ref. : | K14: QTN-YATCO-SCAF-000233
C15: Mobile: +966 565731662 | J15: Date- | K15: 46293
B18: PURCHASE ORDER
B20: WE ARE PLEASED TO PLACE AN ORDER WITH YOU FOR THE GOODS DESCRIBED BELOW. THE ORDER SHALL BE SUBJECT TO THE TERMS AND CONDITIONS SET OUR
B21: BELOW AND ATTACHED. PLEASE SIGN AND RETURN THE ENCLOSED COPY OF THIS ORDER AS CONFIRMATION OF YOUR ACCEPTANCE OF IT WITHIN A WEEK
B22: OTHERWISE THIS ORDER SHALL BE REGARDED AS BEING ACCEPTED BY YOU.
B25: 1 | C25: GOODS
C26: =MRS!B6 & MRS!D6 -> SCAFFOLDING STEEL BOARD 225mm X 38mm x 4.0 mtr | M26: [Please refer to attached Scope of supply & Quotation for more details]
B28: 2 | C28: P/O AMOUNT
C29: Material Value | E29: : | F29: ='PO 2nd page'!G12 -> 120400
C30: VAT 15% | E30: : | F30: ='PO 2nd page'!G13 -> 18060
C31: Total Amount | E31: : | F31: ='PO 2nd page'!G14 -> 138460
B33: 3 | C33: PAYMENT TERMS
C34: 100% Payment after Delivery within 35 days with submission of the following Documents.
C35: a) Tax E-Invoice (From Zakat, Tax and Customs Authority)
C36: b) Delivery/Dispatch Note [Counter signed by Site Representative]
B38: 4 | C38: DELIVERY TERMS
C39: Delivery by Seller to Jafurah HYUNDAI Laydown within a Week after receipt of PO.
B41: 5 | C41: OTHER TERMS AND CONDITIONS
C42: a) Any quantity rejected by the Buyer owing to its poor quality and non conformity of specification shall be replaced and re-delivered
C43: by Seller to Buyer at no extra costs
C44: b) Material Certificate, Data Sheet, Safety Data Sheet and other documents which may required by ARAMCO in material receiving
C45: inspection should be submitted to Buyer
C46: c) MTC / MSDS, Others, If required by Client
B48: 6 | C48: CONTACT POINT:
B49: - | C49: Delivery & Payment : Dong Chang Kim / Daeshin Admin. [ Mobile No. : +966 53 748 5762 / Email : kdchjs@daeshinplant.com ]
B50: - | C50: Commercial (Purchaser) : Youngkyu Choi / Daeshin Planning [ Mobile No. : +966 53 952 0931 / Email : ykchoi@daeshinplant.com ]
B51: - | C51: Invoicing : Nehal Kauser / HDEC Purchase PIC [ Mobile No. : +966 50 610 2363 / Email : nehal_kauser@hdec.co.kr ]
B53: 7 | C53: Bank Account Details:
B54: - | C54: ACCOUNT NAME | F54: YAQOT ALARBYH COMPANY | P54: =UPPER(F54) -> YAQOT ALARBYH COMPANY
...

Sheet PO 2nd page
A2: PO NO. : | B2: =+'PO 1st page'!K11 -> SAC2-DS-PO-0501 | C2: Scope of Supply
A3: DATE : | B3: =+'PO 1st page'!K10 -> 46319 | E3: Jafurah Utilities, Sulfur and Interconnecting Systems(Pkg-2)
A4: S. NO | B4: DESCRIPTION | D4: UNIT | E4: QTY | F4: ='PO 1st page'!C9 -> YATCO(Yaqoot Arabia Trading Company) | H4: Remarks (Details)
F5: Unit Price | G5: Total Amount
A6: =ROW(A1) -> 1 | B6: =MRS!B6&" "&MRS!D6 -> SCAFFOLDING STEEL BOARD 225mm X 38mm x 4.0 mtr | D6: =MRS!G6 -> EA | E6: =MRS!H6 -> 200 | F6: =MRS!I6 -> 112 | G6: =MRS!J6 -> 22400 | H6: One time
A7: =ROW(A2) -> 2 | B7: =MRS!B7&" "&MRS!D7 -> SCAFFOLDING STEEL BOARD 225mm X 38mm x 3.0 mtr | D7: =MRS!G7 -> EA | E7: =MRS!H7 -> 300 | F7: =MRS!I7 -> 85 | G7: =MRS!J7 -> 25500
A8: =ROW(A3) -> 3 | B8: =MRS!B8&" "&MRS!D8 -> SCAFFOLDING STEEL BOARD 225mm X 38mm x 2.5 mtr | D8: =MRS!G8 -> EA | E8: =MRS!H8 -> 200 | F8: =MRS!I8 -> 73 | G8: =MRS!J8 -> 14600
A9: =ROW(A4) -> 4 | B9: =MRS!B9&" "&MRS!D9 -> SCAFFOLDING STEEL BOARD 225mm X 38mm x 2.0 mtr | D9: =MRS!G9 -> EA | E9: =MRS!H9 -> 400 | F9: =MRS!I9 -> 60 | G9: =MRS!J9 -> 24000
A10: =ROW(A5) -> 5 | B10: =MRS!B10&" "&MRS!D10 -> SCAFFOLDING STEEL BOARD 225mm X 38mm x 1.5 mtr | D10: =MRS!G10 -> EA | E10: =MRS!H10 -> 400 | F10: =MRS!I10 -> 46 | G10: =MRS!J10 -> 18400
A11: =ROW(A6) -> 6 | B11: =MRS!B11&" "&MRS!D11 -> SCAFFOLDING STEEL BOARD 225mm X 38mm x 1.0 mtr | D11: =MRS!G11 -> EA | E11: =MRS!H11 -> 500 | F11: =MRS!I11 -> 31 | G11: =MRS!J11 -> 15500
A12: Sub Total Amount | G12: =SUM(G6:G11) -> 120400
A13: VAT 15% | G13: =+G12*0.15 -> 18060
A14: Grand Total in SAR | G14: =G13+G12 -> 138460
A15: =" 1) Above Price are as per your quotation with ref "&'PO 1st page'!K14 -> 1) Above Price are as per your quotation with ref QTN-YATCO-SCAF-000233
A16: 2) Details of each item are attached separately.
A18: Page 2/2
