Workbook

Sheet MRS
A1: ■ Purchase Requisition of Material / Manpower / Equipment Rental / ETC. | J1: DAESHIN PLANT
A2: PJT : SACE2 | D2: Division (In charge Name) : ADMIN MANAGER (Dong Chang Kim) | J2: Subcontract name (SAC2-SC-IK-SMP-01)
A3: MRS No : SAC2-DS-MRS-0505 | E3: =+L3+3 -> 46320 | L3: 46317
A4: No | B4: Item | D4: Specification (Model / Manufacturer / Size) | G4: Unit | H4: Qty | I4: Unit Price (SAR) (Exclude VAT) | J4: Total Price (SAR) (Exclude VAT) | K4: Vendor Name | L4: Remarks
A6: =ROW(A1) -> 1 | B6: Single gas detector | D6: H2S 500ppm T40 ii rattle ISC with calibration certificateS | G6: Nos | H6: 125 | I6: 310 | J6: =H6*I6 -> 38750 | K6: JSAJ | L6: One time
J7: =H7*I7 -> 0
J8: =H8*I8 -> 0
J9: =H9*I9 -> 0
A14: Purpose | I14: Sum | J14: =SUM(J6:J13) -> 38750
A15: * There will be an additional administration expense and financial expense (Depend on contract) deduction of total provision cost price.
O18: SUB-CON | T18: HDEC
O19: In Charge | P19: ADM | Q19: PCM | R19: PM | T19: Construction | U19: Subcon(PC) | V19: Account | Y19: ADM
V20: In Charge | W20: Manager
X22: HEC | Y22: ADM
O44: PROJECT MANAGER | P44: PROJECT MANAGER | S44: ADM
O48: PROJECT MANAGER | P48: PROJECT MANAGER | S48: PCM

Sheet MRS LIST
A1: ■ Purchase Requisition of Equipment Rental | J1: =+MRS!J1 -> DAESHIN PLANT
A2: =+MRS!A2 -> PJT : SACE2 | D2: =+MRS!D2 -> Division (In charge Name) : ADMIN MANAGER (Dong Chang Kim) | J2: =+MRS!J2 -> Subcontract name (SAC2-SC-IK-SMP-01)
A3: =+MRS!A3 -> MRS No : SAC2-DS-MRS-0505 | K3: =+MRS!L3 -> 46317
A4: No | B4: Item | D4: Specification (Model / Manufacturer / Size) | G4: Unit | H4: Q'ty | I4: Unit Price | J4: Total Price | K4: Remarks
A6: =+MRS!A6 -> 1 | B6: =MRS!B6 -> Single gas detector | D6: =MRS!D6 -> H2S 500ppm T40 ii rattle ISC with calibration certificateS | G6: =MRS!G6 -> Nos | H6: =MRS!H6 -> 125 | I6: =MRS!I6 -> 310 | J6: =MRS!J6 -> 38750
B54: =MRS!#REF! -> #REF!
B55: =MRS!#REF! -> #REF!
B56: =MRS!#REF! -> #REF!
B57: =MRS!#REF! -> #REF!
B58: =MRS!B14 -> 0

Sheet PO 1st page
M2: BRANCH OF HYUNDAI ENG. & CONST. CO., LTD.
M3: P. O. Box 77249, Al Khobar 31952
M4: kingdom of Saudi Arabia
B5: C.R. 2051041774 & VAT No.: 300000504500003 | M5: Tel: +966-13-845-1088
M6: Fax: +966-13-845-1099
B9: TO: | C9: JSAJ(Jassim Saif Amer Aljaberi Trading Est.)
C10: CR No. : | D10: 2051247436 | J10: P/O Date: | K10: =MRS!L3 -> 46317
C11: VAT No. : | D11: 311625046900003 | J11: P/O No.: | K11: =SUBSTITUTE(SUBSTITUTE(+MRS!A3," MRS No : ",""),"-MRS","-PO") -> SAC2-DS-PO-0505
C12: In Charge : | D12: Shashank Kamra | J12: (Please mention this No. in
D13: Mobile No. +966 539222074 | J13: All future correspondence)
C14: Building No. 6634, Al Khobar 34423, KSA | J14: Quote Ref. : | K14: Q-20263245
C15: Mobile: +966 539222074 | J15: Date- | K15: 46287
B18: PURCHASE ORDER
B20: WE ARE PLEASED TO PLACE AN ORDER WITH YOU FOR THE GOODS DESCRIBED BELOW. THE ORDER SHALL BE SUBJECT TO THE TERMS AND CONDITIONS SET OUR
B21: BELOW AND ATTACHED. PLEASE SIGN AND RETURN THE ENCLOSED COPY OF THIS ORDER AS CONFIRMATION OF YOUR ACCEPTANCE OF IT WITHIN A WEEK
B22: OTHERWISE THIS ORDER SHALL BE REGARDED AS BEING ACCEPTED BY YOU.
B25: 1 | C25: GOODS
C26: =MRS!$B$6 -> Single gas detector | M26: [Please refer to attached Scope of supply & Quotation for more details]
B28: 2 | C28: P/O AMOUNT
C29: Material Value | E29: : | F29: ='PO 2nd page'!G16 -> 38750
C30: VAT 15% | E30: : | F30: ='PO 2nd page'!G17 -> 5812.5
C31: Total Amount | E31: : | F31: ='PO 2nd page'!G18 -> 44562.5
B33: 3 | C33: PAYMENT TERMS
C34: 100% Payment after Delivery within 35 days with submission of the following Documents.
C35: a) Tax E-Invoice (From Zakat, Tax and Customs Authority)
C36: b) Delivery/Dispatch Note [Counter signed by Site Representative]
B38: 4 | C38: DELIVERY TERMS
C39: Delivery by Seller to Jafurah HYUNDAI Laydown within a Week after receipt of PO.
B41: 5 | C41: OTHER TERMS AND CONDITIONS
C42: a) Any quantity rejected by the Buyer owing to its poor quality and non conformity of specification shall be replaced and re-delivered
C43: by Seller to Buyer at no extra costs
C44: b) Material Certificate, Data Sheet, Safety Data Sheet and other documents which may required by ARAMCO in material receiving
C45: inspection should be submitted to Buyer
C46: c) MTC / MSDS, Others, If required by Client
B48: 6 | C48: CONTACT POINT:
B49: - | C49: Delivery & Payment : Dong Chang Kim / Daeshin Admin. [ Mobile No. : +966 53 748 5762 / Email : kdchjs@daeshinplant.com ]
B50: - | C50: Commercial (Purchaser) : Youngkyu Choi / Daeshin Planning [ Mobile No. : +966 53 952 0931 / Email : ykchoi@daeshinplant.com ]
B51: - | C51: Invoicing : Nehal Kauser / HDEC Purchase PIC [ Mobile No. : +966 50 610 2363 / Email : nehal_kauser@hdec.co.kr ]
B53: 7 | C53: Bank Account Details:
B54: - | C54: ACCOUNT NAME | F54: JASSIM SAIF AMER ALJABERI TRADING EST.
...

Sheet PO 2nd page
A2: PO NO. : | B2: =+'PO 1st page'!K11 -> SAC2-DS-PO-0505 | C2: Scope of Supply
A3: DATE : | B3: =+'PO 1st page'!K10 -> 46317 | E3: Jafurah Utilities, Sulfur and Interconnecting Systems(Pkg-2)
A4: S. NO | B4: DESCRIPTION | D4: UNIT | E4: QTY | F4: ='PO 1st page'!C9 -> JSAJ(Jassim Saif Amer Aljaberi Trading Est.) | H4: Remarks (Details)
F5: Unit Price | G5: Total Amount
A6: =ROW(A1) -> 1 | B6: =MRS!B6&" "&MRS!D6 -> Single gas detector H2S 500ppm T40 ii rattle ISC with calibration certificateS | D6: =MRS!G6 -> Nos | E6: =MRS!H6 -> 125 | F6: =+'MRS LIST'!I6 -> 310 | G6: =+'MRS LIST'!J6 -> 38750 | H6: One time
A16: Sub Total Amount | G16: =SUM(G6:G15) -> 38750
A17: VAT 15% | G17: =+G16*0.15 -> 5812.5
A18: Grand Total in SAR | G18: =G17+G16 -> 44562.5
A19: =" 1) Above Price are as per your quotation with ref "&'PO 1st page'!K14 -> 1) Above Price are as per your quotation with ref Q-20263245
A20: 2) Details of each item are attached separately.
A22: Page 2/2
