Workbook

Sheet MRS
A1: ■ Purchase Requisition of Material / Manpower / Equipment Rental / ETC. | J1: DAESHIN PLANT
A2: PJT : SACE2 | D2: Division (In charge Name) : ADMIN MANAGER (Dong Chang Kim) | J2: Subcontract name (SAC2-SC-IK-SMP-01)
A3: MRS No : SAC2-DS-MRS-0504 | E3: =+L3+3 -> 46323 | L3: 46320
A4: No | B4: Item | D4: Specification (Model / Manufacturer / Size) | G4: Unit | H4: Qty | I4: Unit Price (SAR) (Exclude VAT) | J4: Total Price (SAR) (Exclude VAT) | K4: Vendor Name | L4: Remarks
A6: =ROW(A1) -> 1 | B6: PVC CHAMFER | C6: PVC CHAMFER | D6: 25X25MMX2MTR (50pcs/Bundle) | G6: BNDL | H6: 30 | I6: 81 | J6: =H6*I6 -> 2430 | K6: YATCO | L6: One time
A7: =ROW(A2) -> 2 | B7: TOE FOOT GUARD | C7: TOE FOOT GUARD | G7: PAIR | H7: 50 | I7: 70 | J7: =H7*I7 -> 3500 | K7: - | L7: -
A8: =ROW(A3) -> 3 | B8: ANTI VIBRATION HAND GLOVES | C8: ANTI VIBRATION HAND GLOVES | G8: EA | H8: 100 | I8: 26 | J8: =H8*I8 -> 2600 | K8: - | L8: -
A9: =ROW(A4) -> 4 | B9: INDUSTRIAL PLUG | C9: INDUSTRIAL PLUG | D9: 3PIN 16AMP 220V | G9: EA | H9: 20 | I9: 18 | J9: =H9*I9 -> 360 | K9: - | L9: -
A10: =ROW(A5) -> 5 | B10: HEX PLUG | D10: 1/4" NPT FEMALE BRASS | G10: EA | H10: 50 | I10: 5.85 | J10: =H10*I10 -> 292.5 | K10: - | L10: -
A11: =ROW(A6) -> 6 | B11: REDUCER BUSHING SS(304) | D11: M1/2"XF1/4" NPT | G11: EA | H11: 50 | I11: 8.5 | J11: =H11*I11 -> 425 | K11: - | L11: -
A12: =ROW(A7) -> 7 | B12: EQUAL TEE CS(A105) | D12: 1/2" NPT | G12: EA | H12: 30 | I12: 18 | J12: =H12*I12 -> 540 | K12: - | L12: -
A13: =ROW(A8) -> 8 | B13: ELECTRICAL DRILL MACHINE | D13: 14MM 710W DEWALT WITH TUV | G13: EA | H13: 1 | I13: 1045 | J13: =H13*I13 -> 1045 | K13: - | L13: -
A14: =ROW(A9) -> 9 | B14: DIE GRINDER MACHINE | C14: DIE GRINDER MACHINE | D14: 6MM 450W DEWALT WITH TUV | G14: EA | H14: 1 | I14: 605 | J14: =H14*I14 -> 605 | K14: - | L14: -
A15: =ROW(A10) -> 10 | B15: RAPID GUN TACKER | C15: RAPID GUN TACKER | D15: SUITABLE FOR TYPE 53 STAPLES, 8 MM LEG LENGTH | G15: EA | H15: 5 | I15: 35 | J15: =H15*I15 -> 175 | K15: - | L15: -
A16: =ROW(A11) -> 11 | B16: STAPLE PIN | C16: STAPLE PIN | D16: TYPE 53, 8 MM, 1,000 PCS/PACK | G16: PACK | H16: 5 | I16: 6.75 | J16: =H16*I16 -> 33.75 | K16: - | L16: -
A17: =ROW(A12) -> 12 | B17: Electrical power cable for welding machine | C17: Electrical power cable for welding machine | D17: non-armoured, 4c × 35 mm², flexible stranded copper conductor, epr/rubber insulated, heavy-duty rubber sheathed, 0.6/1 kv | G17: MTR | H17: 200 | I17: 180 | J17: =H17*I17 -> 36000 | K17: - | L17: -
A18: Purpose | I18: Sum | J18: =SUM(J6:J17) -> 48006.25
A19: * There will be an additional administration expense and financial expense (Depend on contract) deduction of total provision cost price.
O22: SUB-CON | T22: HDEC
O23: In Charge | P23: ADM | Q23: PCM | R23: PM | T23: Construction | U23: Subcon(PC) | V23: Account | Y23: ADM
V24: In Charge | W24: Manager
X26: HEC | Y26: ADM
O48: PROJECT MANAGER | P48: PROJECT MANAGER | S48: ADM
O52: PROJECT MANAGER | P52: PROJECT MANAGER | S52: PCM

Sheet MRS LIST
A1: ■ Purchase Requisition of Equipment Rental | J1: =+MRS!J1 -> DAESHIN PLANT
A2: =+MRS!A2 -> PJT : SACE2 | D2: =+MRS!D2 -> Division (In charge Name) : ADMIN MANAGER (Dong Chang Kim) | J2: =+MRS!J2 -> Subcontract name (SAC2-SC-IK-SMP-01)
A3: =+MRS!A3 -> MRS No : SAC2-DS-MRS-0504 | K3: =+MRS!L3 -> 46320
A4: No | B4: Item | D4: Specification (Model / Manufacturer / Size) | G4: Unit | H4: Q'ty | I4: Unit Price | J4: Total Price | K4: Remarks
A6: =+MRS!A6 -> 1 | B6: =MRS!B6 -> PVC CHAMFER | D6: =MRS!D6 -> 25X25MMX2MTR (50pcs/Bundle) | G6: =MRS!G6 -> BNDL | H6: =MRS!H6 -> 30 | I6: =MRS!I6 -> 81 | J6: =MRS!J6 -> 2430
A7: =+MRS!A7 -> 2 | B7: =MRS!B7 -> TOE FOOT GUARD | D7: =MRS!D7 -> 0 | G7: =MRS!G7 -> PAIR | H7: =MRS!H7 -> 50 | I7: =MRS!I7 -> 70 | J7: =MRS!J7 -> 3500
A8: =+MRS!A8 -> 3 | B8: =MRS!B8 -> ANTI VIBRATION HAND GLOVES | D8: =MRS!D8 -> 0 | G8: =MRS!G8 -> EA | H8: =MRS!H8 -> 100 | I8: =MRS!I8 -> 26 | J8: =MRS!J8 -> 2600
A9: =+MRS!A9 -> 4 | B9: =MRS!B9 -> INDUSTRIAL PLUG | D9: =MRS!D9 -> 3PIN 16AMP 220V | G9: =MRS!G9 -> EA | H9: =MRS!H9 -> 20 | I9: =MRS!I9 -> 18 | J9: =MRS!J9 -> 360
A10: =+MRS!A14 -> 9 | B10: =MRS!B10 -> HEX PLUG | D10: =MRS!D10 -> 1/4" NPT FEMALE BRASS | G10: =MRS!G10 -> EA | H10: =MRS!H10 -> 50 | I10: =MRS!I10 -> 5.85 | J10: =MRS!J10 -> 292.5
A11: 6 | B11: =MRS!B11 -> REDUCER BUSHING SS(304) | D11: =MRS!D11 -> M1/2"XF1/4" NPT | G11: =MRS!G11 -> EA | H11: =MRS!H11 -> 50 | I11: =MRS!I11 -> 8.5 | J11: =MRS!J11 -> 425
A12: 7 | B12: =MRS!B12 -> EQUAL TEE CS(A105) | D12: =MRS!D12 -> 1/2" NPT | G12: =MRS!G12 -> EA | H12: =MRS!H12 -> 30 | I12: =MRS!I12 -> 18 | J12: =MRS!J12 -> 540
A13: 8 | B13: =MRS!B13 -> ELECTRICAL DRILL MACHINE | D13: =MRS!D13 -> 14MM 710W DEWALT WITH TUV | G13: =MRS!G13 -> EA | H13: =MRS!H13 -> 1 | I13: =MRS!I13 -> 1045 | J13: =MRS!J13 -> 1045
B14: =MRS!B14 -> DIE GRINDER MACHINE | D14: =MRS!D14 -> 6MM 450W DEWALT WITH TUV | G14: =MRS!G14 -> EA | H14: =MRS!H14 -> 1 | I14: =MRS!I14 -> 605 | J14: =MRS!J14 -> 605
B15: =MRS!B15 -> RAPID GUN TACKER | D15: =MRS!D15 -> SUITABLE FOR TYPE 53 STAPLES, 8 MM LEG LENGTH | G15: =MRS!G15 -> EA | H15: =MRS!H15 -> 5 | I15: =MRS!I15 -> 35 | J15: =MRS!J15 -> 175
B16: =MRS!B16 -> STAPLE PIN | D16: =MRS!D16 -> TYPE 53, 8 MM, 1,000 PCS/PACK | G16: =MRS!G16 -> PACK | H16: =MRS!H16 -> 5 | I16: =MRS!I16 -> 6.75 | J16: =MRS!J16 -> 33.75
B17: =MRS!B17 -> Electrical power cable for welding machine | D17: =MRS!D17 -> non-armoured, 4c × 35 mm², flexible stranded copper conductor, epr/rubber insulated, heavy-duty rubber sheathed, 0.6/1 kv | G17: =MRS!G17 -> MTR | H17: =MRS!H17 -> 200 | I17: =MRS!I17 -> 180 | J17: =MRS!J17 -> 36000

Sheet PO 1st page
M2: BRANCH OF HYUNDAI ENG. & CONST. CO., LTD.
M3: P. O. Box 77249, Al Khobar 31952
M4: kingdom of Saudi Arabia
B5: C.R. 2051041774 & VAT No.: 300000504500003 | M5: Tel: +966-13-845-1088
M6: Fax: +966-13-845-1099
B9: TO: | C9: YATCO(Yaqoot Arabia Trading Company)
C10: CR No. : | D10: 2050187866 | J10: P/O Date: | K10: =MRS!L3 -> 46320
C11: VAT No. : | D11: 312249720500003 | J11: P/O No.: | K11: =SUBSTITUTE(SUBSTITUTE(+MRS!A3," MRS No : ",""),"-MRS","-PO") -> SAC2-DS-PO-0504
C12: In Charge : | D12: Haris | J12: (Please mention this No. in
D13: Mobile No. +966 565731662 | J13: All future correspondence)
C14: Abu Bakr Al-Razi Street Near Dharhan - Jubail Highway, Dammam 34223 | J14: Quote Ref. : | K14: QT-C26-150797
C15: Mobile: +966 565731662 | J15: Date- | K15: 46310
B18: PURCHASE ORDER
B20: WE ARE PLEASED TO PLACE AN ORDER WITH YOU FOR THE GOODS DESCRIBED BELOW. THE ORDER SHALL BE SUBJECT TO THE TERMS AND CONDITIONS SET OUR
B21: BELOW AND ATTACHED. PLEASE SIGN AND RETURN THE ENCLOSED COPY OF THIS ORDER AS CONFIRMATION OF YOUR ACCEPTANCE OF IT WITHIN A WEEK
B22: OTHERWISE THIS ORDER SHALL BE REGARDED AS BEING ACCEPTED BY YOU.
B25: 1 | C25: GOODS
C26: Site Material & Tools | M26: [Please refer to attached Scope of supply & Quotation for more details]
B28: 2 | C28: P/O AMOUNT
C29: Material Value | E29: : | F29: ='PO 2nd page'!G18 -> 48006.25
C30: VAT 15% | E30: : | F30: ='PO 2nd page'!G19 -> 7200.9375
C31: Total Amount | E31: : | F31: ='PO 2nd page'!G20 -> 55207.188
B33: 3 | C33: PAYMENT TERMS
C34: 100% Payment after Delivery within 35 days with submission of the following Documents.
C35: a) Tax E-Invoice (From Zakat, Tax and Customs Authority)
C36: b) Delivery/Dispatch Note [Counter signed by Site Representative]
B38: 4 | C38: DELIVERY TERMS
C39: Delivery by Seller to Jafurah HYUNDAI Laydown within a Week after receipt of PO.
B41: 5 | C41: OTHER TERMS AND CONDITIONS
C42: a) Any quantity rejected by the Buyer owing to its poor quality and non conformity of specification shall be replaced and re-delivered
C43: by Seller to Buyer at no extra costs
C44: b) Material Certificate, Data Sheet, Safety Data Sheet and other documents which may required by ARAMCO in material receiving
C45: inspection should be submitted to Buyer
C46: c) MTC / MSDS, Others, If required by Client
B48: 6 | C48: CONTACT POINT:
B49: - | C49: Delivery & Payment : Dong Chang Kim / Daeshin Admin. [ Mobile No. : +966 53 748 5762 / Email : kdchjs@daeshinplant.com ]
B50: - | C50: Commercial (Purchaser) : Youngkyu Choi / Daeshin Planning [ Mobile No. : +966 53 952 0931 / Email : ykchoi@daeshinplant.com ]
B51: - | C51: Invoicing : Nehal Kauser / HDEC Purchase PIC [ Mobile No. : +966 50 610 2363 / Email : nehal_kauser@hdec.co.kr ]
B53: 7 | C53: Bank Account Details:
B54: - | C54: ACCOUNT NAME | F54: YAQOT ALARBYH COMPANY | P54: =UPPER(F54) -> YAQOT ALARBYH COMPANY
...

Sheet PO 2nd page
A2: PO NO. : | B2: =+'PO 1st page'!K11 -> SAC2-DS-PO-0504 | C2: Scope of Supply
A3: DATE : | B3: =+'PO 1st page'!K10 -> 46320 | E3: Jafurah Utilities, Sulfur and Interconnecting Systems(Pkg-2)
A4: S. NO | B4: DESCRIPTION | D4: UNIT | E4: QTY | F4: ='PO 1st page'!C9 -> YATCO(Yaqoot Arabia Trading Company) | H4: Remarks (Details)
F5: Unit Price | G5: Total Amount
A6: =ROW(A1) -> 1 | B6: =MRS!B6 &MRS!D6 -> PVC CHAMFER 25X25MMX2MTR (50pcs/Bundle) | D6: =MRS!G6 -> BNDL | E6: =MRS!H6 -> 30 | F6: =MRS!I6 -> 81 | G6: =MRS!J6 -> 2430 | H6: One time
A7: =ROW(A2) -> 2 | B7: =MRS!B7 &MRS!D7 -> TOE FOOT GUARD | D7: =MRS!G7 -> PAIR | E7: =MRS!H7 -> 50 | F7: =MRS!I7 -> 70 | G7: =MRS!J7 -> 3500 | H7: -
A8: =ROW(A3) -> 3 | B8: =MRS!B8 &MRS!D8 -> ANTI VIBRATION HAND GLOVES | D8: =MRS!G8 -> EA | E8: =MRS!H8 -> 100 | F8: =MRS!I8 -> 26 | G8: =MRS!J8 -> 2600 | H8: -
A9: =ROW(A4) -> 4 | B9: =MRS!B9 &MRS!D9 -> INDUSTRIAL PLUG 3PIN 16AMP 220V | D9: =MRS!G9 -> EA | E9: =MRS!H9 -> 20 | F9: =MRS!I9 -> 18 | G9: =MRS!J9 -> 360 | H9: -
A10: =ROW(A5) -> 5 | B10: =MRS!B10 &MRS!D10 -> HEX PLUG1/4" NPT FEMALE BRASS | D10: =MRS!G10 -> EA | E10: =MRS!H10 -> 50 | F10: =MRS!I10 -> 5.85 | G10: =MRS!J10 -> 292.5 | H10: -
A11: 6 | B11: =MRS!B11 &MRS!D11 -> REDUCER BUSHING SS(304)M1/2"XF1/4" NPT | D11: =MRS!G11 -> EA | E11: =MRS!H11 -> 50 | F11: =MRS!I11 -> 8.5 | G11: =MRS!J11 -> 425 | H11: -
A12: 7 | B12: =MRS!B12 &MRS!D12 -> EQUAL TEE CS(A105)1/2" NPT | D12: =MRS!G12 -> EA | E12: =MRS!H12 -> 30 | F12: =MRS!I12 -> 18 | G12: =MRS!J12 -> 540 | H12: -
A13: 8 | B13: =MRS!B13 &MRS!D13 -> ELECTRICAL DRILL MACHINE 14MM 710W DEWALT WITH TUV | D13: =MRS!G13 -> EA | E13: =MRS!H13 -> 1 | F13: =MRS!I13 -> 1045 | G13: =MRS!J13 -> 1045 | H13: -
A14: 9 | B14: =MRS!B14 &MRS!D14 -> DIE GRINDER MACHINE 6MM 450W DEWALT WITH TUV | D14: =MRS!G14 -> EA | E14: =MRS!H14 -> 1 | F14: =MRS!I14 -> 605 | G14: =MRS!J14 -> 605 | H14: -
A15: 10 | B15: =MRS!B15 &MRS!D15 -> RAPID GUN TACKERSUITABLE FOR TYPE 53 STAPLES, 8 MM LEG LENGTH | D15: =MRS!G15 -> EA | E15: =MRS!H15 -> 5 | F15: =MRS!I15 -> 35 | G15: =MRS!J15 -> 175 | H15: -
A16: 11 | B16: =MRS!B16 &MRS!D16 -> STAPLE PINTYPE 53, 8 MM, 1,000 PCS/PACK | D16: =MRS!G16 -> PACK | E16: =MRS!H16 -> 5 | F16: =MRS!I16 -> 6.75 | G16: =MRS!J16 -> 33.75 | H16: -
A17: 12 | B17: =MRS!B17 &MRS!D17 -> Electrical power cable for welding machinenon-armoured, 4c × 35 mm², flexible stranded copper conductor, epr/rubber insulated, heavy-duty rubber sheathed, 0.6/1 kv | D17: =MRS!G17 -> MTR | E17: =MRS!H17 -> 200 | G17: =MRS!J17 -> 36000 | H17: -
A18: Sub Total Amount | G18: =SUM(G6:G17) -> 48006.25
A19: VAT 15% | G19: =+G18*0.15 -> 7200.9375
A20: Grand Total in SAR | G20: =G19+G18 -> 55207.188
A21: =" 1) Above Price are as per your quotation with ref "&'PO 1st page'!K14 -> 1) Above Price are as per your quotation with ref QT-C26-150797
A22: 2) Details of each item are attached separately.
A24: Page 2/2
