Workbook

Sheet MRS
A1: ■ Purchase Requisition of Material / Manpower / Equipment Rental / ETC. | J1: DAESHIN PLANT
A2: PJT : SACE2 | D2: Division (In charge Name) : ADMIN MANAGER (Dong Chang Kim) | J2: Subcontract name (SAC2-SC-IK-SMP-01)
A3: MRS No : SAC2-DS-MRS-0500 | E3: =+L3+3 -> 46322 | L3: 46319
A4: No | B4: Item | D4: Specification (Model / Manufacturer / Size) | G4: Unit | H4: Qty | I4: Unit Price (SAR) (Exclude VAT) | J4: Total Price (SAR) (Exclude VAT) | K4: Vendor Name | L4: Remarks
A6: 1 | B6: 3M HALF FACE MASK - 6200 | C6: 3M HALF FACE MASK - 6200 | G6: EA | H6: 64 | I6: 55 | J6: =H6*I6 -> 3520 | K6: FORTUNE | L6: ONE TIME
A7: 2 | B7: SILICON SEALANT WHITE (24PCS/BOX) | C7: SILICON SEALANT WHITE (24PCS/BOX) | G7: BOX | H7: 18 | I7: 96 | J7: =H7*I7 -> 1728 | K7: - | L7: -
A8: 3 | B8: KNIFE BLADE SHORT (10PCS/PACK) | C8: KNIFE BLADE SHORT (10PCS/PACK) | G8: PACK | H8: 50 | I8: 8 | J8: =H8*I8 -> 400 | K8: - | L8: -
A9: 4 | B9: FILE HALF ROUND 12" | C9: FILE HALF ROUND 12" | G9: EA | H9: 10 | I9: 22 | J9: =H9*I9 -> 220 | K9: - | L9: -
A10: 5 | B10: ELECTRICAL TAPE 50FT GREEN | C10: ELECTRICAL TAPE 50FT GREEN | G10: ROLL | H10: 200 | I10: 2.5 | J10: =H10*I10 -> 500 | K10: - | L10: -
A11: 6 | B11: CLEAR TAPE 2" 70YARD (30PCS/BOX) VESTRA | C11: CLEAR TAPE 2" 70YARD (30PCS/BOX) VESTRA | G11: ROLL | H11: 30 | I11: 4 | J11: =H11*I11 -> 120 | K11: - | L11: -
A12: 7 | B12: HACK SAW BLADE 24T CS | C12: HACK SAW BLADE 24T CS | G12: EA | H12: 200 | I12: 1.2 | J12: =H12*I12 -> 240 | K12: - | L12: -
A13: 8 | B13: SAND PAPER ROLL 4'' 120GRIT | C13: SAND PAPER ROLL 4'' 120GRIT | G13: ROLL | H13: 5 | I13: 130 | J13: =H13*I13 -> 650 | K13: - | L13: -
A14: 9 | B14: WRAPPING ROLL 3.5KG VESTRA | C14: WRAPPING ROLL 3.5KG VESTRA | G14: ROLL | H14: 45 | I14: 32 | J14: =H14*I14 -> 1440 | K14: - | L14: -
A15: 10 | B15: ELECTRICAL TAPE 50FT RED | C15: ELECTRICAL TAPE 50FT RED | G15: ROLL | H15: 400 | I15: 2.5 | J15: =H15*I15 -> 1000 | K15: - | L15: -
A16: 11 | B16: MASKING TAPE 2'' 25 YARD (24ROLL/BOX) | C16: MASKING TAPE 2'' 25 YARD (24ROLL/BOX) | G16: BOX | H16: 154 | I16: 75 | J16: =H16*I16 -> 11550 | K16: - | L16: -
A17: 12 | B17: MASKING TAPE 1'' 18 YARD (36ROLL/BOX) | C17: MASKING TAPE 1'' 18 YARD (36ROLL/BOX) | G17: BOX | H17: 16 | I17: 70 | J17: =H17*I17 -> 1120 | K17: - | L17: -
... A44: 39 | B44: PAINT BRUSH 3" (12PCS/BOX) | C44: PAINT BRUSH 3" (12PCS/BOX) | G44: PCS | H44: 24 | I44: 4 | J44: =H44*I44 -> 96 | K44: - | L44: -
A45: Purpose | I45: Sum | J45: =SUM(J6:J44) -> 124889.5
A46: * There will be an additional administration expense and financial expense (Depend on contract) deduction of total provision cost price.
O49: SUB-CON | T49: HDEC
O50: In Charge | P50: ADM | Q50: PCM | R50: PM | T50: Construction | U50: Subcon(PC) | V50: Account | Y50: ADM
V51: In Charge | W51: Manager
X53: HEC | Y53: ADM
T69: PROJECT MANAGER
O75: PROJECT MANAGER | P75: PROJECT MANAGER | Q75: PROJECT MANAGER | T75: PCM | U75: ADM | V75: PROJECT MANAGER
O79: PROJECT MANAGER | P79: PROJECT MANAGER | Q79: PROJECT MANAGER | T79: ADM | U79: PCM | V79: PROJECT MANAGER

Sheet MRS LIST
A1: ■ Purchase Requisition of Equipment Rental | J1: =+MRS!J1 -> DAESHIN PLANT
A2: =+MRS!A2 -> PJT : SACE2 | D2: =+MRS!D2 -> Division (In charge Name) : ADMIN MANAGER (Dong Chang Kim) | J2: =+MRS!J2 -> Subcontract name (SAC2-SC-IK-SMP-01)
A3: =+MRS!A3 -> MRS No : SAC2-DS-MRS-0500 | K3: =+MRS!L3 -> 46319
A4: No | B4: Item | D4: Specification (Model / Manufacturer / Size) | G4: Unit | H4: Q'ty | I4: Unit Price | J4: Total Price | K4: Remarks
A6: 1 | B6: =MRS!B6 & MRS!D6 -> 3M HALF FACE MASK - 6200 | D6: =MRS!D20 -> 0 | G6: =MRS!G6 -> EA | H6: =MRS!H6 -> 64 | I6: =MRS!I6 -> 55 | J6: =MRS!J6 -> 3520
A7: 2 | B7: =MRS!B7 & MRS!D7 -> SILICON SEALANT WHITE (24PCS/BOX) | D7: =MRS!D21 -> 0 | G7: =MRS!G7 -> BOX | H7: =MRS!H7 -> 18 | I7: =MRS!I7 -> 96 | J7: =MRS!J7 -> 1728
A8: 3 | B8: =MRS!B8 & MRS!D8 -> KNIFE BLADE SHORT (10PCS/PACK) | D8: =MRS!D22 -> 0 | G8: =MRS!G8 -> PACK | H8: =MRS!H8 -> 50 | I8: =MRS!I8 -> 8 | J8: =MRS!J8 -> 400
A9: 4 | B9: =MRS!B9 & MRS!D9 -> FILE HALF ROUND 12" | D9: =MRS!D23 -> 0 | G9: =MRS!G9 -> EA | H9: =MRS!H9 -> 10 | I9: =MRS!I9 -> 22 | J9: =MRS!J9 -> 220
A10: 5 | B10: =MRS!B10 & MRS!D10 -> ELECTRICAL TAPE 50FT GREEN | D10: =MRS!D24 -> 0 | G10: =MRS!G10 -> ROLL | H10: =MRS!H10 -> 200 | I10: =MRS!I10 -> 2.5 | J10: =MRS!J10 -> 500
A11: 6 | B11: =MRS!B11 & MRS!D11 -> CLEAR TAPE 2" 70YARD (30PCS/BOX) VESTRA | D11: =MRS!D25 -> 0 | G11: =MRS!G11 -> ROLL | H11: =MRS!H11 -> 30 | I11: =MRS!I11 -> 4 | J11: =MRS!J11 -> 120
A12: 7 | B12: =MRS!B12 & MRS!D12 -> HACK SAW BLADE 24T CS | D12: =MRS!D26 -> 0 | G12: =MRS!G12 -> EA | H12: =MRS!H12 -> 200 | I12: =MRS!I12 -> 1.2 | J12: =MRS!J12 -> 240
A13: 8 | B13: =MRS!B13 & MRS!D13 -> SAND PAPER ROLL 4'' 120GRIT | D13: =MRS!D27 -> 0 | G13: =MRS!G13 -> ROLL | H13: =MRS!H13 -> 5 | I13: =MRS!I13 -> 130 | J13: =MRS!J13 -> 650
A14: 9 | B14: =MRS!B14 & MRS!D14 -> WRAPPING ROLL 3.5KG VESTRA | D14: =MRS!D28 -> 0 | G14: =MRS!G14 -> ROLL | H14: =MRS!H14 -> 45 | I14: =MRS!I14 -> 32 | J14: =MRS!J14 -> 1440
A15: 10 | B15: =MRS!B15 & MRS!D15 -> ELECTRICAL TAPE 50FT RED | D15: =MRS!D29 -> 0 | G15: =MRS!G15 -> ROLL | H15: =MRS!H15 -> 400 | I15: =MRS!I15 -> 2.5 | J15: =MRS!J15 -> 1000
A16: 11 | B16: =MRS!B16 & MRS!D16 -> MASKING TAPE 2'' 25 YARD (24ROLL/BOX) | D16: =MRS!D30 -> 0 | G16: =MRS!G16 -> BOX | H16: =MRS!H16 -> 154 | I16: =MRS!I16 -> 75 | J16: =MRS!J16 -> 11550
A17: 12 | B17: =MRS!B17 & MRS!D17 -> MASKING TAPE 1'' 18 YARD (36ROLL/BOX) | D17: =MRS!D31 -> 0 | G17: =MRS!G17 -> BOX | H17: =MRS!H17 -> 16 | I17: =MRS!I17 -> 70 | J17: =MRS!J17 -> 1120
... A44: 39 | B44: =MRS!B44 & MRS!D44 -> PAINT BRUSH 3" (12PCS/BOX) | D44: =MRS!D58 -> 0 | G44: =MRS!G44 -> PCS | H44: =MRS!H44 -> 24 | I44: =MRS!I44 -> 4 | J44: =MRS!J44 -> 96
A45: 52
A46: 53
A47: 54
A48: 55
A49: 56
A50: 57
A51: 58
A52: 59
A53: 60
A54: 61
A55: 62
A56: 63

Sheet PO 1st page
M2: HYUNDAI ENG. & CONST. CO., LTD.
M3: P. O. Box 77249, Al Khobar 31952
M4: kingdom of Saudi Arabia
B5: C.R. 2051041774 & VAT No.: 300000504500003 | M5: Tel: +966-13-845-1088
M6: Fax: +966-13-845-1099
B9: TO: | C9: FATC(fortune Arabia Trading Company)
C10: CR No. : | D10: 2055015214 | J10: P/O Date: | K10: =MRS!L3 -> 46319
C11: VAT No. : | D11: 311334180900003 | J11: P/O No.: | K11: =SUBSTITUTE(SUBSTITUTE(+MRS!A3," MRS No : ",""),"-MRS","-PO") -> SAC2-DS-PO-0500
C12: In Charge : | D12: Abdul Hafeez | J12: (Please mention this No. in
D13: +966 58 146 3761/ Email:fatrading.ksa@gmail.com | J13: All future correspondence)
C14: P.O. Box 36602 Jubail 31961 Kingdom of Saudi Arabia | J14: Quote Ref. : | K14: FACT/2026027
C15: Landline : +99 13 344 4644. : Mobile : +966 58 146 3761 | J15: Date- | K15: 46312
B18: PURCHASE ORDER
B20: WE ARE PLEASED TO PLACE AN ORDER WITH YOU FOR THE GOODS DESCRIBED BELOW. THE ORDER SHALL BE SUBJECT TO THE TERMS AND CONDITIONS SET OUR
B21: BELOW AND ATTACHED. PLEASE SIGN AND RETURN THE ENCLOSED COPY OF THIS ORDER AS CONFIRMATION OF YOUR ACCEPTANCE OF IT WITHIN A WEEK
B22: OTHERWISE THIS ORDER SHALL BE REGARDED AS BEING ACCEPTED BY YOU.
B25: 1 | C25: GOODS
C26: =MRS!B6 -> 3M HALF FACE MASK - 6200 | M26: [Please refer to attached Scope of supply & Quotation for more details]
B28: 2 | C28: P/O AMOUNT
C29: Material Value | E29: : | F29: ='PO 2nd page'!G45 -> 124889.5
C30: VAT 15% | E30: : | F30: ='PO 2nd page'!G46 -> 18733.425
C31: Total Amount | E31: : | F31: ='PO 2nd page'!G47 -> 143622.92
B33: 3 | C33: PAYMENT TERMS
C34: 100% Payment after Delivery within 35 days with submission of the following Documents.
C35: a) Tax E-Invoice (From Zakat, Tax and Customs Authority)
C36: b) Delivery/Dispatch Note [Counter signed by Site Representative]
B38: 4 | C38: DELIVERY TERMS
C39: Delivery by Seller to Jafurah HYUNDAI Laydown within a Week after receipt of PO.
B41: 5 | C41: OTHER TERMS AND CONDITIONS
C42: a) Any quantity rejected by the Buyer owing to its poor quality and non conformity of specification shall be replaced and re-delivered
C43: by Seller to Buyer at no extra costs
C44: b) Material Certificate, Data Sheet, Safety Data Sheet and other documents which may required by ARAMCO in material receiving
C45: inspection should be submitted to Buyer
C46: c) MTC / MSDS, Others, If required by Client
B48: 6 | C48: CONTACT POINT:
B49: - | C49: Delivery & Payment : Dong Chang Kim / Daeshin Admin. [ Mobile No. : +966 53 748 5762 / Email : kdchjs@daeshinplant.com ]
B50: - | C50: Commercial (Purchaser) : Youngkyu Choi / Daeshin Planning [ Mobile No. : +966 53 952 0931 / Email : ykchoi@daeshinplant.com ]
B51: - | C51: Invoicing : Nehal Kauser / HDEC Purchase PIC [ Mobile No. : +966 50 610 2363 / Email : nehal_kauser@hdec.co.kr ]
B53: 7 | C53: Bank Account Details:
B54: - | C54: ACCOUNT NAME | F54: FORTUNE ARABIA BANK COMPANY | P54: =UPPER(F54) -> FORTUNE ARABIA BANK COMPANY
...

Sheet PO 2nd page
A2: PO NO. : | B2: =+'PO 1st page'!K11 -> SAC2-DS-PO-0500 | C2: Scope of Supply
A3: DATE : | B3: =+'PO 1st page'!K10 -> 46319 | E3: Jafurah Utilities, Sulfur and Interconnecting Systems(Pkg-2)
A4: S. NO | B4: DESCRIPTION | D4: UNIT | E4: QTY | F4: ='PO 1st page'!C9 -> FATC(fortune Arabia Trading Company) | H4: Remarks (Details)
F5: Unit Price | G5: Total Amount
A6: =ROW(A1) -> 1 | B6: =MRS!B6 -> 3M HALF FACE MASK - 6200 | D6: =+'MRS LIST'!G6 -> EA | E6: =+'MRS LIST'!H6 -> 64 | F6: =+'MRS LIST'!I6 -> 55 | G6: =+'MRS LIST'!J6 -> 3520
A7: =ROW(A2) -> 2 | B7: =MRS!B7 -> SILICON SEALANT WHITE (24PCS/BOX) | D7: =+'MRS LIST'!G7 -> BOX | E7: =+'MRS LIST'!H7 -> 18 | F7: =+'MRS LIST'!I7 -> 96 | G7: =+'MRS LIST'!J7 -> 1728
A8: =ROW(A3) -> 3 | B8: =MRS!B8 -> KNIFE BLADE SHORT (10PCS/PACK) | D8: =+'MRS LIST'!G8 -> PACK | E8: =+'MRS LIST'!H8 -> 50 | F8: =+'MRS LIST'!I8 -> 8 | G8: =+'MRS LIST'!J8 -> 400
A9: =ROW(A4) -> 4 | B9: =MRS!B9 -> FILE HALF ROUND 12" | D9: =+'MRS LIST'!G9 -> EA | E9: =+'MRS LIST'!H9 -> 10 | F9: =+'MRS LIST'!I9 -> 22 | G9: =+'MRS LIST'!J9 -> 220
A10: =ROW(A5) -> 5 | B10: =MRS!B10 -> ELECTRICAL TAPE 50FT GREEN | D10: =+'MRS LIST'!G10 -> ROLL | E10: =+'MRS LIST'!H10 -> 200 | F10: =+'MRS LIST'!I10 -> 2.5 | G10: =+'MRS LIST'!J10 -> 500
A11: =ROW(A6) -> 6 | B11: =MRS!B11 -> CLEAR TAPE 2" 70YARD (30PCS/BOX) VESTRA | D11: =+'MRS LIST'!G11 -> ROLL | E11: =+'MRS LIST'!H11 -> 30 | F11: =+'MRS LIST'!I11 -> 4 | G11: =+'MRS LIST'!J11 -> 120
A12: =ROW(A7) -> 7 | B12: =MRS!B12 -> HACK SAW BLADE 24T CS | D12: =+'MRS LIST'!G12 -> EA | E12: =+'MRS LIST'!H12 -> 200 | F12: =+'MRS LIST'!I12 -> 1.2 | G12: =+'MRS LIST'!J12 -> 240
A13: =ROW(A8) -> 8 | B13: =MRS!B13 -> SAND PAPER ROLL 4'' 120GRIT | D13: =+'MRS LIST'!G13 -> ROLL | E13: =+'MRS LIST'!H13 -> 5 | F13: =+'MRS LIST'!I13 -> 130 | G13: =+'MRS LIST'!J13 -> 650
A14: =ROW(A9) -> 9 | B14: =MRS!B14 -> WRAPPING ROLL 3.5KG VESTRA | D14: =+'MRS LIST'!G14 -> ROLL | E14: =+'MRS LIST'!H14 -> 45 | F14: =+'MRS LIST'!I14 -> 32 | G14: =+'MRS LIST'!J14 -> 1440
A15: =ROW(A10) -> 10 | B15: =MRS!B15 -> ELECTRICAL TAPE 50FT RED | D15: =+'MRS LIST'!G15 -> ROLL | E15: =+'MRS LIST'!H15 -> 400 | F15: =+'MRS LIST'!I15 -> 2.5 | G15: =+'MRS LIST'!J15 -> 1000
A16: =ROW(A11) -> 11 | B16: =MRS!B16 -> MASKING TAPE 2'' 25 YARD (24ROLL/BOX) | D16: =+'MRS LIST'!G16 -> BOX | E16: =+'MRS LIST'!H16 -> 154 | F16: =+'MRS LIST'!I16 -> 75 | G16: =+'MRS LIST'!J16 -> 11550
A17: =ROW(A12) -> 12 | B17: =MRS!B17 -> MASKING TAPE 1'' 18 YARD (36ROLL/BOX) | D17: =+'MRS LIST'!G17 -> BOX | E17: =+'MRS LIST'!H17 -> 16 | F17: =+'MRS LIST'!I17 -> 70 | G17: =+'MRS LIST'!J17 -> 1120
... A44: =ROW(A39) -> 39 | B44: =MRS!B44 -> PAINT BRUSH 3" (12PCS/BOX) | D44: =+'MRS LIST'!G44 -> PCS | E44: =+'MRS LIST'!H44 -> 24 | F44: =+'MRS LIST'!I44 -> 4 | G44: =+'MRS LIST'!J44 -> 96
A45: Sub Total Amount | G45: =SUM(G6:G44) -> 124889.5
A46: VAT 15% | G46: =+G45*0.15 -> 18733.425
A47: Grand Total in SAR | G47: =G46+G45 -> 143622.92
A48: =" 1) Above Price are as per your quotation with ref "&'PO 1st page'!K14 -> 1) Above Price are as per your quotation with ref FACT/2026027
A49: 2) Details of each item are attached separately.
A51: Page 2/2
