Workbook

Sheet MRS
A1: ■ Purchase Requisition of Material / Manpower / Equipment Rental / ETC. | J1: DAESHIN PLANT
A2: PJT : SACE2 | D2: Division (In charge Name) : ADMIN MANAGER (Dong Chang Kim) | J2: Subcontract name (SAC2-SC-IK-SMP-01)
A3: MRS No : SAC2-DS-MRS-0055 | E3: =+L3 -> 45780 | L3: 45780
A4: No | B4: Item | D4: Specification (Model / Manufacturer / Size) | G4: Unit | H4: Qty | I4: Unit Price (SAR) (Exclude VAT) | J4: Total Price (SAR) (Exclude VAT) | K4: Vendor Name | L4: Remarks
A6: =ROW(A1) -> 1 | B6: H-Beam CS | D6: 100x100x6x8, 12m | G6: EA | H6: 30 | I6: 800 | J6: =H6*I6 -> 24000 | K6: JSAJ
A7: =ROW(A2) -> 2 | B7: H-Beam CS | D7: 100x100x6x8, 12m | G7: EA | H7: 5 | I7: 800 | J7: =H7*I7 -> 4000
A8: =ROW(A3) -> 3 | B8: H-Beam CS | D8: 150x150x7x10, 12m | G8: EA | H8: 10 | I8: 1480 | J8: =H8*I8 -> 14800 | P8: s
A9: =ROW(A4) -> 4 | B9: Channel CS | D9: 100x50x5x7.5, 6m | G9: EA | H9: 10 | I9: 198 | J9: =H9*I9 -> 1980
A10: =ROW(A5) -> 5 | B10: Angle Bar CS | D10: 75x75x6, 6m | G10: EA | H10: 5 | I10: 145 | J10: =H10*I10 -> 725
A11: =ROW(A6) -> 6 | B11: Angle Bar CS | D11: 50x50x5, 6m | G11: EA | H11: 10 | I11: 77 | J11: =H11*I11 -> 770
A12: =ROW(A7) -> 7 | B12: Angle Bar CS | D12: 50x50x4, 6m | G12: EA | H12: 100 | I12: 62 | J12: =H12*I12 -> 6200
A13: =ROW(A8) -> 8 | B13: Rectangle Bar CS | D13: 80x40x3, 6m | G13: EA | H13: 50 | I13: 118.9 | J13: =H13*I13 -> 5945
A14: =ROW(A9) -> 9 | B14: Rectangle Bar CS | D14: 50x25x3, 6m | G14: EA | H14: 50 | I14: 76 | J14: =H14*I14 -> 3800
A15: =ROW(A10) -> 10 | B15: Rectangle Bar CS | D15: 40x40x3, 6m | G15: EA | H15: 10 | I15: 81 | J15: =H15*I15 -> 810
A16: =ROW(A11) -> 11 | B16: Rectangle Bar CS | D16: 20x20x2, 6m | G16: EA | H16: 120 | I16: 26.5 | J16: =H16*I16 -> 3180
A17: =ROW(A12) -> 12 | B17: Steel Plate CS | D17: 4'x8', 3t | G17: EA | H17: 30 | I17: 250 | J17: =H17*I17 -> 7500
A18: =ROW(A13) -> 13 | B18: Steel Plate CS | D18: 4'x8', 3t | G18: EA | H18: 8 | I18: 250 | J18: =H18*I18 -> 2000
A19: =ROW(A14) -> 14 | B19: Corrugated Sheet | D19: 1X3MX0.32mm | G19: EA | H19: 100 | I19: 47 | J19: =H19*I19 -> 4700
A20: =ROW(A15) -> 15 | B20: Pipe | D20: A106-B 1/2" S160(4.78t) 6m | G20: EA | H20: 1 | I20: 190 | J20: =H20*I20 -> 190
A21: =ROW(A16) -> 16 | B21: Ordinary plywood | D21: 4'x8', 12t , Indonesia | G21: EA | H21: 50 | I21: 98 | J21: =H21*I21 -> 4900
A22: Purpose | I22: Sum | J22: =SUM(J6:J21) -> 85500
A23: * There will be an additional administration expense and financial expense (Depend on contract) deduction of total provision cost price.
S24: HEC | T24: PCM | U24: ADM | V24: PM
T26: / | U26: / | V26: /
O27: Requesting | P27: JV Area PIC | Q27: PCM (Subcon)
O28: Company | S28: HDEC | T28: PCM | U28: ADM | V28: PM
O30: / | P30: / | Q30: / | T30: / | U30: / | V30: /
T46: PROJECT MANAGER
O52: PROJECT MANAGER | P52: PROJECT MANAGER | Q52: PROJECT MANAGER | T52: PCM | U52: ADM | V52: PROJECT MANAGER
O56: PROJECT MANAGER | P56: PROJECT MANAGER | Q56: PROJECT MANAGER | T56: ADM | U56: PCM | V56: PROJECT MANAGER

Sheet MRS LIST
A1: ■ Purchase Requisition of Equipment Rental | J1: =+MRS!J1 -> DAESHIN PLANT
A2: =+MRS!A2 -> PJT : SACE2 | D2: =+MRS!D2 -> Division (In charge Name) : ADMIN MANAGER (Dong Chang Kim) | J2: =+MRS!J2 -> Subcontract name (SAC2-SC-IK-SMP-01)
A3: =+MRS!A3 -> MRS No : SAC2-DS-MRS-0055 | K3: =+MRS!L3 -> 45780
A4: No | B4: Item | D4: Specification (Model / Manufacturer / Size) | G4: Unit | H4: Q'ty | I4: Unit Price | J4: Total Price | K4: Remarks
A6: =+MRS!A6 -> 1 | B6: =MRS!B6 -> H-Beam CS | D6: =MRS!D6 -> 100x100x6x8, 12m | G6: =MRS!G6 -> EA | H6: =MRS!H6 -> 30 | I6: =MRS!I6 -> 800 | J6: =MRS!J6 -> 24000
A7: =+MRS!A7 -> 2 | B7: =MRS!B7 -> H-Beam CS | D7: =MRS!D7 -> 100x100x6x8, 12m | G7: =MRS!G7 -> EA | H7: =MRS!H7 -> 5 | I7: =MRS!I7 -> 800 | J7: =MRS!J7 -> 4000
A8: =+MRS!A8 -> 3 | B8: =MRS!B8 -> H-Beam CS | D8: =MRS!D8 -> 150x150x7x10, 12m | G8: =MRS!G8 -> EA | H8: =MRS!H8 -> 10 | I8: =MRS!I8 -> 1480 | J8: =MRS!J8 -> 14800
A9: =+MRS!A9 -> 4 | B9: =MRS!B9 -> Channel CS | D9: =MRS!D9 -> 100x50x5x7.5, 6m | G9: =MRS!G9 -> EA | H9: =MRS!H9 -> 10 | I9: =MRS!I9 -> 198 | J9: =MRS!J9 -> 1980
A10: =+MRS!A10 -> 5 | B10: =MRS!B10 -> Angle Bar CS | D10: =MRS!D10 -> 75x75x6, 6m | G10: =MRS!G10 -> EA | H10: =MRS!H10 -> 5 | I10: =MRS!I10 -> 145 | J10: =MRS!J10 -> 725
A11: =+MRS!A11 -> 6 | B11: =MRS!B11 -> Angle Bar CS | D11: =MRS!D11 -> 50x50x5, 6m | G11: =MRS!G11 -> EA | H11: =MRS!H11 -> 10 | I11: =MRS!I11 -> 77 | J11: =MRS!J11 -> 770
A12: =+MRS!A12 -> 7 | B12: =MRS!B12 -> Angle Bar CS | D12: =MRS!D12 -> 50x50x4, 6m | G12: =MRS!G12 -> EA | H12: =MRS!H12 -> 100 | I12: =MRS!I12 -> 62 | J12: =MRS!J12 -> 6200
A13: =+MRS!A13 -> 8 | B13: =MRS!B13 -> Rectangle Bar CS | D13: =MRS!D13 -> 80x40x3, 6m | G13: =MRS!G13 -> EA | H13: =MRS!H13 -> 50 | I13: =MRS!I13 -> 118.9 | J13: =MRS!J13 -> 5945
A14: =+MRS!A14 -> 9 | B14: =MRS!B14 -> Rectangle Bar CS | D14: =MRS!D14 -> 50x25x3, 6m | G14: =MRS!G14 -> EA | H14: =MRS!H14 -> 50 | I14: =MRS!I14 -> 76 | J14: =MRS!J14 -> 3800
A15: =+MRS!A15 -> 10 | B15: =MRS!B15 -> Rectangle Bar CS | D15: =MRS!D15 -> 40x40x3, 6m | G15: =MRS!G15 -> EA | H15: =MRS!H15 -> 10 | I15: =MRS!I15 -> 81 | J15: =MRS!J15 -> 810
A16: =+MRS!A16 -> 11 | B16: =MRS!B16 -> Rectangle Bar CS | D16: =MRS!D16 -> 20x20x2, 6m | G16: =MRS!G16 -> EA | H16: =MRS!H16 -> 120 | I16: =MRS!I16 -> 26.5 | J16: =MRS!J16 -> 3180
A17: =+MRS!A17 -> 12 | B17: =MRS!B17 -> Steel Plate CS | D17: =MRS!D17 -> 4'x8', 3t | G17: =MRS!G17 -> EA | H17: =MRS!H17 -> 30 | I17: =MRS!I17 -> 250 | J17: =MRS!J17 -> 7500
... A21: =+MRS!A21 -> 16 | B21: =MRS!B21 -> Ordinary plywood | D21: =MRS!D21 -> 4'x8', 12t , Indonesia | G21: =MRS!G21 -> EA | H21: =MRS!H21 -> 50 | I21: =MRS!I21 -> 98 | J21: =MRS!J21 -> 4900

Sheet PO 1st page
M2: HYUNDAI ENG. & CONST. CO., LTD.
M3: P. O. Box 77249, Al Khobar 31952
M4: kingdom of Saudi Arabia
B5: C.R. 2051041774 & VAT No.: 300000504500003 | M5: Tel: +966-13-845-1088
M6: Fax: +966-13-845-1099
B9: TO: | C9: JSAJ(Jassim Saif Amer Aljaberi Trading Est.)
C10: CR No. : | D10: 2051247436 | J10: P/O Date: | K10: =MRS!L3 -> 45780
C11: VAT No. : | D11: 311625046900003 | J11: P/O No.: | K11: =SUBSTITUTE(SUBSTITUTE(+MRS!A3," MRS No : ",""),"-MRS","-PO") -> SAC2-DS-PO-0055
C12: In Charge : | D12: Shashank Kamra | J12: (Please mention this No. in
D13: Mobile No. +966 539222074 | J13: All future correspondence)
C14: King Fahd Road 3208 - Al Aqeeq District Unit No.778 Zip Code 13519 Riyadh | J14: Quote Ref. : | K14: Q-20253157
C15: Mobile: +966 539222074 | J15: Date- | K15: 45776
B18: PURCHASE ORDER
B20: WE ARE PLEASED TO PLACE AN ORDER WITH YOU FOR THE GOODS DESCRIBED BELOW. THE ORDER SHALL BE SUBJECT TO THE TERMS AND CONDITIONS SET OUR
B21: BELOW AND ATTACHED. PLEASE SIGN AND RETURN THE ENCLOSED COPY OF THIS ORDER AS CONFIRMATION OF YOUR ACCEPTANCE OF IT WITHIN A WEEK
B22: OTHERWISE THIS ORDER SHALL BE REGARDED AS BEING ACCEPTED BY YOU.
B25: 1 | C25: GOODS
C26: Site Materials | M26: [Please refer to attached Scope of supply & Quotation for more details]
B28: 2 | C28: P/O AMOUNT
C29: Material Value | E29: : | F29: ='PO 2nd page'!G22 -> 85500
C30: VAT 15% | E30: : | F30: ='PO 2nd page'!G23 -> 12825
C31: Total Amount | E31: : | F31: ='PO 2nd page'!G24 -> 98325
B33: 3 | C33: PAYMENT TERMS
C34: 100% Payment after Delivery within 35 days with submission of the following Documents.
C35: a) Tax E-Invoice (From Zakat, Tax and Customs Authority)
C36: b) Delivery/Dispatch Note [Counter signed by Site Representative]
B38: 4 | C38: DELIVERY TERMS
C39: Delivery by Seller to Jafurah HYUNDAI Laydown within a Week after receipt of PO.
B41: 5 | C41: OTHER TERMS AND CONDITIONS
C42: a) Any quantity rejected by the Buyer owing to its poor quality and non conformity of specification shall be replaced and re-delivered
C43: by Seller to Buyer at no extra costs
C44: b) Material Certificate, Data Sheet, Safety Data Sheet and other documents which may required by ARAMCO in material receiving
C45: inspection should be submitted to Buyer
C46: c) MTC / MSDS, Others, If required by Client
B48: 6 | C48: CONTACT POINT:
B49: - | C49: Delivery & Payment : Dong Chang Kim / Daeshin Admin. [ Mobile No. : +966 53 748 5762 / Email : kdchjs@daeshinplant.com ]
B50: - | C50: Commercial (Purchaser) : Youngkyu Choi / Daeshin Planning [ Mobile No. : +966 53 952 0931 / Email : ykchoi@daeshinplant.com ]
B51: - | C51: Invoicing : Nehal Kauser / HDEC Purchase PIC [ Mobile No. : +966 50 610 2363 / Email : nehal_kauser@hdec.co.kr ]
B56: Client | J56: Contractor
B58: Signature: | J58: Signature:
...

Sheet PO 2nd page
A2: PO NO. : | B2: =+'PO 1st page'!K11 -> SAC2-DS-PO-0055 | C2: Scope of Supply
A3: DATE : | B3: =+'PO 1st page'!K10 -> 45780 | E3: Jafurah Utilities, Sulfur and Interconnecting Systems(Pkg-2)
A4: S. NO | B4: DESCRIPTION | D4: QTY | E4: UNIT | F4: ='PO 1st page'!C9 -> JSAJ(Jassim Saif Amer Aljaberi Trading Est.) | H4: Remarks (Details)
F5: Unit Price | G5: Total Amount
A6: =ROW(A1) -> 1 | B6: =MRS!B6&" "&MRS!D6 -> H-Beam CS 100x100x6x8, 12m | D6: =MRS!G6 -> EA | E6: =MRS!H6 -> 30 | F6: =+'MRS LIST'!I6 -> 800 | G6: =+'MRS LIST'!J6 -> 24000
A7: =ROW(A2) -> 2 | B7: =MRS!B7&" "&MRS!D7 -> H-Beam CS 100x100x6x8, 12m | D7: =+'MRS LIST'!G7 -> EA | E7: =+'MRS LIST'!H7 -> 5 | F7: =+'MRS LIST'!I7 -> 800 | G7: =+'MRS LIST'!J7 -> 4000
A8: =ROW(A3) -> 3 | B8: =MRS!B8&" "&MRS!D8 -> H-Beam CS 150x150x7x10, 12m | D8: =+'MRS LIST'!G8 -> EA | E8: =+'MRS LIST'!H8 -> 10 | F8: =+'MRS LIST'!I8 -> 1480 | G8: =+'MRS LIST'!J8 -> 14800
A9: =ROW(A4) -> 4 | B9: =MRS!B9&" "&MRS!D9 -> Channel CS 100x50x5x7.5, 6m | D9: =+'MRS LIST'!G9 -> EA | E9: =+'MRS LIST'!H9 -> 10 | F9: =+'MRS LIST'!I9 -> 198 | G9: =+'MRS LIST'!J9 -> 1980
A10: =ROW(A5) -> 5 | B10: =MRS!B10&" "&MRS!D10 -> Angle Bar CS 75x75x6, 6m | D10: =+'MRS LIST'!G10 -> EA | E10: =+'MRS LIST'!H10 -> 5 | F10: =+'MRS LIST'!I10 -> 145 | G10: =+'MRS LIST'!J10 -> 725
A11: =ROW(A6) -> 6 | B11: =MRS!B11&" "&MRS!D11 -> Angle Bar CS 50x50x5, 6m | D11: =+'MRS LIST'!G11 -> EA | E11: =+'MRS LIST'!H11 -> 10 | F11: =+'MRS LIST'!I11 -> 77 | G11: =+'MRS LIST'!J11 -> 770
A12: =ROW(A7) -> 7 | B12: =MRS!B12&" "&MRS!D12 -> Angle Bar CS 50x50x4, 6m | D12: =+'MRS LIST'!G12 -> EA | E12: =+'MRS LIST'!H12 -> 100 | F12: =+'MRS LIST'!I12 -> 62 | G12: =+'MRS LIST'!J12 -> 6200
A13: =ROW(A8) -> 8 | B13: =MRS!B13&" "&MRS!D13 -> Rectangle Bar CS 80x40x3, 6m | D13: =+'MRS LIST'!G13 -> EA | E13: =+'MRS LIST'!H13 -> 50 | F13: =+'MRS LIST'!I13 -> 118.9 | G13: =+'MRS LIST'!J13 -> 5945
A14: =ROW(A9) -> 9 | B14: =MRS!B14&" "&MRS!D14 -> Rectangle Bar CS 50x25x3, 6m | D14: =+'MRS LIST'!G14 -> EA | E14: =+'MRS LIST'!H14 -> 50 | F14: =+'MRS LIST'!I14 -> 76 | G14: =+'MRS LIST'!J14 -> 3800 | J14: \
A15: =ROW(A10) -> 10 | B15: =MRS!B15&" "&MRS!D15 -> Rectangle Bar CS 40x40x3, 6m | D15: =+'MRS LIST'!G15 -> EA | E15: =+'MRS LIST'!H15 -> 10 | F15: =+'MRS LIST'!I15 -> 81 | G15: =+'MRS LIST'!J15 -> 810
A16: =ROW(A11) -> 11 | B16: =MRS!B16&" "&MRS!D16 -> Rectangle Bar CS 20x20x2, 6m | D16: =+'MRS LIST'!G16 -> EA | E16: =+'MRS LIST'!H16 -> 120 | F16: =+'MRS LIST'!I16 -> 26.5 | G16: =+'MRS LIST'!J16 -> 3180
A17: =ROW(A12) -> 12 | B17: =MRS!B17&" "&MRS!D17 -> Steel Plate CS 4'x8', 3t | D17: =+'MRS LIST'!G17 -> EA | E17: =+'MRS LIST'!H17 -> 30 | F17: =+'MRS LIST'!I17 -> 250 | G17: =+'MRS LIST'!J17 -> 7500
A18: =ROW(A13) -> 13 | B18: =MRS!B18&" "&MRS!D18 -> Steel Plate CS 4'x8', 3t | D18: =+'MRS LIST'!G18 -> EA | E18: =+'MRS LIST'!H18 -> 8 | F18: =+'MRS LIST'!I18 -> 250 | G18: =+'MRS LIST'!J18 -> 2000
A19: =ROW(A14) -> 14 | B19: =MRS!B19&" "&MRS!D19 -> Corrugated Sheet 1X3MX0.32mm | D19: =+'MRS LIST'!G19 -> EA | E19: =+'MRS LIST'!H19 -> 100 | F19: =+'MRS LIST'!I19 -> 47 | G19: =+'MRS LIST'!J19 -> 4700
A20: =ROW(A15) -> 15 | B20: =MRS!B20&" "&MRS!D20 -> Pipe A106-B 1/2" S160(4.78t) 6m | D20: =+'MRS LIST'!G20 -> EA | E20: =+'MRS LIST'!H20 -> 1 | F20: =+'MRS LIST'!I20 -> 190 | G20: =+'MRS LIST'!J20 -> 190
A21: =ROW(A16) -> 16 | B21: =MRS!B21&" "&MRS!D21 -> Ordinary plywood 4'x8', 12t , Indonesia | D21: =+'MRS LIST'!G21 -> EA | E21: =+'MRS LIST'!H21 -> 50 | F21: =+'MRS LIST'!I21 -> 98 | G21: =+'MRS LIST'!J21 -> 4900
A22: Sub Total Amount | G22: =SUM(G6:G21) -> 85500
A23: VAT 15% | G23: =+G22*0.15 -> 12825
A24: Grand Total in SAR | G24: =G23+G22 -> 98325
A25: =" 1) Above Price are as per your quotation with ref "&'PO 1st page'!K14 -> 1) Above Price are as per your quotation with ref Q-20253157
A26: 2) Details of each item are attached separately.
A28: Page 2/2
