Workbook

Sheet MRS
A1: ■ Purchase Requisition of Material / Manpower / Equipment Rental / ETC. | J1: DAESHIN PLANT
A2: PJT : SACE2 | D2: Division (In charge Name) : ADMIN MANAGER (Dong Chang Kim) | J2: Subcontract name (SAC2-SC-IK-SMP-01)
A3: MRS No : SAC2-DS-MRS-0493 | E3: =+L3+3 -> 46319 | L3: 46316
A4: No | B4: Item | D4: Specification (Model / Manufacturer / Size) | G4: Unit | H4: Qty | I4: Unit Price (SAR) (Exclude VAT) | J4: Total Price (SAR) (Exclude VAT) | K4: Vendor Name | L4: Remarks
A6: =ROW(A1) -> 1 | B6: Bus with Driver | D6: 66 Seater 2025 to 2026 Model | G6: Month | H6: 1 | I6: 11000 | J6: =H6*I6 -> 11000 | K6: SAGC | L6: Monthly
A7: 2
A8: =ROW(A3) -> 3
A9: 4
A10: =ROW(A5) -> 5
A11: 6
A12: =ROW(A7) -> 7
A13: 8
A14: =ROW(A9) -> 9
A15: 10
A16: Purpose | I16: Sum | J16: =SUM(J6:J15) -> 11000
A17: * There will be an additional administration expense and financial expense (Depend on contract) deduction of total provision cost price.
AD18: HEC | AE18: PCM | AF18: ADM | AG18: PM
O20: SUB-CON | T20: HDEC | AE20: / | AF20: / | AG20: /
O21: In Charge | P21: ADM | Q21: PCM | R21: PM | T21: Construction | U21: Subcon(PC) | V21: Account | Y21: ADM | Z21: Requesting | AA21: JV Area PIC | AB21: PCM (Subcon)
V22: In Charge | W22: Manager | Z22: Company | AD22: HDEC | AE22: PCM | AF22: ADM | AG22: PM
X24: HEC | Y24: ADM | Z24: / | AA24: / | AB24: / | AE24: / | AF24: / | AG24: /
T40: PROJECT MANAGER | AE40: PROJECT MANAGER
O46: PROJECT MANAGER | P46: PROJECT MANAGER | Q46: PROJECT MANAGER | T46: PCM | U46: ADM | V46: PROJECT MANAGER | Z46: PROJECT MANAGER | AA46: PROJECT MANAGER | AB46: PROJECT MANAGER | AE46: PCM | AF46: ADM | AG46: PROJECT MANAGER
O50: PROJECT MANAGER | P50: PROJECT MANAGER | Q50: PROJECT MANAGER | T50: ADM | U50: PCM | V50: PROJECT MANAGER | Z50: PROJECT MANAGER | AA50: PROJECT MANAGER | AB50: PROJECT MANAGER | AE50: ADM | AF50: PCM | AG50: PROJECT MANAGER

Sheet MRS LIST
A1: ■ Purchase Requisition of Equipment Rental | J1: =+MRS!J1 -> DAESHIN PLANT
A2: =+MRS!A2 -> PJT : SACE2 | D2: =+MRS!D2 -> Division (In charge Name) : ADMIN MANAGER (Dong Chang Kim) | J2: =+MRS!J2 -> Subcontract name (SAC2-SC-IK-SMP-01)
A3: =+MRS!A3 -> MRS No : SAC2-DS-MRS-0493 | K3: =+MRS!L3 -> 46316
A4: No | B4: Item | D4: Specification (Model / Manufacturer / Size) | G4: Unit | H4: Q'ty | I4: Unit Price | J4: Total Price | K4: Remarks
A6: =+MRS!A6 -> 1 | B6: =MRS!B6 -> Bus with Driver | D6: =MRS!D6 -> 66 Seater 2025 to 2026 Model | G6: =MRS!G6 -> Month | H6: =MRS!H6 -> 1 | I6: =MRS!I6 -> 11000 | J6: =MRS!J6 -> 11000
A7: =+MRS!#REF! -> #REF! | B7: =MRS!B7 -> 0 | D7: =MRS!D7 -> 0 | G7: =MRS!G7 -> 0 | H7: =MRS!H7 -> 0 | I7: =MRS!I7 -> 0 | J7: =MRS!J7 -> 0
A8: =+MRS!A7 -> 2 | B8: =MRS!B8 -> 0 | D8: =MRS!D8 -> 0 | G8: =MRS!G8 -> 0 | H8: =MRS!H8 -> 0 | I8: =MRS!I8 -> 0 | J8: =MRS!J8 -> 0
A9: =+MRS!A8 -> 3 | B9: =MRS!B9 -> 0 | D9: =MRS!D9 -> 0 | G9: =MRS!G9 -> 0 | H9: =MRS!H9 -> 0 | I9: =MRS!I9 -> 0 | J9: =MRS!J9 -> 0
A10: =+MRS!A9 -> 4 | B10: =MRS!B10 -> 0 | D10: =MRS!D10 -> 0 | G10: =MRS!G10 -> 0 | H10: =MRS!H10 -> 0 | I10: =MRS!I10 -> 0 | J10: =MRS!J10 -> 0
A11: =+MRS!A10 -> 5
A12: =+MRS!A11 -> 6
A13: =+MRS!A12 -> 7
A14: =+MRS!A13 -> 8
A15: =+MRS!A15 -> 10
A16: =+MRS!#REF! -> #REF!
A17: =+MRS!#REF! -> #REF!

Sheet PO 1st page
M2: BRANCH OF HYUNDAI ENG. & CONST. CO., LTD.
M3: P. O. Box 77249, Al Khobar 31952
M4: kingdom of Saudi Arabia
B5: C.R. 2051041774 & VAT No.: 300000504500003 | M5: Tel: +966-13-845-1088
M6: Fax: +966-13-845-1099
B9: TO: | C9: SAGC(Sana Al-Tamiz General Contracting Est.)
C10: CR No. : | D10: 2055136684 | J10: P/O Date: | K10: =MRS!L3 -> 46316
C11: VAT No. : | D11: 311630284900003 | J11: P/O No.: | K11: =SUBSTITUTE(SUBSTITUTE(+MRS!A3," MRS No : ",""),"-MRS","-PO") -> SAC2-DS-PO-0493
C12: In Charge : | D12: Moidin Nisar | J12: (Please mention this No. in
D13: +966 59 054 9362 / email: info@sanatechksa.com | J13: All future correspondence)
C14: Bldg No. 4564 Al Riyadh Street, Al Jubail-35514, KSA | J14: Quote Ref. : | K14: ST/HEC/26/125
C15: Mobile : +966 59 054 9362 | J15: Date- | K15: 46313
B18: PURCHASE ORDER
B20: WE ARE PLEASED TO PLACE AN ORDER WITH YOU FOR THE GOODS DESCRIBED BELOW. THE ORDER SHALL BE SUBJECT TO THE TERMS AND CONDITIONS SET OUR
B21: BELOW AND ATTACHED. PLEASE SIGN AND RETURN THE ENCLOSED COPY OF THIS ORDER AS CONFIRMATION OF YOUR ACCEPTANCE OF IT WITHIN A WEEK
B22: OTHERWISE THIS ORDER SHALL BE REGARDED AS BEING ACCEPTED BY YOU.
B25: 1 | C25: GOODS
C26: =MRS!B6&" "&MRS!D6 -> Bus with Driver 66 Seater 2025 to 2026 Model | M26: [Please refer to attached Scope of supply & Quotation for more details]
B28: 2 | C28: P/O AMOUNT
C29: Material Value | E29: : | F29: Monthly Based
C30: VAT 15% | E30: :
C31: Total Amount | E31: :
B33: 3 | C33: PAYMENT TERMS
C34: 100% Payment after Delivery within 35 days with submission of the following Documents.
C35: a) Tax E-Invoice (From Zakat, Tax and Customs Authority)
C36: b) Delivery/Dispatch Note [Counter signed by Site Representative]
B38: 4 | C38: DELIVERY TERMS
C39: Delivery by Seller to Jafurah HYUNDAI Laydown within a Week after receipt of PO.
B41: 5 | C41: OTHER TERMS AND CONDITIONS
C42: a) Any quantity rejected by the Buyer owing to its poor quality and non conformity of specification shall be replaced and re-delivered
C43: by Seller to Buyer at no extra costs
C44: b) Material Certificate, Data Sheet, Safety Data Sheet and other documents which may required by ARAMCO in material receiving
C45: inspection should be submitted to Buyer
C46: c) MTC / MSDS, Others, If required by Client
B48: 6 | C48: CONTACT POINT:
B49: - | C49: Delivery & Payment : Sang Yeun Cho / Daeshin Admin. [ Mobile No. : +966 53 926 8130 / Email : sycho@daeshinplant.com ]
B50: - | C50: Commercial (Purchaser) : Youngkyu Choi / Daeshin Planning [ Mobile No. : +966 53 952 0931 / Email : ykchoi@daeshinplant.com ]
B51: - | C51: Invoicing : Nehal Kauser / HDEC Purchase PIC [ Mobile No. : +966 50 610 2363 / Email : nehal_kauser@hdec.co.kr ]
B53: 7 | C53: Bank Account Details:
B54: - | C54: ACCOUNT NAME | F54: ESTABLISHMENT SANA AL-TAMIZ FOR GENERAL CONTRACTING | P54: =UPPER(F54) -> ESTABLISHMENT SANA AL-TAMIZ FOR GENERAL CONTRACTING
...

Sheet PO 2nd page
A2: PO NO. : | B2: =+'PO 1st page'!K11 -> SAC2-DS-PO-0493 | C2: Scope of Supply
A3: DATE : | B3: =+'PO 1st page'!K10 -> 46316 | E3: Jafurah Utilities, Sulfur and Interconnecting Systems(Pkg-2)
A4: S. NO | B4: DESCRIPTION | D4: QTY | E4: UNIT | F4: ='PO 1st page'!C9 -> SAGC(Sana Al-Tamiz General Contracting Est.) | H4: Remarks (Details)
F5: Unit Price | G5: Total Amount
A6: =ROW(A1) -> 1 | B6: =MRS!B6&","&MRS!D6 -> Bus with Driver,66 Seater 2025 to 2026 Model | D6: =+'MRS LIST'!G6 -> Month | E6: =+'MRS LIST'!H6 -> 1 | F6: =+'MRS LIST'!I6 -> 11000 | G6: =+'MRS LIST'!J6 -> 11000 | H6: =MRS!L6 -> Monthly
A7: 2 | B7: =MRS!B7&" "&MRS!D7
A8: 3
A9: =ROW(A4) -> 4
A10: =ROW(A5) -> 5
A11: =ROW(A6) -> 6
A12: =ROW(A7) -> 7
A13: =ROW(A8) -> 8
A14: =ROW(A9) -> 9
A15: =ROW(A10) -> 10
A16: =ROW(A11) -> 11
A17: =ROW(A12) -> 12
A18: Sub Total Amount | G18: =SUM(G6:G17) -> 11000
A19: VAT 15% | G19: =+G18*0.15 -> 1650
A20: Registration Fee | G20: 0
A21: Grand Total in SAR | G21: =SUM(G18:G20) -> 12650
A22: =" 1) Above Price are as per your quotation with ref "&'PO 1st page'!K14 -> 1) Above Price are as per your quotation with ref ST/HEC/26/125
A23: 2) Details of each item are attached separately.
A25: Page 2/2
