Workbook

Sheet MRS
A1: ■ Purchase Requisition of Material / Manpower / Equipment Rental / ETC. | G1: DAESHIN PLANT
A2: PJT : SACE2 | C2: Division (In charge Name) : ADMIN MANAGER (Dong Chang Kim) | G2: Subcontract name (SAC2-SC-IK-SMP-01)
A3: MRS No : SAC2-DS-MRS-0095 | I3: 45853
A4: No | B4: Item | C4: Specification (Model / Manufacturer / Size) | D4: Unit | E4: Qty | F4: Unit Price (SAR) (Exclude VAT) | G4: Total Price (SAR) (Exclude VAT) | H4: Vendor Name | I4: Remarks
A6: =ROW(A1) -> 1 | B6: Xerox Printer | C6: B7135 - Black & White | D6: EA | E6: 1 | F6: 14748 | G6: =E6*F6 -> 14748 | H6: BWCT | I6: One time
A7: =ROW(A2) -> 2 | B7: Freezer | C7: Haier | D7: EA | E7: 12 | F7: 2804.4 | G7: =E7*F7 -> 33652.8
A8: =ROW(A3) -> 3 | B8: Xerox Toner | C8: B7135 - Black | D8: EA | E8: 4 | F8: 493.75 | G8: =E8*F8 -> 1975
A9: =ROW(A4) -> 4 | B9: Xerox Toner | C9: B7130 - Black | D9: EA | E9: 4 | F9: 562.5 | G9: =E9*F9 -> 2250
A10: =ROW(A5) -> 5 | B10: Xerox Toner | C10: C7130 - Cyan | D10: EA | E10: 4 | F10: 562.5 | G10: =E10*F10 -> 2250
A11: =ROW(A6) -> 6 | B11: Xerox Toner | C11: C7130 - Magenta | D11: EA | E11: 4 | F11: 562.5 | G11: =E11*F11 -> 2250
A12: =ROW(A7) -> 7 | B12: Xerox Toner | C12: C7130 - Yellow | D12: EA | E12: 4 | F12: 562.5 | G12: =E12*F12 -> 2250
G13: =E13*F13 -> 0
G14: =E14*F14 -> 0
G15: =E15*F15 -> 0
A16: Purpose | F16: Sum | G16: =SUM(G6:G15) -> 59375.8
A17: * There will be an additional administration expense and financial expense (Depend on contract) deduction of total provision cost price.
P18: HEC | Q18: PCM | R18: ADM | S18: PM
Q20: / | R20: / | S20: /
L21: Requesting | M21: JV Area PIC | N21: PCM (Subcon)
L22: Company | P22: HDEC | Q22: PCM | R22: ADM | S22: PM
L24: / | M24: / | N24: / | Q24: / | R24: / | S24: /
Q40: PROJECT MANAGER
L46: PROJECT MANAGER | M46: PROJECT MANAGER | N46: PROJECT MANAGER | Q46: PCM | R46: ADM | S46: PROJECT MANAGER
L50: PROJECT MANAGER | M50: PROJECT MANAGER | N50: PROJECT MANAGER | Q50: ADM | R50: PCM | S50: PROJECT MANAGER

Sheet MRS LIST
A1: ■ Purchase Requisition of Equipment Rental | J1: =+MRS!G1 -> DAESHIN PLANT
A2: =+MRS!A2 -> PJT : SACE2 | D2: =+MRS!C2 -> Division (In charge Name) : ADMIN MANAGER (Dong Chang Kim) | J2: =+MRS!G2 -> Subcontract name (SAC2-SC-IK-SMP-01)
A3: =+MRS!A3 -> MRS No : SAC2-DS-MRS-0095 | K3: =+MRS!I3 -> 45853
A4: No | B4: Item | D4: Specification (Model / Manufacturer / Size) | G4: Unit | H4: Q'ty | I4: Unit Price | J4: Total Price | K4: Remarks
A6: =+MRS!A6 -> 1 | B6: =MRS!B6 -> Xerox Printer | D6: =MRS!C6 -> B7135 - Black & White | G6: =MRS!D6 -> EA | H6: =MRS!E6 -> 1 | I6: =MRS!F6 -> 14748 | J6: =MRS!G6 -> 14748
A7: =+MRS!A7 -> 2 | B7: =MRS!B7 -> Freezer | D7: =MRS!C7 -> Haier | G7: =MRS!D7 -> EA | H7: =MRS!E7 -> 12 | I7: =MRS!F7 -> 2804.4 | J7: =MRS!G7 -> 33652.8
A8: =+MRS!A8 -> 3 | B8: =MRS!B8 -> Xerox Toner | D8: =MRS!C8 -> B7135 - Black | G8: =MRS!D8 -> EA | H8: =MRS!E8 -> 4 | I8: =MRS!F8 -> 493.75 | J8: =MRS!G8 -> 1975
A9: =+MRS!A9 -> 4 | B9: =MRS!B9 -> Xerox Toner | D9: =MRS!C9 -> B7130 - Black | G9: =MRS!D9 -> EA | H9: =MRS!E9 -> 4 | I9: =MRS!F9 -> 562.5 | J9: =MRS!G9 -> 2250
A10: =+MRS!A10 -> 5 | B10: =MRS!B10 -> Xerox Toner | D10: =MRS!C10 -> C7130 - Cyan | G10: =MRS!D10 -> EA | H10: =MRS!E10 -> 4 | I10: =MRS!F10 -> 562.5 | J10: =MRS!G10 -> 2250
A11: =+MRS!A11 -> 6 | B11: =MRS!B11 -> Xerox Toner | D11: =MRS!C11 -> C7130 - Magenta | G11: =MRS!D11 -> EA | H11: =MRS!E11 -> 4 | I11: =MRS!F11 -> 562.5 | J11: =MRS!G11 -> 2250
A12: =+MRS!A12 -> 7 | B12: =MRS!B12 -> Xerox Toner | D12: =MRS!C12 -> C7130 - Yellow | G12: =MRS!D12 -> EA | H12: =MRS!E12 -> 4 | I12: =MRS!F12 -> 562.5 | J12: =MRS!G12 -> 2250
A13: =+MRS!A13 -> 0 | B13: =MRS!B13 -> 0 | D13: =MRS!C13 -> 0 | G13: =MRS!D13 -> 0 | H13: =MRS!E13 -> 0 | I13: =MRS!F13 -> 0 | J13: =MRS!G13 -> 0
A14: =+MRS!A14 -> 0 | B14: =MRS!B13 -> 0 | D14: =MRS!C13 -> 0 | G14: =MRS!D13 -> 0 | H14: =MRS!E13 -> 0 | I14: =MRS!F13 -> 0 | J14: =MRS!G13 -> 0
A15: =+MRS!A14 -> 0 | B15: =MRS!B14 -> 0 | D15: =MRS!C14 -> 0 | G15: =MRS!D14 -> 0 | H15: =MRS!E14 -> 0 | I15: =MRS!F14 -> 0 | J15: =MRS!G14 -> 0
A16: =+MRS!A15 -> 0 | B16: =MRS!B15 -> 0 | D16: =MRS!C15 -> 0 | G16: =MRS!D15 -> 0 | H16: =MRS!E15 -> 0 | I16: =MRS!F15 -> 0 | J16: =MRS!G15 -> 0

Sheet PO 1st page
M2: BRANCH OF HYUNDAI ENG. & CONST. CO., LTD.
M3: P. O. Box 77249, Al Khobar 31952
M4: kingdom of Saudi Arabia
B5: C.R. 2051041774 & VAT No.: 300000504500003 | M5: Tel: +966-13-845-1088
M6: Fax: +966-13-845-1099
B9: TO: | C9: BWCT(Blue Arabia Ways Co. for Trading)
C10: CR No. : | D10: 2051242967 | J10: P/O Date: | K10: =MRS!I3 -> 45853
C11: VAT No. : | D11: 311461390400003 | J11: P/O No.: | K11: =SUBSTITUTE(SUBSTITUTE(+MRS!A3," MRS No : ",""),"-MRS","-PO") -> SAC2-DS-PO-0095
C12: In Charge : | D12: Vijay Kumar | J12: (Please mention this No. in
D13: +966 56 431 5378 / Email:bluearabiaways@gmail.com | J13: All future correspondence)
C14: Floor No. 2 Office No. 11, Dammam Al Anud 32426 KSA | J14: Quote Ref. : | K14: QT-BWC-2025-607
C15: Mobile : +966 56 431 5378 | J15: Date- | K15: 45850
B18: PURCHASE ORDER
B20: WE ARE PLEASED TO PLACE AN ORDER WITH YOU FOR THE GOODS DESCRIBED BELOW. THE ORDER SHALL BE SUBJECT TO THE TERMS AND CONDITIONS SET OUR
B21: BELOW AND ATTACHED. PLEASE SIGN AND RETURN THE ENCLOSED COPY OF THIS ORDER AS CONFIRMATION OF YOUR ACCEPTANCE OF IT WITHIN A WEEK
B22: OTHERWISE THIS ORDER SHALL BE REGARDED AS BEING ACCEPTED BY YOU.
B25: 1 | C25: GOODS
C26: Office Materials | M26: [Please refer to attached Scope of supply & Quotation for more details]
B28: 2 | C28: P/O AMOUNT
C29: Material Value | E29: : | F29: ='PO 2nd page'!G20 -> 59375.8
C30: VAT 15% | E30: : | F30: ='PO 2nd page'!G21 -> 8906.37
C31: Total Amount | E31: : | F31: ='PO 2nd page'!G22 -> 68282.17
B33: 3 | C33: PAYMENT TERMS
C34: 100% Payment after Delivery within 35 days with submission of the following Documents.
C35: a) Tax E-Invoice (From Zakat, Tax and Customs Authority)
C36: b) Delivery/Dispatch Note [Counter signed by Site Representative]
B38: 4 | C38: DELIVERY TERMS
C39: Delivery by Seller to Jafurah HYUNDAI Laydown within a Week after receipt of PO.
B41: 5 | C41: OTHER TERMS AND CONDITIONS
C42: a) Any quantity rejected by the Buyer owing to its poor quality and non conformity of specification shall be replaced and re-delivered
C43: by Seller to Buyer at no extra costs
C44: b) Material Certificate, Data Sheet, Safety Data Sheet and other documents which may required by ARAMCO in material receiving
C45: inspection should be submitted to Buyer
C46: c) MTC / MSDS, Others, If required by Client
B48: 6 | C48: CONTACT POINT:
B49: - | C49: Delivery & Payment : Dong Chang Kim / Daeshin Admin. [ Mobile No. : +966 53 748 5762 / Email : kdchjs@daeshinplant.com ]
B50: - | C50: Commercial (Purchaser) : Youngkyu Choi / Daeshin Planning [ Mobile No. : +966 53 952 0931 / Email : ykchoi@daeshinplant.com ]
B51: - | C51: Invoicing : Nehal Kauser / HDEC Purchase PIC [ Mobile No. : +966 50 610 2363 / Email : nehal_kauser@hdec.co.kr ]
B56: Client | J56: Contractor
B58: Signature: | J58: Signature:
...

Sheet PO 2nd page
A2: PO NO. : | B2: =+'PO 1st page'!K11 -> SAC2-DS-PO-0095 | C2: Scope of Supply
A3: DATE : | B3: =+'PO 1st page'!K10 -> 45853 | E3: Jafurah Utilities, Sulfur and Interconnecting Systems(Pkg-2)
A4: S. NO | B4: DESCRIPTION | D4: QTY | E4: UNIT | F4: ='PO 1st page'!C9 -> BWCT(Blue Arabia Ways Co. for Trading) | H4: Remarks (Details)
F5: Unit Price | G5: Total Amount
A6: =ROW(A1) -> 1 | B6: =+'MRS LIST'!B6 -> Xerox Printer | D6: =+'MRS LIST'!G6 -> EA | E6: =+'MRS LIST'!H6 -> 1 | F6: =+'MRS LIST'!I6 -> 14748 | G6: =+'MRS LIST'!J6 -> 14748
A7: =ROW(A2) -> 2 | B7: =+'MRS LIST'!B7 -> Freezer | D7: =+'MRS LIST'!G7 -> EA | E7: =+'MRS LIST'!H7 -> 12 | F7: =+'MRS LIST'!I7 -> 2804.4 | G7: =+'MRS LIST'!J7 -> 33652.8
A8: =ROW(A3) -> 3 | B8: =+'MRS LIST'!B8 -> Xerox Toner | D8: =+'MRS LIST'!G8 -> EA | E8: =+'MRS LIST'!H8 -> 4 | F8: =+'MRS LIST'!I8 -> 493.75 | G8: =+'MRS LIST'!J8 -> 1975
A9: =ROW(A4) -> 4 | B9: =+'MRS LIST'!B9 -> Xerox Toner | D9: =+'MRS LIST'!G9 -> EA | E9: =+'MRS LIST'!H9 -> 4 | F9: =+'MRS LIST'!I9 -> 562.5 | G9: =+'MRS LIST'!J9 -> 2250
A10: =ROW(A5) -> 5 | B10: =+'MRS LIST'!B10 -> Xerox Toner | D10: =+'MRS LIST'!G10 -> EA | E10: =+'MRS LIST'!H10 -> 4 | F10: =+'MRS LIST'!I10 -> 562.5 | G10: =+'MRS LIST'!J10 -> 2250
A11: =ROW(A6) -> 6 | B11: =+'MRS LIST'!B11 -> Xerox Toner | D11: =+'MRS LIST'!G11 -> EA | E11: =+'MRS LIST'!H11 -> 4 | F11: =+'MRS LIST'!I11 -> 562.5 | G11: =+'MRS LIST'!J11 -> 2250
A12: =ROW(A7) -> 7 | B12: =+'MRS LIST'!B12 -> Xerox Toner | D12: =+'MRS LIST'!G12 -> EA | E12: =+'MRS LIST'!H12 -> 4 | F12: =+'MRS LIST'!I12 -> 562.5 | G12: =+'MRS LIST'!J12 -> 2250
A20: Sub Total Amount | G20: =SUM(G6:G19) -> 59375.8
A21: VAT 15% | G21: =+G20*0.15 -> 8906.37
A22: Grand Total in SAR | G22: =G21+G20 -> 68282.17
A23: =" 1) Above Price are as per your quotation with ref "&'PO 1st page'!K14 -> 1) Above Price are as per your quotation with ref QT-BWC-2025-607
A24: 2) Details of each item are attached separately.
A26: Page 2/2
