Workbook

Sheet MRS
A1: ■ Purchase Requisition of Material / Manpower / Equipment Rental / ETC. | J1: DAESHIN PLANT
A2: PJT : SACE2 | D2: Division (In charge Name) : ADMIN MANAGER (Dong Chang Kim) | J2: Subcontract name (SAC2-SC-IK-SMP-01)
A3: MRS No : SAC2-DS-MRS-0488 | E3: =+L3+3 -> 46305 | L3: 46302
A4: No | B4: Item | D4: Specification (Model / Manufacturer / Size) | G4: Unit | H4: Qty | I4: Unit Price (SAR) (Exclude VAT) | J4: Total Price (SAR) (Exclude VAT) | K4: Vendor Name | L4: Remarks
A6: =ROW(A1) -> 1 | B6: Pipe Fabricator | G6: Hour | H6: 1 | I6: 24 | J6: =H6*I6 -> 24 | K6: DSGC | L6: Monthly
A7: =ROW(A2) -> 2 | B7: Iron Worker | G7: Hour | H7: 1 | I7: 18 | J7: =H7*I7 -> 18 | K7: " | L7: "
A8: =ROW(A3) -> 3
A9: =ROW(A4) -> 4
A10: =ROW(A5) -> 5
A11: =ROW(A6) -> 6
A12: =ROW(A7) -> 7
A13: =ROW(A8) -> 8
A14: =ROW(A9) -> 9
A15: =ROW(A10) -> 10
A16: Purpose | I16: Sum | J16: =SUM(J6:J15) -> 42
A17: * There will be an additional administration expense and financial expense (Depend on contract) deduction of total provision cost price.
O20: SUB-CON | T20: HDEC
O21: In Charge | P21: ADM | Q21: PCM | R21: PM | T21: Construction | U21: Subcon(PC) | V21: Account | Y21: ADM
V22: In Charge | W22: Manager
X24: HEC | Y24: ADM
T40: PROJECT MANAGER
O46: PROJECT MANAGER | P46: PROJECT MANAGER | Q46: PROJECT MANAGER | T46: PCM | U46: ADM | V46: PROJECT MANAGER
O50: PROJECT MANAGER | P50: PROJECT MANAGER | Q50: PROJECT MANAGER | T50: ADM | U50: PCM | V50: PROJECT MANAGER

Sheet MRS LIST
A1: ■ Purchase Requisition of Equipment Rental | J1: =+MRS!J1 -> DAESHIN PLANT
A2: =+MRS!A2 -> PJT : SACE2 | D2: =+MRS!D2 -> Division (In charge Name) : ADMIN MANAGER (Dong Chang Kim) | J2: =+MRS!J2 -> Subcontract name (SAC2-SC-IK-SMP-01)
A3: =+MRS!A3 -> MRS No : SAC2-DS-MRS-0488 | K3: =+MRS!L3 -> 46302
A4: No | B4: Item | D4: Specification (Model / Manufacturer / Size) | G4: Unit | H4: Q'ty | I4: Unit Price | J4: Total Price | K4: Remarks
A6: =+MRS!A6 -> 1 | B6: =MRS!B6 -> Pipe Fabricator | D6: =MRS!D6 -> 0 | G6: =MRS!G6 -> Hour | H6: =MRS!H6 -> 1 | I6: =MRS!I6 -> 24 | J6: =MRS!J6 -> 24
A7: =+MRS!A7 -> 2 | B7: =MRS!B7 -> Iron Worker | D7: =MRS!D7 -> 0 | G7: =MRS!G7 -> Hour | H7: =MRS!H7 -> 1 | I7: =MRS!I7 -> 18 | J7: =MRS!J7 -> 18
A8: =+MRS!A8 -> 3
A9: =+MRS!A9 -> 4
A10: =+MRS!A10 -> 5
A11: =+MRS!A11 -> 6
A12: =+MRS!A12 -> 7
A13: =+MRS!A13 -> 8
A14: =+MRS!A14 -> 9
A15: =+MRS!A15 -> 10
A16: =+MRS!#REF! -> #REF!
A17: =+MRS!#REF! -> #REF!

Sheet PO 1st page
M2: BRANCH OF HYUNDAI ENG. & CONST. CO., LTD.
M3: P. O. Box 77249, Al Khobar 31952
M4: kingdom of Saudi Arabia
B5: C.R. 2051041774 & VAT No.: 300000504500003 | M5: Tel: +966-13-845-1088
M6: Fax: +966-13-845-1099
B9: TO: | C9: DSGC (Desert Solution General Contracting Company LLC)
C10: CR No. : | D10: 2055104339 | J10: P/O Date: | K10: =MRS!L3 -> 46302
C11: VAT No. : | D11: 311318994400003 | J11: P/O No.: | K11: =SUBSTITUTE(SUBSTITUTE(+MRS!A3," MRS No : ",""),"-MRS","-PO") -> SAC2-DS-PO-0488
C12: In Charge : | D12: Mohammed Irshad | J12: (Please mention this No. in
D13: +966 53 3121661 / Email:admin@desertsolutionindus.com | J13: All future correspondence)
C14: P.O. Box No. 1015, Jubail-31951, KSA | J14: Quote Ref. : | K14: DSCE/HYU/Q-11197
C15: Landline: +966 13 362 3735 / Mobile : +966 533121661 | J15: Date- | K15: 46287
B18: PURCHASE ORDER
B20: WE ARE PLEASED TO PLACE AN ORDER WITH YOU FOR THE GOODS DESCRIBED BELOW. THE ORDER SHALL BE SUBJECT TO THE TERMS AND CONDITIONS SET OUR
B21: BELOW AND ATTACHED. PLEASE SIGN AND RETURN THE ENCLOSED COPY OF THIS ORDER AS CONFIRMATION OF YOUR ACCEPTANCE OF IT WITHIN A WEEK
B22: OTHERWISE THIS ORDER SHALL BE REGARDED AS BEING ACCEPTED BY YOU.
B25: 1 | C25: GOODS
C26: =MRS!B6&", "&MRS!B7 -> Pipe Fabricator, Iron Worker | M26: [Please refer to attached Scope of supply & Quotation for more details]
B28: 2 | C28: P/O AMOUNT
C29: Material Value | E29: : | F29: Monthly Based
C30: VAT 15% | E30: :
C31: Total Amount | E31: :
B33: 3 | C33: PAYMENT TERMS
C34: 100% Payment after Delivery within 35 days with submission of the following Documents.
C35: a) Tax E-Invoice (From Zakat, Tax and Customs Authority)
C36: b) Delivery/Dispatch Note [Counter signed by Site Representative]
B38: 4 | C38: DELIVERY TERMS
C39: Delivery by Seller to Jafurah HYUNDAI Laydown within a Week after receipt of PO.
B41: 5 | C41: OTHER TERMS AND CONDITIONS
C42: a) Any quantity rejected by the Buyer owing to its poor quality and non conformity of specification shall be replaced and re-delivered
C43: by Seller to Buyer at no extra costs
C44: b) Material Certificate, Data Sheet, Safety Data Sheet and other documents which may required by ARAMCO in material receiving
C45: inspection should be submitted to Buyer
C46: c) MTC / MSDS, Others, If required by Client
B48: 6 | C48: CONTACT POINT:
B49: - | C49: Delivery & Payment : Sang Yeun Cho / Daeshin Admin. [ Mobile No. : +966 53 926 8130 / Email : sycho@daeshinplant.com ]
B50: - | C50: Commercial (Purchaser) : Youngkyu Choi / Daeshin Planning [ Mobile No. : +966 53 952 0931 / Email : ykchoi@daeshinplant.com ]
B51: - | C51: Invoicing : Nehal Kauser / HDEC Purchase PIC [ Mobile No. : +966 50 610 2363 / Email : nehal_kauser@hdec.co.kr ]
B53: 7 | C53: Bank Account Details:
B54: - | C54: ACCOUNT NAME | F54: DESERT SOLUTION GENERAL CONTRACTING EST | P54: =UPPER(F54) -> DESERT SOLUTION GENERAL CONTRACTING EST
...

Sheet PO 2nd page
A2: PO NO. : | B2: =+'PO 1st page'!K11 -> SAC2-DS-PO-0488 | C2: Scope of Supply
A3: DATE : | B3: =+'PO 1st page'!K10 -> 46302 | E3: Jafurah Utilities, Sulfur and Interconnecting Systems(Pkg-2)
A4: S. NO | B4: DESCRIPTION | D4: QTY | E4: UNIT | F4: ='PO 1st page'!C9 -> DSGC (Desert Solution General Contracting Company LLC) | H4: Remarks (Details)
F5: Unit Price | G5: Total Amount
A6: =ROW(A1) -> 1 | B6: =CONCATENATE(MRS!B6," ",MRS!D6) -> Pipe Fabricator | D6: =+'MRS LIST'!G6 -> Hour | E6: =+'MRS LIST'!H6 -> 1 | F6: =+'MRS LIST'!I6 -> 24 | G6: =+'MRS LIST'!J6 -> 24 | H6: =MRS!L6 -> Monthly
A7: =ROW(A2) -> 2 | B7: =CONCATENATE(MRS!B7," ",MRS!D7) -> Iron Worker | D7: =+'MRS LIST'!G7 -> Hour | E7: =+'MRS LIST'!H7 -> 1 | F7: =+'MRS LIST'!I7 -> 18 | G7: =+'MRS LIST'!J7 -> 18 | H7: =MRS!L7 -> "
A8: =ROW(A3) -> 3
A9: =ROW(A4) -> 4
A10: =ROW(A5) -> 5
A11: =ROW(A6) -> 6
A12: =ROW(A7) -> 7
A13: =ROW(A8) -> 8
A14: =ROW(A9) -> 9
A15: =ROW(A10) -> 10
A16: =ROW(A11) -> 11
A17: =ROW(A12) -> 12
A18: Sub Total Amount | G18: =SUM(G6:G17) -> 42
A19: VAT 15% | G19: =+G18*0.15 -> 6.3
A20: Grand Total in SAR | G20: =G19+G18 -> 48.3
A21: =" 1) Above Price are as per your quotation with ref "&'PO 1st page'!K14 -> 1) Above Price are as per your quotation with ref DSCE/HYU/Q-11197
A22: 2) Details of each item are attached separately.
A24: Page 2/2
