Workbook

Sheet MRS
A1: ■ Purchase Requisition of Material / Manpower / Equipment Rental / ETC. | J1: DAESHIN PLANT
A2: PJT : SACE2 | D2: Division (In charge Name) : ADMIN MANAGER (Dong Chang Kim) | J2: Subcontract name (SAC2-SC-IK-SMP-01)
A3: MRS No : SAC2-DS-MRS-0463 | E3: =+L3+3 -> 46283 | L3: 46280
A4: No | B4: Item | D4: Specification (Model / Manufacturer / Size) | G4: Unit | H4: Qty | I4: Unit Price (SAR) (Exclude VAT) | J4: Total Price (SAR) (Exclude VAT) | K4: Vendor Name | L4: Remarks
A6: =ROW(A1) -> 1 | B6: BOW SHACKLE | D6: 1 1/2"X17TON | G6: EA | H6: 4 | I6: 110 | J6: =+H6*I6 -> 440 | K6: AMT | L6: One time
A7: =ROW(A2) -> 2 | B7: BOW SHACKLE | D7: 1 1/4"X12TON | G7: EA | H7: 4 | I7: 70 | J7: =+H7*I7 -> 280
A8: =ROW(A3) -> 3 | B8: BOW SHACKLE | D8: 1 3/4"X25TON | G8: EA | H8: 4 | I8: 210 | J8: =+H8*I8 -> 840
A9: =ROW(A4) -> 4 | B9: BOW SHACKLE | D9: 1"X8.5TON | G9: EA | H9: 4 | I9: 34 | J9: =+H9*I9 -> 136
A10: =ROW(A5) -> 5 | B10: BOW SHACKLE | D10: 1"X8.5TON | G10: EA | H10: 100 | I10: 34 | J10: =+H10*I10 -> 3400
A11: =ROW(A6) -> 6 | B11: BOW SHACKLE | D11: 1/2"X2TON | G11: EA | H11: 24 | I11: 10 | J11: =+H11*I11 -> 240
A12: =ROW(A7) -> 7 | B12: BOW SHACKLE | D12: 2"X35TON | G12: EA | H12: 2 | I12: 320 | J12: =+H12*I12 -> 640
A13: =ROW(A8) -> 8 | B13: BOW SHACKLE | D13: 3/4"X4.75TON | G13: EA | H13: 24 | I13: 20 | J13: =+H13*I13 -> 480
A14: =ROW(A9) -> 9 | B14: BOW SHACKLE | D14: 3/4"X4.75TON | G14: EA | H14: 200 | I14: 20 | J14: =+H14*I14 -> 4000
A15: =ROW(A10) -> 10 | B15: BOW SHACKLE | D15: 7/8"X6.5TON | G15: EA | H15: 24 | I15: 25 | J15: =+H15*I15 -> 600
A16: =ROW(A11) -> 11 | B16: BOW SHACKLE | D16: 7/8"X6.5TON | G16: EA | H16: 200 | I16: 25 | J16: =+H16*I16 -> 5000
A17: =ROW(A12) -> 12 | B17: CHAIN BLOCK | D17: 1.5TONX3MTR | G17: EA | H17: 10 | I17: 240 | J17: =+H17*I17 -> 2400
A18: =ROW(A13) -> 13 | B18: CHAIN BLOCK | D18: 2TONX3MTR | G18: EA | H18: 10 | I18: 280 | J18: =+H18*I18 -> 2800
... A38: =ROW(A33) -> 33 | B38: SAFETY HARNESS BELT WITH LANYARD (Double) | D38: ANSI Z 3591 | G38: EA | H38: 20 | I38: 110 | J38: =+H38*I38 -> 2200
A39: Purpose | I39: Sum | J39: =SUM(J6:J38) -> 63510
A40: * There will be an additional administration expense and financial expense (Depend on contract) deduction of total provision cost price.
O43: SUB-CON | T43: HDEC
O44: In Charge | P44: ADM | Q44: PCM | R44: PM | T44: Construction | U44: Subcon(PC) | V44: Account | Y44: ADM
V45: In Charge | W45: Manager
X47: HEC | Y47: ADM
O69: PROJECT MANAGER | P69: PROJECT MANAGER | S69: ADM
O73: PROJECT MANAGER | P73: PROJECT MANAGER | S73: PCM

Sheet MRS LIST
A1: ■ Purchase Requisition of Equipment Rental | J1: =+MRS!J1 -> DAESHIN PLANT
A2: =+MRS!A2 -> PJT : SACE2 | D2: =+MRS!D2 -> Division (In charge Name) : ADMIN MANAGER (Dong Chang Kim) | J2: =+MRS!J2 -> Subcontract name (SAC2-SC-IK-SMP-01)
A3: =+MRS!A3 -> MRS No : SAC2-DS-MRS-0463 | K3: =+MRS!L3 -> 46280
A4: No | B4: Item | D4: Specification (Model / Manufacturer / Size) | G4: Unit | H4: Q'ty | I4: Unit Price | J4: Total Price | K4: Remarks
A6: =+MRS!A6 -> 1 | B6: =MRS!B6 -> BOW SHACKLE | D6: =MRS!D6 -> 1 1/2"X17TON | G6: =MRS!G6 -> EA | H6: =MRS!H6 -> 4 | I6: =MRS!I6 -> 110 | J6: =MRS!J6 -> 440
A7: =+MRS!A7 -> 2 | B7: =MRS!B7 -> BOW SHACKLE | D7: =MRS!D7 -> 1 1/4"X12TON | G7: =MRS!G7 -> EA | H7: =MRS!H7 -> 4 | I7: =MRS!I7 -> 70 | J7: =MRS!J7 -> 280
A8: =+MRS!A8 -> 3 | B8: =MRS!B8 -> BOW SHACKLE | D8: =MRS!D8 -> 1 3/4"X25TON | G8: =MRS!G8 -> EA | H8: =MRS!H8 -> 4 | I8: =MRS!I8 -> 210 | J8: =MRS!J8 -> 840
A9: =+MRS!A9 -> 4 | B9: =MRS!B9 -> BOW SHACKLE | D9: =MRS!D9 -> 1"X8.5TON | G9: =MRS!G9 -> EA | H9: =MRS!H9 -> 4 | I9: =MRS!I9 -> 34 | J9: =MRS!J9 -> 136
A10: =+MRS!A10 -> 5 | B10: =MRS!B10 -> BOW SHACKLE | D10: =MRS!D10 -> 1"X8.5TON | G10: =MRS!G10 -> EA | H10: =MRS!H10 -> 100 | I10: =MRS!I10 -> 34 | J10: =MRS!J10 -> 3400
A11: =+MRS!A11 -> 6 | B11: =MRS!B11 -> BOW SHACKLE | D11: =MRS!D11 -> 1/2"X2TON | G11: =MRS!G11 -> EA | H11: =MRS!H11 -> 24 | I11: =MRS!I11 -> 10 | J11: =MRS!J11 -> 240
A12: =+MRS!A12 -> 7 | B12: =MRS!B12 -> BOW SHACKLE | D12: =MRS!D12 -> 2"X35TON | G12: =MRS!G12 -> EA | H12: =MRS!H12 -> 2 | I12: =MRS!I12 -> 320 | J12: =MRS!J12 -> 640
A13: =+MRS!A13 -> 8 | B13: =MRS!B13 -> BOW SHACKLE | D13: =MRS!D13 -> 3/4"X4.75TON | G13: =MRS!G13 -> EA | H13: =MRS!H13 -> 24 | I13: =MRS!I13 -> 20 | J13: =MRS!J13 -> 480
A14: =+MRS!A14 -> 9 | B14: =MRS!B14 -> BOW SHACKLE | D14: =MRS!D14 -> 3/4"X4.75TON | G14: =MRS!G14 -> EA | H14: =MRS!H14 -> 200 | I14: =MRS!I14 -> 20 | J14: =MRS!J14 -> 4000
A15: =+MRS!A15 -> 10 | B15: =MRS!B15 -> BOW SHACKLE | D15: =MRS!E15 -> 0 | G15: =MRS!G15 -> EA | H15: =MRS!H15 -> 24 | I15: =MRS!I15 -> 25 | J15: =MRS!J15 -> 600
A16: =+MRS!#REF! -> #REF! | B16: =MRS!#REF! -> #REF! | D16: =MRS!#REF! -> #REF! | G16: =MRS!#REF! -> #REF! | H16: =MRS!#REF! -> #REF! | I16: =MRS!#REF! -> #REF! | J16: =MRS!#REF! -> #REF!
A17: =+MRS!#REF! -> #REF! | B17: =MRS!#REF! -> #REF! | D17: =MRS!#REF! -> #REF! | G17: =MRS!#REF! -> #REF! | H17: =MRS!#REF! -> #REF! | I17: =MRS!#REF! -> #REF! | J17: =MRS!#REF! -> #REF!
A18: =+MRS!#REF! -> #REF! | B18: =MRS!#REF! -> #REF! | D18: =MRS!#REF! -> #REF! | G18: =MRS!#REF! -> #REF! | H18: =MRS!#REF! -> #REF! | I18: =MRS!#REF! -> #REF! | J18: =MRS!#REF! -> #REF!

Sheet PO 1st page
M2: BRANCH OF HYUNDAI ENG. & CONST. CO., LTD.
M3: P. O. Box 77249, Al Khobar 31952
M4: kingdom of Saudi Arabia
B5: C.R. 2051041774 & VAT No.: 300000504500003 | M5: Tel: +966-13-845-1088
M6: Fax: +966-13-845-1099
B9: TO: | C9: AMT(Alam Alamani Trading Company)
C10: CR No. : | D10: 2051229875 | J10: P/O Date: | K10: =MRS!L3 -> 46280
C11: VAT No. : | D11: 311236644400003 | J11: P/O No.: | K11: =SUBSTITUTE(SUBSTITUTE(+MRS!A3," MRS No : ",""),"-MRS","-PO") -> SAC2-DS-PO-0463
C12: In Charge : | D12: Rafeeq Kotyadi | J12: (Please mention this No. in
D13: +966 56 482 5879 / Email: sales@alamaniya.com | J13: All future correspondence)
C14: Building No. 3345,Ath Thuqbah Dist. Al Khobar 34623, KSA | J14: Quote Ref. : | K14: QT26-1931
C15: Mobile: | D15: +966 56 482 5879 | J15: Date- | K15: 46279
B18: PURCHASE ORDER
B20: WE ARE PLEASED TO PLACE AN ORDER WITH YOU FOR THE GOODS DESCRIBED BELOW. THE ORDER SHALL BE SUBJECT TO THE TERMS AND CONDITIONS SET OUR
B21: BELOW AND ATTACHED. PLEASE SIGN AND RETURN THE ENCLOSED COPY OF THIS ORDER AS CONFIRMATION OF YOUR ACCEPTANCE OF IT WITHIN A WEEK
B22: OTHERWISE THIS ORDER SHALL BE REGARDED AS BEING ACCEPTED BY YOU.
B25: 1 | C25: GOODS
C26: Site Materials | M26: [Please refer to attached Scope of supply & Quotation for more details]
B28: 2 | C28: P/O AMOUNT
C29: Material Value | E29: : | F29: ='PO 2nd page'!G39 -> 63510
C30: VAT 15% | E30: : | F30: ='PO 2nd page'!G40 -> 9526.5
C31: Total Amount | E31: : | F31: ='PO 2nd page'!G41 -> 73036.5
B33: 3 | C33: PAYMENT TERMS
C34: 100% Payment after Delivery within 35 days with submission of the following Documents.
C35: a) Tax E-Invoice (From Zakat, Tax and Customs Authority)
C36: b) Delivery/Dispatch Note [Counter signed by Site Representative]
B38: 4 | C38: DELIVERY TERMS
C39: Delivery by Seller to Jafurah HYUNDAI Laydown within a Week after receipt of PO.
B41: 5 | C41: OTHER TERMS AND CONDITIONS
C42: a) Any quantity rejected by the Buyer owing to its poor quality and non conformity of specification shall be replaced and re-delivered
C43: by Seller to Buyer at no extra costs
C44: b) Material Certificate, Data Sheet, Safety Data Sheet and other documents which may required by ARAMCO in material receiving
C45: inspection should be submitted to Buyer
C46: c) MTC / MSDS, Others, If required by Client
B48: 6 | C48: CONTACT POINT:
B49: - | C49: Delivery & Payment : Dong Chang Kim / Daeshin Admin. [ Mobile No. : +966 53 748 5762 / Email : kdchjs@daeshinplant.com ]
B50: - | C50: Commercial (Purchaser) : Youngkyu Choi / Daeshin Planning [ Mobile No. : +966 53 952 0931 / Email : ykchoi@daeshinplant.com ]
B51: - | C51: Invoicing : Nehal Kauser / HDEC Purchase PIC [ Mobile No. : +966 50 610 2363 / Email : nehal_kauser@hdec.co.kr ]
B53: 7 | C53: Bank Account Details:
B54: - | C54: ACCOUNT NAME | F54: ALAM ALAMANI TRADING COMPANY | P54: =UPPER(F54) -> ALAM ALAMANI TRADING COMPANY
...

Sheet PO 2nd page
A2: PO NO. : | B2: =+'PO 1st page'!K11 -> SAC2-DS-PO-0463 | C2: Scope of Supply
A3: DATE : | B3: =+'PO 1st page'!K10 -> 46280 | E3: Jafurah Utilities, Sulfur and Interconnecting Systems(Pkg-2)
A4: S. NO | B4: DESCRIPTION | D4: QTY | E4: UNIT | F4: ='PO 1st page'!C9 -> AMT(Alam Alamani Trading Company) | H4: Remarks (Details)
F5: Unit Price | G5: Total Amount
A6: =ROW(A1) -> 1 | B6: =_xlfn.CONCAT(MRS!B6," ",MRS!D6) -> BOW SHACKLE 1 1/2"X17TON | D6: =MRS!G6 -> EA | E6: =MRS!H6 -> 4 | F6: =MRS!I6 -> 110 | G6: =MRS!J6 -> 440 | H6: One time
A7: =ROW(A2) -> 2 | B7: =_xlfn.CONCAT(MRS!B7," ",MRS!D7) -> BOW SHACKLE 1 1/4"X12TON | D7: =MRS!G7 -> EA | E7: =MRS!H7 -> 4 | F7: =MRS!I7 -> 70 | G7: =MRS!J7 -> 280
A8: =ROW(A3) -> 3 | B8: =_xlfn.CONCAT(MRS!B8," ",MRS!D8) -> BOW SHACKLE 1 3/4"X25TON | D8: =MRS!G8 -> EA | E8: =MRS!H8 -> 4 | F8: =MRS!I8 -> 210 | G8: =MRS!J8 -> 840
A9: =ROW(A4) -> 4 | B9: =_xlfn.CONCAT(MRS!B9," ",MRS!D9) -> BOW SHACKLE 1"X8.5TON | D9: =MRS!G9 -> EA | E9: =MRS!H9 -> 4 | F9: =MRS!I9 -> 34 | G9: =MRS!J9 -> 136
A10: =ROW(A5) -> 5 | B10: =_xlfn.CONCAT(MRS!B10," ",MRS!D10) -> BOW SHACKLE 1"X8.5TON | D10: =MRS!G10 -> EA | E10: =MRS!H10 -> 100 | F10: =MRS!I10 -> 34 | G10: =MRS!J10 -> 3400
A11: =ROW(A6) -> 6 | B11: =_xlfn.CONCAT(MRS!B11," ",MRS!D11) -> BOW SHACKLE 1/2"X2TON | D11: =MRS!G11 -> EA | E11: =MRS!H11 -> 24 | F11: =MRS!I11 -> 10 | G11: =MRS!J11 -> 240
A12: =ROW(A7) -> 7 | B12: =_xlfn.CONCAT(MRS!B12," ",MRS!D12) -> BOW SHACKLE 2"X35TON | D12: =MRS!G12 -> EA | E12: =MRS!H12 -> 2 | F12: =MRS!I12 -> 320 | G12: =MRS!J12 -> 640
A13: =ROW(A8) -> 8 | B13: =_xlfn.CONCAT(MRS!B13," ",MRS!D13) -> BOW SHACKLE 3/4"X4.75TON | D13: =MRS!G13 -> EA | E13: =MRS!H13 -> 24 | F13: =MRS!I13 -> 20 | G13: =MRS!J13 -> 480
A14: =ROW(A9) -> 9 | B14: =_xlfn.CONCAT(MRS!B14," ",MRS!D14) -> BOW SHACKLE 3/4"X4.75TON | D14: =MRS!G14 -> EA | E14: =MRS!H14 -> 200 | F14: =MRS!I14 -> 20 | G14: =MRS!J14 -> 4000
A15: =ROW(A10) -> 10 | B15: =_xlfn.CONCAT(MRS!B15," ",MRS!D15) -> BOW SHACKLE 7/8"X6.5TON | D15: =MRS!G15 -> EA | E15: =MRS!H15 -> 24 | F15: =MRS!I15 -> 25 | G15: =MRS!J15 -> 600
A16: =ROW(A11) -> 11 | B16: =_xlfn.CONCAT(MRS!B16," ",MRS!D16) -> BOW SHACKLE 7/8"X6.5TON | D16: =MRS!G16 -> EA | E16: =MRS!H16 -> 200 | F16: =MRS!I16 -> 25 | G16: =MRS!J16 -> 5000
A17: =ROW(A12) -> 12 | B17: =_xlfn.CONCAT(MRS!B17," ",MRS!D17) -> CHAIN BLOCK 1.5TONX3MTR | D17: =MRS!G17 -> EA | E17: =MRS!H17 -> 10 | F17: =MRS!I17 -> 240 | G17: =MRS!J17 -> 2400
A18: =ROW(A13) -> 13 | B18: =_xlfn.CONCAT(MRS!B18," ",MRS!D18) -> CHAIN BLOCK 2TONX3MTR | D18: =MRS!G18 -> EA | E18: =MRS!H18 -> 10 | F18: =MRS!I18 -> 280 | G18: =MRS!J18 -> 2800
... A38: =ROW(A33) -> 33 | B38: =_xlfn.CONCAT(MRS!B38," ",MRS!D38) -> SAFETY HARNESS BELT WITH LANYARD (Double) ANSI Z 3591 | D38: =MRS!G38 -> EA | E38: =MRS!H38 -> 20 | F38: =MRS!I38 -> 110 | G38: =MRS!J38 -> 2200
A39: Sub Total Amount | G39: =SUM(G6:G38) -> 63510
A40: VAT 15% | G40: =+G39*0.15 -> 9526.5
A41: Grand Total in SAR | G41: =G40+G39 -> 73036.5
A42: =" 1) Above Price are as per your quotation with ref "&'PO 1st page'!K14 -> 1) Above Price are as per your quotation with ref QT26-1931
A43: 2) Details of each item are attached separately.
A45: Page 2/2
