Workbook

Sheet MRS
A1: ■ Purchase Requisition of Material / Manpower / Equipment Rental / ETC. | J1: DAESHIN PLANT
A2: PJT : SACE2 | D2: Division (In charge Name) : ADMIN MANAGER (Dong Chang Kim) | J2: Subcontract name (SAC2-SC-IK-SMP-01)
A3: MRS No : SAC2-DS-MRS-0080 | E3: =+L3 -> 45805 | L3: 45805
A4: No | B4: Item | D4: Specification (Model / Manufacturer / Size) | G4: Unit | H4: Qty | I4: Unit Price (SAR) (Exclude VAT) | J4: Total Price (SAR) (Exclude VAT) | K4: Vendor Name | L4: Remarks
A6: =ROW(A2) -> 2 | B6: Air ticket | D6: India DMM to COK | H6: 1 | I6: 2400 | J6: =I6 -> 2400 | K6: GTA | L6: Monthly
A7: =ROW(A2) -> 2 | B7: Air ticket | D7: India DMM to CCJ | H7: 1 | I7: 2350 | J7: =I7 -> 2350
A8: =ROW(A3) -> 3 | B8: Air ticket | D8: India DMM to DEL | H8: 1 | I8: 1800 | J8: =I8 -> 1800
A9: =ROW(A4) -> 4 | B9: Air ticket | D9: India DMM to CCU | H9: 1 | I9: 2100 | J9: =I9 -> 2100
A10: =ROW(A5) -> 5 | B10: Air ticket | D10: India DMM to LKO | H10: 1 | I10: 2200 | J10: =I10 -> 2200
A11: =ROW(A6) -> 6 | B11: Air ticket | D11: India DMM to MAA | H11: 1 | I11: 2050 | J11: =I11 -> 2050
A12: =ROW(A7) -> 7 | B12: Air ticket | D12: India DMM to BOM | H12: 1 | I12: 1800 | J12: =I12 -> 1800
A13: =ROW(A8) -> 8 | B13: Air ticket | D13: India DMM to BLR | H13: 1 | I13: 2200 | J13: =I13 -> 2200
A14: =ROW(A9) -> 9 | B14: Air ticket | D14: India DMM to IXE | H14: 1 | I14: 2350 | J14: =I14 -> 2350
A15: =ROW(A10) -> 10 | B15: Air ticket | D15: India DMM to PAT | H15: 1 | I15: 2350 | J15: =I15 -> 2350
A16: =ROW(A11) -> 11 | B16: Air ticket | D16: India DMM to GOA | H16: 1 | I16: 2250 | J16: =I16 -> 2250
A17: =ROW(A12) -> 12 | B17: Air ticket | D17: India DMM to GAY | H17: 1 | I17: 2100 | J17: =I17 -> 2100
A18: =ROW(A13) -> 13 | B18: Air ticket | D18: India DMM to HYD | H18: 1 | I18: 2200 | J18: =I18 -> 2200
... A30: =ROW(A25) -> 25 | B30: Air ticket | D30: Nepal DMM to KTM | H30: 1 | I30: 2100 | J30: =I30 -> 2100
A31: Purpose | I31: Sum | J31: =SUM(J6:J30) -> 57100
A32: * There will be an additional administration expense and financial expense (Depend on contract) deduction of total provision cost price.
S33: HEC | T33: PCM | U33: ADM | V33: PM
T35: / | U35: / | V35: /
O36: Requesting | P36: JV Area PIC | Q36: PCM (Subcon)
O37: Company | S37: HDEC | T37: PCM | U37: ADM | V37: PM
O39: / | P39: / | Q39: / | T39: / | U39: / | V39: /
T55: PROJECT MANAGER
O61: PROJECT MANAGER | P61: PROJECT MANAGER | Q61: PROJECT MANAGER | T61: PCM | U61: ADM | V61: PROJECT MANAGER
O65: PROJECT MANAGER | P65: PROJECT MANAGER | Q65: PROJECT MANAGER | T65: ADM | U65: PCM | V65: PROJECT MANAGER

Sheet MRS LIST
A1: ■ Purchase Requisition of Equipment Rental | J1: =+MRS!J1 -> DAESHIN PLANT
A2: =+MRS!A2 -> PJT : SACE2 | D2: =+MRS!D2 -> Division (In charge Name) : ADMIN MANAGER (Dong Chang Kim) | J2: =+MRS!J2 -> Subcontract name (SAC2-SC-IK-SMP-01)
A3: =+MRS!A3 -> MRS No : SAC2-DS-MRS-0080 | K3: =+MRS!L3 -> 45805
A4: No | B4: Item | D4: Specification (Model / Manufacturer / Size) | G4: Unit | H4: Q'ty | I4: Unit Price | J4: Total Price | K4: Remarks
A6: =+MRS!#REF! -> #REF! | B6: =MRS!#REF! -> #REF! | D6: =MRS!#REF! -> #REF! | G6: =MRS!#REF! -> #REF! | H6: =MRS!#REF! -> #REF! | I6: =MRS!#REF! -> #REF! | J6: =MRS!#REF! -> #REF!
A7: =+MRS!A7 -> 2 | B7: =MRS!B7 -> Air ticket | D7: =MRS!D7 -> India DMM to CCJ | G7: =MRS!G7 -> 0 | H7: =MRS!H7 -> 1 | I7: =MRS!I7 -> 2350 | J7: =MRS!J7 -> 2350
A8: =+MRS!A8 -> 3 | B8: =MRS!B8 -> Air ticket | D8: =MRS!D8 -> India DMM to DEL | G8: =MRS!G8 -> 0 | H8: =MRS!H8 -> 1 | I8: =MRS!I8 -> 1800 | J8: =MRS!J8 -> 1800
A9: =+MRS!A9 -> 4 | B9: =MRS!B9 -> Air ticket | D9: =MRS!D9 -> India DMM to CCU | G9: =MRS!G9 -> 0 | H9: =MRS!H9 -> 1 | I9: =MRS!I9 -> 2100 | J9: =MRS!J9 -> 2100
A10: =+MRS!A10 -> 5 | B10: =MRS!B10 -> Air ticket | D10: =MRS!D10 -> India DMM to LKO | G10: =MRS!G10 -> 0 | H10: =MRS!H10 -> 1 | I10: =MRS!I10 -> 2200 | J10: =MRS!J10 -> 2200
A11: =+MRS!A11 -> 6 | B11: =MRS!B11 -> Air ticket | D11: =MRS!D11 -> India DMM to MAA | G11: =MRS!G11 -> 0 | H11: =MRS!H11 -> 1 | I11: =MRS!I11 -> 2050 | J11: =MRS!J11 -> 2050
A12: =+MRS!A12 -> 7 | B12: =MRS!B12 -> Air ticket | D12: =MRS!D12 -> India DMM to BOM | G12: =MRS!G12 -> 0 | H12: =MRS!H12 -> 1 | I12: =MRS!I12 -> 1800 | J12: =MRS!J12 -> 1800
A13: =+MRS!A13 -> 8 | B13: =MRS!B13 -> Air ticket | D13: =MRS!D13 -> India DMM to BLR | G13: =MRS!G13 -> 0 | H13: =MRS!H13 -> 1 | I13: =MRS!I13 -> 2200 | J13: =MRS!J13 -> 2200
A14: =+MRS!A14 -> 9 | B14: =MRS!B14 -> Air ticket | D14: =MRS!D14 -> India DMM to IXE | G14: =MRS!G14 -> 0 | H14: =MRS!H14 -> 1 | I14: =MRS!I14 -> 2350 | J14: =MRS!J14 -> 2350
A15: =+MRS!A15 -> 10 | B15: =MRS!B15 -> Air ticket | D15: =MRS!D15 -> India DMM to PAT | G15: =MRS!G15 -> 0 | H15: =MRS!H15 -> 1 | I15: =MRS!I15 -> 2350 | J15: =MRS!J15 -> 2350
A16: =+MRS!A16 -> 11 | B16: =MRS!B16 -> Air ticket | D16: =MRS!D16 -> India DMM to GOA | G16: =MRS!G16 -> 0 | H16: =MRS!H16 -> 1 | I16: =MRS!I16 -> 2250 | J16: =MRS!J16 -> 2250
A17: =+MRS!A17 -> 12 | B17: =MRS!B17 -> Air ticket | D17: =MRS!D17 -> India DMM to GAY | G17: =MRS!G17 -> 0 | H17: =MRS!H17 -> 1 | I17: =MRS!I17 -> 2100 | J17: =MRS!J17 -> 2100
A18: =+MRS!A18 -> 13 | B18: =MRS!B18 -> Air ticket | D18: =MRS!D18 -> India DMM to HYD | G18: =MRS!G18 -> 0 | H18: =MRS!H18 -> 1 | I18: =MRS!I18 -> 2200 | J18: =MRS!J18 -> 2200
... A30: =+MRS!A30 -> 25 | B30: =MRS!B30 -> Air ticket | D30: =MRS!D30 -> Nepal DMM to KTM | G30: =MRS!G30 -> 0 | H30: =MRS!H30 -> 1 | I30: =MRS!I30 -> 2100 | J30: =MRS!J30 -> 2100

Sheet PO 1st page
M2: HYUNDAI ENG. & CONST. CO., LTD.
M3: P. O. Box 77249, Al Khobar 31952
M4: kingdom of Saudi Arabia
B5: C.R. 2051041774 & VAT No.: 300000504500003 | M5: Tel: +966-13-845-1088
M6: Fax: +966-13-845-1099
B9: TO: | C9: GTATT(Global Traveler Agency For Travel & Tourism)
C10: CR No. : | D10: 2053023946 | J10: P/O Date: | K10: =MRS!L3 -> 45805
C11: VAT No. : | D11: 300565091900003 | J11: P/O No.: | K11: =SUBSTITUTE(SUBSTITUTE(+MRS!A3," MRS No : ",""),"-MRS","-PO") -> SAC2-DS-PO-0080
C12: In Charge : | D12: Naveed Shahzad | J12: (Please mention this No. in
D13: +966 55 1011741 / Email:naveed@gtb.com.sa | J13: All future correspondence)
C14: Quds Street P.O. Box 60787 - Postal Code 31911 | J14: Quote Ref. :
C15: Mobile : +966 55 1011741 / +966 13 8552233 | J15: Date-
B18: PURCHASE ORDER
B20: WE ARE PLEASED TO PLACE AN ORDER WITH YOU FOR THE GOODS DESCRIBED BELOW. THE ORDER SHALL BE SUBJECT TO THE TERMS AND CONDITIONS SET OUR
B21: BELOW AND ATTACHED. PLEASE SIGN AND RETURN THE ENCLOSED COPY OF THIS ORDER AS CONFIRMATION OF YOUR ACCEPTANCE OF IT WITHIN A WEEK
B22: OTHERWISE THIS ORDER SHALL BE REGARDED AS BEING ACCEPTED BY YOU.
B25: 1 | C25: GOODS
M26: [Please refer to attached Scope of supply & Quotation for more details]
B28: 2 | C28: P/O AMOUNT
C29: Material Value | E29: : | F29: Monthly
C30: VAT 15% | E30: :
C31: Total Amount | E31: :
B33: 3 | C33: PAYMENT TERMS
C34: 100% Payment after Delivery within 35 days with submission of the following Documents.
C35: a) Tax E-Invoice (From Zakat, Tax and Customs Authority)
C36: b) Delivery/Dispatch Note [Counter signed by Site Representative]
B38: 4 | C38: DELIVERY TERMS
C39: Delivery by Seller to Jafurah HYUNDAI Laydown within a Week after receipt of PO.
B41: 5 | C41: OTHER TERMS AND CONDITIONS
C42: a) Any quantity rejected by the Buyer owing to its poor quality and non conformity of specification shall be replaced and re-delivered
C43: by Seller to Buyer at no extra costs
C44: b) Material Certificate, Data Sheet, Safety Data Sheet and other documents which may required by ARAMCO in material receiving
C45: inspection should be submitted to Buyer
C46: c) MTC / MSDS, Others, If required by Client
B48: 6 | C48: CONTACT POINT:
B49: - | C49: Delivery & Payment : Dong Chang Kim / Daeshin Admin. [ Mobile No. : +966 53 748 5762 / Email : kdchjs@daeshinplant.com ]
B50: - | C50: Commercial (Purchaser) : Youngkyu Choi / Daeshin Planning [ Mobile No. : +966 53 952 0931 / Email : ykchoi@daeshinplant.com ]
B51: - | C51: Invoicing : Nehal Kauser / HDEC Purchase PIC [ Mobile No. : +966 50 610 2363 / Email : nehal_kauser@hdec.co.kr ]
B56: Client | J56: Contractor
B58: Signature: | J58: Signature:
...

Sheet PO 2nd page
A2: PO NO. : | B2: =+'PO 1st page'!K11 -> SAC2-DS-PO-0080 | C2: Scope of Supply
A3: DATE : | B3: =+'PO 1st page'!K10 -> 45805 | E3: Jafurah Utilities, Sulfur and Interconnecting Systems(Pkg-2)
A4: S. NO | B4: DESCRIPTION | D4: QTY | E4: UNIT | F4: ='PO 1st page'!C9 -> GTATT(Global Traveler Agency For Travel & Tourism) | H4: Remarks (Details)
F5: Unit Price | G5: Total Amount
A6: =ROW(A1) -> 1 | B6: =+'MRS LIST'!B6&" "&MRS!#REF! -> #REF! | D6: =+'MRS LIST'!G6 -> #REF! | E6: =+'MRS LIST'!H6 -> #REF! | F6: =+'MRS LIST'!I6 -> #REF! | G6: =+'MRS LIST'!J6 -> #REF! | H6: =MRS!#REF! -> #REF!
A7: =ROW(A2) -> 2 | B7: =+'MRS LIST'!B7&" "&MRS!D7 -> Air ticket India DMM to CCJ | D7: =+'MRS LIST'!G7 -> 0 | E7: =+'MRS LIST'!H7 -> 1 | F7: =+'MRS LIST'!I7 -> 2350 | G7: =+'MRS LIST'!J7 -> 2350
A8: =ROW(A3) -> 3 | B8: =+'MRS LIST'!B8&" "&MRS!D8 -> Air ticket India DMM to DEL | D8: =+'MRS LIST'!G8 -> 0 | E8: =+'MRS LIST'!H8 -> 1 | F8: =+'MRS LIST'!I8 -> 1800 | G8: =+'MRS LIST'!J8 -> 1800
A9: =ROW(A4) -> 4 | B9: =+'MRS LIST'!B9&" "&MRS!D9 -> Air ticket India DMM to CCU | D9: =+'MRS LIST'!G9 -> 0 | E9: =+'MRS LIST'!H9 -> 1 | F9: =+'MRS LIST'!I9 -> 2100 | G9: =+'MRS LIST'!J9 -> 2100
A10: =ROW(A5) -> 5 | B10: =+'MRS LIST'!B10&" "&MRS!D10 -> Air ticket India DMM to LKO | D10: =+'MRS LIST'!G10 -> 0 | E10: =+'MRS LIST'!H10 -> 1 | F10: =+'MRS LIST'!I10 -> 2200 | G10: =+'MRS LIST'!J10 -> 2200
A11: =ROW(A6) -> 6 | B11: =+'MRS LIST'!B11&" "&MRS!D11 -> Air ticket India DMM to MAA | D11: =+'MRS LIST'!G11 -> 0 | E11: =+'MRS LIST'!H11 -> 1 | F11: =+'MRS LIST'!I11 -> 2050 | G11: =+'MRS LIST'!J11 -> 2050
A12: =ROW(A7) -> 7 | B12: =+'MRS LIST'!B12&" "&MRS!D12 -> Air ticket India DMM to BOM | D12: =+'MRS LIST'!G12 -> 0 | E12: =+'MRS LIST'!H12 -> 1 | F12: =+'MRS LIST'!I12 -> 1800 | G12: =+'MRS LIST'!J12 -> 1800
A13: =ROW(A8) -> 8 | B13: =+'MRS LIST'!B13&" "&MRS!D13 -> Air ticket India DMM to BLR | D13: =+'MRS LIST'!G13 -> 0 | E13: =+'MRS LIST'!H13 -> 1 | F13: =+'MRS LIST'!I13 -> 2200 | G13: =+'MRS LIST'!J13 -> 2200
A14: =ROW(A9) -> 9 | B14: =+'MRS LIST'!B14&" "&MRS!D14 -> Air ticket India DMM to IXE | D14: =+'MRS LIST'!G14 -> 0 | E14: =+'MRS LIST'!H14 -> 1 | F14: =+'MRS LIST'!I14 -> 2350 | G14: =+'MRS LIST'!J14 -> 2350
A15: =ROW(A10) -> 10 | B15: =+'MRS LIST'!B15&" "&MRS!D15 -> Air ticket India DMM to PAT | D15: =+'MRS LIST'!G15 -> 0 | E15: =+'MRS LIST'!H15 -> 1 | F15: =+'MRS LIST'!I15 -> 2350 | G15: =+'MRS LIST'!J15 -> 2350
A16: =ROW(A11) -> 11 | B16: =+'MRS LIST'!B16&" "&MRS!D16 -> Air ticket India DMM to GOA | D16: =+'MRS LIST'!G16 -> 0 | E16: =+'MRS LIST'!H16 -> 1 | F16: =+'MRS LIST'!I16 -> 2250 | G16: =+'MRS LIST'!J16 -> 2250
A17: =ROW(A12) -> 12 | B17: =+'MRS LIST'!B17&" "&MRS!D17 -> Air ticket India DMM to GAY | D17: =+'MRS LIST'!G17 -> 0 | E17: =+'MRS LIST'!H17 -> 1 | F17: =+'MRS LIST'!I17 -> 2100 | G17: =+'MRS LIST'!J17 -> 2100
A18: =ROW(A13) -> 13 | B18: =+'MRS LIST'!B18&" "&MRS!D18 -> Air ticket India DMM to HYD | D18: =+'MRS LIST'!G18 -> 0 | E18: =+'MRS LIST'!H18 -> 1 | F18: =+'MRS LIST'!I18 -> 2200 | G18: =+'MRS LIST'!J18 -> 2200
... A24: =ROW(A19) -> 19 | B24: =+'MRS LIST'!B24&" "&MRS!D24 -> Air ticket Pakistan DMM to SKT | D24: =+'MRS LIST'!G24 -> 0 | E24: =+'MRS LIST'!H24 -> 1 | F24: =+'MRS LIST'!I24 -> 2100 | G24: =+'MRS LIST'!J24 -> 2100
A25: =ROW(A20) -> 20 | B25: =+'MRS LIST'!B25&" "&MRS!D25 -> Air ticket Pakistan DMM to ISB | D25: =+'MRS LIST'!G25 -> 0 | E25: =+'MRS LIST'!H25 -> 1 | F25: =+'MRS LIST'!I25 -> 2100 | G25: =+'MRS LIST'!J25 -> 2100 | N25: s
A26: =ROW(A21) -> 21 | B26: =+'MRS LIST'!B26&" "&MRS!D26 -> Air ticket Pakistan DMM to LHE | D26: =+'MRS LIST'!G26 -> 0 | E26: =+'MRS LIST'!H26 -> 1 | F26: =+'MRS LIST'!I26 -> 2100 | G26: =+'MRS LIST'!J26 -> 2100
A27: =ROW(A22) -> 22 | B27: =+'MRS LIST'!B27&" "&MRS!D27 -> Air ticket Philippines DMM to MNL | D27: =+'MRS LIST'!G27 -> 0 | E27: =+'MRS LIST'!H27 -> 1 | F27: =+'MRS LIST'!I27 -> 3200 | G27: =+'MRS LIST'!J27 -> 3200
A28: =ROW(A23) -> 23 | B28: =+'MRS LIST'!B28&" "&MRS!D28 -> Air ticket Philippines DMM to CRK | D28: =+'MRS LIST'!G28 -> 0 | E28: =+'MRS LIST'!H28 -> 1 | F28: =+'MRS LIST'!I28 -> 3600 | G28: =+'MRS LIST'!J28 -> 3600
A29: =ROW(A24) -> 24 | B29: =+'MRS LIST'!B29&" "&MRS!D29 -> Air ticket Bangladesh DMM to DAC | D29: =+'MRS LIST'!G29 -> 0 | E29: =+'MRS LIST'!H29 -> 1 | F29: =+'MRS LIST'!I29 -> 2250 | G29: =+'MRS LIST'!J29 -> 2250
A30: =ROW(A25) -> 25 | B30: =+'MRS LIST'!B30&" "&MRS!D30 -> Air ticket Nepal DMM to KTM | D30: =+'MRS LIST'!G30 -> 0 | E30: =+'MRS LIST'!H30 -> 1 | F30: =+'MRS LIST'!I30 -> 2100 | G30: =+'MRS LIST'!J30 -> 2100
A31: Sub Total Amount | G31: =SUM(G6:G30) -> #REF!
A32: VAT 15%
A33: Grand Total in SAR | G33: =G32+G31 -> #REF!
A34: =" 1) Above Price are as per your quotation with ref "&'PO 1st page'!K14 -> 1) Above Price are as per your quotation with ref
A35: 2) Details of each item are attached separately.
A37: Page 2/2
