Workbook

Sheet MRS
A1: ■ Purchase Requisition of Material / Manpower / Equipment Rental / ETC. | J1: DAESHIN PLANT
A2: PJT : SACE2 | D2: Division (In charge Name) : ADMIN MANAGER (Sang Yeun Cho) | J2: Subcontract name (SAC2-SC-IK-SMP-01)
A3: MRS No : SAC2-DS-MRS-0123 | E3: =+L3 -> 45909 | L3: 45909
A4: No | B4: Item | D4: Specification (Model / Manufacturer / Size) | G4: Unit | H4: Qty | I4: Unit Price (SAR) (Exclude VAT) | J4: Total Price (SAR) (Exclude VAT) | K4: Vendor Name | L4: Remarks
A6: =ROW(A1) -> 1 | B6: Container Toilet | D6: 4 meter (2 Western Commode, 2 Indian Commode, 1 Washbasin, 3 Urinals, 4 Exhaust fan, 2 Mirror, 2 Window AC, 1 Water pressure pump, 6000 ltr Water tank, 6000 ltr Septic tank with stairs) | G6: 1 | H6: 1 | I6: 38000 | J6: =H6*I6 -> 38000 | K6: SCCL | L6: One time
A7: 2 | B7: Transportation Charges | G7: Trip | H7: 1 | I7: 2200 | J7: =H7*I7 -> 2200 | K7: " | L7: "
A8: =ROW(A3) -> 3
A9: =ROW(A4) -> 4
A10: =ROW(A5) -> 5
A11: =ROW(A6) -> 6
A12: =ROW(A7) -> 7
A13: =ROW(A8) -> 8
A14: Purpose | I14: Sum | J14: =SUM(J6:J13) -> 40200
A15: * There will be an additional administration expense and financial expense (Depend on contract) deduction of total provision cost price.
S16: HEC | T16: PCM | U16: ADM | V16: PM
T18: / | U18: / | V18: /
O19: Requesting | P19: JV Area PIC | Q19: PCM (Subcon)
O20: Company | S20: HDEC | T20: PCM | U20: ADM | V20: PM
O22: / | P22: / | Q22: / | T22: / | U22: / | V22: /
T38: PROJECT MANAGER
O44: PROJECT MANAGER | P44: PROJECT MANAGER | Q44: PROJECT MANAGER | T44: PCM | U44: ADM | V44: PROJECT MANAGER
O48: PROJECT MANAGER | P48: PROJECT MANAGER | Q48: PROJECT MANAGER | T48: ADM | U48: PCM | V48: PROJECT MANAGER

Sheet MRS LIST
A1: ■ Purchase Requisition of Equipment Rental | J1: =+MRS!J1 -> DAESHIN PLANT
A2: =+MRS!A2 -> PJT : SACE2 | D2: =+MRS!D2 -> Division (In charge Name) : ADMIN MANAGER (Sang Yeun Cho) | J2: =+MRS!J2 -> Subcontract name (SAC2-SC-IK-SMP-01)
A3: =+MRS!A3 -> MRS No : SAC2-DS-MRS-0123 | K3: =+MRS!L3 -> 45909
A4: No | B4: Item | D4: Specification (Model / Manufacturer / Size) | G4: Unit | H4: Q'ty | I4: Unit Price | J4: Total Price | K4: Remarks
A6: =+MRS!A6 -> 1 | B6: =MRS!B6 -> Container Toilet | D6: =MRS!D6 -> 4 meter (2 Western Commode, 2 Indian Commode, 1 Washbasin, 3 Urinals, 4 Exhaust fan, 2 Mirror, 2 Window AC, 1 Water pressure pump, 6000 ltr Water tank, 6000 ltr Septic tank with stairs) | G6: =MRS!G6 -> 1 | H6: =MRS!H6 -> 1 | I6: =MRS!I6 -> 38000 | J6: =MRS!J6 -> 38000
A7: =+MRS!#REF! -> #REF! | B7: =MRS!B7 -> Transportation Charges | D7: =MRS!D7 -> 0 | G7: =MRS!G7 -> Trip | H7: =MRS!H7 -> 1 | I7: =MRS!I7 -> 2200 | J7: =MRS!J7 -> 2200
A8: =+MRS!A7 -> 2 | B8: =MRS!B8 -> 0 | D8: =MRS!D8 -> 0 | G8: =MRS!G8 -> 0 | H8: =MRS!H8 -> 0 | I8: =MRS!I8 -> 0 | J8: =MRS!J8 -> 0
A9: =+MRS!A8 -> 3 | B9: =MRS!#REF! -> #REF! | D9: =MRS!#REF! -> #REF! | G9: =MRS!#REF! -> #REF! | H9: =MRS!#REF! -> #REF! | I9: =MRS!#REF! -> #REF! | J9: =MRS!#REF! -> #REF!
A10: =+MRS!#REF! -> #REF! | B10: =MRS!#REF! -> #REF! | D10: =MRS!#REF! -> #REF! | G10: =MRS!#REF! -> #REF! | H10: =MRS!#REF! -> #REF! | I10: =MRS!#REF! -> #REF! | J10: =MRS!#REF! -> #REF!
A11: =+MRS!#REF! -> #REF!
A12: =+MRS!A9 -> 4
A13: =+MRS!A10 -> 5
A14: =+MRS!A11 -> 6
A15: =+MRS!A13 -> 8
A16: =+MRS!#REF! -> #REF!
A17: =+MRS!#REF! -> #REF!

Sheet PO 1st page
M2: BRANCH OF HYUNDAI ENG. & CONST. CO., LTD.
M3: P. O. Box 77249, Al Khobar 31952
M4: kingdom of Saudi Arabia
B5: C.R. 2051041774 & VAT No.: 300000504500003 | M5: Tel: +966-13-845-1088
M6: Fax: +966-13-845-1099
B9: TO: | C9: SCCL(Sweep Care Co. Ltd.)
C10: CR No. : | D10: 2055131152 | J10: P/O Date: | K10: =MRS!L3 -> 45909
C11: VAT No. : | D11: 312009886200003 | J11: P/O No.: | K11: =SUBSTITUTE(SUBSTITUTE(+MRS!A3," MRS No : ",""),"-MRS","-PO") -> SAC2-DS-PO-0123
C12: In Charge : | D12: Mohammed Ashraf | J12: (Please mention this No. in
D13: +966 56 5759777 / info@sweepcare.com | J13: All future correspondence)
C14: Bldg 8590 Jabal Street, Jubail City | J14: Quote Ref. : | K14: SC-EQTN-2025-0601
C15: Landline : +966 13 3627417 / Mobile : +966 56 5759777 | J15: Date- | K15: 45901
B17: PURCHASE ORDER
B19: WE ARE PLEASED TO PLACE AN ORDER WITH YOU FOR THE GOODS DESCRIBED BELOW. THE ORDER SHALL BE SUBJECT TO THE TERMS AND CONDITIONS SET OUR
B20: BELOW AND ATTACHED. PLEASE SIGN AND RETURN THE ENCLOSED COPY OF THIS ORDER AS CONFIRMATION OF YOUR ACCEPTANCE OF IT WITHIN A WEEK
B21: OTHERWISE THIS ORDER SHALL BE REGARDED AS BEING ACCEPTED BY YOU.
B24: 1 | C24: GOODS
C25: Container Toilet 4 meter | M25: [Please refer to attached Scope of supply & Quotation for more details]
B27: 2 | C27: P/O AMOUNT
C28: Material Value | E28: : | F28: 40200
C29: VAT 15% | E29: : | F29: =F28*15% -> 6030
C30: Total Amount | E30: : | F30: =SUM(F28:G29) -> 46230
B32: 3 | C32: PAYMENT TERMS
C33: 100% Payment after Delivery within 35 days with submission of the following Documents.
C34: a) Tax E-Invoice (From Zakat, Tax and Customs Authority)
C35: b) Delivery/Dispatch Note [Counter signed by Site Representative]
B37: 4 | C37: DELIVERY TERMS
C38: Delivery by Seller to Jafurah HYUNDAI Laydown within a Week after receipt of PO.
B40: 5 | C40: OTHER TERMS AND CONDITIONS
C41: a) Any quantity rejected by the Buyer owing to its poor quality and non conformity of specification shall be replaced and re-delivered
C42: by Seller to Buyer at no extra costs
C43: b) Material Certificate, Data Sheet, Safety Data Sheet and other documents which may required by ARAMCO in material receiving
C44: inspection should be submitted to Buyer
C45: c) MTC / MSDS, Others, If required by Client
B47: 6 | C47: CONTACT POINT:
B48: - | C48: Delivery & Payment : Sang Yeun Cho / Daeshin Admin. [ Mobile No. : +966 53 926 8130 / Email : sycho@daeshinplant.com ]
B49: - | C49: Commercial (Purchaser) : Youngkyu Choi / Daeshin Planning [ Mobile No. : +966 53 952 0931 / Email : ykchoi@daeshinplant.com ]
B50: - | C50: Invoicing : Nehal Kauser / HDEC Purchase PIC [ Mobile No. : +966 50 610 2363 / Email : nehal_kauser@hdec.co.kr ]
B55: Client | J55: Contractor
B57: Signature: | J57: Signature:
...

Sheet PO 2nd page
A2: PO NO. : | B2: =+'PO 1st page'!K11 -> SAC2-DS-PO-0123 | C2: Scope of Supply
A3: DATE : | B3: =+'PO 1st page'!K10 -> 45909 | E3: Jafurah Utilities, Sulfur and Interconnecting Systems(Pkg-2)
A4: S. NO | B4: DESCRIPTION | D4: QTY | E4: UNIT | F4: ='PO 1st page'!C9 -> SCCL(Sweep Care Co. Ltd.) | H4: Remarks (Details)
F5: Unit Price | G5: Total Amount
A6: =ROW(A1) -> 1 | B6: =MRS!B6 &" " &MRS!D6 -> Container Toilet 4 meter (2 Western Commode, 2 Indian Commode, 1 Washbasin, 3 Urinals, 4 Exhaust fan, 2 Mirror, 2 Window AC, 1 Water pressure pump, 6000 ltr Water tank, 6000 ltr Septic tank with stairs) | D6: =+'MRS LIST'!G6 -> 1 | E6: =+'MRS LIST'!H6 -> 1 | F6: =+'MRS LIST'!I6 -> 38000 | G6: =+'MRS LIST'!J6 -> 38000 | H6: =MRS!L6 -> One time
A7: =ROW(A2) -> 2 | B7: =MRS!B7 -> Transportation Charges | D7: =+'MRS LIST'!G7 -> Trip | E7: =+'MRS LIST'!H7 -> 1 | F7: =+'MRS LIST'!I7 -> 2200 | G7: =+'MRS LIST'!J7 -> 2200 | H7: =MRS!L7 -> "
A8: =ROW(A3) -> 3
A9: =ROW(A4) -> 4
A10: =ROW(A5) -> 5
A11: =ROW(A6) -> 6
A12: =ROW(A7) -> 7
A13: =ROW(A8) -> 8
A14: =ROW(A9) -> 9
A15: =ROW(A10) -> 10
A16: =ROW(A11) -> 11
A17: =ROW(A12) -> 12
A18: Sub Total Amount | G18: =SUM(G6:G17) -> 40200
A19: VAT 15% | G19: =+G18*0.15 -> 6030
A20: Registration Fee | G20: 0
A21: Grand Total in SAR | G21: =SUM(G18:G20) -> 46230
A22: =" 1) Above Price are as per your quotation with ref "&'PO 1st page'!K14 -> 1) Above Price are as per your quotation with ref SC-EQTN-2025-0601
A23: 2) Details of each item are attached separately.
A25: Page 2/2
