Workbook

Sheet MRS
A1: ■ Purchase Requisition of Material / Manpower / Equipment Rental / ETC. | J1: DAESHIN PLANT
A2: PJT : SACE2 | D2: Division (In charge Name) : ADMIN MANAGER (Dong Chang Kim) | J2: Subcontract name (SAC2-SC-IK-SMP-01)
A3: MRS No : SAC2-DS-MRS-0472 | E3: =+L3+3 -> 46298 | L3: 46295
A4: No | B4: Item | D4: Specification (Model / Manufacturer / Size) | G4: Unit | H4: Qty | I4: Unit Price (SAR) (Exclude VAT) | J4: Total Price (SAR) (Exclude VAT) | K4: Vendor Name | L4: Remarks
A6: =ROW(A1) -> 1 | B6: Conbextra GP (25kg) | D6: General purpose non-shrink cementitious grout Consumption rate: 13.25 litres/bag | G6: KG | H6: 1000 | I6: 14 | J6: =H6*I6 -> 14000 | K6: FCL | L6: One time
J7: =H7*I7 -> 0
J8: =H8*I8 -> 0
A10: =ROW(A5) -> 5
A11: 4
A12: =ROW(A7) -> 7
A13: 5
A14: =ROW(A9) -> 9
A15: 6
A16: Purpose | I16: Sum | J16: =SUM(J6:J15) -> 14000
A17: * There will be an additional administration expense and financial expense (Depend on contract) deduction of total provision cost price.
O20: SUB-CON | T20: HDEC
O21: In Charge | P21: ADM | Q21: PCM | R21: PM | T21: Construction | U21: Subcon(PC) | V21: Account | Y21: ADM
V22: In Charge | W22: Manager
X24: HEC | Y24: ADM
T40: PROJECT MANAGER
O46: PROJECT MANAGER | P46: PROJECT MANAGER | Q46: PROJECT MANAGER | T46: PCM | U46: ADM | V46: PROJECT MANAGER
O50: PROJECT MANAGER | P50: PROJECT MANAGER | Q50: PROJECT MANAGER | T50: ADM | U50: PCM | V50: PROJECT MANAGER

Sheet MRS LIST
A1: ■ Purchase Requisition of Equipment Rental | J1: =+MRS!J1 -> DAESHIN PLANT
A2: =+MRS!A2 -> PJT : SACE2 | D2: =+MRS!D2 -> Division (In charge Name) : ADMIN MANAGER (Dong Chang Kim) | J2: =+MRS!J2 -> Subcontract name (SAC2-SC-IK-SMP-01)
A3: =+MRS!A3 -> MRS No : SAC2-DS-MRS-0472 | K3: =+MRS!L3 -> 46295
A4: No | B4: Item | D4: Specification (Model / Manufacturer / Size) | G4: Unit | H4: Q'ty | I4: Unit Price | J4: Total Price | K4: Remarks
A6: =+MRS!A6 -> 1 | B6: =MRS!B6 -> Conbextra GP (25kg) | D6: =MRS!D6 -> General purpose non-shrink cementitious grout Consumption rate: 13.25 litres/bag | G6: =MRS!G6 -> KG | H6: =MRS!H6 -> 1000 | I6: =MRS!I6 -> 14 | J6: =MRS!J6 -> 14000
A7: =+MRS!#REF! -> #REF! | B7: =MRS!B7 -> 0 | D7: =MRS!D7 -> 0 | G7: =MRS!G7 -> 0 | H7: =MRS!H7 -> 0 | I7: =MRS!I7 -> 0 | J7: =MRS!J7 -> 0
A8: =+MRS!A7 -> 0 | B8: =MRS!B8 -> 0 | D8: =MRS!D8 -> 0 | G8: =MRS!G8 -> 0 | H8: =MRS!H8 -> 0 | I8: =MRS!I8 -> 0 | J8: =MRS!J8 -> 0
A9: =+MRS!A8 -> 0 | B9: =MRS!B9 -> 0 | D9: =MRS!D9 -> 0 | G9: =MRS!G9 -> 0 | H9: =MRS!H9 -> 0 | I9: =MRS!I9 -> 0 | J9: =MRS!J9 -> 0
A10: =+MRS!A9 -> 0 | B10: =MRS!B10 -> 0 | D10: =MRS!D10 -> 0 | G10: =MRS!G10 -> 0 | H10: =MRS!H10 -> 0 | I10: =MRS!I10 -> 0 | J10: =MRS!J10 -> 0
A11: =+MRS!A10 -> 5
A12: =+MRS!A11 -> 4
A13: =+MRS!A12 -> 7
A14: =+MRS!A13 -> 5
A15: =+MRS!A15 -> 6
A16: =+MRS!#REF! -> #REF!
A17: =+MRS!#REF! -> #REF!

Sheet PO 1st page
M2: BRANCH OF HYUNDAI ENG. & CONST. CO., LTD.
M3: P. O. Box 77249, Al Khobar 31952
M4: kingdom of Saudi Arabia
B5: C.R. 2051041774 & VAT No.: 300000504500003 | M5: Tel: +966-13-845-1088
M6: Fax: +966-13-845-1099
B9: TO: | C9: FCL(Fosam Company Ltd.)
C10: CR No. : | D10: 2050106915 | J10: P/O Date: | K10: =MRS!L3 -> 46295
C11: VAT No. : | D11: 300050279500003 | J11: P/O No.: | K11: =SUBSTITUTE(SUBSTITUTE(+MRS!A3," MRS No : ",""),"-MRS","-PO") -> SAC2-DS-PO-0472
C12: In Charge : | D12: Abdulrahman Wahbe | J12: (Please mention this No. in
D13: Email: Abdulrahman.Wahbe@Fosroc.com | J13: All future correspondence)
C14: P.O. Box 21453 Jeddah 21453 Saudi Arabia | J14: Quote Ref. : | K14: QUO-187472-N0J7L8-0
C15: Landline : +966 12 6375345 | J15: Date- | K15: 45813
B17: PURCHASE ORDER
B19: WE ARE PLEASED TO PLACE AN ORDER WITH YOU FOR THE GOODS DESCRIBED BELOW. THE ORDER SHALL BE SUBJECT TO THE TERMS AND CONDITIONS SET OUR
B20: BELOW AND ATTACHED. PLEASE SIGN AND RETURN THE ENCLOSED COPY OF THIS ORDER AS CONFIRMATION OF YOUR ACCEPTANCE OF IT WITHIN A WEEK
B21: OTHERWISE THIS ORDER SHALL BE REGARDED AS BEING ACCEPTED BY YOU.
B24: 1 | C24: GOODS
C25: =MRS!$B$6 -> Conbextra GP (25kg) | M25: [Please refer to attached Scope of supply & Quotation for more details]
B27: 2 | C27: P/O AMOUNT
C28: Material Value | E28: : | F28: ='PO 2nd page'!G18 -> 14000
C29: VAT 15% | E29: : | F29: =F28*15% -> 2100
C30: Total Amount | E30: : | F30: =SUM(F28:G29) -> 16100
B32: 3 | C32: PAYMENT TERMS
C33: 100% Payment after Delivery within 35 days with submission of the following Documents.
C34: a) Tax E-Invoice (From Zakat, Tax and Customs Authority)
C35: b) Delivery/Dispatch Note [Counter signed by Site Representative]
B37: 4 | C37: DELIVERY TERMS
C38: Delivery by Seller to Jafurah HYUNDAI Laydown within a Week after receipt of PO.
B40: 5 | C40: OTHER TERMS AND CONDITIONS
C41: a) Any quantity rejected by the Buyer owing to its poor quality and non conformity of specification shall be replaced and re-delivered
C42: by Seller to Buyer at no extra costs
C43: b) Material Certificate, Data Sheet, Safety Data Sheet and other documents which may required by ARAMCO in material receiving
C44: inspection should be submitted to Buyer
C45: c) MTC / MSDS, Others, If required by Client
B47: 6 | C47: CONTACT POINT:
B48: - | C48: Delivery & Payment : Sang Yeun Cho / Daeshin Admin. [ Mobile No. : +966 53 926 8130 / Email : sycho@daeshinplant.com ]
B49: - | C49: Commercial (Purchaser) : Youngkyu Choi / Daeshin Planning [ Mobile No. : +966 53 952 0931 / Email : ykchoi@daeshinplant.com ]
B50: - | C50: Invoicing : Nehal Kauser / HDEC Purchase PIC [ Mobile No. : +966 50 610 2363 / Email : nehal_kauser@hdec.co.kr ]
B53: 7 | C53: Bank Account Details:
B54: - | C54: ACCOUNT NAME | F54: FOSAM COMPANY LTD. | P54: =UPPER(F54) -> FOSAM COMPANY LTD.
...

Sheet PO 2nd page
A2: PO NO. : | B2: =+'PO 1st page'!K11 -> SAC2-DS-PO-0472 | C2: Scope of Supply
A3: DATE : | B3: =+'PO 1st page'!K10 -> 46295 | E3: Jafurah Utilities, Sulfur and Interconnecting Systems(Pkg-2)
A4: S. NO | B4: DESCRIPTION | D4: QTY | E4: UNIT | F4: ='PO 1st page'!C9 -> FCL(Fosam Company Ltd.) | H4: Remarks (Details)
F5: Unit Price | G5: Total Amount
A6: =ROW(A1) -> 1 | B6: =CONCATENATE(MRS!B6," ",MRS!D6) -> Conbextra GP (25kg) General purpose non-shrink cementitious grout Consumption rate: 13.25 litres/bag | D6: =+'MRS LIST'!G6 -> KG | E6: =+'MRS LIST'!H6 -> 1000 | F6: =+'MRS LIST'!I6 -> 14 | G6: =+'MRS LIST'!J6 -> 14000 | H6: =MRS!L6 -> One time
A7: 2 | B7: =CONCATENATE(MRS!B7," ",MRS!D7)
A8: 3 | B8: =CONCATENATE(MRS!B8," ",MRS!D8)
A9: =ROW(A4) -> 4
A10: =ROW(A5) -> 5
A11: =ROW(A6) -> 6
A12: =ROW(A7) -> 7
A13: =ROW(A8) -> 8
A14: =ROW(A9) -> 9
A15: =ROW(A10) -> 10
A16: =ROW(A11) -> 11
A17: =ROW(A12) -> 12
A18: Sub Total Amount | G18: =SUM(G6:G17) -> 14000
A19: VAT 15% | G19: =+G18*0.15 -> 2100
A20: Registration Fee | G20: 0
A21: Grand Total in SAR | G21: =SUM(G18:G20) -> 16100
A22: =" 1) Above Price are as per your quotation with ref "&'PO 1st page'!K14 -> 1) Above Price are as per your quotation with ref QUO-187472-N0J7L8-0
A23: 2) Details of each item are attached separately.
A25: Page 2/2
