Workbook

Sheet MRS
A1: ■ Purchase Requisition of Material / Manpower / Equipment Rental / ETC. | J1: DAESHIN PLANT
A2: PJT : SACE2 | D2: Division (In charge Name) : ADMIN MANAGER (Dong Chang Kim) | J2: Subcontract name (SAC2-SC-IK-SMP-01)
A3: MRS No : SAC2-DS-MRS-0495 | E3: =+L3+3 -> 46316 | L3: 46313
A4: No | B4: Item | D4: Specification (Model / Manufacturer / Size) | G4: Unit | H4: Qty | I4: Unit Price (SAR) (Exclude VAT) | J4: Total Price (SAR) (Exclude VAT) | K4: Vendor Name | L4: Remarks
A6: =ROW(A1) -> 1 | B6: Injectable Mortar | D6: HIT-RE 500 V4/500 | G6: PC | H6: 200 | I6: 330 | J6: =H6*I6 -> 66000 | K6: HILTI | L6: One time
A7: =ROW(A2) -> 2 | B7: Discount 32% | G7: PC | H7: 200 | I7: =-I6*32% -> -105.6 | J7: =H7*I7 -> -21120
A8: =ROW(A3) -> 3 | B8: Transportation Charge | J8: 448.8
A9: =ROW(A4) -> 4 | J9: =H9*I9 -> 0
A10: =ROW(A5) -> 5
A11: =ROW(A6) -> 6
A12: =ROW(A7) -> 7
A13: =ROW(A8) -> 8
A14: =ROW(A9) -> 9
A15: =ROW(A10) -> 10
A16: Purpose | I16: Sum | J16: =SUM(J6:J15) -> 45328.8
A17: * There will be an additional administration expense and financial expense (Depend on contract) deduction of total provision cost price.
O20: SUB-CON | T20: HDEC
O21: In Charge | P21: ADM | Q21: PCM | R21: PM | T21: Construction | U21: Subcon(PC) | V21: Account | Y21: ADM
V22: In Charge | W22: Manager
X24: HEC | Y24: ADM
O46: PROJECT MANAGER | P46: PROJECT MANAGER | S46: ADM
O50: PROJECT MANAGER | P50: PROJECT MANAGER | S50: PCM

Sheet MRS LIST
A1: ■ Purchase Requisition of Equipment Rental | J1: =+MRS!J1 -> DAESHIN PLANT
A2: =+MRS!A2 -> PJT : SACE2 | D2: =+MRS!D2 -> Division (In charge Name) : ADMIN MANAGER (Dong Chang Kim) | J2: =+MRS!J2 -> Subcontract name (SAC2-SC-IK-SMP-01)
A3: =+MRS!A3 -> MRS No : SAC2-DS-MRS-0495 | K3: =+MRS!L3 -> 46313
A4: No | B4: Item | D4: Specification (Model / Manufacturer / Size) | G4: Unit | H4: Q'ty | I4: Unit Price | J4: Total Price | K4: Remarks
A6: =+MRS!A6 -> 1 | B6: =MRS!B6 -> Injectable Mortar | D6: =MRS!D6 -> HIT-RE 500 V4/500 | G6: =MRS!G6 -> PC | H6: =MRS!H6 -> 200 | I6: =MRS!I6 -> 330 | J6: =MRS!J6 -> 66000
A7: =+MRS!A7 -> 2 | B7: =MRS!B7 -> Discount 32% | D7: =MRS!D7 -> 0 | G7: =MRS!G7 -> PC | H7: =MRS!H7 -> 200 | I7: =MRS!I7 -> -105.6 | J7: =MRS!J7 -> -21120
A8: =+MRS!#REF! -> #REF! | B8: =MRS!B8 -> Transportation Charge | D8: =MRS!D8 -> 0 | G8: =MRS!G8 -> 0 | H8: =MRS!H8 -> 0 | I8: =MRS!I8 -> 0 | J8: =MRS!J8 -> 448.8
A9: =+MRS!#REF! -> #REF! | B9: =MRS!B9 -> 0 | D9: =MRS!D9 -> 0 | G9: =MRS!G9 -> 0 | H9: =MRS!H9 -> 0 | I9: =MRS!I9 -> 0 | J9: =MRS!J9 -> 0
A10: =+MRS!#REF! -> #REF! | B10: =MRS!B10 -> 0 | D10: =MRS!D10 -> 0 | G10: =MRS!G10 -> 0 | H10: =MRS!H10 -> 0 | I10: =MRS!I10 -> 0 | J10: =MRS!J10 -> 0
A11: =+MRS!#REF! -> #REF! | B11: =MRS!B11 -> 0 | D11: =MRS!D11 -> 0 | G11: =MRS!G11 -> 0 | H11: =MRS!H11 -> 0 | I11: =MRS!I11 -> 0 | J11: =MRS!J11 -> 0
A12: =+MRS!#REF! -> #REF! | B12: =MRS!B12 -> 0 | D12: =MRS!D12 -> 0 | G12: =MRS!G12 -> 0 | H12: =MRS!H12 -> 0 | I12: =MRS!I12 -> 0 | J12: =MRS!J12 -> 0
A13: =+MRS!#REF! -> #REF! | B13: =MRS!B13 -> 0 | D13: =MRS!D13 -> 0 | G13: =MRS!G13 -> 0 | H13: =MRS!H13 -> 0 | I13: =MRS!I13 -> 0 | J13: =MRS!J13 -> 0
A14: =+MRS!#REF! -> #REF! | B14: =MRS!B14 -> 0 | D14: =MRS!D14 -> 0 | G14: =MRS!G14 -> 0 | H14: =MRS!H14 -> 0 | I14: =MRS!I14 -> 0 | J14: =MRS!J14 -> 0
A15: =+MRS!#REF! -> #REF! | B15: =MRS!B15 -> 0 | D15: =MRS!D15 -> 0 | G15: =MRS!G15 -> 0 | H15: =MRS!H15 -> 0 | I15: =MRS!I15 -> 0 | J15: =MRS!J15 -> 0
B16: =MRS!#REF! -> #REF! | D16: =MRS!#REF! -> #REF! | G16: =MRS!#REF! -> #REF! | H16: =MRS!#REF! -> #REF! | I16: =MRS!#REF! -> #REF! | J16: =MRS!#REF! -> #REF!
B17: =MRS!#REF! -> #REF! | D17: =MRS!#REF! -> #REF! | G17: =MRS!#REF! -> #REF! | H17: =MRS!#REF! -> #REF! | I17: =MRS!#REF! -> #REF! | J17: =MRS!#REF! -> #REF!
B18: =MRS!#REF! -> #REF! | D18: =MRS!#REF! -> #REF! | G18: =MRS!#REF! -> #REF! | H18: =MRS!#REF! -> #REF! | I18: =MRS!#REF! -> #REF! | J18: =MRS!#REF! -> #REF!
B19: =MRS!#REF! -> #REF! | D19: =MRS!#REF! -> #REF! | G19: =MRS!#REF! -> #REF! | H19: =MRS!#REF! -> #REF! | I19: =MRS!#REF! -> #REF! | J19: =MRS!#REF! -> #REF!
B20: =MRS!#REF! -> #REF! | D20: =MRS!#REF! -> #REF! | G20: =MRS!#REF! -> #REF! | H20: =MRS!#REF! -> #REF! | I20: =MRS!#REF! -> #REF! | J20: =MRS!#REF! -> #REF!
B21: =MRS!#REF! -> #REF! | D21: =MRS!#REF! -> #REF! | G21: =MRS!#REF! -> #REF! | H21: =MRS!#REF! -> #REF! | I21: =MRS!#REF! -> #REF! | J21: =MRS!#REF! -> #REF!
B22: =MRS!#REF! -> #REF! | D22: =MRS!#REF! -> #REF! | G22: =MRS!#REF! -> #REF! | H22: =MRS!#REF! -> #REF! | I22: =MRS!#REF! -> #REF! | J22: =MRS!#REF! -> #REF!
B23: =MRS!#REF! -> #REF! | D23: =MRS!#REF! -> #REF! | G23: =MRS!#REF! -> #REF! | H23: =MRS!#REF! -> #REF! | I23: =MRS!#REF! -> #REF! | J23: =MRS!#REF! -> #REF!
B24: =MRS!#REF! -> #REF! | D24: =MRS!#REF! -> #REF! | G24: =MRS!#REF! -> #REF! | H24: =MRS!#REF! -> #REF! | I24: =MRS!#REF! -> #REF! | J24: =MRS!#REF! -> #REF!
B25: =MRS!#REF! -> #REF! | D25: =MRS!#REF! -> #REF! | G25: =MRS!#REF! -> #REF! | H25: =MRS!#REF! -> #REF! | I25: =MRS!#REF! -> #REF! | J25: =MRS!#REF! -> #REF!
B26: =MRS!#REF! -> #REF! | D26: =MRS!#REF! -> #REF! | G26: =MRS!#REF! -> #REF! | H26: =MRS!#REF! -> #REF! | I26: =MRS!#REF! -> #REF! | J26: =MRS!#REF! -> #REF!
B27: =MRS!#REF! -> #REF! | D27: =MRS!#REF! -> #REF! | G27: =MRS!#REF! -> #REF! | H27: =MRS!#REF! -> #REF! | I27: =MRS!#REF! -> #REF! | J27: =MRS!#REF! -> #REF!
... B53: =MRS!#REF! -> #REF! | D53: =MRS!#REF! -> #REF! | G53: =MRS!#REF! -> #REF! | H53: =MRS!#REF! -> #REF! | I53: =MRS!#REF! -> #REF! | J53: =MRS!#REF! -> #REF!
B54: =MRS!#REF! -> #REF!
B55: =MRS!#REF! -> #REF!
B56: =MRS!#REF! -> #REF!
B57: =MRS!#REF! -> #REF!
B58: =MRS!B16 -> 0

Sheet PO 1st page
M2: BRANCH OF HYUNDAI ENG. & CONST. CO., LTD.
M3: P. O. Box 77249, Al Khobar 31952
M4: kingdom of Saudi Arabia
B5: C.R. 2051041774 & VAT No.: 300000504500003 | M5: Tel: +966-13-845-1088
M6: Fax: +966-13-845-1099
B9: TO: | C9: HILTI (HILTI Saudi Arabia Construction Tools)
C10: CR No. : | D10: 1010278712 | J10: P/O Date: | K10: =MRS!L3 -> 46313
C11: VAT No. : | D11: 300234512600003 | J11: P/O No.: | K11: =SUBSTITUTE(SUBSTITUTE(+MRS!A3," MRS No : ",""),"-MRS","-PO") -> SAC2-DS-PO-0495
C12: In Charge : | D12: Ahmed Ghazi | J12: (Please mention this No. in
D13: Mobile No. +966 55 859 7306 Email: Ahmed.Ghazi@hilti.com | J13: All future correspondence)
C14: Al Sahafah P.O. Box 8170 Riyadh 13321 Anas Ibn Malik Street | J14: Quote Ref. : | K14: 935508263
C15: Mobile: +966 539222074 | J15: Date- | K15: 46289
B18: PURCHASE ORDER
B20: WE ARE PLEASED TO PLACE AN ORDER WITH YOU FOR THE GOODS DESCRIBED BELOW. THE ORDER SHALL BE SUBJECT TO THE TERMS AND CONDITIONS SET OUR
B21: BELOW AND ATTACHED. PLEASE SIGN AND RETURN THE ENCLOSED COPY OF THIS ORDER AS CONFIRMATION OF YOUR ACCEPTANCE OF IT WITHIN A WEEK
B22: OTHERWISE THIS ORDER SHALL BE REGARDED AS BEING ACCEPTED BY YOU.
B25: 1 | C25: GOODS
C26: =_xlfn.CONCAT(MRS!B6," ",MRS!D6) -> Injectable Mortar HIT-RE 500 V4/500 | M26: [Please refer to attached Scope of supply & Quotation for more details]
B28: 2 | C28: P/O AMOUNT
C29: Material Value | E29: : | F29: ='PO 2nd page'!G16 -> 45328.8
C30: VAT 15% | E30: : | F30: ='PO 2nd page'!G17 -> 6799.32
C31: Total Amount | E31: : | F31: ='PO 2nd page'!G18 -> 52128.12
B33: 3 | C33: PAYMENT TERMS
C34: 100% Payment after Delivery within 35 days with submission of the following Documents.
C35: a) Tax E-Invoice (From Zakat, Tax and Customs Authority)
C36: b) Delivery/Dispatch Note [Counter signed by Site Representative]
B38: 4 | C38: DELIVERY TERMS
C39: Delivery by Seller to Jafurah HYUNDAI Laydown within a Week after receipt of PO.
B41: 5 | C41: OTHER TERMS AND CONDITIONS
C42: a) Any quantity rejected by the Buyer owing to its poor quality and non conformity of specification shall be replaced and re-delivered
C43: by Seller to Buyer at no extra costs
C44: b) Material Certificate, Data Sheet, Safety Data Sheet and other documents which may required by ARAMCO in material receiving
C45: inspection should be submitted to Buyer
C46: c) MTC / MSDS, Others, If required by Client
B48: 6 | C48: CONTACT POINT:
B49: - | C49: Delivery & Payment : Dong Chang Kim / Daeshin Admin. [ Mobile No. : +966 53 748 5762 / Email : kdchjs@daeshinplant.com ]
B50: - | C50: Commercial (Purchaser) : Youngkyu Choi / Daeshin Planning [ Mobile No. : +966 53 952 0931 / Email : ykchoi@daeshinplant.com ]
B51: - | C51: Invoicing : Nehal Kauser / HDEC Purchase PIC [ Mobile No. : +966 50 610 2363 / Email : nehal_kauser@hdec.co.kr ]
B53: 7 | C53: Bank Account Details:
B54: - | C54: ACCOUNT NAME | F54: HILTI SAUDI ARABIA CONSTRUCTION TOOLS | P54: =UPPER(F54) -> HILTI SAUDI ARABIA CONSTRUCTION TOOLS
...

Sheet PO 2nd page
A2: PO NO. : | B2: =+'PO 1st page'!K11 -> SAC2-DS-PO-0495 | C2: Scope of Supply
A3: DATE : | B3: =+'PO 1st page'!K10 -> 46313 | E3: Jafurah Utilities, Sulfur and Interconnecting Systems(Pkg-2)
A4: S. NO | B4: DESCRIPTION | D4: QTY | E4: UNIT | F4: ='PO 1st page'!C9 -> HILTI (HILTI Saudi Arabia Construction Tools) | H4: Remarks (Details)
F5: Unit Price | G5: Total Amount
A6: =ROW(A1) -> 1 | B6: =MRS!B6&" "&MRS!D6 -> Injectable Mortar HIT-RE 500 V4/500 | D6: =MRS!G6 -> PC | E6: =MRS!H6 -> 200 | F6: =+'MRS LIST'!I6 -> 330 | G6: =+'MRS LIST'!J6 -> 66000 | H6: One time
A7: =ROW(A2) -> 2 | B7: =MRS!B7&" "&MRS!D7 -> Discount 32% | D7: =MRS!G7 -> PC | E7: =MRS!H7 -> 200 | F7: =+'MRS LIST'!I7 -> -105.6 | G7: =+'MRS LIST'!J7 -> -21120
A8: =ROW(A3) -> 3 | B8: =MRS!B8&" "&MRS!D8 -> Transportation Charge | G8: =+'MRS LIST'!J8 -> 448.8
A9: =ROW(A4) -> 4
A10: =ROW(A5) -> 5
A11: =ROW(A6) -> 6
A12: =ROW(A7) -> 7
A13: =ROW(A8) -> 8
A14: =ROW(A9) -> 9
A15: =ROW(A10) -> 10
A16: Sub Total Amount | G16: =SUM(G6:G15) -> 45328.8
A17: VAT 15% | G17: =+G16*0.15 -> 6799.32
A18: Grand Total in SAR | G18: =G17+G16 -> 52128.12
A19: =" 1) Above Price are as per your quotation with ref "&'PO 1st page'!K14 -> 1) Above Price are as per your quotation with ref 935508263
A20: 2) Details of each item are attached separately.
A22: Page 2/2
