Workbook

Sheet MRS
A1: ■ Purchase Requisition of Material / Manpower / Equipment Rental / ETC. | J1: DAESHIN PLANT
A2: PJT : SACE2 | D2: Division (In charge Name) : ADMIN MANAGER (Dong Chang Kim) | J2: Subcontract name (SAC2-SC-IK-SMP-01)
A3: MRS No : SAC2-DS-MRS-0291 | E3: =+L3 -> 46134 | L3: 46134
A4: No | B4: Item | D4: Specification (Model / Manufacturer / Size) | G4: Unit | H4: Qty | I4: Unit Price (SAR) (Exclude VAT) | J4: Total Price (SAR) (Exclude VAT) | K4: Vendor Name | L4: Remarks
A6: =ROW(A1) -> 1 | B6: DELL PC | D6: 512GB-KB+MOUSE-BT | G6: EA | H6: 5 | I6: 2218 | J6: =H6*I6 -> 11090 | K6: ATGC | L6: One time
A7: =ROW(A2) -> 2 | B7: DELL MONITOR | D7: 24" | G7: EA | H7: 4 | I7: 465 | J7: =H7*I7 -> 1860
A8: =ROW(A3) -> 3 | B8: SAFETY FLAG | D8: RED | G8: EA | H8: 10 | I8: 3.8 | J8: =H8*I8 -> 38
A9: =ROW(A4) -> 4 | B9: SAFETY FLAG | D9: GREEN | G9: EA | H9: 10 | I9: 3.8 | J9: =H9*I9 -> 38
A10: =ROW(A5) -> 5 | B10: SAFETY HELMET | D10: 3M,YELLOW | G10: EA | H10: 60 | I10: 44 | J10: =H10*I10 -> 2640
A11: =ROW(A6) -> 6 | B11: 1/2 HP WATER PUMP | D11: 1"*1",HYUNDI | G11: EA | H11: 1 | I11: 175 | J11: =H11*I11 -> 175
A12: =ROW(A7) -> 7 | B12: 2 HOLE PAPER PUNCH | D12: 35SHEET | G12: EA | H12: 2 | I12: 24 | J12: =H12*I12 -> 48
A13: =ROW(A8) -> 8 | B13: HEAVY DUTY PUNCH | D13: DELI,100 PAGE CAPSITY | G13: EA | H13: 1 | I13: 146 | J13: =H13*I13 -> 146
A14: =ROW(A9) -> 9 | B14: OFFICE CHAIR | D14: WITHOUT NECK | G14: EA | H14: 5 | I14: 156 | J14: =H14*I14 -> 780
A15: =ROW(A10) -> 10 | B15: SAFETY SHOES ROTO | D15: ASORTED SIZE | G15: PAIR | H15: 382 | I15: 63.5 | J15: =H15*I15 -> 24257
A16: =ROW(A11) -> 11 | B16: A3 PAPER | D16: ROCO,80GSM | G16: BOX | H16: 10 | I16: 172 | J16: =H16*I16 -> 1720
A17: =ROW(A12) -> 12 | B17: A4 PAPER | D17: DOUBLE A 80GSM | G17: BOX | H17: 10 | I17: 76 | J17: =H17*I17 -> 760
A18: =ROW(A13) -> 13 | B18: BOARD MARKER | D18: FABER CASTELL | G18: PKT | H18: 10 | I18: 21 | J18: =H18*I18 -> 210
... A25: =ROW(A20) -> 20 | B25: RUBBER BOOT BLACK | D25: WITHOUT STEEL,SIZE 42 | G25: PAIR | H25: 7 | I25: 19 | J25: =H25*I25 -> 133
A26: =ROW(A21) -> 21 | B26: PORTABLE SPEAKER | G26: EA | H26: 1 | I26: 256 | J26: =H26*I26 -> 256
A27: =ROW(A22) -> 22 | B27: MIC | G27: EA | H27: 1 | I27: 127 | J27: =H27*I27 -> 127
A28: =ROW(A23) -> 23 | B28: SAFETY VEST WITH LOGO | D28: M-50/L-50/XL-50/XXL-50 | G28: EA | H28: 380 | I28: 16 | J28: =H28*I28 -> 6080
A29: =ROW(A24) -> 24 | B29: MICROPHONE | D29: EA | G29: EA | H29: 6 | I29: 90 | J29: =H29*I29 -> 540
A30: =ROW(A25) -> 25 | B30: BATTERY | D30: C2,DURACELL | G30: PAIR | H30: 36 | I30: 18.3 | J30: =H30*I30 -> 658.8
A31: =ROW(A26) -> 26 | B31: FIRE EXTINGUISHER TAG | D31: YELLOW 100/PKT | G31: EA | H31: 300 | I31: 0.16 | J31: =H31*I31 -> 48
A32: =ROW(A27) -> 27 | B32: NOTE BOOK | D32: A5 | G32: EA | H32: 10 | I32: 5.25 | J32: =H32*I32 -> 52.5
A33: =ROW(A28) -> 28 | B33: ENVELOPE | G33: PKT | H33: 20 | I33: 4.25 | J33: =H33*I33 -> 85
A34: =ROW(A29) -> 29 | B34: BATTERY | D34: C TYPE | G34: EA | H34: 12 | I34: 18.3 | J34: =H34*I34 -> 219.6
A35: =ROW(A30) -> 30 | B35: BATTERY | D35: AAA | G35: PKT | H35: 20 | I35: 21.5 | J35: =H35*I35 -> 430
A36: =ROW(A31) -> 31 | B36: ELECTRICAL TAPE | D36: RED-200/YELLOW-200/BLUE- 200/GREEN-200 | G36: EA | H36: 800 | I36: 2.22 | J36: =H36*I36 -> 1776
A37: =ROW(A32) -> 32 | B37: TRASH BAG | D37: 10GLN,4KG | G37: BDL | H37: 1 | I37: 50 | J37: =H37*I37 -> 50
A38: =ROW(A33) -> 33 | B38: DURACELL BATTERY | D38: C2,ALKALINE 1.5V | G38: EA | H38: 12 | I38: 18.3 | J38: =H38*I38 -> 219.6
A39: =ROW(A34) -> 34 | B39: A3 LAMINATION POUCH | D39: BRAND LEENA | G39: PKT | H39: 10 | I39: 60 | J39: =H39*I39 -> 600
A40: =ROW(A35) -> 35 | B40: FIRE WATCHER VEST RED WITH POCKET | D40: M-50/L-50 | G40: EA | H40: 100 | I40: 10 | J40: =H40*I40 -> 1000
A41: =ROW(A36) -> 36 | B41: BINDER CLIP | D41: 15MM | G41: PKT | H41: 50 | I41: 1 | J41: =H41*I41 -> 50
A42: =ROW(A37) -> 37 | B42: STICKY NOTE | D42: FANTASTIC,SMALL | G42: PKT | H42: 5 | I42: 7.32 | J42: =H42*I42 -> 36.6
A43: =ROW(A38) -> 38 | B43: STICKY NOTE | D43: FANTASTIC,MEDIUM | G43: PKT | H43: 5 | I43: 11.23 | J43: =H43*I43 -> 56.15
A44: =ROW(A39) -> 39 | B44: PERMANENT MARKER | D44: DOUBLE SIDE | G44: PKT | H44: 10 | I44: 33 | J44: =H44*I44 -> 330
A45: =ROW(A40) -> 40 | B45: RECORD BOOK | D45: A5 | G45: EA | H45: 5 | I45: 5.25 | J45: =H45*I45 -> 26.25
A46: =ROW(A41) -> 41 | B46: TRIANGE STICKER | G46: EA | H46: 1000 | I46: 1 | J46: =H46*I46 -> 1000
A47: =ROW(A42) -> 42 | B47: ROUND STICKER | D47: RED SMP 1 | G47: EA | H47: 1000 | I47: 1 | J47: =H47*I47 -> 1000
...

Sheet MRS LIST
A1: ■ Purchase Requisition of Equipment Rental | J1: =+MRS!J1 -> DAESHIN PLANT
A2: =+MRS!A2 -> PJT : SACE2 | D2: =+MRS!D2 -> Division (In charge Name) : ADMIN MANAGER (Dong Chang Kim) | J2: =+MRS!J2 -> Subcontract name (SAC2-SC-IK-SMP-01)
A3: =+MRS!A3 -> MRS No : SAC2-DS-MRS-0291 | K3: =+MRS!L3 -> 46134
A4: No | B4: Item | D4: Specification (Model / Manufacturer / Size) | G4: Unit | H4: Q'ty | I4: Unit Price | J4: Total Price | K4: Remarks
A6: =+MRS!A6 -> 1 | B6: =MRS!B6 -> DELL PC | D6: =MRS!D6 -> 512GB-KB+MOUSE-BT | G6: =MRS!G6 -> EA | H6: =MRS!H6 -> 5 | I6: =MRS!I6 -> 2218 | J6: =MRS!J6 -> 11090
A7: =+MRS!A7 -> 2 | B7: =MRS!B7 -> DELL MONITOR | D7: =MRS!D7 -> 24" | G7: =MRS!G7 -> EA | H7: =MRS!H7 -> 4 | I7: =MRS!I7 -> 465 | J7: =MRS!J7 -> 1860
A8: =+MRS!A8 -> 3 | B8: =MRS!B8 -> SAFETY FLAG | D8: =MRS!D8 -> RED | G8: =MRS!G8 -> EA | H8: =MRS!H8 -> 10 | I8: =MRS!I8 -> 3.8 | J8: =MRS!J8 -> 38
A9: =+MRS!A9 -> 4 | B9: =MRS!B9 -> SAFETY FLAG | D9: =MRS!D9 -> GREEN | G9: =MRS!G9 -> EA | H9: =MRS!H9 -> 10 | I9: =MRS!I9 -> 3.8 | J9: =MRS!J9 -> 38
A10: =+MRS!A10 -> 5 | B10: =MRS!B10 -> SAFETY HELMET | D10: =MRS!D10 -> 3M,YELLOW | G10: =MRS!G10 -> EA | H10: =MRS!H10 -> 60 | I10: =MRS!I10 -> 44 | J10: =MRS!J10 -> 2640
A11: =+MRS!A11 -> 6 | B11: =MRS!B11 -> 1/2 HP WATER PUMP | D11: =MRS!D11 -> 1"*1",HYUNDI | G11: =MRS!G11 -> EA | H11: =MRS!H11 -> 1 | I11: =MRS!I11 -> 175 | J11: =MRS!J11 -> 175
A12: =+MRS!A12 -> 7 | B12: =MRS!B12 -> 2 HOLE PAPER PUNCH | D12: =MRS!D12 -> 35SHEET | G12: =MRS!G12 -> EA | H12: =MRS!H12 -> 2 | I12: =MRS!I12 -> 24 | J12: =MRS!J12 -> 48
A13: =+MRS!A13 -> 8 | B13: =MRS!B13 -> HEAVY DUTY PUNCH | D13: =MRS!D13 -> DELI,100 PAGE CAPSITY | G13: =MRS!G13 -> EA | H13: =MRS!H13 -> 1 | I13: =MRS!I13 -> 146 | J13: =MRS!J13 -> 146
A14: =+MRS!A14 -> 9 | B14: =MRS!B14 -> OFFICE CHAIR | D14: =MRS!D14 -> WITHOUT NECK | G14: =MRS!G14 -> EA | H14: =MRS!H14 -> 5 | I14: =MRS!I14 -> 156 | J14: =MRS!J14 -> 780
A15: =+MRS!A15 -> 10 | B15: =MRS!B15 -> SAFETY SHOES ROTO | D15: =MRS!D15 -> ASORTED SIZE | G15: =MRS!G15 -> PAIR | H15: =MRS!H15 -> 382 | I15: =MRS!I15 -> 63.5 | J15: =MRS!J15 -> 24257
A16: =+MRS!A16 -> 11 | B16: =MRS!B16 -> A3 PAPER | D16: =MRS!D16 -> ROCO,80GSM | G16: =MRS!G16 -> BOX | H16: =MRS!H16 -> 10 | I16: =MRS!I16 -> 172 | J16: =MRS!J16 -> 1720
A17: =+MRS!A17 -> 12 | B17: =MRS!B17 -> A4 PAPER | D17: =MRS!D17 -> DOUBLE A 80GSM | G17: =MRS!G17 -> BOX | H17: =MRS!H17 -> 10 | I17: =MRS!I17 -> 76 | J17: =MRS!J17 -> 760
... A22: =+MRS!A22 -> 17 | B22: =MRS!B22 -> WATER BOTTLE | D22: =MRS!D22 -> 1050ML,HI-TEX | G22: =MRS!G22 -> EA | H22: =MRS!H22 -> 48 | I22: =MRS!I22 -> 8 | J22: =MRS!J22 -> 384
A23: =+MRS!#REF! -> #REF! | B23: =MRS!#REF! -> #REF! | D23: =MRS!#REF! -> #REF! | G23: =MRS!#REF! -> #REF! | H23: =MRS!#REF! -> #REF! | I23: =MRS!#REF! -> #REF! | J23: =MRS!#REF! -> #REF!
A24: =+MRS!#REF! -> #REF! | B24: =MRS!#REF! -> #REF! | D24: =MRS!#REF! -> #REF! | G24: =MRS!#REF! -> #REF! | H24: =MRS!#REF! -> #REF! | I24: =MRS!#REF! -> #REF! | J24: =MRS!#REF! -> #REF!
A25: =+MRS!#REF! -> #REF! | B25: =MRS!#REF! -> #REF! | D25: =MRS!#REF! -> #REF! | G25: =MRS!#REF! -> #REF! | H25: =MRS!#REF! -> #REF! | I25: =MRS!#REF! -> #REF! | J25: =MRS!#REF! -> #REF!
A26: =+MRS!#REF! -> #REF! | B26: =MRS!#REF! -> #REF! | D26: =MRS!#REF! -> #REF! | G26: =MRS!#REF! -> #REF! | H26: =MRS!#REF! -> #REF! | I26: =MRS!#REF! -> #REF! | J26: =MRS!#REF! -> #REF!
A27: =+MRS!#REF! -> #REF! | B27: =MRS!#REF! -> #REF! | D27: =MRS!#REF! -> #REF! | G27: =MRS!#REF! -> #REF! | H27: =MRS!#REF! -> #REF! | I27: =MRS!#REF! -> #REF! | J27: =MRS!#REF! -> #REF!
A28: =+MRS!#REF! -> #REF! | B28: =MRS!#REF! -> #REF! | D28: =MRS!#REF! -> #REF! | G28: =MRS!#REF! -> #REF! | H28: =MRS!#REF! -> #REF! | I28: =MRS!#REF! -> #REF! | J28: =MRS!#REF! -> #REF!
A29: =+MRS!#REF! -> #REF! | B29: =MRS!#REF! -> #REF! | D29: =MRS!#REF! -> #REF! | G29: =MRS!#REF! -> #REF! | H29: =MRS!#REF! -> #REF! | I29: =MRS!#REF! -> #REF! | J29: =MRS!#REF! -> #REF!
A30: =+MRS!#REF! -> #REF! | B30: =MRS!#REF! -> #REF! | D30: =MRS!#REF! -> #REF! | G30: =MRS!#REF! -> #REF! | H30: =MRS!#REF! -> #REF! | I30: =MRS!#REF! -> #REF! | J30: =MRS!#REF! -> #REF!

Sheet PO 1st page
M2: BRANCH OF HYUNDAI ENG. & CONST. CO., LTD.
M3: P. O. Box 77249, Al Khobar 31952
M4: kingdom of Saudi Arabia
B5: C.R. 2051041774 & VAT No.: 300000504500003 | M5: Tel: +966-13-845-1088
M6: Fax: +966-13-845-1099
B9: TO: | C9: ATGC(Alrmooz Technical for General Contracting Est.)
C10: CR No. : | D10: 2053026325 | J10: P/O Date: | K10: =MRS!L3 -> 46134
C11: VAT No. : | D11: 300900558400003 | J11: P/O No.: | K11: =SUBSTITUTE(SUBSTITUTE(+MRS!A3," MRS No : ",""),"-MRS","-PO") -> SAC2-DS-PO-0291
C12: In Charge : | D12: Muhammed Rafi | J12: (Please mention this No. in
D13: +966 57 5956527 / Email:info@alrmoozsa.com | J13: All future correspondence)
C14: P.O. Box 2746, Al-Jubail 31951 | J14: Quote Ref. : | K14: QUO-MAT-26031014
C15: Landline : +99 13 8022775. : Mobile : +966 583694645 | J15: Date- | K15: 46092
B18: PURCHASE ORDER
B20: WE ARE PLEASED TO PLACE AN ORDER WITH YOU FOR THE GOODS DESCRIBED BELOW. THE ORDER SHALL BE SUBJECT TO THE TERMS AND CONDITIONS SET OUR
B21: BELOW AND ATTACHED. PLEASE SIGN AND RETURN THE ENCLOSED COPY OF THIS ORDER AS CONFIRMATION OF YOUR ACCEPTANCE OF IT WITHIN A WEEK
B22: OTHERWISE THIS ORDER SHALL BE REGARDED AS BEING ACCEPTED BY YOU.
B25: 1 | C25: GOODS
C26: Office Materials | M26: [Please refer to attached Scope of supply & Quotation for more details]
B28: 2 | C28: P/O AMOUNT
C29: Material Value | E29: : | F29: ='PO 2nd page'!G69 -> 72690.35
C30: VAT 15% | E30: : | F30: ='PO 2nd page'!G70 -> 10903.552
C31: Total Amount | E31: : | F31: ='PO 2nd page'!G71 -> 83593.903
B33: 3 | C33: PAYMENT TERMS
C34: 100% Payment after Delivery within 35 days with submission of the following Documents.
C35: a) Tax E-Invoice (From Zakat, Tax and Customs Authority)
C36: b) Delivery/Dispatch Note [Counter signed by Site Representative]
B38: 4 | C38: DELIVERY TERMS
C39: Delivery by Seller to Jafurah HYUNDAI Laydown within a Week after receipt of PO.
B41: 5 | C41: OTHER TERMS AND CONDITIONS
C42: a) Any quantity rejected by the Buyer owing to its poor quality and non conformity of specification shall be replaced and re-delivered
C43: by Seller to Buyer at no extra costs
C44: b) Material Certificate, Data Sheet, Safety Data Sheet and other documents which may required by ARAMCO in material receiving
C45: inspection should be submitted to Buyer
C46: c) MTC / MSDS, Others, If required by Client
B48: 6 | C48: CONTACT POINT:
B49: - | C49: Delivery & Payment : Dong Chang Kim / Daeshin Admin. [ Mobile No. : +966 53 748 5762 / Email : kdchjs@daeshinplant.com ]
B50: - | C50: Commercial (Purchaser) : Youngkyu Choi / Daeshin Planning [ Mobile No. : +966 53 952 0931 / Email : ykchoi@daeshinplant.com ]
B51: - | C51: Invoicing : Nehal Kauser / HDEC Purchase PIC [ Mobile No. : +966 50 610 2363 / Email : nehal_kauser@hdec.co.kr ]
B53: 7 | C53: Bank Account Details:
B54: - | C54: ACCOUNT NAME | F54: ALRMOOZ TECHNICAL FOR GENERAL CONTRACTING EST. | P54: =UPPER(F54) -> ALRMOOZ TECHNICAL FOR GENERAL CONTRACTING EST.
...

Sheet PO 2nd page
A2: PO NO. : | B2: =+'PO 1st page'!K11 -> SAC2-DS-PO-0291 | C2: Scope of Supply
A3: DATE : | B3: =+'PO 1st page'!K10 -> 46134 | E3: Jafurah Utilities, Sulfur and Interconnecting Systems(Pkg-2)
A4: S. NO | B4: DESCRIPTION | D4: QTY | E4: UNIT | F4: ='PO 1st page'!C9 -> ATGC(Alrmooz Technical for General Contracting Est.) | H4: Remarks (Details)
F5: Unit Price | G5: Total Amount
A6: =ROW(A1) -> 1 | B6: =_xlfn.CONCAT(MRS!B6," ",MRS!D6) -> DELL PC 512GB-KB+MOUSE-BT | D6: =MRS!G6 -> EA | E6: =MRS!H6 -> 5 | F6: =MRS!I6 -> 2218 | G6: =F6*E6 -> 11090
A7: =ROW(A2) -> 2 | B7: =_xlfn.CONCAT(MRS!B7," ",MRS!D7) -> DELL MONITOR 24" | D7: =MRS!G7 -> EA | E7: =MRS!H7 -> 4 | F7: =MRS!I7 -> 465 | G7: =F7*E7 -> 1860
A8: =ROW(A3) -> 3 | B8: =_xlfn.CONCAT(MRS!B8," ",MRS!D8) -> SAFETY FLAG RED | D8: =MRS!G8 -> EA | E8: =MRS!H8 -> 10 | F8: =MRS!I8 -> 3.8 | G8: =F8*E8 -> 38
A9: =ROW(A4) -> 4 | B9: =_xlfn.CONCAT(MRS!B9," ",MRS!D9) -> SAFETY FLAG GREEN | D9: =MRS!G9 -> EA | E9: =MRS!H9 -> 10 | F9: =MRS!I9 -> 3.8 | G9: =F9*E9 -> 38
A10: =ROW(A5) -> 5 | B10: =_xlfn.CONCAT(MRS!B10," ",MRS!D10) -> SAFETY HELMET 3M,YELLOW | D10: =MRS!G10 -> EA | E10: =MRS!H10 -> 60 | F10: =MRS!I10 -> 44 | G10: =F10*E10 -> 2640
A11: =ROW(A6) -> 6 | B11: =_xlfn.CONCAT(MRS!B11," ",MRS!D11) -> 1/2 HP WATER PUMP 1"*1",HYUNDI | D11: =MRS!G11 -> EA | E11: =MRS!H11 -> 1 | F11: =MRS!I11 -> 175 | G11: =F11*E11 -> 175
A12: =ROW(A7) -> 7 | B12: =_xlfn.CONCAT(MRS!B12," ",MRS!D12) -> 2 HOLE PAPER PUNCH 35SHEET | D12: =MRS!G12 -> EA | E12: =MRS!H12 -> 2 | F12: =MRS!I12 -> 24 | G12: =F12*E12 -> 48
A13: =ROW(A8) -> 8 | B13: =_xlfn.CONCAT(MRS!B13," ",MRS!D13) -> HEAVY DUTY PUNCH DELI,100 PAGE CAPSITY | D13: =MRS!G13 -> EA | E13: =MRS!H13 -> 1 | F13: =MRS!I13 -> 146 | G13: =F13*E13 -> 146
A14: =ROW(A9) -> 9 | B14: =_xlfn.CONCAT(MRS!B14," ",MRS!D14) -> OFFICE CHAIR WITHOUT NECK | D14: =MRS!G14 -> EA | E14: =MRS!H14 -> 5 | F14: =MRS!I14 -> 156 | G14: =F14*E14 -> 780
A15: =ROW(A10) -> 10 | B15: =_xlfn.CONCAT(MRS!B15," ",MRS!D15) -> SAFETY SHOES ROTO ASORTED SIZE | D15: =MRS!G15 -> PAIR | E15: =MRS!H15 -> 382 | F15: =MRS!I15 -> 63.5 | G15: =F15*E15 -> 24257
A16: =ROW(A11) -> 11 | B16: =_xlfn.CONCAT(MRS!B16," ",MRS!D16) -> A3 PAPER ROCO,80GSM | D16: =MRS!G16 -> BOX | E16: =MRS!H16 -> 10 | F16: =MRS!I16 -> 172 | G16: =F16*E16 -> 1720
A17: =ROW(A12) -> 12 | B17: =_xlfn.CONCAT(MRS!B17," ",MRS!D17) -> A4 PAPER DOUBLE A 80GSM | D17: =MRS!G17 -> BOX | E17: =MRS!H17 -> 10 | F17: =MRS!I17 -> 76 | G17: =F17*E17 -> 760
... A68: =ROW(A63) -> 63 | B68: =_xlfn.CONCAT(MRS!B68," ",MRS!D68) -> DURACELL BATTERY C2 | D68: =MRS!G68 -> PAIR | E68: =MRS!H68 -> 100 | F68: =MRS!I68 -> 18.3 | G68: =F68*E68 -> 1830
A69: Sub Total Amount | G69: =SUM(G6:G68) -> 72690.35
A70: VAT 15% | G70: =+G69*0.15 -> 10903.552
A71: Grand Total in SAR | G71: =G70+G69 -> 83593.903
A72: =" 1) Above Price are as per your quotation with ref "&'PO 1st page'!K14 -> 1) Above Price are as per your quotation with ref QUO-MAT-26031014
A73: 2) Details of each item are attached separately.
A75: Page 2/2
