Workbook

Sheet MRS
A1: ■ Purchase Requisition of Material / Manpower / Equipment Rental / ETC. | J1: DAESHIN PLANT
A2: PJT : SACE2 | D2: Division (In charge Name) : ADMIN MANAGER (Dong Chang Kim) | J2: Subcontract name (SAC2-SC-IK-SMP-01)
A3: MRS No : SAC2-DS-MRS-0303 | E3: =+L3 -> 46146 | L3: 46146
A4: No | B4: Item | D4: Specification (Model / Manufacturer / Size) | G4: Unit | H4: Qty | I4: Unit Price (SAR) (Exclude VAT) | J4: Total Price (SAR) (Exclude VAT) | K4: Vendor Name | L4: Remarks
A6: =ROW(A1) -> 1 | B6: Welding Torch | D6: 25x50 | G6: EA | H6: 50 | I6: 2064 | J6: =H6*I6 -> 103200 | K6: JSAJ | L6: One time
A7: =ROW(A2) -> 2 | B7: Remote Control | D7: 50M | G7: EA | H7: 150 | I7: 708 | J7: =H7*I7 -> 106200
A8: =ROW(A3) -> 3 | B8: Connector | D8: 25K-2P | G8: EA | H8: 50 | I8: 299 | J8: =H8*I8 -> 14950
A9: =ROW(A4) -> 4 | B9: Connector | D9: 25K-4P | G9: EA | H9: 50 | I9: 299 | J9: =H9*I9 -> 14950
A10: =ROW(A5) -> 5 | B10: No Fuse Breaker | D10: 80A | G10: EA | H10: 10 | I10: 380 | J10: =H10*I10 -> 3800
A11: =ROW(A6) -> 6 | B11: No Fuse Breaker | D11: 50A | G11: EA | H11: 10 | I11: 371 | J11: =H11*I11 -> 3710
A12: =ROW(A7) -> 7 | B12: Custom Duties and Clearance | G12: Lot | H12: 1 | I12: 19980 | J12: =H12*I12 -> 19980
A13: =ROW(A8) -> 8 | J13: =H13*I13 -> 0
A14: =ROW(A9) -> 9 | J14: =H14*I14 -> 0
A15: =ROW(A10) -> 10 | J15: =H15*I15 -> 0
A16: Purpose | I16: Sum | J16: =SUM(J6:J15) -> 266790
A17: * There will be an additional administration expense and financial expense (Depend on contract) deduction of total provision cost price.
R18: HEC | S18: ADM
S20: /
O21: Requesting | P21: JV Area PIC
O22: Company | R22: HDEC | S22: ADM
O24: / | P24: / | S24: /
O46: PROJECT MANAGER | P46: PROJECT MANAGER | S46: ADM
O50: PROJECT MANAGER | P50: PROJECT MANAGER | S50: PCM

Sheet MRS LIST
A1: ■ Purchase Requisition of Equipment Rental | J1: =+MRS!J1 -> DAESHIN PLANT
A2: =+MRS!A2 -> PJT : SACE2 | D2: =+MRS!D2 -> Division (In charge Name) : ADMIN MANAGER (Dong Chang Kim) | J2: =+MRS!J2 -> Subcontract name (SAC2-SC-IK-SMP-01)
A3: =+MRS!A3 -> MRS No : SAC2-DS-MRS-0303 | K3: =+MRS!L3 -> 46146
A4: No | B4: Item | D4: Specification (Model / Manufacturer / Size) | G4: Unit | H4: Q'ty | I4: Unit Price | J4: Total Price | K4: Remarks
A6: =+MRS!A6 -> 1 | B6: =MRS!B6 -> Welding Torch | D6: =MRS!D6 -> 25x50 | G6: =MRS!G6 -> EA | H6: =MRS!H6 -> 50 | I6: =MRS!I6 -> 2064 | J6: =MRS!J6 -> 103200
A7: =+MRS!A7 -> 2 | B7: =MRS!B7 -> Remote Control | D7: =MRS!D7 -> 50M | G7: =MRS!G7 -> EA | H7: =MRS!H7 -> 150 | I7: =MRS!I7 -> 708 | J7: =MRS!J7 -> 106200
A8: =+MRS!A8 -> 3 | B8: =MRS!B8 -> Connector | D8: =MRS!D8 -> 25K-2P | G8: =MRS!G8 -> EA | H8: =MRS!H8 -> 50 | I8: =MRS!I8 -> 299 | J8: =MRS!J8 -> 14950
A9: =+MRS!A9 -> 4 | B9: =MRS!B9 -> Connector | D9: =MRS!D9 -> 25K-4P | G9: =MRS!G9 -> EA | H9: =MRS!H9 -> 50 | I9: =MRS!I9 -> 299 | J9: =MRS!J9 -> 14950
A10: =+MRS!A10 -> 5 | B10: =MRS!B10 -> No Fuse Breaker | D10: =MRS!D10 -> 80A | G10: =MRS!G10 -> EA | H10: =MRS!H10 -> 10 | I10: =MRS!I10 -> 380 | J10: =MRS!J10 -> 3800
A11: =+MRS!A11 -> 6 | B11: =MRS!B11 -> No Fuse Breaker | D11: =MRS!D11 -> 50A | G11: =MRS!G11 -> EA | H11: =MRS!H11 -> 10 | I11: =MRS!I11 -> 371 | J11: =MRS!J11 -> 3710
A12: =+MRS!A12 -> 7 | B12: =MRS!B12 -> Custom Duties and Clearance | D12: =MRS!D12 -> 0 | G12: =MRS!G12 -> Lot | H12: =MRS!H12 -> 1 | I12: =MRS!I12 -> 19980 | J12: =MRS!J12 -> 19980
A13: =+MRS!A13 -> 8 | B13: =MRS!B13 -> 0 | D13: =MRS!D13 -> 0 | G13: =MRS!G13 -> 0 | H13: =MRS!H13 -> 0 | I13: =MRS!I13 -> 0 | J13: =MRS!J13 -> 0
A14: =+MRS!A14 -> 9 | B14: =MRS!B14 -> 0 | D14: =MRS!D14 -> 0 | G14: =MRS!G14 -> 0 | H14: =MRS!H14 -> 0 | I14: =MRS!I14 -> 0 | J14: =MRS!J14 -> 0
A15: =+MRS!A15 -> 10 | B15: =MRS!B15 -> 0 | D15: =MRS!D15 -> 0 | G15: =MRS!G15 -> 0 | H15: =MRS!H15 -> 0 | I15: =MRS!I15 -> 0 | J15: =MRS!J15 -> 0

Sheet PO 1st page
M2: BRANCH OF HYUNDAI ENG. & CONST. CO., LTD.
M3: P. O. Box 77249, Al Khobar 31952
M4: kingdom of Saudi Arabia
B5: C.R. 2051041774 & VAT No.: 300000504500003 | M5: Tel: +966-13-845-1088
M6: Fax: +966-13-845-1099
B9: TO: | C9: JSAJ(Jassim Saif Amer Aljaberi Trading Est.)
C10: CR No. : | D10: 2051247436 | J10: P/O Date: | K10: =MRS!L3 -> 46146
C11: VAT No. : | D11: 311625046900003 | J11: P/O No.: | K11: =SUBSTITUTE(SUBSTITUTE(+MRS!A3," MRS No : ",""),"-MRS","-PO") -> SAC2-DS-PO-0303
C12: In Charge : | D12: Shashank Kamra | J12: (Please mention this No. in
D13: Mobile No. +966 539222074 | J13: All future correspondence)
C14: Building No. 6634, Al Khobar 34423, KSA | J14: Quote Ref. : | K14: Q-20263204
C15: Mobile: +966 539222074 | J15: Date- | K15: 46140
B18: PURCHASE ORDER
B20: WE ARE PLEASED TO PLACE AN ORDER WITH YOU FOR THE GOODS DESCRIBED BELOW. THE ORDER SHALL BE SUBJECT TO THE TERMS AND CONDITIONS SET OUR
B21: BELOW AND ATTACHED. PLEASE SIGN AND RETURN THE ENCLOSED COPY OF THIS ORDER AS CONFIRMATION OF YOUR ACCEPTANCE OF IT WITHIN A WEEK
B22: OTHERWISE THIS ORDER SHALL BE REGARDED AS BEING ACCEPTED BY YOU.
B25: 1 | C25: GOODS
C26: Welding Machine Accessories | M26: [Please refer to attached Scope of supply & Quotation for more details]
B28: 2 | C28: P/O AMOUNT
C29: Material Value | E29: : | F29: ='PO 2nd page'!G22 -> 266790
C30: VAT 15% | E30: : | F30: ='PO 2nd page'!G23 -> 40018.5
C31: Total Amount | E31: : | F31: ='PO 2nd page'!G24 -> 306808.5
B33: 3 | C33: PAYMENT TERMS
C34: 100% Payment after Delivery within 35 days with submission of the following Documents.
C35: a) Tax E-Invoice (From Zakat, Tax and Customs Authority)
C36: b) Delivery/Dispatch Note [Counter signed by Site Representative]
B38: 4 | C38: DELIVERY TERMS
C39: Delivery by Seller to Jafurah HYUNDAI Laydown within a Week after receipt of PO.
B41: 5 | C41: OTHER TERMS AND CONDITIONS
C42: a) Any quantity rejected by the Buyer owing to its poor quality and non conformity of specification shall be replaced and re-delivered
C43: by Seller to Buyer at no extra costs
C44: b) Material Certificate, Data Sheet, Safety Data Sheet and other documents which may required by ARAMCO in material receiving
C45: inspection should be submitted to Buyer
C46: c) MTC / MSDS, Others, If required by Client
B48: 6 | C48: CONTACT POINT:
B49: - | C49: Delivery & Payment : Dong Chang Kim / Daeshin Admin. [ Mobile No. : +966 53 748 5762 / Email : kdchjs@daeshinplant.com ]
B50: - | C50: Commercial (Purchaser) : Youngkyu Choi / Daeshin Planning [ Mobile No. : +966 53 952 0931 / Email : ykchoi@daeshinplant.com ]
B51: - | C51: Invoicing : Nehal Kauser / HDEC Purchase PIC [ Mobile No. : +966 50 610 2363 / Email : nehal_kauser@hdec.co.kr ]
B53: 7 | C53: Bank Account Details:
B54: - | C54: ACCOUNT NAME | F54: JASSIM SAIF AMER ALJABERI TRADING EST.
...

Sheet PO 2nd page
A2: PO NO. : | B2: =+'PO 1st page'!K11 -> SAC2-DS-PO-0303 | C2: Scope of Supply
A3: DATE : | B3: =+'PO 1st page'!K10 -> 46146 | E3: Jafurah Utilities, Sulfur and Interconnecting Systems(Pkg-2)
A4: S. NO | B4: DESCRIPTION | D4: QTY | E4: UNIT | F4: ='PO 1st page'!C9 -> JSAJ(Jassim Saif Amer Aljaberi Trading Est.) | H4: Remarks (Details)
F5: Unit Price | G5: Total Amount
A6: =ROW(A1) -> 1 | B6: =MRS!B6&" "&MRS!D6 -> Welding Torch 25x50 | D6: =MRS!G6 -> EA | E6: =MRS!H6 -> 50 | F6: =+'MRS LIST'!I6 -> 2064 | G6: =+'MRS LIST'!J6 -> 103200 | H6: One time
A7: =ROW(A2) -> 2 | B7: =MRS!B7&" "&MRS!D7 -> Remote Control 50M | D7: =MRS!G7 -> EA | E7: =MRS!H7 -> 150 | F7: =+'MRS LIST'!I7 -> 708 | G7: =+'MRS LIST'!J7 -> 106200
A8: =ROW(A3) -> 3 | B8: =MRS!B8&" "&MRS!D8 -> Connector 25K-2P | D8: =MRS!G8 -> EA | E8: =MRS!H8 -> 50 | F8: =+'MRS LIST'!I8 -> 299 | G8: =+'MRS LIST'!J8 -> 14950
A9: =ROW(A4) -> 4 | B9: =MRS!B9&" "&MRS!D9 -> Connector 25K-4P | D9: =MRS!G9 -> EA | E9: =MRS!H9 -> 50 | F9: =+'MRS LIST'!I9 -> 299 | G9: =+'MRS LIST'!J9 -> 14950
A10: =ROW(A5) -> 5 | B10: =MRS!B10&" "&MRS!D10 -> No Fuse Breaker 80A | D10: =MRS!G10 -> EA | E10: =MRS!H10 -> 10 | F10: =+'MRS LIST'!I10 -> 380 | G10: =+'MRS LIST'!J10 -> 3800
A11: =ROW(A6) -> 6 | B11: =MRS!B11&" "&MRS!D11 -> No Fuse Breaker 50A | D11: =MRS!G11 -> EA | E11: =MRS!H11 -> 10 | F11: =+'MRS LIST'!I11 -> 371 | G11: =+'MRS LIST'!J11 -> 3710
A12: =ROW(A7) -> 7 | B12: =MRS!B12&" "&MRS!D12 -> Custom Duties and Clearance | D12: =MRS!G12 -> Lot | E12: =MRS!H12 -> 1 | F12: =+'MRS LIST'!I12 -> 19980 | G12: =+'MRS LIST'!J12 -> 19980
A13: =ROW(A8) -> 8
A14: =ROW(A9) -> 9
A15: =ROW(A10) -> 10
A22: Sub Total Amount | G22: =SUM(G6:G21) -> 266790
A23: VAT 15% | G23: =+G22*0.15 -> 40018.5
A24: Grand Total in SAR | G24: =G23+G22 -> 306808.5
A25: =" 1) Above Price are as per your quotation with ref "&'PO 1st page'!K14 -> 1) Above Price are as per your quotation with ref Q-20263204
A26: 2) Details of each item are attached separately.
A28: Page 2/2
