Workbook

Sheet MRS
A1: ■ Purchase Requisition of Material / Manpower / Equipment Rental / ETC. | J1: DAESHIN PLANT
A2: PJT : SACE2 | D2: Division (In charge Name) : ADMIN MANAGER (Sang Yeun Cho) | J2: Subcontract name ()
A3: MRS No : SAC2-DS-MRS-0016 | E3: =+L3 -> 45648 | L3: 45648
A4: No | B4: Item | D4: Specification (Model / Manufacturer / Size) | G4: Unit | H4: Qty | I4: Unit Price (SAR) (Exclude VAT) | J4: Total Price (SAR) (Exclude VAT) | K4: Vendor Name | L4: Remarks
A6: =ROW(A1) -> 1 | B6: Portland Cement | D6: Portland Cement Type 1 as pe ASTM C150 Cement content min 360 grms per 09 SAMSS-097 | G6: m3 | H6: 24 | I6: 354 | J6: =H6*I6 -> 8496 | K6: ERMC
A7: =ROW(A3) -> 3
A8: =ROW(A4) -> 4
A9: =ROW(A5) -> 5
A10: =ROW(A6) -> 6
A11: =ROW(A7) -> 7
A12: =ROW(A8) -> 8
A13: =ROW(A9) -> 9
A14: =ROW(A10) -> 10
A15: Purpose | I15: Sum | J15: =SUM(J6:J14) -> 8496
A16: * There will be an additional administration expense and financial expense (Depend on contract) deduction of total provision cost price.
S17: HEC | T17: PCM | U17: ADM | V17: PM
T19: / | U19: / | V19: /
O20: Requesting | P20: JV Area PIC | Q20: PCM (Subcon)
O21: Company | S21: HDEC | T21: PCM | U21: ADM | V21: PM
O23: / | P23: / | Q23: / | T23: / | U23: / | V23: /
T39: PROJECT MANAGER
O45: PROJECT MANAGER | P45: PROJECT MANAGER | Q45: PROJECT MANAGER | T45: PCM | U45: ADM | V45: PROJECT MANAGER
O49: PROJECT MANAGER | P49: PROJECT MANAGER | Q49: PROJECT MANAGER | T49: ADM | U49: PCM | V49: PROJECT MANAGER

Sheet MRS LIST
A1: ■ Purchase Requisition of Equipment Rental | J1: =+MRS!J1 -> DAESHIN PLANT
A2: =+MRS!A2 -> PJT : SACE2 | D2: =+MRS!D2 -> Division (In charge Name) : ADMIN MANAGER (Sang Yeun Cho) | J2: =+MRS!J2 -> Subcontract name ()
A3: =+MRS!A3 -> MRS No : SAC2-DS-MRS-0016 | K3: =+MRS!L3 -> 45648
A4: No | B4: Item | D4: Specification (Model / Manufacturer / Size) | G4: Unit | H4: Q'ty | I4: Unit Price | J4: Total Price | K4: Remarks
A6: =+MRS!A6 -> 1 | B6: =MRS!B6 -> Portland Cement | D6: =MRS!D6 -> Portland Cement Type 1 as pe ASTM C150 Cement content min 360 grms per 09 SAMSS-097 | G6: =MRS!G6 -> m3 | H6: =MRS!H6 -> 24 | I6: =MRS!I6 -> 354 | J6: =MRS!J6 -> 8496
A7: =+MRS!#REF! -> #REF!
A8: =+MRS!A7 -> 3
A9: =+MRS!A8 -> 4
A10: =+MRS!A9 -> 5
A11: =+MRS!A10 -> 6
A12: =+MRS!A11 -> 7
A13: =+MRS!A12 -> 8
A14: =+MRS!A13 -> 9
A15: =+MRS!A14 -> 10
A16: =+MRS!#REF! -> #REF!
A17: =+MRS!#REF! -> #REF!

Sheet PO 1st page
M2: BRANCH OF HYUNDAI ENG. & CONST. CO., LTD.
M3: P. O. Box 77249, Al Khobar 31952
M4: kingdom of Saudi Arabia
B5: C.R. 2051041774 & VAT No.: 300000504500003 | M5: Tel: +966-13-845-1088
M6: Fax: +966-13-845-1099
B9: TO: | C9: ERMC(Eastern Ready Mix Concrete Company)
C10: CR No. : | D10: 2066002155 | J10: P/O Date: | K10: =MRS!L3 -> 45648
C11: VAT No. : | D11: 310495012200003 | J11: P/O No.: | K11: =SUBSTITUTE(SUBSTITUTE(+MRS!A3," MRS No : ",""),"-MRS","-PO") -> SAC2-DS-PO-0016
C12: In Charge : | D12: Emrah Ozturk | J12: (Please mention this No. in
D13: +966 54 343 3179 | J13: All future correspondence)
C14: P.O. Box 56006 Riyadh 11554 | J14: Quote Ref. :
C15: Landline : +966 112899999 / Mobile : +966 543433179 | J15: Date-
B17: PURCHASE ORDER
B19: WE ARE PLEASED TO PLACE AN ORDER WITH YOU FOR THE GOODS DESCRIBED BELOW. THE ORDER SHALL BE SUBJECT TO THE TERMS AND CONDITIONS SET OUR
B20: BELOW AND ATTACHED. PLEASE SIGN AND RETURN THE ENCLOSED COPY OF THIS ORDER AS CONFIRMATION OF YOUR ACCEPTANCE OF IT WITHIN A WEEK
B21: OTHERWISE THIS ORDER SHALL BE REGARDED AS BEING ACCEPTED BY YOU.
B24: 1 | C24: GOODS
C25: Portland Cement | M25: [Please refer to attached Scope of supply & Quotation for more details]
B27: 2 | C27: P/O AMOUNT
C28: Material Value | E28: : | F28: =+'PO 2nd page'!G18 -> 8496 | H28: [Excludes Vat]
C29: VAT 15% | E29: : | F29: =+F28*0.15 -> 1274.4
C30: Total Amount | E30: : | F30: =F28+F29 -> 9770.4
B32: 3 | C32: PAYMENT TERMS
C33: 100% Payment after Delivery within 35 days with submission of the following Documents.
C34: a) Tax E-Invoice (From Zakat, Tax and Customs Authority)
C35: b) Delivery/Dispatch Note [Counter signed by Site Representative]
B37: 4 | C37: DELIVERY TERMS
C38: Delivery by Seller to Jafurah HYUNDAI Laydown within a Week after receipt of PO.
B40: 5 | C40: OTHER TERMS AND CONDITIONS
C41: a) Any quantity rejected by the Buyer owing to its poor quality and non conformity of specification shall be replaced and re-delivered
C42: by Seller to Buyer at no extra costs
C43: b) Material Certificate, Data Sheet, Safety Data Sheet and other documents which may required by ARAMCO in material receiving
C44: inspection should be submitted to Buyer
C45: c) MTC / MSDS, Others, If required by Client
B47: 6 | C47: CONTACT POINT:
B48: - | C48: Delivery & Payment : Sang Yeun Cho / Daeshin Admin. [ Mobile No. : +966 53 926 8130 / Email : sycho@daeshinplant.com ]
B49: - | C49: Commercial (Purchaser) : Youngkyu Choi / Daeshin Planning [ Mobile No. : +966 53 952 0931 / Email : ykchoi@daeshinplant.com ]
B50: - | C50: Invoicing : Nehal Kauser / HDEC Purchase PIC [ Mobile No. : +966 50 610 2363 / Email : nehal_kauser@hdec.co.kr ]
B55: Client | J55: Contractor
B57: Signature: | J57: Signature:
...

Sheet PO 2nd page
A2: PO NO. : | B2: =+'PO 1st page'!K11 -> SAC2-DS-PO-0016 | C2: Scope of Supply
A3: DATE : | B3: =+'PO 1st page'!K10 -> 45648 | E3: Jafurah Utilities, Sulfur and Interconnecting Systems(Pkg-2)
A4: S. NO | B4: DESCRIPTION | D4: QTY | E4: UNIT | F4: ='PO 1st page'!C9 -> ERMC(Eastern Ready Mix Concrete Company) | H4: Remarks (Details)
F5: Unit Price | G5: Total Amount
A6: =ROW(A1) -> 1 | B6: Poretland Cement Type 1 as pe ASTM C150 Cement content min 360 grms per 09 SAMSS-097 35Mpa | D6: =+'MRS LIST'!G6 -> m3 | E6: =+'MRS LIST'!H6 -> 24 | F6: =+'MRS LIST'!I6 -> 354 | G6: =+'MRS LIST'!J6 -> 8496
A7: =ROW(A2) -> 2
A8: =ROW(A3) -> 3
A9: =ROW(A4) -> 4
A10: =ROW(A5) -> 5
A11: =ROW(A6) -> 6
A12: =ROW(A7) -> 7
A13: =ROW(A8) -> 8
A14: =ROW(A9) -> 9
A15: =ROW(A10) -> 10
A16: =ROW(A11) -> 11
A17: =ROW(A12) -> 12
A18: Sub Total Amount | G18: =SUM(G6:G17) -> 8496
A19: VAT 15% | G19: =+G18*0.15 -> 1274.4
A20: Grand Total in SAR | G20: =G19+G18 -> 9770.4
A21: =" 1) Above Price are as per your quotation with ref "&'PO 1st page'!K14 -> 1) Above Price are as per your quotation with ref
A22: 2) Details of each item are attached separately.
A24: Page 2/2
