Workbook

Sheet MRS
A1: ■ Purchase Requisition of Material / Manpower / Equipment Rental / ETC. | J1: DAESHIN PLANT
A2: PJT : SACE2 | D2: Division (In charge Name) : ADMIN MANAGER (Dong Chang Kim) | J2: Subcontract name (SAC2-SC-IK-SMP-01)
A3: MRS No : SAC2-DS-MRS-0141 | E3: =+L3 -> 45945 | L3: 45945
A4: No | B4: Item | D4: Specification (Model / Manufacturer / Size) | G4: Unit | H4: Qty | I4: Unit Price (SAR) (Exclude VAT) | J4: Total Price (SAR) (Exclude VAT) | K4: Vendor Name | L4: Remarks
A6: =ROW(A1) -> 1 | B6: AGT | G6: EA | H6: 12 | I6: 490 | J6: =I6*H6 -> 5880 | K6: EECE | L6: One time
A7: =ROW(A2) -> 2 | B7: SCABA | G7: EA | H7: 12 | I7: 560 | J7: =I7*H7 -> 6720 | K7: "
A8: =ROW(A3) -> 3 | B8: Trainer Travel Charges | H8: 1 | I8: 1000 | J8: =I8*H8 -> 1000 | P8: s
A9: =ROW(A4) -> 4
A10: =ROW(A5) -> 5
A11: =ROW(A6) -> 6 | J11: =H11*I11 -> 0
A12: =ROW(A7) -> 7
A13: =ROW(A8) -> 8
A14: =ROW(A9) -> 9
A15: =ROW(A10) -> 10
A16: Purpose | I16: Sum | J16: =SUM(J6:J15) -> 13600
A17: * There will be an additional administration expense and financial expense (Depend on contract) deduction of total provision cost price.
S18: HEC | T18: PCM | U18: ADM | V18: PM
T20: / | U20: / | V20: /
O21: Requesting | P21: JV Area PIC | Q21: PCM (Subcon)
O22: Company | S22: HDEC | T22: PCM | U22: ADM | V22: PM
O24: / | P24: / | Q24: / | T24: / | U24: / | V24: /
T40: PROJECT MANAGER
O46: PROJECT MANAGER | P46: PROJECT MANAGER | Q46: PROJECT MANAGER | T46: PCM | U46: ADM | V46: PROJECT MANAGER
O50: PROJECT MANAGER | P50: PROJECT MANAGER | Q50: PROJECT MANAGER | T50: ADM | U50: PCM | V50: PROJECT MANAGER

Sheet MRS LIST
A1: ■ Purchase Requisition of Equipment Rental | J1: =+MRS!J1 -> DAESHIN PLANT
A2: =+MRS!A2 -> PJT : SACE2 | D2: =+MRS!D2 -> Division (In charge Name) : ADMIN MANAGER (Dong Chang Kim) | J2: =+MRS!J2 -> Subcontract name (SAC2-SC-IK-SMP-01)
A3: =+MRS!A3 -> MRS No : SAC2-DS-MRS-0141 | K3: =+MRS!L3 -> 45945
A4: No | B4: Item | D4: Specification (Model / Manufacturer / Size) | G4: Unit | H4: Q'ty | I4: Unit Price | J4: Total Price | K4: Remarks
A6: =+MRS!A6 -> 1 | B6: =MRS!B6 -> AGT | D6: =MRS!D6 -> 0 | G6: =MRS!G6 -> EA | H6: =MRS!H6 -> 12 | I6: =MRS!I6 -> 490 | J6: =MRS!J6 -> 5880
A7: =+MRS!A7 -> 2 | B7: =MRS!B7 -> SCABA | D7: =MRS!D7 -> 0 | G7: =MRS!G7 -> EA | H7: =MRS!H7 -> 12 | I7: =MRS!I7 -> 560 | J7: =MRS!J7 -> 6720
A8: =+MRS!A8 -> 3 | B8: =MRS!B8 -> Trainer Travel Charges | D8: =MRS!D8 -> 0 | G8: =MRS!G8 -> 0 | H8: =MRS!H8 -> 1 | I8: =MRS!I8 -> 1000 | J8: =MRS!J8 -> 1000
A9: =+MRS!A9 -> 4 | B9: =MRS!B9 -> 0 | D9: =MRS!D9 -> 0 | G9: =MRS!G9 -> 0 | H9: =MRS!H9 -> 0 | I9: =MRS!I9 -> 0 | J9: =MRS!J9 -> 0
A10: =+MRS!A10 -> 5 | B10: =MRS!B10 -> 0 | D10: =MRS!D10 -> 0 | G10: =MRS!G10 -> 0 | H10: =MRS!H10 -> 0 | I10: =MRS!I10 -> 0 | J10: =MRS!J10 -> 0
A11: =+MRS!A11 -> 6 | B11: =MRS!B11 -> 0 | D11: =MRS!D11 -> 0 | G11: =MRS!G11 -> 0 | H11: =MRS!H11 -> 0 | I11: =MRS!I11 -> 0 | J11: =MRS!J11 -> 0
A12: =+MRS!A12 -> 7
A13: =+MRS!A13 -> 8
A14: =+MRS!A14 -> 9
A15: =+MRS!A15 -> 10
A16: =+MRS!#REF! -> #REF!
A17: =+MRS!#REF! -> #REF!

Sheet PO 1st page
M2: BRANCH OF HYUNDAI ENG. & CONST. CO., LTD.
M3: P. O. Box 77249, Al Khobar 31952
M4: kingdom of Saudi Arabia
B5: C.R. 2051041774 & VAT No.: 300000504500003 | M5: Tel: +966-13-845-1088
M6: Fax: +966-13-845-1099
B9: TO: | C9: EECE(Elegance East Contracting Est.)
C10: CR No. : | D10: 2050176801 | J10: P/O Date: | K10: =MRS!L3 -> 45945
C11: VAT No. : | D11: 310031087600003 | J11: P/O No.: | K11: =SUBSTITUTE(SUBSTITUTE(+MRS!A3," MRS No : ",""),"-MRS","-PO") -> SAC2-DS-PO-0141
C12: In Charge : | D12: Azmal | J12: (Please mention this No. in
D13: Mobile No. +966 53 6373734 / email: azmal@eleganceksa.com | J13: All future correspondence)
C14: Al Jubail , Kingdom of Saudi Arabia | J14: Quote Ref. : | K14: ELEGANCE 25/0228
C15: Mobile: +966 53 6373734 | J15: Date- | K15: 45945
B18: PURCHASE ORDER
B20: WE ARE PLEASED TO PLACE AN ORDER WITH YOU FOR THE GOODS DESCRIBED BELOW. THE ORDER SHALL BE SUBJECT TO THE TERMS AND CONDITIONS SET OUR
B21: BELOW AND ATTACHED. PLEASE SIGN AND RETURN THE ENCLOSED COPY OF THIS ORDER AS CONFIRMATION OF YOUR ACCEPTANCE OF IT WITHIN A WEEK
B22: OTHERWISE THIS ORDER SHALL BE REGARDED AS BEING ACCEPTED BY YOU.
B25: 1 | C25: GOODS
C26: =MRS!B6 &", "&MRS!B7&", "&MRS!B8 -> AGT, SCABA, Trainer Travel Charges | M26: [Please refer to attached Scope of supply & Quotation for more details]
B28: 2 | C28: P/O AMOUNT
C29: Material Value | E29: : | F29: 13600
C30: VAT 15% | E30: : | F30: =F29*15% -> 2040
C31: Total Amount | E31: : | F31: =SUM(F29:F30) -> 15640
B33: 3 | C33: PAYMENT TERMS
C34: 100% Payment after Delivery within 35 days with submission of the following Documents.
C35: a) Tax E-Invoice (From Zakat, Tax and Customs Authority)
C36: b) Delivery/Dispatch Note [Counter signed by Site Representative]
B38: 4 | C38: DELIVERY TERMS
C39: Delivery by Seller to Jafurah HYUNDAI Laydown within a Week after receipt of PO.
B41: 5 | C41: OTHER TERMS AND CONDITIONS
C42: a) Any quantity rejected by the Buyer owing to its poor quality and non conformity of specification shall be replaced and re-delivered
C43: by Seller to Buyer at no extra costs
C44: b) Material Certificate, Data Sheet, Safety Data Sheet and other documents which may required by ARAMCO in material receiving
C45: inspection should be submitted to Buyer
C46: c) MTC / MSDS, Others, If required by Client
B48: 6 | C48: CONTACT POINT:
B49: - | C49: Delivery & Payment : Dong Chang Kim / Daeshin Admin. [ Mobile No. : +966 53 748 5762 / Email : kdchjs@daeshinplant.com ]
B50: - | C50: Commercial (Purchaser) : Youngkyu Choi / Daeshin Planning [ Mobile No. : +966 53 952 0931 / Email : ykchoi@daeshinplant.com ]
B51: - | C51: Invoicing : Nehal Kauser / HDEC Purchase PIC [ Mobile No. : +966 50 610 2363 / Email : nehal_kauser@hdec.co.kr ]
B56: Client | J56: Contractor
B58: Signature: | J58: Signature:
...

Sheet PO 2nd page
A2: PO NO. : | B2: =+'PO 1st page'!K11 -> SAC2-DS-PO-0141 | C2: Scope of Supply
A3: DATE : | B3: =+'PO 1st page'!K10 -> 45945 | E3: Jafurah Utilities, Sulfur and Interconnecting Systems(Pkg-2)
A4: S. NO | B4: DESCRIPTION | D4: QTY | E4: UNIT | F4: ='PO 1st page'!C9 -> EECE(Elegance East Contracting Est.) | H4: Remarks (Details)
F5: Unit Price | G5: Total Amount
A6: =ROW(A1) -> 1 | B6: =+'MRS LIST'!B6 -> AGT | D6: =+'MRS LIST'!G6 -> EA | E6: =+'MRS LIST'!H6 -> 12 | F6: =+'MRS LIST'!I6 -> 490 | G6: =+'MRS LIST'!J6 -> 5880 | H6: =MRS!L6 -> One time
A7: =ROW(A2) -> 2 | B7: =+'MRS LIST'!B7 -> SCABA | D7: =+'MRS LIST'!G7 -> EA | E7: =+'MRS LIST'!H7 -> 12 | F7: =+'MRS LIST'!I7 -> 560 | G7: =+'MRS LIST'!J7 -> 6720
A8: =ROW(A3) -> 3 | B8: =+'MRS LIST'!B8 -> Trainer Travel Charges | D8: =+'MRS LIST'!G8 -> 0 | E8: =+'MRS LIST'!H8 -> 1 | F8: =+'MRS LIST'!I8 -> 1000 | G8: =+'MRS LIST'!J8 -> 1000
A9: =ROW(A4) -> 4
A10: =ROW(A5) -> 5
A11: =ROW(A6) -> 6
A12: =ROW(A7) -> 7
A13: =ROW(A8) -> 8
A14: =ROW(A9) -> 9
A15: =ROW(A10) -> 10
A16: =ROW(A11) -> 11 | J16: s
A17: =ROW(A12) -> 12
A18: Sub Total Amount | G18: =SUM(G6:G17) -> 13600
A19: VAT 15% | G19: =+G18*0.15 -> 2040
A20: Grand Total in SAR | G20: =G19+G18 -> 15640
A21: =" 1) Above Price are as per your quotation with ref "&'PO 1st page'!K14 -> 1) Above Price are as per your quotation with ref ELEGANCE 25/0228
A22: 2) Details of each item are attached separately.
A24: Page 2/2
