Workbook

Sheet MRS
A1: ■ Purchase Requisition of Material / Manpower / Equipment Rental / ETC. | J1: DAESHIN PLANT
A2: PJT : SACE2 | D2: Division (In charge Name) : ADMIN MANAGER (Dong Chang Kim) | J2: Subcontract name (SAC2-SC-IK-SMP-01)
A3: MRS No : SAC2-DS-MRS-0426 | E3: =+L3+3 -> 46255 | L3: 46252
A4: No | B4: Item | D4: Specification (Model / Manufacturer / Size) | G4: Unit | H4: Qty | I4: Unit Price (SAR) (Exclude VAT) | J4: Total Price (SAR) (Exclude VAT) | K4: Vendor Name | L4: Remarks
A6: =ROW(A1) -> 1 | B6: POLYESTER ENDLESS ROUND SLING | D6: SWL-20MT, LENGTH-10Mtr, CIRCUM-20Mtr, FOS-7:1, | G6: EA | H6: 1 | I6: 980 | J6: =+H6*I6 -> 980 | K6: AMT | L6: One time
A7: =ROW(A2) -> 2 | B7: POLYESTER ENDLESS ROUND SLING | D7: SWL-20MT, LENGTH-10Mtr, CIRCUM-20Mtr, FOS-7:1, | G7: EA | H7: 4 | I7: 980 | J7: =+H7*I7 -> 3920
A8: =ROW(A3) -> 3 | B8: POLYESTER ENDLESS ROUND SLING | D8: SWL-10MT, LENGTH-10Mtr, CIRCUM-20Mtr, FOS-7:1, | G8: EA | H8: 4 | I8: 330 | J8: =+H8*I8 -> 1320
A9: =ROW(A4) -> 4 | B9: Manually Operated Chain Lever Block | D9: SWL-1.5MT, Load Chain Length-3Mtr, | G9: EA | H9: 10 | I9: 290 | J9: =+H9*I9 -> 2900
A10: =ROW(A5) -> 5 | B10: Manually Operated Chain Lever Block | D10: SWL-1.5MT, Load Chain Length-3Mtr, | G10: EA | H10: 6 | I10: 290 | J10: =+H10*I10 -> 1740
A11: =ROW(A6) -> 6 | B11: Manually Operated Chain Lever Block | D11: SWL-2MT, Load Chain Length-3Mtr, | G11: EA | H11: 3 | I11: 350 | J11: =+H11*I11 -> 1050
A12: =ROW(A7) -> 7 | B12: 3" WIDE POLYESTER DUPLEX WEBBING SLING, | D12: BOTH END SOFT EYE, LENGTH-3Mtr, SWL-3Ton, FOS-7:1, | G12: EA | H12: 4 | I12: 27 | J12: =+H12*I12 -> 108
A13: =ROW(A8) -> 8 | B13: 3" WIDE POLYESTER DUPLEX WEBBING SLING, | D13: BOTH END SOFT EYE, LENGTH-6Mtr, SWL-3Ton, FOS-7:1, | G13: EA | H13: 4 | I13: 56 | J13: =+H13*I13 -> 224
A14: =ROW(A9) -> 9 | B14: 3" WIDE POLYESTER DUPLEX WEBBING SLING, | D14: BOTH END SOFT EYE, LENGTH-8Mtr, SWL-3Ton, FOS-7:1, | G14: EA | H14: 4 | I14: 65 | J14: =+H14*I14 -> 260
A15: =ROW(A10) -> 10 | B15: 3/4" G209 SCREW PIN TYPE ALLOY BOW SHACKLE, | D15: SWL-4.75MT, | G15: EA | H15: 4 | I15: 20 | J15: =+H15*I15 -> 80
A16: Purpose | I16: Sum | J16: =SUM(J6:J15) -> 12582
A17: * There will be an additional administration expense and financial expense (Depend on contract) deduction of total provision cost price.
O20: SUB-CON | T20: HDEC
O21: In Charge | P21: ADM | Q21: PCM | R21: PM | T21: Construction | U21: Subcon(PC) | V21: Account | Y21: ADM
V22: In Charge | W22: Manager
X24: HEC | Y24: ADM
O46: PROJECT MANAGER | P46: PROJECT MANAGER | S46: ADM
O50: PROJECT MANAGER | P50: PROJECT MANAGER | S50: PCM

Sheet MRS LIST
A1: ■ Purchase Requisition of Equipment Rental | J1: =+MRS!J1 -> DAESHIN PLANT
A2: =+MRS!A2 -> PJT : SACE2 | D2: =+MRS!D2 -> Division (In charge Name) : ADMIN MANAGER (Dong Chang Kim) | J2: =+MRS!J2 -> Subcontract name (SAC2-SC-IK-SMP-01)
A3: =+MRS!A3 -> MRS No : SAC2-DS-MRS-0426 | K3: =+MRS!L3 -> 46252
A4: No | B4: Item | D4: Specification (Model / Manufacturer / Size) | G4: Unit | H4: Q'ty | I4: Unit Price | J4: Total Price | K4: Remarks
A6: =+MRS!A6 -> 1 | B6: =MRS!B6 -> POLYESTER ENDLESS ROUND SLING | D6: =MRS!D6 -> SWL-20MT, LENGTH-10Mtr, CIRCUM-20Mtr, FOS-7:1, | G6: =MRS!G6 -> EA | H6: =MRS!H6 -> 1 | I6: =MRS!I6 -> 980 | J6: =MRS!J6 -> 980
A7: =+MRS!A7 -> 2 | B7: =MRS!B7 -> POLYESTER ENDLESS ROUND SLING | D7: =MRS!D7 -> SWL-20MT, LENGTH-10Mtr, CIRCUM-20Mtr, FOS-7:1, | G7: =MRS!G7 -> EA | H7: =MRS!H7 -> 4 | I7: =MRS!I7 -> 980 | J7: =MRS!J7 -> 3920
A8: =+MRS!A8 -> 3 | B8: =MRS!B8 -> POLYESTER ENDLESS ROUND SLING | D8: =MRS!D8 -> SWL-10MT, LENGTH-10Mtr, CIRCUM-20Mtr, FOS-7:1, | G8: =MRS!G8 -> EA | H8: =MRS!H8 -> 4 | I8: =MRS!I8 -> 330 | J8: =MRS!J8 -> 1320
A9: =+MRS!A9 -> 4 | B9: =MRS!B9 -> Manually Operated Chain Lever Block | D9: =MRS!D9 -> SWL-1.5MT, Load Chain Length-3Mtr, | G9: =MRS!G9 -> EA | H9: =MRS!H9 -> 10 | I9: =MRS!I9 -> 290 | J9: =MRS!J9 -> 2900
A10: =+MRS!A10 -> 5 | B10: =MRS!B10 -> Manually Operated Chain Lever Block | D10: =MRS!D10 -> SWL-1.5MT, Load Chain Length-3Mtr, | G10: =MRS!G10 -> EA | H10: =MRS!H10 -> 6 | I10: =MRS!I10 -> 290 | J10: =MRS!J10 -> 1740
A11: =+MRS!A11 -> 6 | B11: =MRS!B11 -> Manually Operated Chain Lever Block | D11: =MRS!D11 -> SWL-2MT, Load Chain Length-3Mtr, | G11: =MRS!G11 -> EA | H11: =MRS!H11 -> 3 | I11: =MRS!I11 -> 350 | J11: =MRS!J11 -> 1050
A12: =+MRS!A12 -> 7 | B12: =MRS!B12 -> 3" WIDE POLYESTER DUPLEX WEBBING SLING, | D12: =MRS!D12 -> BOTH END SOFT EYE, LENGTH-3Mtr, SWL-3Ton, FOS-7:1, | G12: =MRS!G12 -> EA | H12: =MRS!H12 -> 4 | I12: =MRS!I12 -> 27 | J12: =MRS!J12 -> 108
A13: =+MRS!A13 -> 8 | B13: =MRS!B13 -> 3" WIDE POLYESTER DUPLEX WEBBING SLING, | D13: =MRS!D13 -> BOTH END SOFT EYE, LENGTH-6Mtr, SWL-3Ton, FOS-7:1, | G13: =MRS!G13 -> EA | H13: =MRS!H13 -> 4 | I13: =MRS!I13 -> 56 | J13: =MRS!J13 -> 224
A14: =+MRS!A14 -> 9 | B14: =MRS!B14 -> 3" WIDE POLYESTER DUPLEX WEBBING SLING, | D14: =MRS!D14 -> BOTH END SOFT EYE, LENGTH-8Mtr, SWL-3Ton, FOS-7:1, | G14: =MRS!G14 -> EA | H14: =MRS!H14 -> 4 | I14: =MRS!I14 -> 65 | J14: =MRS!J14 -> 260
A15: =+MRS!A15 -> 10 | B15: =MRS!B15 -> 3/4" G209 SCREW PIN TYPE ALLOY BOW SHACKLE, | D15: =MRS!E15 -> 0 | G15: =MRS!G15 -> EA | H15: =MRS!H15 -> 4 | I15: =MRS!I15 -> 20 | J15: =MRS!J15 -> 80
A16: =+MRS!#REF! -> #REF! | B16: =MRS!#REF! -> #REF! | D16: =MRS!#REF! -> #REF! | G16: =MRS!#REF! -> #REF! | H16: =MRS!#REF! -> #REF! | I16: =MRS!#REF! -> #REF! | J16: =MRS!#REF! -> #REF!
A17: =+MRS!#REF! -> #REF! | B17: =MRS!#REF! -> #REF! | D17: =MRS!#REF! -> #REF! | G17: =MRS!#REF! -> #REF! | H17: =MRS!#REF! -> #REF! | I17: =MRS!#REF! -> #REF! | J17: =MRS!#REF! -> #REF!
A18: =+MRS!#REF! -> #REF! | B18: =MRS!#REF! -> #REF! | D18: =MRS!#REF! -> #REF! | G18: =MRS!#REF! -> #REF! | H18: =MRS!#REF! -> #REF! | I18: =MRS!#REF! -> #REF! | J18: =MRS!#REF! -> #REF!

Sheet PO 1st page
M2: BRANCH OF HYUNDAI ENG. & CONST. CO., LTD.
M3: P. O. Box 77249, Al Khobar 31952
M4: kingdom of Saudi Arabia
B5: C.R. 2051041774 & VAT No.: 300000504500003 | M5: Tel: +966-13-845-1088
M6: Fax: +966-13-845-1099
B9: TO: | C9: AMT(Alam Alamani Trading Company)
C10: CR No. : | D10: 2051229875 | J10: P/O Date: | K10: =MRS!L3 -> 46252
C11: VAT No. : | D11: 311236644400003 | J11: P/O No.: | K11: =SUBSTITUTE(SUBSTITUTE(+MRS!A3," MRS No : ",""),"-MRS","-PO") -> SAC2-DS-PO-0426
C12: In Charge : | D12: Rafeeq Kotyadi | J12: (Please mention this No. in
D13: +966 56 482 5879 / Email: sales@alamaniya.com | J13: All future correspondence)
C14: Building No. 3345,Ath Thuqbah Dist. Al Khobar 34623, KSA | J14: Quote Ref. : | K14: QT26-1562
C15: Mobile: | D15: +966 56 482 5879 | J15: Date- | K15: 46243
B18: PURCHASE ORDER
B20: WE ARE PLEASED TO PLACE AN ORDER WITH YOU FOR THE GOODS DESCRIBED BELOW. THE ORDER SHALL BE SUBJECT TO THE TERMS AND CONDITIONS SET OUR
B21: BELOW AND ATTACHED. PLEASE SIGN AND RETURN THE ENCLOSED COPY OF THIS ORDER AS CONFIRMATION OF YOUR ACCEPTANCE OF IT WITHIN A WEEK
B22: OTHERWISE THIS ORDER SHALL BE REGARDED AS BEING ACCEPTED BY YOU.
B25: 1 | C25: GOODS
C26: Site Materials | M26: [Please refer to attached Scope of supply & Quotation for more details]
B28: 2 | C28: P/O AMOUNT
C29: Material Value | E29: : | F29: ='PO 2nd page'!G16 -> 12582
C30: VAT 15% | E30: : | F30: ='PO 2nd page'!G17 -> 1887.3
C31: Total Amount | E31: : | F31: ='PO 2nd page'!G18 -> 14469.3
B33: 3 | C33: PAYMENT TERMS
C34: 100% Payment after Delivery within 35 days with submission of the following Documents.
C35: a) Tax E-Invoice (From Zakat, Tax and Customs Authority)
C36: b) Delivery/Dispatch Note [Counter signed by Site Representative]
B38: 4 | C38: DELIVERY TERMS
C39: Delivery by Seller to Jafurah HYUNDAI Laydown within a Week after receipt of PO.
B41: 5 | C41: OTHER TERMS AND CONDITIONS
C42: a) Any quantity rejected by the Buyer owing to its poor quality and non conformity of specification shall be replaced and re-delivered
C43: by Seller to Buyer at no extra costs
C44: b) Material Certificate, Data Sheet, Safety Data Sheet and other documents which may required by ARAMCO in material receiving
C45: inspection should be submitted to Buyer
C46: c) MTC / MSDS, Others, If required by Client
B48: 6 | C48: CONTACT POINT:
B49: - | C49: Delivery & Payment : Dong Chang Kim / Daeshin Admin. [ Mobile No. : +966 53 748 5762 / Email : kdchjs@daeshinplant.com ]
B50: - | C50: Commercial (Purchaser) : Youngkyu Choi / Daeshin Planning [ Mobile No. : +966 53 952 0931 / Email : ykchoi@daeshinplant.com ]
B51: - | C51: Invoicing : Nehal Kauser / HDEC Purchase PIC [ Mobile No. : +966 50 610 2363 / Email : nehal_kauser@hdec.co.kr ]
B53: 7 | C53: Bank Account Details:
B54: - | C54: ACCOUNT NAME | F54: ALAM ALAMANI TRADING COMPANY | P54: =UPPER(F54) -> ALAM ALAMANI TRADING COMPANY
...

Sheet PO 2nd page
A2: PO NO. : | B2: =+'PO 1st page'!K11 -> SAC2-DS-PO-0426 | C2: Scope of Supply
A3: DATE : | B3: =+'PO 1st page'!K10 -> 46252 | E3: Jafurah Utilities, Sulfur and Interconnecting Systems(Pkg-2)
A4: S. NO | B4: DESCRIPTION | D4: QTY | E4: UNIT | F4: ='PO 1st page'!C9 -> AMT(Alam Alamani Trading Company) | H4: Remarks (Details)
F5: Unit Price | G5: Total Amount
A6: =ROW(A1) -> 1 | B6: =_xlfn.CONCAT(MRS!B6," ",MRS!D6) -> POLYESTER ENDLESS ROUND SLING SWL-20MT, LENGTH-10Mtr, CIRCUM-20Mtr, FOS-7:1, | D6: =MRS!G6 -> EA | E6: =MRS!H6 -> 1 | F6: =MRS!I6 -> 980 | G6: =MRS!J6 -> 980 | H6: One time
A7: =ROW(A2) -> 2 | B7: =_xlfn.CONCAT(MRS!B7," ",MRS!D7) -> POLYESTER ENDLESS ROUND SLING SWL-20MT, LENGTH-10Mtr, CIRCUM-20Mtr, FOS-7:1, | D7: =MRS!G7 -> EA | E7: =MRS!H7 -> 4 | F7: =MRS!I7 -> 980 | G7: =MRS!J7 -> 3920
A8: =ROW(A3) -> 3 | B8: =_xlfn.CONCAT(MRS!B8," ",MRS!D8) -> POLYESTER ENDLESS ROUND SLING SWL-10MT, LENGTH-10Mtr, CIRCUM-20Mtr, FOS-7:1, | D8: =MRS!G8 -> EA | E8: =MRS!H8 -> 4 | F8: =MRS!I8 -> 330 | G8: =MRS!J8 -> 1320
A9: =ROW(A4) -> 4 | B9: =_xlfn.CONCAT(MRS!B9," ",MRS!D9) -> Manually Operated Chain Lever Block SWL-1.5MT, Load Chain Length-3Mtr, | D9: =MRS!G9 -> EA | E9: =MRS!H9 -> 10 | F9: =MRS!I9 -> 290 | G9: =MRS!J9 -> 2900
A10: =ROW(A5) -> 5 | B10: =_xlfn.CONCAT(MRS!B10," ",MRS!D10) -> Manually Operated Chain Lever Block SWL-1.5MT, Load Chain Length-3Mtr, | D10: =MRS!G10 -> EA | E10: =MRS!H10 -> 6 | F10: =MRS!I10 -> 290 | G10: =MRS!J10 -> 1740
A11: =ROW(A6) -> 6 | B11: =_xlfn.CONCAT(MRS!B11," ",MRS!D11) -> Manually Operated Chain Lever Block SWL-2MT, Load Chain Length-3Mtr, | D11: =MRS!G11 -> EA | E11: =MRS!H11 -> 3 | F11: =MRS!I11 -> 350 | G11: =MRS!J11 -> 1050
A12: =ROW(A7) -> 7 | B12: =_xlfn.CONCAT(MRS!B12," ",MRS!D12) -> 3" WIDE POLYESTER DUPLEX WEBBING SLING, BOTH END SOFT EYE, LENGTH-3Mtr, SWL-3Ton, FOS-7:1, | D12: =MRS!G12 -> EA | E12: =MRS!H12 -> 4 | F12: =MRS!I12 -> 27 | G12: =MRS!J12 -> 108
A13: =ROW(A8) -> 8 | B13: =_xlfn.CONCAT(MRS!B13," ",MRS!D13) -> 3" WIDE POLYESTER DUPLEX WEBBING SLING, BOTH END SOFT EYE, LENGTH-6Mtr, SWL-3Ton, FOS-7:1, | D13: =MRS!G13 -> EA | E13: =MRS!H13 -> 4 | F13: =MRS!I13 -> 56 | G13: =MRS!J13 -> 224
A14: =ROW(A9) -> 9 | B14: =_xlfn.CONCAT(MRS!B14," ",MRS!D14) -> 3" WIDE POLYESTER DUPLEX WEBBING SLING, BOTH END SOFT EYE, LENGTH-8Mtr, SWL-3Ton, FOS-7:1, | D14: =MRS!G14 -> EA | E14: =MRS!H14 -> 4 | F14: =MRS!I14 -> 65 | G14: =MRS!J14 -> 260
A15: =ROW(A10) -> 10 | B15: =_xlfn.CONCAT(MRS!B15," ",MRS!E15) -> 3/4" G209 SCREW PIN TYPE ALLOY BOW SHACKLE, | D15: =MRS!G15 -> EA | E15: =MRS!H15 -> 4 | F15: =MRS!I15 -> 20 | G15: =MRS!J15 -> 80
A16: Sub Total Amount | G16: =SUM(G6:G15) -> 12582
A17: VAT 15% | G17: =+G16*0.15 -> 1887.3
A18: Grand Total in SAR | G18: =G17+G16 -> 14469.3
A19: =" 1) Above Price are as per your quotation with ref "&'PO 1st page'!K14 -> 1) Above Price are as per your quotation with ref QT26-1562
A20: 2) Details of each item are attached separately.
A22: Page 2/2
