Workbook

Sheet MRS
A1: ■ Purchase Requisition of Material / Manpower / Equipment Rental / ETC. | J1: DAESHIN PLANT
A2: PJT : SACE2 | D2: Division (In charge Name) : ADMIN MANAGER (Dong Chang Kim) | J2: Subcontract name (SAC2-SC-IK-SMP-01)
A3: MRS No : SAC2-DS-MRS-0285 | E3: =+L3 -> 46128 | L3: 46128
A4: No | B4: Item | D4: Specification (Model / Manufacturer / Size) | G4: Unit | H4: Qty | I4: Unit Price (SAR) (Exclude VAT) | J4: Total Price (SAR) (Exclude VAT) | K4: Vendor Name | L4: Remarks
A6: =ROW(A1) -> 1 | B6: 16A/220V 3PIN MOBILE PLUG IP66/67 MQ | G6: EA | H6: 200 | I6: 18.5 | J6: =H6*I6 -> 3700 | K6: OSAZ | L6: One time
A7: =ROW(A2) -> 2 | B7: 16A/220V 3PIN MOBILE SOCKET IP66/67 MQ | G7: EA | H7: 200 | I7: 26.5 | J7: =H7*I7 -> 5300
A8: =ROW(A3) -> 3 | B8: 1 GANG 32A SWITCHED SOCKET WITH BOX | G8: EA | H8: 10 | I8: 15 | J8: =H8*I8 -> 150
A9: =ROW(A4) -> 4 | B9: FLAT CABLE WHITE 1.5MM² 48 X 20 X 80Y - CARTEL | G9: RL | H9: 1 | I9: 65 | J9: =H9*I9 -> 65
A10: =ROW(A5) -> 5 | B10: DIGITAL MULTIMETER FLUKE | G10: EA | H10: 1 | I10: 720 | J10: =H10*I10 -> 720
A11: =ROW(A6) -> 6 | B11: RCCB 25A 2P 10mA | G11: EA | H11: 20 | I11: 110 | J11: =H11*I11 -> 2200
A12: =ROW(A7) -> 7 | B12: 32A/220V 3PIN MOBILE PLUG IP66/67 MQ | G12: EA | H12: 100 | I12: 38.5 | J12: =H12*I12 -> 3850
A13: =ROW(A8) -> 8 | B13: 32A/220V 3PIN MOBILE SOCKET IP66/67 MQ | G13: EA | H13: 100 | I13: 65 | J13: =H13*I13 -> 6500
A14: =ROW(A9) -> 9 | B14: LED FLOOD LIGHT 400W | G14: EA | H14: 200 | I14: 95 | J14: =H14*I14 -> 19000
A15: =ROW(A10) -> 10 | B15: FLEXIBLE CABLE WHITE 3C X 6MM² 100YARD / ROLL | G15: RL | H15: 50 | I15: 585 | J15: =H15*I15 -> 29250
A16: =ROW(A11) -> 11 | B16: FLEXIBLE CABLE WHITE 4C X 6MM² 100YARD / ROLL | G16: RL | H16: 5 | I16: 760 | J16: =H16*I16 -> 3800
A17: =ROW(A12) -> 12 | B17: 16A/220V 3PIN MOBILE PLUG IP66/67 MQ | G17: EA | H17: 50 | I17: 18.5 | J17: =H17*I17 -> 925
A18: =ROW(A13) -> 13 | B18: 16A/220V 3PIN MOBILE SOCKET IP66/67 MQ | G18: EA | H18: 50 | I18: 26.5 | J18: =H18*I18 -> 1325
A19: Purpose | I19: Sum | J19: =SUM(J6:J18) -> 76785
A20: * There will be an additional administration expense and financial expense (Depend on contract) deduction of total provision cost price.
R21: HEC | S21: ADM
S23: /
O24: Requesting | P24: JV Area PIC
O25: Company | R25: HDEC | S25: ADM
O27: / | P27: / | S27: /
O49: PROJECT MANAGER | P49: PROJECT MANAGER | S49: ADM
O53: PROJECT MANAGER | P53: PROJECT MANAGER | S53: PCM

Sheet MRS LIST
A1: ■ Purchase Requisition of Equipment Rental | J1: =+MRS!J1 -> DAESHIN PLANT
A2: =+MRS!A2 -> PJT : SACE2 | D2: =+MRS!D2 -> Division (In charge Name) : ADMIN MANAGER (Dong Chang Kim) | J2: =+MRS!J2 -> Subcontract name (SAC2-SC-IK-SMP-01)
A3: =+MRS!A3 -> MRS No : SAC2-DS-MRS-0285 | K3: =+MRS!L3 -> 46128
A4: No | B4: Item | D4: Specification (Model / Manufacturer / Size) | G4: Unit | H4: Q'ty | I4: Unit Price | J4: Total Price | K4: Remarks
A6: =+MRS!A6 -> 1 | B6: =MRS!B6 -> 16A/220V 3PIN MOBILE PLUG IP66/67 MQ | D6: =MRS!D6 -> 0 | G6: =MRS!G6 -> EA | H6: =MRS!H6 -> 200 | I6: =MRS!I6 -> 18.5 | J6: =MRS!J6 -> 3700
A7: =+MRS!A7 -> 2 | B7: =MRS!B7 -> 16A/220V 3PIN MOBILE SOCKET IP66/67 MQ | D7: =MRS!D7 -> 0 | G7: =MRS!G7 -> EA | H7: =MRS!H7 -> 200 | I7: =MRS!I7 -> 26.5 | J7: =MRS!J7 -> 5300
A8: =+MRS!A8 -> 3 | B8: =MRS!B8 -> 1 GANG 32A SWITCHED SOCKET WITH BOX | D8: =MRS!D8 -> 0 | G8: =MRS!G8 -> EA | H8: =MRS!H8 -> 10 | I8: =MRS!I8 -> 15 | J8: =MRS!J8 -> 150
A9: =+MRS!A9 -> 4 | B9: =MRS!B9 -> FLAT CABLE WHITE 1.5MM² 48 X 20 X 80Y - CARTEL | D9: =MRS!D9 -> 0 | G9: =MRS!G9 -> RL | H9: =MRS!H9 -> 1 | I9: =MRS!I9 -> 65 | J9: =MRS!J9 -> 65
A10: =+MRS!A10 -> 5 | B10: =MRS!B10 -> DIGITAL MULTIMETER FLUKE | D10: =MRS!D10 -> 0 | G10: =MRS!G10 -> EA | H10: =MRS!H10 -> 1 | I10: =MRS!I10 -> 720 | J10: =MRS!J10 -> 720
A11: =+MRS!A11 -> 6 | B11: =MRS!B11 -> RCCB 25A 2P 10mA | D11: =MRS!D11 -> 0 | G11: =MRS!G11 -> EA | H11: =MRS!H11 -> 20 | I11: =MRS!I11 -> 110 | J11: =MRS!J11 -> 2200
A12: =+MRS!A12 -> 7 | B12: =MRS!B12 -> 32A/220V 3PIN MOBILE PLUG IP66/67 MQ | D12: =MRS!D12 -> 0 | G12: =MRS!G12 -> EA | H12: =MRS!H12 -> 100 | I12: =MRS!I12 -> 38.5 | J12: =MRS!J12 -> 3850
A13: =+MRS!A13 -> 8 | B13: =MRS!B13 -> 32A/220V 3PIN MOBILE SOCKET IP66/67 MQ | D13: =MRS!D13 -> 0 | G13: =MRS!G13 -> EA | H13: =MRS!H13 -> 100 | I13: =MRS!I13 -> 65 | J13: =MRS!J13 -> 6500
A14: =+MRS!A14 -> 9 | B14: =MRS!B14 -> LED FLOOD LIGHT 400W | D14: =MRS!D14 -> 0 | G14: =MRS!G14 -> EA | H14: =MRS!H14 -> 200 | I14: =MRS!I14 -> 95 | J14: =MRS!J14 -> 19000
A15: =+MRS!#REF! -> #REF! | B15: =MRS!#REF! -> #REF! | D15: =MRS!#REF! -> #REF! | G15: =MRS!#REF! -> #REF! | H15: =MRS!#REF! -> #REF! | I15: =MRS!#REF! -> #REF! | J15: =MRS!#REF! -> #REF!

Sheet PO 1st page
M2: BRANCH OF HYUNDAI ENG. & CONST. CO., LTD.
M3: P. O. Box 77249, Al Khobar 31952
M4: kingdom of Saudi Arabia
B5: C.R. 2051041774 & VAT No.: 300000504500003 | M5: Tel: +966-13-845-1088
M6: Fax: +966-13-845-1099
B9: TO: | C9: OSAZ (Omar Saleh Abdullah Al-Zahrani Electricals)
C10: CR No. : | D10: 2055009599 | J10: P/O Date: | K10: =MRS!L3 -> 46128
C11: VAT No. : | D11: 300512826400003 | J11: P/O No.: | K11: =SUBSTITUTE(SUBSTITUTE(+MRS!A3," MRS No : ",""),"-MRS","-PO") -> SAC2-DS-PO-0285
C12: In Charge : | D12: Mansoor | J12: (Please mention this No. in
D13: Mobile: +966 57 694 3329 | J13: All future correspondence)
C14: Building No. 3350,King Fahad Street-8603,Al Dana Dist. Al Jubail 35514, KSA | J14: Quote Ref. : | K14: 101696
C15: Mobile: +966 57 694 3329 | J15: Date- | K15: 46126
B18: PURCHASE ORDER
B20: WE ARE PLEASED TO PLACE AN ORDER WITH YOU FOR THE GOODS DESCRIBED BELOW. THE ORDER SHALL BE SUBJECT TO THE TERMS AND CONDITIONS SET OUR
B21: BELOW AND ATTACHED. PLEASE SIGN AND RETURN THE ENCLOSED COPY OF THIS ORDER AS CONFIRMATION OF YOUR ACCEPTANCE OF IT WITHIN A WEEK
B22: OTHERWISE THIS ORDER SHALL BE REGARDED AS BEING ACCEPTED BY YOU.
B25: 1 | C25: GOODS
C26: Electrical Items | M26: [Please refer to attached Scope of supply & Quotation for more details]
B28: 2 | C28: P/O AMOUNT
C29: Material Value | E29: : | F29: ='PO 2nd page'!G29 -> 76785
C30: VAT 15% | E30: : | F30: ='PO 2nd page'!G30 -> 11517.75
C31: Total Amount | E31: : | F31: ='PO 2nd page'!G31 -> 88302.75
B33: 3 | C33: PAYMENT TERMS
C34: 100% Payment after Delivery within 35 days with submission of the following Documents.
C35: a) Tax E-Invoice (From Zakat, Tax and Customs Authority)
C36: b) Delivery/Dispatch Note [Counter signed by Site Representative]
B38: 4 | C38: DELIVERY TERMS
C39: Delivery by Seller to Jafurah HYUNDAI Laydown within a Week after receipt of PO.
B41: 5 | C41: OTHER TERMS AND CONDITIONS
C42: a) Any quantity rejected by the Buyer owing to its poor quality and non conformity of specification shall be replaced and re-delivered
C43: by Seller to Buyer at no extra costs
C44: b) Material Certificate, Data Sheet, Safety Data Sheet and other documents which may required by ARAMCO in material receiving
C45: inspection should be submitted to Buyer
C46: c) MTC / MSDS, Others, If required by Client
B48: 6 | C48: CONTACT POINT:
B49: - | C49: Delivery & Payment : Dong Chang Kim / Daeshin Admin. [ Mobile No. : +966 53 748 5762 / Email : kdchjs@daeshinplant.com ]
B50: - | C50: Commercial (Purchaser) : Youngkyu Choi / Daeshin Planning [ Mobile No. : +966 53 952 0931 / Email : ykchoi@daeshinplant.com ]
B51: - | C51: Invoicing : Nehal Kauser / HDEC Purchase PIC [ Mobile No. : +966 50 610 2363 / Email : nehal_kauser@hdec.co.kr ]
B53: 7 | C53: Bank Account Details:
B54: - | C54: ACCOUNT NAME | F54: OMAR SALEH ABDULLAH AL-ZAHRANI ELECTRICALS | P54: =UPPER(F54) -> OMAR SALEH ABDULLAH AL-ZAHRANI ELECTRICALS
...

Sheet PO 2nd page
A2: PO NO. : | B2: =+'PO 1st page'!K11 -> SAC2-DS-PO-0285 | C2: Scope of Supply
A3: DATE : | B3: =+'PO 1st page'!K10 -> 46128 | E3: Jafurah Utilities, Sulfur and Interconnecting Systems(Pkg-2)
A4: S. NO | B4: DESCRIPTION | D4: QTY | E4: UNIT | F4: ='PO 1st page'!C9 -> OSAZ (Omar Saleh Abdullah Al-Zahrani Electricals) | H4: Remarks (Details)
F5: Unit Price | G5: Total Amount
A6: =ROW(A1) -> 1 | B6: =MRS!B6&" "&MRS!D6 -> 16A/220V 3PIN MOBILE PLUG IP66/67 MQ | D6: =MRS!G6 -> EA | E6: =MRS!H6 -> 200 | F6: =MRS!I6 -> 18.5 | G6: =MRS!J6 -> 3700 | H6: One time
A7: =ROW(A2) -> 2 | B7: =MRS!B7&" "&MRS!D7 -> 16A/220V 3PIN MOBILE SOCKET IP66/67 MQ | D7: =MRS!G7 -> EA | E7: =MRS!H7 -> 200 | F7: =MRS!I7 -> 26.5 | G7: =MRS!J7 -> 5300
A8: =ROW(A3) -> 3 | B8: =MRS!B8&" "&MRS!D8 -> 1 GANG 32A SWITCHED SOCKET WITH BOX | D8: =MRS!G8 -> EA | E8: =MRS!H8 -> 10 | F8: =MRS!I8 -> 15 | G8: =MRS!J8 -> 150
A9: =ROW(A4) -> 4 | B9: =MRS!B9&" "&MRS!D9 -> FLAT CABLE WHITE 1.5MM² 48 X 20 X 80Y - CARTEL | D9: =MRS!G9 -> RL | E9: =MRS!H9 -> 1 | F9: =MRS!I9 -> 65 | G9: =MRS!J9 -> 65
A10: =ROW(A5) -> 5 | B10: =MRS!B10&" "&MRS!D10 -> DIGITAL MULTIMETER FLUKE | D10: =MRS!G10 -> EA | E10: =MRS!H10 -> 1 | F10: =MRS!I10 -> 720 | G10: =MRS!J10 -> 720
A11: =ROW(A6) -> 6 | B11: =MRS!B11&" "&MRS!D11 -> RCCB 25A 2P 10mA | D11: =MRS!G11 -> EA | E11: =MRS!H11 -> 20 | F11: =MRS!I11 -> 110 | G11: =MRS!J11 -> 2200
A12: =ROW(A7) -> 7 | B12: =MRS!B12&" "&MRS!D12 -> 32A/220V 3PIN MOBILE PLUG IP66/67 MQ | D12: =MRS!G12 -> EA | E12: =MRS!H12 -> 100 | F12: =MRS!I12 -> 38.5 | G12: =MRS!J12 -> 3850
A13: =ROW(A8) -> 8 | B13: =MRS!B13&" "&MRS!D13 -> 32A/220V 3PIN MOBILE SOCKET IP66/67 MQ | D13: =MRS!G13 -> EA | E13: =MRS!H13 -> 100 | F13: =MRS!I13 -> 65 | G13: =MRS!J13 -> 6500
A14: =ROW(A9) -> 9 | B14: =MRS!B14&" "&MRS!D14 -> LED FLOOD LIGHT 400W | D14: =MRS!G14 -> EA | E14: =MRS!H14 -> 200 | F14: =MRS!I14 -> 95 | G14: =MRS!J14 -> 19000
A15: =ROW(A10) -> 10 | B15: =MRS!B15&" "&MRS!D15 -> FLEXIBLE CABLE WHITE 3C X 6MM² 100YARD / ROLL | D15: =MRS!G15 -> RL | E15: =MRS!H15 -> 50 | F15: =MRS!I15 -> 585 | G15: =MRS!J15 -> 29250
A16: =ROW(A11) -> 11 | B16: =MRS!B16&" "&MRS!D16 -> FLEXIBLE CABLE WHITE 4C X 6MM² 100YARD / ROLL | D16: =MRS!G16 -> RL | E16: =MRS!H16 -> 5 | F16: =MRS!I16 -> 760 | G16: =MRS!J16 -> 3800
A17: =ROW(A12) -> 12 | B17: =MRS!B17&" "&MRS!D17 -> 16A/220V 3PIN MOBILE PLUG IP66/67 MQ | D17: =MRS!G17 -> EA | E17: =MRS!H17 -> 50 | F17: =MRS!I17 -> 18.5 | G17: =MRS!J17 -> 925
A18: =ROW(A13) -> 13 | B18: =MRS!B18&" "&MRS!D18 -> 16A/220V 3PIN MOBILE SOCKET IP66/67 MQ | D18: =MRS!G18 -> EA | E18: =MRS!H18 -> 50 | F18: =MRS!I18 -> 26.5 | G18: =MRS!J18 -> 1325
A29: Sub Total Amount | G29: =SUM(G6:G28) -> 76785
A30: VAT 15% | G30: =+G29*0.15 -> 11517.75
A31: Grand Total in SAR | G31: =G30+G29 -> 88302.75
A32: =" 1) Above Price are as per your quotation with ref "&'PO 1st page'!K14 -> 1) Above Price are as per your quotation with ref 101696
A33: 2) Details of each item are attached separately.
A35: Page 2/2
