Workbook

Sheet MRS
A1: ■ Purchase Requisition of Material / Manpower / Equipment Rental / ETC. | J1: DAESHIN PLANT
A2: PJT : SACE2 | D2: Division (In charge Name) : ADMIN MANAGER (Sang Yeun Cho) | J2: Subcontract name (SAC2-SC-IK-SMP-01)
A3: MRS No : SAC2-DS-MRS-0026 | E3: =+L3 -> 45684 | L3: 45684
A4: No | B4: Item | D4: Specification (Model / Manufacturer / Size) | G4: Unit | H4: Qty | I4: Unit Price (SAR) (Exclude VAT) | J4: Total Price (SAR) (Exclude VAT) | K4: Vendor Name | L4: Remarks
A6: =ROW(A1) -> 1 | B6: Skip Container | D6: 10 Yard / Rent | G6: 1 | H6: 1 | I6: 50 | J6: =H6*I6 -> 50 | K6: SCCL | L6: Monthly Rent
A7: 2 | B7: Skip Container Waste Disposal | D7: Service Charge | G7: Trip | H7: 1 | I7: 370 | J7: =I7 -> 370 | K7: SCCL
A8: =ROW(A3) -> 3 | B8: Block Toilet Waste Water Removal | D8: Service Charge | G8: EA | H8: 1 | I8: 300 | J8: =I8 -> 300 | K8: SCCL
A9: 3 | B9: 1 x 1 Portable Toilet Cleaning | D9: Service Charge | G9: EA | H9: 1 | I9: 50 | J9: =I9 -> 50 | K9: SCCL
A10: =ROW(A5) -> 5 | B10: 1 x 1 Portable Toilet | D10: Rent | G10: EA | H10: 1 | I10: 200 | J10: =I10 -> 200 | K10: SCCL | L10: Monthly Rent
A11: 4
A12: =ROW(A7) -> 7
A13: 5
A14: =ROW(A9) -> 9
A15: 6
A16: Purpose | I16: Sum | J16: =SUM(J6:J15) -> 970
A17: * There will be an additional administration expense and financial expense (Depend on contract) deduction of total provision cost price.
S18: HEC | T18: PCM | U18: ADM | V18: PM
T20: / | U20: / | V20: /
O21: Requesting | P21: JV Area PIC | Q21: PCM (Subcon)
O22: Company | S22: HDEC | T22: PCM | U22: ADM | V22: PM
O24: / | P24: / | Q24: / | T24: / | U24: / | V24: /
T40: PROJECT MANAGER
O46: PROJECT MANAGER | P46: PROJECT MANAGER | Q46: PROJECT MANAGER | T46: PCM | U46: ADM | V46: PROJECT MANAGER
O50: PROJECT MANAGER | P50: PROJECT MANAGER | Q50: PROJECT MANAGER | T50: ADM | U50: PCM | V50: PROJECT MANAGER

Sheet MRS LIST
A1: ■ Purchase Requisition of Equipment Rental | J1: =+MRS!J1 -> DAESHIN PLANT
A2: =+MRS!A2 -> PJT : SACE2 | D2: =+MRS!D2 -> Division (In charge Name) : ADMIN MANAGER (Sang Yeun Cho) | J2: =+MRS!J2 -> Subcontract name (SAC2-SC-IK-SMP-01)
A3: =+MRS!A3 -> MRS No : SAC2-DS-MRS-0026 | K3: =+MRS!L3 -> 45684
A4: No | B4: Item | D4: Specification (Model / Manufacturer / Size) | G4: Unit | H4: Q'ty | I4: Unit Price | J4: Total Price | K4: Remarks
A6: =+MRS!A6 -> 1 | B6: =MRS!B6 -> Skip Container | D6: =MRS!D6 -> 10 Yard / Rent | G6: =MRS!G6 -> 1 | H6: =MRS!H6 -> 1 | I6: =MRS!I6 -> 50 | J6: =MRS!J6 -> 50
A7: =+MRS!#REF! -> #REF! | B7: =MRS!B7 -> Skip Container Waste Disposal | D7: =MRS!D7 -> Service Charge | G7: =MRS!G7 -> Trip | H7: =MRS!H7 -> 1 | I7: =MRS!I7 -> 370 | J7: =MRS!J7 -> 370
A8: =+MRS!A7 -> 2 | B8: =MRS!B8 -> Block Toilet Waste Water Removal | D8: =MRS!D8 -> Service Charge | G8: =MRS!G8 -> EA | H8: =MRS!H8 -> 1 | I8: =MRS!I8 -> 300 | J8: =MRS!J8 -> 300
A9: =+MRS!A8 -> 3 | B9: =MRS!B9 -> 1 x 1 Portable Toilet Cleaning | D9: =MRS!D9 -> Service Charge | G9: =MRS!G9 -> EA | H9: =MRS!H9 -> 1 | I9: =MRS!I9 -> 50 | J9: =MRS!J9 -> 50
A10: =+MRS!A9 -> 3 | B10: =MRS!B10 -> 1 x 1 Portable Toilet | D10: =MRS!D10 -> Rent | G10: =MRS!G10 -> EA | H10: =MRS!H10 -> 1 | I10: =MRS!I10 -> 200 | J10: =MRS!J10 -> 200
A11: =+MRS!A10 -> 5
A12: =+MRS!A11 -> 4
A13: =+MRS!A12 -> 7
A14: =+MRS!A13 -> 5
A15: =+MRS!A15 -> 6
A16: =+MRS!#REF! -> #REF!
A17: =+MRS!#REF! -> #REF!

Sheet PO 1st page
M2: BRANCH OF HYUNDAI ENG. & CONST. CO., LTD.
M3: P. O. Box 77249, Al Khobar 31952
M4: kingdom of Saudi Arabia
B5: C.R. 2051041774 & VAT No.: 300000504500003 | M5: Tel: +966-13-845-1088
M6: Fax: +966-13-845-1099
B9: TO: | C9: SCCL(Sweep Care Co. Ltd.)
C10: CR No. : | D10: 2055131152 | J10: P/O Date: | K10: =MRS!L3 -> 45684
C11: VAT No. : | D11: 312009886200003 | J11: P/O No.: | K11: =SUBSTITUTE(SUBSTITUTE(+MRS!A3," MRS No : ",""),"-MRS","-PO") -> SAC2-DS-PO-0026
C12: In Charge : | D12: Mohammed Ashraf | J12: (Please mention this No. in
D13: +966 56 5759777 / info@sweepcare.com | J13: All future correspondence)
C14: Bldg 8590 Jabal Street, Jubail City | J14: Quote Ref. : | K14: SC-EQTN-2025-0444
C15: Landline : +966 13 3627417 / Mobile : +966 56 5759777 | J15: Date- | K15: 45678
B17: PURCHASE ORDER
B19: WE ARE PLEASED TO PLACE AN ORDER WITH YOU FOR THE GOODS DESCRIBED BELOW. THE ORDER SHALL BE SUBJECT TO THE TERMS AND CONDITIONS SET OUR
B20: BELOW AND ATTACHED. PLEASE SIGN AND RETURN THE ENCLOSED COPY OF THIS ORDER AS CONFIRMATION OF YOUR ACCEPTANCE OF IT WITHIN A WEEK
B21: OTHERWISE THIS ORDER SHALL BE REGARDED AS BEING ACCEPTED BY YOU.
B24: 1 | C24: GOODS
C25: Waste Management | M25: [Please refer to attached Scope of supply & Quotation for more details]
B27: 2 | C27: P/O AMOUNT
C28: Material Value | E28: : | F28: Monthly Based
C29: VAT 15% | E29: :
C30: Total Amount | E30: :
B32: 3 | C32: PAYMENT TERMS
C33: 100% Payment after Delivery within 35 days with submission of the following Documents.
C34: a) Tax E-Invoice (From Zakat, Tax and Customs Authority)
C35: b) Delivery/Dispatch Note [Counter signed by Site Representative]
B37: 4 | C37: DELIVERY TERMS
C38: Delivery by Seller to Jafurah HYUNDAI Laydown within a Week after receipt of PO.
B40: 5 | C40: OTHER TERMS AND CONDITIONS
C41: a) Any quantity rejected by the Buyer owing to its poor quality and non conformity of specification shall be replaced and re-delivered
C42: by Seller to Buyer at no extra costs
C43: b) Material Certificate, Data Sheet, Safety Data Sheet and other documents which may required by ARAMCO in material receiving
C44: inspection should be submitted to Buyer
C45: c) MTC / MSDS, Others, If required by Client
B47: 6 | C47: CONTACT POINT:
B48: - | C48: Delivery & Payment : Sang Yeun Cho / Daeshin Admin. [ Mobile No. : +966 53 926 8130 / Email : sycho@daeshinplant.com ]
B49: - | C49: Commercial (Purchaser) : Youngkyu Choi / Daeshin Planning [ Mobile No. : +966 53 952 0931 / Email : ykchoi@daeshinplant.com ]
B50: - | C50: Invoicing : Nehal Kauser / HDEC Purchase PIC [ Mobile No. : +966 50 610 2363 / Email : nehal_kauser@hdec.co.kr ]
B55: Client | J55: Contractor
B57: Signature: | J57: Signature:
...

Sheet PO 2nd page
A2: PO NO. : | B2: =+'PO 1st page'!K11 -> SAC2-DS-PO-0026 | C2: Scope of Supply
A3: DATE : | B3: =+'PO 1st page'!K10 -> 45684 | E3: Jafurah Utilities, Sulfur and Interconnecting Systems(Pkg-2)
A4: S. NO | B4: DESCRIPTION | D4: QTY | E4: UNIT | F4: ='PO 1st page'!C9 -> SCCL(Sweep Care Co. Ltd.) | H4: Remarks (Details)
F5: Unit Price | G5: Total Amount
A6: =ROW(A1) -> 1 | B6: =MRS!B6 -> Skip Container | D6: =+'MRS LIST'!G6 -> 1 | E6: =+'MRS LIST'!H6 -> 1 | F6: =+'MRS LIST'!I6 -> 50 | G6: =+'MRS LIST'!J6 -> 50 | H6: =MRS!L6 -> Monthly Rent
A7: =ROW(A2) -> 2 | B7: =MRS!B7 -> Skip Container Waste Disposal | D7: =+'MRS LIST'!G7 -> Trip | E7: =+'MRS LIST'!H7 -> 1 | F7: =+'MRS LIST'!I7 -> 370 | G7: =+'MRS LIST'!J7 -> 370
A8: =ROW(A3) -> 3 | B8: =MRS!B8 -> Block Toilet Waste Water Removal | D8: =+'MRS LIST'!G8 -> EA | E8: =+'MRS LIST'!H8 -> 1 | F8: =+'MRS LIST'!I8 -> 300 | G8: =+'MRS LIST'!J8 -> 300
A9: =ROW(A4) -> 4 | B9: =MRS!B9 -> 1 x 1 Portable Toilet Cleaning | D9: =+'MRS LIST'!G9 -> EA | E9: =+'MRS LIST'!H9 -> 1 | F9: =+'MRS LIST'!I9 -> 50 | G9: =+'MRS LIST'!J9 -> 50
A10: =ROW(A5) -> 5 | B10: =MRS!B10 -> 1 x 1 Portable Toilet | D10: =+'MRS LIST'!G10 -> EA | E10: =+'MRS LIST'!H10 -> 1 | F10: =+'MRS LIST'!I10 -> 200 | G10: =+'MRS LIST'!J10 -> 200 | H10: =MRS!L10 -> Monthly Rent
A11: =ROW(A6) -> 6
A12: =ROW(A7) -> 7
A13: =ROW(A8) -> 8
A14: =ROW(A9) -> 9
A15: =ROW(A10) -> 10
A16: =ROW(A11) -> 11
A17: =ROW(A12) -> 12
A18: Sub Total Amount | G18: =SUM(G6:G17) -> 970
A19: VAT 15% | G19: =+G18*0.15 -> 145.5
A20: Registration Fee | G20: 0
A21: Grand Total in SAR | G21: =SUM(G18:G20) -> 1115.5
A22: =" 1) Above Price are as per your quotation with ref "&'PO 1st page'!K14 -> 1) Above Price are as per your quotation with ref SC-EQTN-2025-0444
A23: 2) Details of each item are attached separately.
A25: Page 2/2
