Workbook

Sheet MRS
A1: ■ Purchase Requisition of Material / Manpower / Equipment Rental / ETC. | J1: DAESHIN PLANT
A2: PJT : SACE2 | D2: Division (In charge Name) : ADMIN MANAGER (Dong Chang Kim)) | J2: Subcontract name (SAC2-SC-IK-SMP-01)
A3: MRS No : SAC2-DS-MRS-0036 | E3: =+L3 -> 45734 | L3: 45734
A4: No | B4: Item | D4: Specification (Model / Manufacturer / Size) | G4: Unit | H4: Qty | I4: Unit Price (SAR) (Exclude VAT) | J4: Total Price (SAR) (Exclude VAT) | K4: Vendor Name | L4: Remarks
A6: =ROW(A1) -> 1 | B6: Pick-up | D6: L200 Diesel 2.4L GLX DC 4WD 6AT | G6: 1 | H6: 1 | I6: =100000-3000 -> 97000 | J6: =H6*I6 -> 97000 | K6: ATCC
A7: =ROW(A3) -> 3 | B7: Registration Fee | G7: 1 | H7: 1 | I7: 700 | J7: =H7*I7 -> 700 | K7: ATCC | L7: VAT not Applicable
A8: =ROW(A4) -> 4 | B8: New Fuel Eficiency Tax | G8: 1 | H8: 1 | I8: 255 | J8: =H8*I8 -> 255 | K8: ATCC | L8: VAT not Applicable
A9: =ROW(A5) -> 5 | B9: Admin Fees | G9: 1 | H9: 1 | I9: 434.78 | J9: =H9*I9 -> 434.78 | K9: ATCC
A10: =ROW(A6) -> 6
A11: =ROW(A7) -> 7
A12: =ROW(A8) -> 8
A13: =ROW(A9) -> 9
A14: =ROW(A10) -> 10
A15: Purpose | I15: Sum | J15: =SUM(J6:J14) -> 98389.78
A16: * There will be an additional administration expense and financial expense (Depend on contract) deduction of total provision cost price.
S17: HEC | T17: PCM | U17: ADM | V17: PM
T19: / | U19: / | V19: /
O20: Requesting | P20: JV Area PIC | Q20: PCM (Subcon)
O21: Company | S21: HDEC | T21: PCM | U21: ADM | V21: PM
O23: / | P23: / | Q23: / | T23: / | U23: / | V23: /
T39: PROJECT MANAGER
O45: PROJECT MANAGER | P45: PROJECT MANAGER | Q45: PROJECT MANAGER | T45: PCM | U45: ADM | V45: PROJECT MANAGER
O49: PROJECT MANAGER | P49: PROJECT MANAGER | Q49: PROJECT MANAGER | T49: ADM | U49: PCM | V49: PROJECT MANAGER

Sheet MRS LIST
A1: ■ Purchase Requisition of Equipment Rental | J1: =+MRS!J1 -> DAESHIN PLANT
A2: =+MRS!A2 -> PJT : SACE2 | D2: =+MRS!D2 -> Division (In charge Name) : ADMIN MANAGER (Dong Chang Kim)) | J2: =+MRS!J2 -> Subcontract name (SAC2-SC-IK-SMP-01)
A3: =+MRS!A3 -> MRS No : SAC2-DS-MRS-0036 | K3: =+MRS!L3 -> 45734
A4: No | B4: Item | D4: Specification (Model / Manufacturer / Size) | G4: Unit | H4: Q'ty | I4: Unit Price | J4: Total Price | K4: Remarks
A6: =+MRS!A6 -> 1 | B6: =MRS!B6 -> Pick-up | D6: =MRS!D6 -> L200 Diesel 2.4L GLX DC 4WD 6AT | G6: =MRS!G6 -> 1 | H6: =MRS!H6 -> 1 | I6: =MRS!I6 -> 97000 | J6: =MRS!J6 -> 97000
A7: =+MRS!#REF! -> #REF! | B7: =MRS!B7 -> Registration Fee | D7: =MRS!D7 -> 0 | G7: =MRS!G7 -> 1 | H7: =MRS!H7 -> 1 | I7: =MRS!I7 -> 700 | J7: =MRS!J7 -> 700
A8: =+MRS!A7 -> 3 | B8: =MRS!B8 -> New Fuel Eficiency Tax | D8: =MRS!D8 -> 0 | G8: =MRS!G8 -> 1 | H8: =MRS!H8 -> 1 | I8: =MRS!I8 -> 255 | J8: =MRS!J8 -> 255
A9: =+MRS!A8 -> 4 | B9: =MRS!B9 -> Admin Fees | D9: =MRS!D9 -> 0 | G9: =MRS!G9 -> 1 | H9: =MRS!H9 -> 1 | I9: =MRS!I9 -> 434.78 | J9: =MRS!J9 -> 434.78
A10: =+MRS!A9 -> 5
A11: =+MRS!A10 -> 6
A12: =+MRS!A11 -> 7
A13: =+MRS!A12 -> 8
A14: =+MRS!A13 -> 9
A15: =+MRS!A14 -> 10
A16: =+MRS!#REF! -> #REF!
A17: =+MRS!#REF! -> #REF!

Sheet PO 1st page
M2: BRANCH OF HYUNDAI ENG. & CONST. CO., LTD.
M3: P. O. Box 77249, Al Khobar 31952
M4: kingdom of Saudi Arabia
B5: C.R. 2051041774 & VAT No.: 300000504500003 | M5: Tel: +966-13-845-1088
M6: Fax: +966-13-845-1099
B9: TO: | C9: ATCC(Alesayi Motors)
C10: CR No. : | D10: 1001975695 | J10: P/O Date: | K10: =MRS!L3 -> 45734
C11: VAT No. : | D11: 300208467100003 | J11: P/O No.: | K11: =SUBSTITUTE(SUBSTITUTE(+MRS!A3," MRS No : ",""),"-MRS","-PO") -> SAC2-DS-PO-0036
C12: In Charge : | D12: Taleb Mohammad Sadeq AlKhalefa | J12: (Please mention this No. in
D13: +966 54 1200290 / | J13: All future correspondence)
C14: No. 3915 Jeddah Al Madina Road, P.O. Box : 1342 Jeddah 21431 - KSA | J14: Quote Ref. : | K14: 434139
C15: LandLine : 012 6691232 Mobile : +966 541200290 | J15: Date- | K15: 45724
B17: PURCHASE ORDER
B19: WE ARE PLEASED TO PLACE AN ORDER WITH YOU FOR THE GOODS DESCRIBED BELOW. THE ORDER SHALL BE SUBJECT TO THE TERMS AND CONDITIONS SET OUR
B20: BELOW AND ATTACHED. PLEASE SIGN AND RETURN THE ENCLOSED COPY OF THIS ORDER AS CONFIRMATION OF YOUR ACCEPTANCE OF IT WITHIN A WEEK
B21: OTHERWISE THIS ORDER SHALL BE REGARDED AS BEING ACCEPTED BY YOU.
B24: 1 | C24: GOODS
C25: Pick-up L200 Diesel 2.4L GLX DC 4WD 6AT | M25: [Please refer to attached Scope of supply & Quotation for more details]
B27: 2 | C27: P/O AMOUNT
C28: Material Value | E28: : | F28: =+'PO 2nd page'!G18 -> 97434.78 | H28: [Excludes Vat]
C29: VAT 15% | E29: : | F29: =+F28*0.15 -> 14615.217
C30: Registration Fee | E30: : | F30: 700 | H30: [VAT not applicable)
C31: New Fuel Efficiency Tax | F31: 255 | H31: [VAT not applicable)
C32: Total Amount | E32: : | F32: =F28+F29+F30+F31 -> 113005
B34: 3 | C34: PAYMENT TERMS
C35: 100% Payment after Delivery within 35 days with submission of the following Documents.
C36: a) Tax E-Invoice (From Zakat, Tax and Customs Authority)
C37: b) Delivery/Dispatch Note [Counter signed by Site Representative]
B39: 4 | C39: DELIVERY TERMS
C40: Delivery by Seller to Jafurah HYUNDAI Laydown within a Week after receipt of PO.
B42: 5 | C42: OTHER TERMS AND CONDITIONS
C43: a) Any quantity rejected by the Buyer owing to its poor quality and non conformity of specification shall be replaced and re-delivered
C44: by Seller to Buyer at no extra costs
C45: b) Material Certificate, Data Sheet, Safety Data Sheet and other documents which may required by ARAMCO in material receiving
C46: inspection should be submitted to Buyer
C47: c) MTC / MSDS, Others, If required by Client
B49: 6 | C49: CONTACT POINT:
B50: - | C50: Delivery & Payment : Dong Chang Kim / Daeshin Admin. [ Mobile No. : +966 53 748 5762 / Email : kdchjs@daeshinplant.com ]
B51: - | C51: Commercial (Purchaser) : Youngkyu Choi / Daeshin Planning [ Mobile No. : +966 53 952 0931 / Email : ykchoi@daeshinplant.com ]
B52: - | C52: Invoicing : Nehal Kauser / HDEC Purchase PIC [ Mobile No. : +966 50 610 2363 / Email : nehal_kauser@hdec.co.kr ]
...

Sheet PO 2nd page
A2: PO NO. : | B2: =+'PO 1st page'!K11 -> SAC2-DS-PO-0036 | C2: Scope of Supply
A3: DATE : | B3: =+'PO 1st page'!K10 -> 45734 | E3: Jafurah Utilities, Sulfur and Interconnecting Systems(Pkg-2)
A4: S. NO | B4: DESCRIPTION | D4: QTY | E4: UNIT | F4: ='PO 1st page'!C9 -> ATCC(Alesayi Motors) | H4: Remarks (Details)
F5: Unit Price | G5: Total Amount
A6: =ROW(A1) -> 1 | B6: =MRS!B6 -> Pick-up | D6: =+'MRS LIST'!G6 -> 1 | E6: =+'MRS LIST'!H6 -> 1 | F6: =+'MRS LIST'!I6 -> 97000 | G6: =+'MRS LIST'!J6 -> 97000
A7: =ROW(A2) -> 2 | B7: ='MRS LIST'!B9 -> Admin Fees | D7: =+'MRS LIST'!G7 -> 1 | E7: =+'MRS LIST'!H7 -> 1 | F7: ='MRS LIST'!I9 -> 434.78 | G7: =F7 -> 434.78
A8: =ROW(A3) -> 3
A9: =ROW(A4) -> 4
A10: =ROW(A5) -> 5
A11: =ROW(A6) -> 6
A12: =ROW(A7) -> 7
A13: =ROW(A8) -> 8
A14: =ROW(A9) -> 9
A15: =ROW(A10) -> 10
A16: =ROW(A11) -> 11
A17: =ROW(A12) -> 12
A18: Sub Total Amount | G18: =SUM(G6:G17) -> 97434.78
A19: VAT 15% | G19: =+G18*0.15 -> 14615.217
A20: Registration Fee | G20: 700 | H20: VAT not applicable
A21: New Fuel Efficiency Tax | G21: 255 | H21: VAT not applicable
A22: Grand Total in SAR | G22: =SUM(G18:G21) -> 113005
A23: =" 1) Above Price are as per your quotation with ref "&'PO 1st page'!K14 -> 1) Above Price are as per your quotation with ref 434139
A24: 2) Details of each item are attached separately.
A26: Page 2/2
