Workbook

Sheet MRS
A1: ■ Purchase Requisition of Material / Manpower / Equipment Rental / ETC. | J1: DAESHIN PLANT
A2: PJT : SACE2 | D2: Division (In charge Name) : ADMIN MANAGER (Dong Chang Kim) | J2: Subcontract name (SAC2-SC-IK-SMP-01)
A3: MRS No : SAC2-DS-MRS-0064 | E3: =+L3 -> 45780 | L3: 45780
A4: No | B4: Item | D4: Specification (Model / Manufacturer / Size) | G4: Unit | H4: Qty | I4: Unit Price (SAR) (Exclude VAT) | J4: Total Price (SAR) (Exclude VAT) | K4: Vendor Name | L4: Remarks
A6: 1.0 | B6: Welder Qualification Testing (WQT) Services Mob, Demobilization Welding inspector charge for one day | G6: 10 hrs | I6: 1000 | J6: =I6 -> 1000 | K6: GEH | L6: Monthly Based
A7: 1.1 | B7: Overtime More than 10 hours | G7: 1 | I7: 100 | J7: =I7 -> 100
A8: 1.2 | B8: RT Test coupon up to 12mm thickness | G8: EA | I8: 150 | J8: =I8 -> 150
A9: 1.3 | B9: RT Test coupon more than 12 mm thickness | G9: EA | I9: 200 | J9: =I9 -> 200
A10: 1.4 | B10: Welder Card (include revalidation) | G10: EA | I10: 200 | J10: =I10 -> 200
A11: 2.0 | B11: Welders Qualification Testing (PQR) | G11: 10 hrs | I11: 1200 | J11: =I11 -> 1200
A12: 2.1 | B12: Overtime More than 10 hours | G12: 1 | I12: 120 | J12: =I12 -> 120
A13: 2.2 | B13: Tensile Testing | G13: Test | I13: 500 | J13: =I13 -> 500
A14: 2.3 | B14: Bend Testing | G14: Test | I14: 320 | J14: =I14 -> 320
A15: 2.4 | B15: Fillet BreakTest | G15: Test | I15: 320 | J15: =I15 -> 320
A16: 2.5 | B16: Nick break test | G16: Test | I16: 320 | J16: =I16 -> 320
A17: 2.6 | B17: Macro Test with Photograph | G17: Test | I17: 360 | J17: =I17 -> 360
A18: 2.7 | B18: Section Test for Brazing | G18: Test | I18: 360 | J18: =I18 -> 360
A19: 2.8 | B19: impact Testing (3 specimens per set) | G19: Test | I19: 1100 | J19: =I19 -> 1100
A20: 2.9 | B20: Vickers Hardness Testing | G20: Test | I20: 500 | J20: =I20 -> 500
A21: 2.10 | B21: Brinell HardnessTesting | G21: Test | I21: 250 | J21: =I21 -> 250
A22: 2.11 | B22: Chemical Composition with 8 Elements by OES | G22: Test | I22: 950 | J22: =I22 -> 950
A23: 2.12 | B23: Ferrite content and ferrite scope | G23: Test | I23: 1100 | J23: =I23 -> 1100
B24: NDE for manifold (GEH LAB) | J24: =I24 -> 0
A25: 3.0 | B25: PT-Manifold - 3A - 1 1/2 a Minimum required to offer 10 joints | G25: Joint | I25: 50 | J25: =I25 -> 50
A26: 4.0 | B26: RT-Manifold - % - 1 1/2 - Minimum required to offer 10 joints | G26: Joint | I26: 120 | J26: =I26 -> 120
A27: 5.0 | B27: LIQUID PENETRANT TESTING (PT) or MAGNETIC PARTICLE TESTING (MT) Liquid Penetrate Testing by ASNT— (ASNT CP‘189) Level II qualified technician‘ using Solvent removable or Water washable Penetrate and non-aqueous developer. Both visible and fluorescent(Ultraviolet lamp) methods available. Magnetic Particle Testing using dry/wet/continuous/residualmethods. Using electromagnetic Yoke (AC/DC/HWDC) or permanent Yoke and dry powder or white contrastpaint/ Black ink. Use of B/C strips, ASTM field indicators etc.
B28: Prods, cable wrap and demagnetization techniques are avaitable for specialized applications.
A29: 5.1 | B29: Minimum callout charge | G29: 10 Hrs | I29: 900 | J29: =I29 -> 900
A30: 5.2 | B30: Over Time exceeds than 10 Hrs. and standby | G30: Hr | I30: 90 | J30: =I30 -> 90
A31: 5.3 | B31: Consumables | G31: Can | I31: 41 | J31: =I31 -> 41
A32: 6.0 | B32: HARDNESS TESTING Minimum callout charge | G32: 10 Hrs | I32: 1200 | J32: =I32 -> 1200
A33: 6.1 | B33: OverTime exceeds than 10 Hrs. and standby | G33: Hr | I33: 120 | J33: =I33 -> 120
A34: 6.2 | B34: Hardness Bar (optional) | G34: 1 | I34: 135 | J34: =I34 -> 135
A35: 7.0 | B35: ULTRASONIC TESTING (UTSW) One-man Ultrasonic Testing Crew with equipment 08 hrs /day. A - Scan flaw detector with a necessary set of approved calibration, probes, Couplant and other accessories. UT—ASNT (ASNT CP~189) —Level ll qualified technician. | G35: 10 Hrs | I35: 1200 | J35: =I35 -> 1200
A36: 7.1 | B36: Overtime more than 10 hours | G36: 10 Hrs | I36: 120 | J36: =I36 -> 120
A37: 8.0 | B37: Positive Material Identification (XRF) Minimum calloutcharge | G37: 10 Hrs | I37: 1200 | J37: =I37 -> 1200
A38: 8.1 | B38: OverTime exceed than 10 Hrs. and standby | G38: Hr | I38: 150 | J38: =I38 -> 150
A39: 9.0 | B39: Positive Material Identification (Carbon detection) Minimum callout charge | G39: 10 hrs | I39: 2100 | J39: =I39 -> 2100
A40: 9.1 | B40: Over Time exceeds than 10 Hrs. and standby | G40: Hr | I40: 210 | J40: =I40 -> 210
A41: 10.0 | B41: Borescope Borescope technician with Equipment with minimum charge | G41: 10 hrs | I41: 1400 | J41: =I41 -> 1400
...

Sheet MRS LIST
A1: ■ Purchase Requisition of Equipment Rental | J1: =+MRS!J1 -> DAESHIN PLANT
A2: =+MRS!A2 -> PJT : SACE2 | D2: =+MRS!D2 -> Division (In charge Name) : ADMIN MANAGER (Dong Chang Kim) | J2: =+MRS!J2 -> Subcontract name (SAC2-SC-IK-SMP-01)
A3: =+MRS!A3 -> MRS No : SAC2-DS-MRS-0064 | K3: =+MRS!L3 -> 45780
A4: No | B4: Item | D4: Specification (Model / Manufacturer / Size) | G4: Unit | H4: Q'ty | I4: Unit Price | J4: Total Price | K4: Remarks
A6: =+MRS!A6 -> 1.0 | B6: =MRS!B6 -> Welder Qualification Testing (WQT) Services Mob, Demobilization Welding inspector charge for one day | D6: =MRS!D6 -> 0 | G6: =MRS!G6 -> 10 hrs | H6: =MRS!H6 -> 0 | I6: =MRS!I6 -> 1000 | J6: =MRS!J6 -> 1000
A7: =+MRS!A7 -> 1.1 | B7: =MRS!B7 -> Overtime More than 10 hours | D7: =MRS!D7 -> 0 | G7: =MRS!G7 -> 1 | H7: =MRS!H7 -> 0 | I7: =MRS!I7 -> 100 | J7: =MRS!J7 -> 100
A8: =+MRS!A8 -> 1.2 | B8: =MRS!B8 -> RT Test coupon up to 12mm thickness | D8: =MRS!D8 -> 0 | G8: =MRS!G8 -> EA | H8: =MRS!H8 -> 0 | I8: =MRS!I8 -> 150 | J8: =MRS!J8 -> 150
A9: =+MRS!A9 -> 1.3 | B9: =MRS!B9 -> RT Test coupon more than 12 mm thickness | D9: =MRS!D9 -> 0 | G9: =MRS!G9 -> EA | H9: =MRS!H9 -> 0 | I9: =MRS!I9 -> 200 | J9: =MRS!J9 -> 200
A10: =+MRS!A10 -> 1.4 | B10: =MRS!B10 -> Welder Card (include revalidation) | D10: =MRS!D10 -> 0 | G10: =MRS!G10 -> EA | H10: =MRS!H10 -> 0 | I10: =MRS!I10 -> 200 | J10: =MRS!J10 -> 200
A11: =+MRS!A11 -> 2.0 | B11: =MRS!B11 -> Welders Qualification Testing (PQR) | D11: =MRS!D11 -> 0 | G11: =MRS!G11 -> 10 hrs | H11: =MRS!H11 -> 0 | I11: =MRS!I11 -> 1200 | J11: =MRS!J11 -> 1200
A12: =+MRS!A12 -> 2.1 | B12: =MRS!B12 -> Overtime More than 10 hours | D12: =MRS!D12 -> 0 | G12: =MRS!G12 -> 1 | H12: =MRS!H12 -> 0 | I12: =MRS!I12 -> 120 | J12: =MRS!J12 -> 120
A13: =+MRS!A13 -> 2.2 | B13: =MRS!B13 -> Tensile Testing | D13: =MRS!D13 -> 0 | G13: =MRS!G13 -> Test | H13: =MRS!H13 -> 0 | I13: =MRS!I13 -> 500 | J13: =MRS!J13 -> 500
A14: =+MRS!A14 -> 2.3 | B14: =MRS!B14 -> Bend Testing | D14: =MRS!D14 -> 0 | G14: =MRS!G14 -> Test | H14: =MRS!H14 -> 0 | I14: =MRS!I14 -> 320 | J14: =MRS!J14 -> 320
A15: =+MRS!A15 -> 2.4 | B15: =MRS!B15 -> Fillet BreakTest | D15: =MRS!D15 -> 0 | G15: =MRS!G15 -> Test | H15: =MRS!H15 -> 0 | I15: =MRS!I15 -> 320 | J15: =MRS!J15 -> 320
A16: =+MRS!A16 -> 2.5 | B16: =MRS!B16 -> Nick break test | D16: =MRS!D16 -> 0 | G16: =MRS!G16 -> Test | H16: =MRS!H16 -> 0 | I16: =MRS!I16 -> 320 | J16: =MRS!J16 -> 320
A17: =+MRS!A17 -> 2.6 | B17: =MRS!B17 -> Macro Test with Photograph | D17: =MRS!D17 -> 0 | G17: =MRS!G17 -> Test | H17: =MRS!H17 -> 0 | I17: =MRS!I17 -> 360 | J17: =MRS!J17 -> 360
... A42: =+MRS!A42 -> 10.1 | B42: =MRS!B42 -> OverTime exceeding 10 Hrs. or stand by | D42: =MRS!D42 -> 0 | G42: =MRS!G42 -> Hr | H42: =MRS!H42 -> 0 | I42: =MRS!I42 -> 140 | J42: =MRS!J42 -> 140

Sheet PO 1st page
M2: HYUNDAI ENG. & CONST. CO., LTD.
M3: P. O. Box 77249, Al Khobar 31952
M4: kingdom of Saudi Arabia
B5: C.R. 2051041774 & VAT No.: 300000504500003 | M5: Tel: +966-13-845-1088
M6: Fax: +966-13-845-1099
B9: TO: | C9: GEH(Gulf Engineering House )
C10: CR No. : | D10: 1010415504 | J10: P/O Date: | K10: =MRS!L3 -> 45780
C11: VAT No. : | D11: 311201535600003 | J11: P/O No.: | K11: =SUBSTITUTE(SUBSTITUTE(+MRS!A3," MRS No : ",""),"-MRS","-PO") -> SAC2-DS-PO-0064
C12: In Charge : | D12: Riyas Khan U | J12: (Please mention this No. in
D13: +966 56 538862304 / email:riyas@daralkhalij.com | J13: All future correspondence)
C14: King Saud Road, Bldg 2819, Riyadh, KSA | J14: Quote Ref. : | K14: NDT/QN/1425/2025
C15: Landline : +096 - 8210415 / Mobile : +966 53 8862304 | J15: Date- | K15: 45763
B18: PURCHASE ORDER
B20: WE ARE PLEASED TO PLACE AN ORDER WITH YOU FOR THE GOODS DESCRIBED BELOW. THE ORDER SHALL BE SUBJECT TO THE TERMS AND CONDITIONS SET OUR
B21: BELOW AND ATTACHED. PLEASE SIGN AND RETURN THE ENCLOSED COPY OF THIS ORDER AS CONFIRMATION OF YOUR ACCEPTANCE OF IT WITHIN A WEEK
B22: OTHERWISE THIS ORDER SHALL BE REGARDED AS BEING ACCEPTED BY YOU.
B25: 1 | C25: GOODS
C26: Welder Qualification Testing (WQT) Services | M26: [Please refer to attached Scope of supply & Quotation for more details]
B28: 2 | C28: P/O AMOUNT
C29: Material Value | E29: : | F29: Monthly Based
C30: VAT 15% | E30: :
C31: Total Amount | E31: :
B33: 3 | C33: PAYMENT TERMS
C34: 100% Payment after Delivery within 35 days with submission of the following Documents.
C35: a) Tax E-Invoice (From Zakat, Tax and Customs Authority)
C36: b) Delivery/Dispatch Note [Counter signed by Site Representative]
B38: 4 | C38: DELIVERY TERMS
C39: Delivery by Seller to Jafurah HYUNDAI Laydown within a Week after receipt of PO.
B41: 5 | C41: OTHER TERMS AND CONDITIONS
C42: a) Any quantity rejected by the Buyer owing to its poor quality and non conformity of specification shall be replaced and re-delivered
C43: by Seller to Buyer at no extra costs
C44: b) Material Certificate, Data Sheet, Safety Data Sheet and other documents which may required by ARAMCO in material receiving
C45: inspection should be submitted to Buyer
C46: c) MTC / MSDS, Others, If required by Client
B48: 6 | C48: CONTACT POINT:
B49: - | C49: Delivery & Payment : Dong Chang Kim / Daeshin Admin. [ Mobile No. : +966 53 748 5762 / Email : kdchjs@daeshinplant.com ]
B50: - | C50: Commercial (Purchaser) : Youngkyu Choi / Daeshin Planning [ Mobile No. : +966 53 952 0931 / Email : ykchoi@daeshinplant.com ]
B51: - | C51: Invoicing : Nehal Kauser / HDEC Purchase PIC [ Mobile No. : +966 50 610 2363 / Email : nehal_kauser@hdec.co.kr ]
B56: Client | J56: Contractor
B58: Signature: | J58: Signature:
...

Sheet PO 2nd page
A2: PO NO. : | B2: =+'PO 1st page'!K11 -> SAC2-DS-PO-0064 | C2: Scope of Supply
A3: DATE : | B3: =+'PO 1st page'!K10 -> 45780 | E3: Jafurah Utilities, Sulfur and Interconnecting Systems(Pkg-2)
A4: S. NO | B4: DESCRIPTION | D4: QTY | E4: UNIT | F4: ='PO 1st page'!C9 -> GEH(Gulf Engineering House ) | H4: Remarks (Details)
F5: Unit Price | G5: Total Amount
A6: =MRS!A6 -> 1.0 | B6: =+'MRS LIST'!B6 -> Welder Qualification Testing (WQT) Services Mob, Demobilization Welding inspector charge for one day | D6: =+'MRS LIST'!G6 -> 10 hrs | F6: =+'MRS LIST'!I6 -> 1000 | G6: =+'MRS LIST'!J6 -> 1000 | H6: Manthly Based
A7: =MRS!A7 -> 1.1 | B7: =+'MRS LIST'!B7 -> Overtime More than 10 hours | D7: =+'MRS LIST'!G7 -> 1 | F7: =+'MRS LIST'!I7 -> 100 | G7: =+'MRS LIST'!J7 -> 100
A8: =MRS!A8 -> 1.2 | B8: =+'MRS LIST'!B8 -> RT Test coupon up to 12mm thickness | D8: =+'MRS LIST'!G8 -> EA | F8: =+'MRS LIST'!I8 -> 150 | G8: =+'MRS LIST'!J8 -> 150
A9: =MRS!A9 -> 1.3 | B9: =+'MRS LIST'!B9 -> RT Test coupon more than 12 mm thickness | D9: =+'MRS LIST'!G9 -> EA | F9: =+'MRS LIST'!I9 -> 200 | G9: =+'MRS LIST'!J9 -> 200
A10: =MRS!A10 -> 1.4 | B10: =+'MRS LIST'!B10 -> Welder Card (include revalidation) | D10: =+'MRS LIST'!G10 -> EA | F10: =+'MRS LIST'!I10 -> 200 | G10: =+'MRS LIST'!J10 -> 200
A11: =MRS!A11 -> 2.0 | B11: =+'MRS LIST'!B11 -> Welders Qualification Testing (PQR) | D11: =+'MRS LIST'!G11 -> 10 hrs | F11: =+'MRS LIST'!I11 -> 1200 | G11: =+'MRS LIST'!J11 -> 1200
A12: =MRS!A12 -> 2.1 | B12: =+'MRS LIST'!B12 -> Overtime More than 10 hours | D12: =+'MRS LIST'!G12 -> 1 | F12: =+'MRS LIST'!I12 -> 120 | G12: =+'MRS LIST'!J12 -> 120
A13: =MRS!A13 -> 2.2 | B13: =+'MRS LIST'!B13 -> Tensile Testing | D13: =+'MRS LIST'!G13 -> Test | F13: =+'MRS LIST'!I13 -> 500 | G13: =+'MRS LIST'!J13 -> 500
A14: =MRS!A14 -> 2.3 | B14: =+'MRS LIST'!B14 -> Bend Testing | D14: =+'MRS LIST'!G14 -> Test | F14: =+'MRS LIST'!I14 -> 320 | G14: =+'MRS LIST'!J14 -> 320
A15: =MRS!A15 -> 2.4 | B15: =+'MRS LIST'!B15 -> Fillet BreakTest | D15: =+'MRS LIST'!G15 -> Test | F15: =+'MRS LIST'!I15 -> 320 | G15: =+'MRS LIST'!J15 -> 320
A16: =MRS!A16 -> 2.5 | B16: =+'MRS LIST'!B16 -> Nick break test | D16: =+'MRS LIST'!G16 -> Test | F16: =+'MRS LIST'!I16 -> 320 | G16: =+'MRS LIST'!J16 -> 320
A17: =MRS!A17 -> 2.6 | B17: =+'MRS LIST'!B17 -> Macro Test with Photograph | D17: =+'MRS LIST'!G17 -> Test | F17: =+'MRS LIST'!I17 -> 360 | G17: =+'MRS LIST'!J17 -> 360
A18: =MRS!A18 -> 2.7 | B18: =+'MRS LIST'!B18 -> Section Test for Brazing | D18: =+'MRS LIST'!G18 -> Test | F18: =+'MRS LIST'!I18 -> 360 | G18: =+'MRS LIST'!J18 -> 360
... A26: =MRS!A26 -> 4.0 | B26: =+'MRS LIST'!B26 -> RT-Manifold - % - 1 1/2 - Minimum required to offer 10 joints | D26: =+'MRS LIST'!G26 -> Joint | F26: =+'MRS LIST'!I26 -> 120 | G26: =+'MRS LIST'!J26 -> 120
A27: =MRS!A27 -> 5.0 | B27: =+'MRS LIST'!B27 -> LIQUID PENETRANT TESTING (PT) or MAGNETIC PARTICLE TESTING (MT) Liquid Penetrate Testing by ASNT— (ASNT CP‘189) Level II qualified technician‘ using Solvent removable or Water washable Penetrate and non-aqueous developer. Both visible and fluorescent(Ultraviolet lamp) methods available. Magnetic Particle Testing using dry/wet/continuous/residualmethods. Using electromagnetic Yoke (AC/DC/HWDC) or permanent Yoke and dry powder or white contrastpaint/ Black ink. Use of B/C strips, ASTM field indicators etc. | G27: =+'MRS LIST'!J27 -> 0
B28: =+'MRS LIST'!B28 -> Prods, cable wrap and demagnetization techniques are avaitable for specialized applications. | F28: =+'MRS LIST'!I28 -> 0 | G28: =+'MRS LIST'!J28 -> 0
A29: =MRS!A29 -> 5.1 | B29: =+'MRS LIST'!B29 -> Minimum callout charge | D29: =+'MRS LIST'!G29 -> 10 Hrs | F29: =+'MRS LIST'!I29 -> 900 | G29: =+'MRS LIST'!J29 -> 900
A30: =MRS!A30 -> 5.2 | B30: =+'MRS LIST'!B30 -> Over Time exceeds than 10 Hrs. and standby | D30: =+'MRS LIST'!G30 -> Hr | F30: =+'MRS LIST'!I30 -> 90 | G30: =+'MRS LIST'!J30 -> 90
A31: =MRS!A31 -> 5.3 | B31: =+'MRS LIST'!B31 -> Consumables | D31: =+'MRS LIST'!G31 -> Can | F31: =+'MRS LIST'!I31 -> 41 | G31: =+'MRS LIST'!J31 -> 41
A32: =MRS!A32 -> 6.0 | B32: =+'MRS LIST'!B32 -> HARDNESS TESTING Minimum callout charge | D32: =+'MRS LIST'!G32 -> 10 Hrs | F32: =+'MRS LIST'!I32 -> 1200 | G32: =+'MRS LIST'!J32 -> 1200
A33: =MRS!A33 -> 6.1 | B33: =+'MRS LIST'!B33 -> OverTime exceeds than 10 Hrs. and standby | D33: =+'MRS LIST'!G33 -> Hr | F33: =+'MRS LIST'!I33 -> 120 | G33: =+'MRS LIST'!J33 -> 120
A34: =MRS!A34 -> 6.2 | B34: =+'MRS LIST'!B34 -> Hardness Bar (optional) | D34: =+'MRS LIST'!G34 -> 1 | F34: =+'MRS LIST'!I34 -> 135 | G34: =+'MRS LIST'!J34 -> 135
A35: =MRS!A35 -> 7.0 | B35: =+'MRS LIST'!B35 -> ULTRASONIC TESTING (UTSW) One-man Ultrasonic Testing Crew with equipment 08 hrs /day. A - Scan flaw detector with a necessary set of approved calibration, probes, Couplant and other accessories. UT—ASNT (ASNT CP~189) —Level ll qualified technician. | D35: =+'MRS LIST'!G35 -> 10 Hrs | F35: =+'MRS LIST'!I35 -> 1200 | G35: =+'MRS LIST'!J35 -> 1200
A36: =MRS!A36 -> 7.1 | B36: =+'MRS LIST'!B36 -> Overtime more than 10 hours | D36: =+'MRS LIST'!G36 -> 10 Hrs | F36: =+'MRS LIST'!I36 -> 120 | G36: =+'MRS LIST'!J36 -> 120
A37: =MRS!A37 -> 8.0 | B37: =+'MRS LIST'!B37 -> Positive Material Identification (XRF) Minimum calloutcharge | D37: =+'MRS LIST'!G37 -> 10 Hrs | F37: =+'MRS LIST'!I37 -> 1200 | G37: =+'MRS LIST'!J37 -> 1200
A38: =MRS!A38 -> 8.1 | B38: =+'MRS LIST'!B38 -> OverTime exceed than 10 Hrs. and standby | D38: =+'MRS LIST'!G38 -> Hr | F38: =+'MRS LIST'!I38 -> 150 | G38: =+'MRS LIST'!J38 -> 150
A39: =MRS!A39 -> 9.0 | B39: =+'MRS LIST'!B39 -> Positive Material Identification (Carbon detection) Minimum callout charge | D39: =+'MRS LIST'!G39 -> 10 hrs | F39: =+'MRS LIST'!I39 -> 2100 | G39: =+'MRS LIST'!J39 -> 2100
A40: =MRS!A40 -> 9.1 | B40: =+'MRS LIST'!B40 -> Over Time exceeds than 10 Hrs. and standby | D40: =+'MRS LIST'!G40 -> Hr | F40: =+'MRS LIST'!I40 -> 210 | G40: =+'MRS LIST'!J40 -> 210
... A42: =MRS!A42 -> 10.1 | B42: =+'MRS LIST'!B42 -> OverTime exceeding 10 Hrs. or stand by | D42: =+'MRS LIST'!G42 -> Hr | F42: =+'MRS LIST'!I42 -> 140 | G42: =+'MRS LIST'!J42 -> 140
A43: Sub Total Amount | G43: =SUM(G6:G42) -> 18226
A44: VAT 15% | G44: =+G43*0.15 -> 2733.9
A45: Grand Total in SAR | G45: =G44+G43 -> 20959.9
A46: =" 1) Above Price are as per your quotation with ref "&'PO 1st page'!K14 -> 1) Above Price are as per your quotation with ref NDT/QN/1425/2025
A47: 2) Details of each item are attached separately.
A49: Page 2/2
