Workbook

Sheet MRS
A1: ■ Purchase Requisition of Material / Manpower / Equipment Rental / ETC. | J1: DAESHIN PLANT
A2: PJT : SACE2 | D2: Division (In charge Name) : ADMIN MANAGER (Dong Chang Kim) | J2: Subcontract name (SAC2-SC-IK-SMP-01)
A3: MRS No : SAC2-DS-MRS-0497 | E3: =+L3+3 -> 46319 | L3: 46316
A4: No | B4: Item | D4: Specification (Model / Manufacturer / Size) | G4: Unit | H4: Qty | I4: Unit Price (SAR) (Exclude VAT) | J4: Total Price (SAR) (Exclude VAT) | K4: Vendor Name | L4: Remarks
A6: =ROW(A1) -> 1 | B6: Boom Truck | D6: 10 Ton with Aramco Certified Operator | G6: Month | H6: 1 | I6: 34000 | J6: =H6*I6 -> 34000 | K6: TCO | L6: Monthly Based
A7: =ROW(A2) -> 2
A8: =ROW(A3) -> 3
A9: =ROW(A4) -> 4
A10: =ROW(A5) -> 5
A11: =ROW(A6) -> 6
A12: =ROW(A7) -> 7
A13: =ROW(A8) -> 8
A14: Purpose | I14: Sum | J14: =SUM(J6:J13) -> 34000
A15: * There will be an additional administration expense and financial expense (Depend on contract) deduction of total provision cost price.
AD16: HEC | AE16: PCM | AF16: ADM | AG16: PM
O18: SUB-CON | T18: HDEC | AE18: / | AF18: / | AG18: /
O19: In Charge | P19: ADM | Q19: PCM | R19: PM | T19: Construction | U19: Subcon(PC) | V19: Account | Y19: ADM | Z19: Requesting | AA19: JV Area PIC | AB19: PCM (Subcon)
V20: In Charge | W20: Manager | Z20: Company | AD20: HDEC | AE20: PCM | AF20: ADM | AG20: PM
X22: HEC | Y22: ADM | Z22: / | AA22: / | AB22: / | AE22: / | AF22: / | AG22: /
AE38: PROJECT MANAGER
O44: PROJECT MANAGER | P44: PROJECT MANAGER | S44: ADM | Z44: PROJECT MANAGER | AA44: PROJECT MANAGER | AB44: PROJECT MANAGER | AE44: PCM | AF44: ADM | AG44: PROJECT MANAGER
O48: PROJECT MANAGER | P48: PROJECT MANAGER | S48: PCM | Z48: PROJECT MANAGER | AA48: PROJECT MANAGER | AB48: PROJECT MANAGER | AE48: ADM | AF48: PCM | AG48: PROJECT MANAGER

Sheet MRS LIST
A1: ■ Purchase Requisition of Equipment Rental | J1: =+MRS!J1 -> DAESHIN PLANT
A2: =+MRS!A2 -> PJT : SACE2 | D2: =+MRS!D2 -> Division (In charge Name) : ADMIN MANAGER (Dong Chang Kim) | J2: =+MRS!J2 -> Subcontract name (SAC2-SC-IK-SMP-01)
A3: =+MRS!A3 -> MRS No : SAC2-DS-MRS-0497 | K3: =+MRS!L3 -> 46316
A4: No | B4: Item | D4: Specification (Model / Manufacturer / Size) | G4: Unit | H4: Q'ty | I4: Unit Price | J4: Total Price | K4: Remarks
A6: =+MRS!A6 -> 1 | B6: =MRS!B6 -> Boom Truck | D6: =MRS!D6 -> 10 Ton with Aramco Certified Operator | G6: =MRS!G6 -> Month | H6: =MRS!H6 -> 1 | I6: =MRS!I6 -> 34000 | J6: =MRS!J6 -> 34000
A7: =+MRS!A7 -> 2 | B7: =MRS!B7 -> 0 | D7: =MRS!D7 -> 0 | G7: =MRS!G7 -> 0 | H7: =MRS!H7 -> 0 | I7: =MRS!I7 -> 0 | J7: =MRS!J7 -> 0
A8: =+MRS!A8 -> 3 | B8: =MRS!B8 -> 0 | D8: =MRS!D8 -> 0 | G8: =MRS!G8 -> 0 | H8: =MRS!H8 -> 0 | I8: =MRS!I8 -> 0 | J8: =MRS!J8 -> 0
A9: =+MRS!A9 -> 4
A10: =+MRS!A10 -> 5
A11: =+MRS!#REF! -> #REF!
A12: =+MRS!#REF! -> #REF!
A13: =+MRS!A11 -> 6
A14: =+MRS!A12 -> 7
A15: =+MRS!A13 -> 8
A16: =+MRS!#REF! -> #REF!
A17: =+MRS!#REF! -> #REF!

Sheet PO 1st page
M2: BRANCH OF HYUNDAI ENG. & CONST. CO., LTD.
M3: P. O. Box 77249, Al Khobar 31952
M4: kingdom of Saudi Arabia
B5: C.R. 2051041774 & VAT No.: 300000504500003 | M5: Tel: +966-13-845-1088
M6: Fax: +966-13-845-1099
B9: TO: | C9: TCO (Toekoms Contracting Company)
C10: CR No. : | D10: 2055104793 | J10: P/O Date: | K10: =MRS!L3 -> 46316
C11: VAT No. : | D11: 311236456300003 | J11: P/O No.: | K11: =SUBSTITUTE(SUBSTITUTE(+MRS!A3," MRS No : ",""),"-MRS","-PO") -> SAC2-DS-PO-0497
C12: In Charge : | D12: Mudassar Nazar | J12: (Please mention this No. in
D13: +966 54 3677555 / email:nazar@toekomsksa.com | J13: All future correspondence)
C14: Al Dakhal Al Mahdud Subdivision, Al Jubail, KSA 35513 | J14: Quote Ref. : | K14: QTN-00066
C15: Mobile : +966 54 3677555 | J15: Date- | K15: 46312
B18: PURCHASE ORDER
B20: WE ARE PLEASED TO PLACE AN ORDER WITH YOU FOR THE GOODS DESCRIBED BELOW. THE ORDER SHALL BE SUBJECT TO THE TERMS AND CONDITIONS SET OUR
B21: BELOW AND ATTACHED. PLEASE SIGN AND RETURN THE ENCLOSED COPY OF THIS ORDER AS CONFIRMATION OF YOUR ACCEPTANCE OF IT WITHIN A WEEK
B22: OTHERWISE THIS ORDER SHALL BE REGARDED AS BEING ACCEPTED BY YOU.
B25: 1 | C25: GOODS
C26: =_xlfn.CONCAT(MRS!B6," ",MRS!D6) -> Boom Truck 10 Ton with Aramco Certified Operator | M26: [Please refer to attached Scope of supply & Quotation for more details]
B28: 2 | C28: P/O AMOUNT
C29: Material Value | E29: : | F29: Monthly Based
C30: VAT 15% | E30: :
C31: Total Amount | E31: :
B33: 3 | C33: PAYMENT TERMS
C34: 100% Payment after Delivery within 35 days with submission of the following Documents.
C35: a) Tax E-Invoice (From Zakat, Tax and Customs Authority)
C36: b) Delivery/Dispatch Note [Counter signed by Site Representative]
B38: 4 | C38: DELIVERY TERMS
C39: Delivery by Seller to Jafurah HYUNDAI Laydown within a Week after receipt of PO.
B41: 5 | C41: OTHER TERMS AND CONDITIONS
C42: a) Any quantity rejected by the Buyer owing to its poor quality and non conformity of specification shall be replaced and re-delivered
C43: by Seller to Buyer at no extra costs
C44: b) Material Certificate, Data Sheet, Safety Data Sheet and other documents which may required by ARAMCO in material receiving
C45: inspection should be submitted to Buyer
C46: c) MTC / MSDS, Others, If required by Client
B48: 6 | C48: CONTACT POINT:
B49: - | C49: Delivery & Payment : Dong Chang Kim / Daeshin Admin. [ Mobile No. : +966 53 748 5762 / Email : kdchjs@daeshinplant.com ]
B50: - | C50: Commercial (Purchaser) : Youngkyu Choi / Daeshin Planning [ Mobile No. : +966 53 952 0931 / Email : ykchoi@daeshinplant.com ]
B51: - | C51: Invoicing : Nehal Kauser / HDEC Purchase PIC [ Mobile No. : +966 50 610 2363 / Email : nehal_kauser@hdec.co.kr ]
B53: 7 | C53: Bank Account Details:
B54: - | C54: ACCOUNT NAME | F54: TOEKOMS CONTRACTING COMPANY | P54: =UPPER(F54) -> TOEKOMS CONTRACTING COMPANY
...

Sheet PO 2nd page
A2: PO NO. : | B2: =+'PO 1st page'!K11 -> SAC2-DS-PO-0497 | C2: Scope of Supply
A3: DATE : | B3: =+'PO 1st page'!K10 -> 46316 | E3: Jafurah Utilities, Sulfur and Interconnecting Systems(Pkg-2)
A4: S. NO | B4: DESCRIPTION | D4: QTY | E4: UNIT | F4: ='PO 1st page'!C9 -> TCO (Toekoms Contracting Company) | H4: Remarks (Details)
F5: Unit Price | G5: Total Amount
A6: =ROW(A1) -> 1 | B6: =CONCATENATE(MRS!B6," ",MRS!D6) -> Boom Truck 10 Ton with Aramco Certified Operator | D6: =+'MRS LIST'!G6 -> Month | E6: =+'MRS LIST'!H6 -> 1 | F6: =+'MRS LIST'!I6 -> 34000 | G6: =+'MRS LIST'!J6 -> 34000 | H6: =MRS!L6 -> Monthly Based
A7: =ROW(A2) -> 2
A8: =ROW(A3) -> 3
A9: =ROW(A4) -> 4
A10: =ROW(A5) -> 5
A11: =ROW(A6) -> 6
A12: =ROW(A7) -> 7
A13: =ROW(A8) -> 8
A14: =ROW(A9) -> 9
A15: =ROW(A10) -> 10
A16: =ROW(A11) -> 11
A17: =ROW(A12) -> 12
A18: Sub Total Amount | G18: =SUM(G6:G17) -> 34000
A19: VAT 15% | G19: =+G18*0.15 -> 5100
A20: Grand Total in SAR | G20: =G19+G18 -> 39100
A21: =" 1) Above Price are as per your quotation with ref "&'PO 1st page'!K14 -> 1) Above Price are as per your quotation with ref QTN-00066
A22: 2) Details of each item are attached separately.
A24: Page 2/2
