Workbook

Sheet MRS
A1: ■ Purchase Requisition of Material / Manpower / Equipment Rental / ETC. | J1: DAESHIN PLANT
A2: PJT : SACE2 | D2: Division (In charge Name) : ADMIN MANAGER (Dong Chang Kim) | J2: Subcontract name (SAC2-SC-IK-SMP-01)
A3: MRS No : SAC2-DS-MRS-0162 | E3: =+L3 -> 45978 | L3: 45978
A4: No | B4: Item | D4: Specification (Model / Manufacturer / Size) | G4: Unit | H4: Qty | I4: Unit Price (SAR) (Exclude VAT) | J4: Total Price (SAR) (Exclude VAT) | K4: Vendor Name | L4: Remarks
A6: =ROW(A1) -> 1 | B6: Hard Disk | D6: WD 1TB | G6: EA | H6: 1 | I6: 285 | J6: =H6*I6 -> 285 | K6: ATGC | L6: One time
A7: =ROW(A2) -> 2 | B7: Xerox Versalink Drum Unit | D7: Cyan, Magenta, Yellow, Black | G7: EA | H7: 7 | I7: 1080 | J7: =H7*I7 -> 7560
A8: =ROW(A3) -> 3 | B8: Safety Shoes | D8: Size 42 | G8: Pair | H8: 80 | I8: 63.5 | J8: =H8*I8 -> 5080
A9: =ROW(A4) -> 4 | B9: Stamp Pad | G9: EA | H9: 1 | I9: 19 | J9: =H9*I9 -> 19
A10: =ROW(A5) -> 5 | B10: Staples | D10: 26/6-5MM Kangaro 10Pkt/Box | G10: Box | H10: 2 | I10: 37 | J10: =H10*I10 -> 74
A11: =ROW(A6) -> 6 | B11: 2 Hole Punch | D11: Kangaro | G11: EA | H11: 5 | I11: 30 | J11: =H11*I11 -> 150
A12: =ROW(A7) -> 7 | B12: Speaker | G12: EA | H12: 1 | I12: 150 | J12: =H12*I12 -> 150
A13: =ROW(A8) -> 8 | B13: Amplifier | D13: 30W | G13: EA | H13: 1 | I13: 350 | J13: =H13*I13 -> 350
A14: =ROW(A9) -> 9 | B14: Steel Cabinet | G14: EA | H14: 2 | I14: 660 | J14: =H14*I14 -> 1320
A15: =ROW(A10) -> 10 | B15: TP Link Wireless Router | G15: EA | H15: 1 | I15: 106 | J15: =H15*I15 -> 106
A16: =ROW(A11) -> 11 | B16: Magnnetic White Board | D16: 60*90CM | G16: EA | H16: 1 | I16: 74 | J16: =H16*I16 -> 74
A17: Purpose | I17: Sum | J17: =SUM(J6:J16) -> 15168
A18: * There will be an additional administration expense and financial expense (Depend on contract) deduction of total provision cost price.
S19: HEC | T19: PCM | U19: ADM | V19: PM
T21: / | U21: / | V21: /
O22: Requesting | P22: JV Area PIC | Q22: PCM (Subcon)
O23: Company | S23: HDEC | T23: PCM | U23: ADM | V23: PM
O25: / | P25: / | Q25: / | T25: / | U25: / | V25: /
T41: PROJECT MANAGER
O47: PROJECT MANAGER | P47: PROJECT MANAGER | Q47: PROJECT MANAGER | T47: PCM | U47: ADM | V47: PROJECT MANAGER
O51: PROJECT MANAGER | P51: PROJECT MANAGER | Q51: PROJECT MANAGER | T51: ADM | U51: PCM | V51: PROJECT MANAGER

Sheet MRS LIST
A1: ■ Purchase Requisition of Equipment Rental | J1: =+MRS!J1 -> DAESHIN PLANT
A2: =+MRS!A2 -> PJT : SACE2 | D2: =+MRS!D2 -> Division (In charge Name) : ADMIN MANAGER (Dong Chang Kim) | J2: =+MRS!J2 -> Subcontract name (SAC2-SC-IK-SMP-01)
A3: =+MRS!A3 -> MRS No : SAC2-DS-MRS-0162 | K3: =+MRS!L3 -> 45978
A4: No | B4: Item | D4: Specification (Model / Manufacturer / Size) | G4: Unit | H4: Q'ty | I4: Unit Price | J4: Total Price | K4: Remarks
A6: =+MRS!A6 -> 1 | B6: =MRS!B6 -> Hard Disk | D6: =MRS!D6 -> WD 1TB | G6: =MRS!G6 -> EA | H6: =MRS!H6 -> 1 | I6: =MRS!I6 -> 285 | J6: =MRS!J6 -> 285
A7: =+MRS!A7 -> 2 | B7: =MRS!B7 -> Xerox Versalink Drum Unit | D7: =MRS!D7 -> Cyan, Magenta, Yellow, Black | G7: =MRS!G7 -> EA | H7: =MRS!H7 -> 7 | I7: =MRS!I7 -> 1080 | J7: =MRS!J7 -> 7560
A8: =+MRS!A8 -> 3 | B8: =MRS!B8 -> Safety Shoes | D8: =MRS!D8 -> Size 42 | G8: =MRS!G8 -> Pair | H8: =MRS!H8 -> 80 | I8: =MRS!I8 -> 63.5 | J8: =MRS!J8 -> 5080
A9: =+MRS!A9 -> 4 | B9: =MRS!B9 -> Stamp Pad | D9: =MRS!D9 -> 0 | G9: =MRS!G9 -> EA | H9: =MRS!H9 -> 1 | I9: =MRS!I9 -> 19 | J9: =MRS!J9 -> 19
A10: =+MRS!A10 -> 5 | B10: =MRS!B10 -> Staples | D10: =MRS!D10 -> 26/6-5MM Kangaro 10Pkt/Box | G10: =MRS!G10 -> Box | H10: =MRS!H10 -> 2 | I10: =MRS!I10 -> 37 | J10: =MRS!J10 -> 74
A11: =+MRS!A11 -> 6 | B11: =MRS!B11 -> 2 Hole Punch | D11: =MRS!D11 -> Kangaro | G11: =MRS!G11 -> EA | H11: =MRS!H11 -> 5 | I11: =MRS!I11 -> 30 | J11: =MRS!J11 -> 150
A12: =+MRS!A12 -> 7 | B12: =MRS!B12 -> Speaker | D12: =MRS!D12 -> 0 | G12: =MRS!G12 -> EA | H12: =MRS!H12 -> 1 | I12: =MRS!I12 -> 150 | J12: =MRS!J12 -> 150
A13: =+MRS!A13 -> 8 | B13: =MRS!B13 -> Amplifier | D13: =MRS!D13 -> 30W | G13: =MRS!G13 -> EA | H13: =MRS!H13 -> 1 | I13: =MRS!I13 -> 350 | J13: =MRS!J13 -> 350
A14: =+MRS!A14 -> 9 | B14: =MRS!B14 -> Steel Cabinet | D14: =MRS!D14 -> 0 | G14: =MRS!G14 -> EA | H14: =MRS!H14 -> 2 | I14: =MRS!I14 -> 660 | J14: =MRS!J14 -> 1320
A15: =+MRS!A15 -> 10 | B15: =MRS!B15 -> TP Link Wireless Router | D15: =MRS!D15 -> 0 | G15: =MRS!G15 -> EA | H15: =MRS!H15 -> 1 | I15: =MRS!I15 -> 106 | J15: =MRS!J15 -> 106
A16: =+MRS!A16 -> 11 | B16: =MRS!B16 -> Magnnetic White Board | D16: =MRS!D16 -> 60*90CM | G16: =MRS!G16 -> EA | H16: =MRS!H16 -> 1 | I16: =MRS!I16 -> 74 | J16: =MRS!J16 -> 74
A17: 12 | B17: =MRS!#REF! -> #REF! | D17: =MRS!#REF! -> #REF! | G17: =MRS!#REF! -> #REF! | H17: =MRS!#REF! -> #REF! | I17: =MRS!#REF! -> #REF! | J17: =MRS!#REF! -> #REF!
A18: 13 | B18: =MRS!#REF! -> #REF! | D18: =MRS!#REF! -> #REF! | G18: =MRS!#REF! -> #REF! | H18: =MRS!#REF! -> #REF! | I18: =MRS!#REF! -> #REF! | J18: =MRS!#REF! -> #REF!
B19: =MRS!#REF! -> #REF! | D19: =MRS!#REF! -> #REF! | G19: =MRS!#REF! -> #REF! | H19: =MRS!#REF! -> #REF! | I19: =MRS!#REF! -> #REF! | J19: =MRS!#REF! -> #REF!
B20: =MRS!#REF! -> #REF! | D20: =MRS!#REF! -> #REF! | G20: =MRS!#REF! -> #REF! | H20: =MRS!#REF! -> #REF! | I20: =MRS!#REF! -> #REF! | J20: =MRS!#REF! -> #REF!
B21: =MRS!#REF! -> #REF! | D21: =MRS!#REF! -> #REF! | G21: =MRS!#REF! -> #REF! | H21: =MRS!#REF! -> #REF! | I21: =MRS!#REF! -> #REF! | J21: =MRS!#REF! -> #REF!
B22: =MRS!#REF! -> #REF! | D22: =MRS!#REF! -> #REF! | G22: =MRS!#REF! -> #REF! | H22: =MRS!#REF! -> #REF! | I22: =MRS!#REF! -> #REF! | J22: =MRS!#REF! -> #REF!
B23: =MRS!#REF! -> #REF! | D23: =MRS!#REF! -> #REF! | G23: =MRS!#REF! -> #REF! | H23: =MRS!#REF! -> #REF! | I23: =MRS!#REF! -> #REF! | J23: =MRS!#REF! -> #REF!
B24: =MRS!#REF! -> #REF! | D24: =MRS!#REF! -> #REF! | G24: =MRS!#REF! -> #REF! | H24: =MRS!#REF! -> #REF! | I24: =MRS!#REF! -> #REF! | J24: =MRS!#REF! -> #REF!
B25: =MRS!#REF! -> #REF! | D25: =MRS!#REF! -> #REF! | G25: =MRS!#REF! -> #REF! | H25: =MRS!#REF! -> #REF! | I25: =MRS!#REF! -> #REF! | J25: =MRS!#REF! -> #REF!
B26: =MRS!#REF! -> #REF! | D26: =MRS!#REF! -> #REF! | G26: =MRS!#REF! -> #REF! | H26: =MRS!#REF! -> #REF! | I26: =MRS!#REF! -> #REF! | J26: =MRS!#REF! -> #REF!
B27: =MRS!#REF! -> #REF! | D27: =MRS!#REF! -> #REF! | G27: =MRS!#REF! -> #REF! | H27: =MRS!#REF! -> #REF! | I27: =MRS!#REF! -> #REF! | J27: =MRS!#REF! -> #REF!

Sheet PO 1st page
M2: BRANCH OF HYUNDAI ENG. & CONST. CO., LTD.
M3: P. O. Box 77249, Al Khobar 31952
M4: kingdom of Saudi Arabia
B5: C.R. 2051041774 & VAT No.: 300000504500003 | M5: Tel: +966-13-845-1088
M6: Fax: +966-13-845-1099
B9: TO: | C9: ATGC(Alrmooz Technical for General Contracting Est.)
C10: CR No. : | D10: 2053026325 | J10: P/O Date: | K10: =MRS!L3 -> 45978
C11: VAT No. : | D11: 300900558400003 | J11: P/O No.: | K11: =SUBSTITUTE(SUBSTITUTE(+MRS!A3," MRS No : ",""),"-MRS","-PO") -> SAC2-DS-PO-0162
C12: In Charge : | D12: Muhammed Rafi | J12: (Please mention this No. in
D13: +966 57 5956527 / Email:info@alrmoozsa.com | J13: All future correspondence)
C14: P.O. Box 2746, Al-Jubail 31951 | J14: Quote Ref. : | K14: QUO-MAT-25111207
C15: Landline : +99 13 8022775. : Mobile : +966 583694645 | J15: Date- | K15: 45969
B18: PURCHASE ORDER
B20: WE ARE PLEASED TO PLACE AN ORDER WITH YOU FOR THE GOODS DESCRIBED BELOW. THE ORDER SHALL BE SUBJECT TO THE TERMS AND CONDITIONS SET OUR
B21: BELOW AND ATTACHED. PLEASE SIGN AND RETURN THE ENCLOSED COPY OF THIS ORDER AS CONFIRMATION OF YOUR ACCEPTANCE OF IT WITHIN A WEEK
B22: OTHERWISE THIS ORDER SHALL BE REGARDED AS BEING ACCEPTED BY YOU.
B25: 1 | C25: GOODS
C26: Office Materials | M26: [Please refer to attached Scope of supply & Quotation for more details]
B28: 2 | C28: P/O AMOUNT
C29: Material Value | E29: : | F29: ='PO 2nd page'!G28 -> 15168
C30: VAT 15% | E30: : | F30: ='PO 2nd page'!G29 -> 2275.2
C31: Total Amount | E31: : | F31: ='PO 2nd page'!G30 -> 17443.2
B33: 3 | C33: PAYMENT TERMS
C34: 100% Payment after Delivery within 35 days with submission of the following Documents.
C35: a) Tax E-Invoice (From Zakat, Tax and Customs Authority)
C36: b) Delivery/Dispatch Note [Counter signed by Site Representative]
B38: 4 | C38: DELIVERY TERMS
C39: Delivery by Seller to Jafurah HYUNDAI Laydown within a Week after receipt of PO.
B41: 5 | C41: OTHER TERMS AND CONDITIONS
C42: a) Any quantity rejected by the Buyer owing to its poor quality and non conformity of specification shall be replaced and re-delivered
C43: by Seller to Buyer at no extra costs
C44: b) Material Certificate, Data Sheet, Safety Data Sheet and other documents which may required by ARAMCO in material receiving
C45: inspection should be submitted to Buyer
C46: c) MTC / MSDS, Others, If required by Client
B48: 6 | C48: CONTACT POINT:
B49: - | C49: Delivery & Payment : Dong Chang Kim / Daeshin Admin. [ Mobile No. : +966 53 748 5762 / Email : kdchjs@daeshinplant.com ]
B50: - | C50: Commercial (Purchaser) : Youngkyu Choi / Daeshin Planning [ Mobile No. : +966 53 952 0931 / Email : ykchoi@daeshinplant.com ]
B51: - | C51: Invoicing : Nehal Kauser / HDEC Purchase PIC [ Mobile No. : +966 50 610 2363 / Email : nehal_kauser@hdec.co.kr ]
B56: Client | J56: Contractor
B58: Signature: | J58: Signature:
...

Sheet PO 2nd page
A2: PO NO. : | B2: =+'PO 1st page'!K11 -> SAC2-DS-PO-0162 | C2: Scope of Supply
A3: DATE : | B3: =+'PO 1st page'!K10 -> 45978 | E3: Jafurah Utilities, Sulfur and Interconnecting Systems(Pkg-2)
A4: S. NO | B4: DESCRIPTION | D4: QTY | E4: UNIT | F4: ='PO 1st page'!C9 -> ATGC(Alrmooz Technical for General Contracting Est.) | H4: Remarks (Details)
F5: Unit Price | G5: Total Amount
A6: =ROW(A1) -> 1 | B6: =+'MRS LIST'!B6 -> Hard Disk | D6: =+'MRS LIST'!G6 -> EA | E6: =+'MRS LIST'!H6 -> 1 | F6: =+'MRS LIST'!I6 -> 285 | G6: =+'MRS LIST'!J6 -> 285
A7: =ROW(A2) -> 2 | B7: =+'MRS LIST'!B7 -> Xerox Versalink Drum Unit | D7: =+'MRS LIST'!G7 -> EA | E7: =+'MRS LIST'!H7 -> 7 | F7: =+'MRS LIST'!I7 -> 1080 | G7: =+'MRS LIST'!J7 -> 7560
A8: =ROW(A3) -> 3 | B8: =+'MRS LIST'!B8&" "&MRS!D8 -> Safety Shoes Size 42 | D8: =+'MRS LIST'!G8 -> Pair | E8: =+'MRS LIST'!H8 -> 80 | F8: =+'MRS LIST'!I8 -> 63.5 | G8: =+'MRS LIST'!J8 -> 5080
A9: =ROW(A4) -> 4 | B9: =+'MRS LIST'!B9&" "&MRS!D9 -> Stamp Pad | D9: =+'MRS LIST'!G9 -> EA | E9: =+'MRS LIST'!H9 -> 1 | F9: =+'MRS LIST'!I9 -> 19 | G9: =+'MRS LIST'!J9 -> 19
A10: =ROW(A5) -> 5 | B10: =+'MRS LIST'!B10&" "&MRS!D10 -> Staples 26/6-5MM Kangaro 10Pkt/Box | D10: =+'MRS LIST'!G10 -> Box | E10: =+'MRS LIST'!H10 -> 2 | F10: =+'MRS LIST'!I10 -> 37 | G10: =+'MRS LIST'!J10 -> 74
A11: =ROW(A6) -> 6 | B11: =+'MRS LIST'!B11&" "&MRS!D11 -> 2 Hole Punch Kangaro | D11: =+'MRS LIST'!G11 -> EA | E11: =+'MRS LIST'!H11 -> 5 | F11: =+'MRS LIST'!I11 -> 30 | G11: =+'MRS LIST'!J11 -> 150
A12: =ROW(A7) -> 7 | B12: =+'MRS LIST'!B12&" "&MRS!D12 -> Speaker | D12: =+'MRS LIST'!G12 -> EA | E12: =+'MRS LIST'!H12 -> 1 | F12: =+'MRS LIST'!I12 -> 150 | G12: =+'MRS LIST'!J12 -> 150
A13: =ROW(A8) -> 8 | B13: =+'MRS LIST'!B13&" "&MRS!D13 -> Amplifier 30W | D13: =+'MRS LIST'!G13 -> EA | E13: =+'MRS LIST'!H13 -> 1 | F13: =+'MRS LIST'!I13 -> 350 | G13: =+'MRS LIST'!J13 -> 350
A14: =ROW(A9) -> 9 | B14: =+'MRS LIST'!B14&" "&MRS!D14 -> Steel Cabinet | D14: =+'MRS LIST'!G14 -> EA | E14: =+'MRS LIST'!H14 -> 2 | F14: =+'MRS LIST'!I14 -> 660 | G14: =+'MRS LIST'!J14 -> 1320
A15: =ROW(A10) -> 10 | B15: =+'MRS LIST'!B15&" "&MRS!D15 -> TP Link Wireless Router | D15: =+'MRS LIST'!G15 -> EA | E15: =+'MRS LIST'!H15 -> 1 | F15: =+'MRS LIST'!I15 -> 106 | G15: =+'MRS LIST'!J15 -> 106
A16: =ROW(A11) -> 11 | B16: =+'MRS LIST'!B16&" "&MRS!D16 -> Magnnetic White Board 60*90CM | D16: =+'MRS LIST'!G16 -> EA | E16: =+'MRS LIST'!H16 -> 1 | F16: =+'MRS LIST'!I16 -> 74 | G16: =+'MRS LIST'!J16 -> 74
A28: Sub Total Amount | G28: =SUM(G6:G27) -> 15168
A29: VAT 15% | G29: =+G28*0.15 -> 2275.2
A30: Grand Total in SAR | G30: =G29+G28 -> 17443.2
A31: =" 1) Above Price are as per your quotation with ref "&'PO 1st page'!K14 -> 1) Above Price are as per your quotation with ref QUO-MAT-25111207
A32: 2) Details of each item are attached separately.
A34: Page 2/2
