Workbook

Sheet MRS
A1: ■ Purchase Requisition of Material / Manpower / Equipment Rental / ETC. | J1: DAESHIN PLANT
A2: PJT : SACE2 | D2: Division (In charge Name) : ADMIN MANAGER (Dong Chang Kim) | J2: Subcontract name (SAC2-SC-IK-SMP-01)
A3: MRS No : SAC2-DS-MRS-0386 | E3: =+L3+3 -> 46238 | L3: 46235
A4: No | B4: Item | D4: Specification (Model / Manufacturer / Size) | G4: Unit | H4: Qty | I4: Unit Price (SAR) (Exclude VAT) | J4: Total Price (SAR) (Exclude VAT) | K4: Vendor Name | L4: Remarks
A6: 1 | B6: Steel Structure Foreman | G6: Hr | H6: 1 | I6: 29 | J6: =H6*I6 -> 29 | K6: HGC | L6: Monthly Based
A7: 2 | B7: Helper | G7: Hr | H7: 1 | I7: 13 | J7: =H7*I7 -> 13
A8: 3 | B8: Painting Supervisor | D8: Aramco Certified | G8: Hr | H8: 1 | I8: 48 | J8: =H8*I8 -> 48
A9: 4 | B9: Painter | D9: Aramco Certified | G9: Hr | H9: 1 | I9: 25 | J9: =H9*I9 -> 25
J12: =H12*I12 -> 0
J13: =H13*I13 -> 0
A18: Purpose | I18: Sum | J18: =SUM(J6:J17) -> 115
A19: * There will be an additional administration expense and financial expense (Depend on contract) deduction of total provision cost price.
O22: SUB-CON | T22: HDEC
O23: In Charge | P23: ADM | Q23: PCM | R23: PM | T23: Construction | U23: Subcon(PC) | V23: Account | Y23: ADM
V24: In Charge | W24: Manager
X26: HEC | Y26: ADM
O48: PROJECT MANAGER | P48: PROJECT MANAGER | S48: ADM
O52: PROJECT MANAGER | P52: PROJECT MANAGER | S52: PCM

Sheet MRS LIST
A1: ■ Purchase Requisition of Equipment Rental | J1: =+MRS!J1 -> DAESHIN PLANT
A2: =+MRS!A2 -> PJT : SACE2 | D2: =+MRS!D2 -> Division (In charge Name) : ADMIN MANAGER (Dong Chang Kim) | J2: =+MRS!J2 -> Subcontract name (SAC2-SC-IK-SMP-01)
A3: =+MRS!A3 -> MRS No : SAC2-DS-MRS-0386 | K3: =+MRS!L3 -> 46235
A4: No | B4: Item | D4: Specification (Model / Manufacturer / Size) | G4: Unit | H4: Q'ty | I4: Unit Price | J4: Total Price | K4: Remarks
A6: =+MRS!A6 -> 1 | B6: =MRS!B6 -> Steel Structure Foreman | D6: =MRS!D6 -> 0 | G6: =MRS!G6 -> Hr | H6: =MRS!H6 -> 1 | I6: =MRS!I6 -> 29 | J6: =MRS!J6 -> 29
A7: =+MRS!A7 -> 2 | B7: =MRS!B7 -> Helper | D7: =MRS!D7 -> 0 | G7: =MRS!G7 -> Hr | H7: =MRS!H7 -> 1 | I7: =MRS!I7 -> 13 | J7: =MRS!J7 -> 13
A8: =+MRS!A8 -> 3 | B8: =MRS!B8 -> Painting Supervisor | D8: =MRS!D8 -> Aramco Certified | G8: =MRS!G8 -> Hr | H8: =MRS!H8 -> 1 | I8: =MRS!I8 -> 48 | J8: =MRS!J8 -> 48
A9: =+MRS!A9 -> 4 | B9: =MRS!B9 -> Painter | D9: =MRS!D9 -> Aramco Certified | G9: =MRS!G9 -> Hr | H9: =MRS!H9 -> 1 | I9: =MRS!I9 -> 25 | J9: =MRS!J9 -> 25
A10: =+MRS!A10 -> 0 | B10: =MRS!B10 -> 0 | D10: =MRS!D10 -> 0 | G10: =MRS!G10 -> 0 | H10: =MRS!H10 -> 0 | I10: =MRS!I10 -> 0 | J10: =MRS!J10 -> 0
A11: =+MRS!A11 -> 0 | B11: =MRS!B11 -> 0 | D11: =MRS!D11 -> 0 | G11: =MRS!G11 -> 0 | H11: =MRS!H11 -> 0 | I11: =MRS!I11 -> 0 | J11: =MRS!J11 -> 0
A12: =+MRS!A12 -> 0
A13: =+MRS!A13 -> 0
A14: =+MRS!A14 -> 0
A15: =+MRS!A17 -> 0
A16: =+MRS!#REF! -> #REF!
A17: =+MRS!#REF! -> #REF!

Sheet PO 1st page
M2: BRANCH OF HYUNDAI ENG. & CONST. CO., LTD.
M3: P. O. Box 77249, Al Khobar 31952
M4: kingdom of Saudi Arabia
B5: C.R. 2051041774 & VAT No.: 300000504500003 | M5: Tel: +966-13-845-1088
M6: Fax: +966-13-845-1099
B9: TO: | C9: HGC(Hussain Saleh Al Saffar General Contracting Est.)
C10: CR No. : | D10: 2050045368 | J10: P/O Date: | K10: =MRS!L3 -> 46235
C11: VAT No. : | D11: 300370362100003 | J11: P/O No.: | K11: =SUBSTITUTE(SUBSTITUTE(+MRS!A3," MRS No : ",""),"-MRS","-PO") -> SAC2-DS-PO-0386
C12: In Charge : | D12: Mohammad Rafiqul Islam | J12: (Please mention this No. in
D13: +966 55 3096020/ Email:info@hussainsaleh.com | J13: All future correspondence)
C14: P.O. Box 10716, Dammam 3191, Kingdom of Saudi Arabia | J14: Quote Ref. : | K14: HGC-00962, HGC-00963
C15: Mobile : +966 553096020 | J15: Date- | K15: 46214 | L15: 46222
B18: PURCHASE ORDER
B20: WE ARE PLEASED TO PLACE AN ORDER WITH YOU FOR THE GOODS DESCRIBED BELOW. THE ORDER SHALL BE SUBJECT TO THE TERMS AND CONDITIONS SET OUR
B21: BELOW AND ATTACHED. PLEASE SIGN AND RETURN THE ENCLOSED COPY OF THIS ORDER AS CONFIRMATION OF YOUR ACCEPTANCE OF IT WITHIN A WEEK
B22: OTHERWISE THIS ORDER SHALL BE REGARDED AS BEING ACCEPTED BY YOU.
B25: 1 | C25: GOODS
C26: =MRS!B6&" "&MRS!B7 -> Steel Structure Foreman Helper | M26: [Please refer to attached Scope of supply & Quotation for more details]
C27: =MRS!B8&" "&MRS!B9 -> Painting Supervisor Painter
B28: 2 | C28: P/O AMOUNT
C29: Material Value | E29: : | F29: Monthly Based
C30: VAT 15% | E30: :
C31: Total Amount | E31: :
B33: 3 | C33: PAYMENT TERMS
C34: 100% Payment after Delivery within 35 days with submission of the following Documents.
C35: a) Tax E-Invoice (From Zakat, Tax and Customs Authority)
C36: b) Delivery/Dispatch Note [Counter signed by Site Representative]
B38: 4 | C38: DELIVERY TERMS
C39: Delivery by Seller to Jafurah HYUNDAI Laydown within a Week after receipt of PO.
B41: 5 | C41: OTHER TERMS AND CONDITIONS
C42: a) Any quantity rejected by the Buyer owing to its poor quality and non conformity of specification shall be replaced and re-delivered
C43: by Seller to Buyer at no extra costs
C44: b) Material Certificate, Data Sheet, Safety Data Sheet and other documents which may required by ARAMCO in material receiving
C45: inspection should be submitted to Buyer
C46: c) MTC / MSDS, Others, If required by Client
B48: 6 | C48: CONTACT POINT:
B49: - | C49: Delivery & Payment : Dong Chang Kim / Daeshin Admin. [ Mobile No. : +966 53 748 5762 / Email : kdchjs@daeshinplant.com ]
B50: - | C50: Commercial (Purchaser) : Youngkyu Choi / Daeshin Planning [ Mobile No. : +966 53 952 0931 / Email : ykchoi@daeshinplant.com ]
B51: - | C51: Invoicing : Nehal Kauser / HDEC Purchase PIC [ Mobile No. : +966 50 610 2363 / Email : nehal_kauser@hdec.co.kr ]
B53: 7 | C53: Bank Account Details:
...

Sheet PO 2nd page
A2: PO NO. : | B2: =+'PO 1st page'!K11 -> SAC2-DS-PO-0386 | C2: Scope of Supply
A3: DATE : | B3: =+'PO 1st page'!K10 -> 46235 | E3: Jafurah Utilities, Sulfur and Interconnecting Systems(Pkg-2)
A4: S. NO | B4: DESCRIPTION | D4: QTY | E4: UNIT | F4: ='PO 1st page'!C9 -> HGC(Hussain Saleh Al Saffar General Contracting Est.) | H4: Remarks (Details)
F5: Unit Price | G5: Total Amount
A6: =ROW(A1) -> 1 | B6: =CONCATENATE(MRS!B6," ",MRS!D6) -> Steel Structure Foreman | D6: =MRS!G6 -> Hr | E6: =MRS!H6 -> 1 | F6: =MRS!I6 -> 29 | G6: =MRS!J6 -> 29 | H6: =MRS!L6 -> Monthly Based
A7: =ROW(A2) -> 2 | B7: =CONCATENATE(MRS!B7," ",MRS!D7) -> Helper | D7: =MRS!G7 -> Hr | E7: =MRS!H7 -> 1 | F7: =MRS!I7 -> 13 | G7: =MRS!J7 -> 13
A8: =ROW(A3) -> 3 | B8: =CONCATENATE(MRS!B8," ",MRS!D8) -> Painting Supervisor Aramco Certified | D8: =MRS!G8 -> Hr | E8: =MRS!H8 -> 1 | F8: =MRS!I8 -> 48 | G8: =MRS!J8 -> 48
A9: =ROW(A4) -> 4 | B9: =CONCATENATE(MRS!B9," ",MRS!D9) -> Painter Aramco Certified | D9: =MRS!G9 -> Hr | E9: =MRS!H9 -> 1 | F9: =MRS!I9 -> 25 | G9: =MRS!J9 -> 25
A10: =ROW(A5) -> 5 | B10: =CONCATENATE(MRS!B10," ",MRS!D10)
A11: =ROW(A6) -> 6
A12: =ROW(A7) -> 7 | B12: =CONCATENATE(MRS!B12," ",MRS!D12)
A13: =ROW(A8) -> 8 | B13: =CONCATENATE(MRS!B13," ",MRS!D13)
A14: =ROW(A9) -> 9 | B14: =CONCATENATE(MRS!B14," ",MRS!D14)
A15: =ROW(A10) -> 10 | B15: =CONCATENATE(MRS!B15," ",MRS!D15)
A16: =ROW(A11) -> 11 | B16: =CONCATENATE(MRS!B16," ",MRS!D16)
A17: =ROW(A12) -> 12 | B17: =CONCATENATE(MRS!B17," ",MRS!D17)
A18: Sub Total Amount | G18: =SUM(G6:G17) -> 115
A19: VAT 15% | G19: =+G18*0.15 -> 17.25
A20: Grand Total in SAR | G20: =G19+G18 -> 132.25
A21: =" 1) Above Price are as per your quotation with ref "&'PO 1st page'!K14 -> 1) Above Price are as per your quotation with ref HGC-00962, HGC-00963
A22: 2) Details of each item are attached separately.
A24: Page 2/2
