Workbook

Sheet MRS
A1: ■ Purchase Requisition of Material / Manpower / Equipment Rental / ETC. | J1: DAESHIN PLANT
A2: PJT : SACE2 | D2: Division (In charge Name) : ADMIN MANAGER (Dong Chang Kim)) | J2: Subcontract name (SAC2-SC-IK-SMP-01)
A3: MRS No : SAC2-DS-MRS-0140 | E3: =+L3 -> 45941 | L3: 45941
A4: No | B4: Item | D4: Specification (Model / Manufacturer / Size) | G4: Unit | H4: Qty | I4: Unit Price (SAR) (Exclude VAT) | J4: Total Price (SAR) (Exclude VAT) | K4: Vendor Name | L4: Remarks
A6: =ROW(A1) -> 1 | B6: Mitsubishi Pick-up | D6: L24D-DC4-D07 (2024) | G6: EA | H6: 1 | I6: 96000 | J6: =H6*I6 -> 96000 | K6: ATCC | L6: One time
A7: 2 | B7: Administrative Expenses | G7: EA | H7: 1 | I7: 440 | J7: =H7*I7 -> 440 | K7: "
A8: 3 | B8: Registration Fee | G8: EA | H8: 1 | I8: 700 | J8: =H8*I8 -> 700 | K8: " | L8: VAT not Applicable
A9: 4 | B9: Fuel Efficiency | G9: EA | H9: 1 | I9: 150 | J9: =H9*I9 -> 150 | K9: " | L9: VAT not Applicable
A10: 5 | B10: Special Discount for Companies | H10: 1 | I10: -11600 | J10: =H10*I10 -> -11600 | K10: "
A11: 6
A12: 7
A13: 8
A14: 9
A15: 10
A16: Purpose | I16: Sum | J16: =SUM(J6:J15) -> 85690
A17: * There will be an additional administration expense and financial expense (Depend on contract) deduction of total provision cost price.
R18: HEC | S18: ADM
S20: /
O21: Requesting | P21: JV Area PIC
O22: Company | R22: HDEC | S22: ADM
O24: / | P24: / | S24: /
O46: PROJECT MANAGER | P46: PROJECT MANAGER | S46: ADM
O50: PROJECT MANAGER | P50: PROJECT MANAGER | S50: PCM

Sheet MRS LIST
A1: ■ Purchase Requisition of Equipment Rental | J1: =+MRS!J1 -> DAESHIN PLANT
A2: =+MRS!A2 -> PJT : SACE2 | D2: =+MRS!D2 -> Division (In charge Name) : ADMIN MANAGER (Dong Chang Kim)) | J2: =+MRS!J2 -> Subcontract name (SAC2-SC-IK-SMP-01)
A3: =+MRS!A3 -> MRS No : SAC2-DS-MRS-0140 | K3: =+MRS!L3 -> 45941
A4: No | B4: Item | D4: Specification (Model / Manufacturer / Size) | G4: Unit | H4: Q'ty | I4: Unit Price | J4: Total Price | K4: Remarks
A6: =+MRS!A6 -> 1 | B6: =MRS!B6 -> Mitsubishi Pick-up | D6: =MRS!D6 -> L24D-DC4-D07 (2024) | G6: =MRS!G6 -> EA | H6: =MRS!H6 -> 1 | I6: =MRS!I6 -> 96000 | J6: =MRS!J6 -> 96000
A7: =+MRS!#REF! -> #REF! | B7: =MRS!B7 -> Administrative Expenses | D7: =MRS!D7 -> 0 | G7: =MRS!G7 -> EA | H7: =MRS!H7 -> 1 | I7: =MRS!I7 -> 440 | J7: =MRS!J7 -> 440
A8: =+MRS!A7 -> 2 | B8: =MRS!B8 -> Registration Fee | D8: =MRS!D8 -> 0 | G8: =MRS!G8 -> EA | H8: =MRS!H8 -> 1 | I8: =MRS!I8 -> 700 | J8: =MRS!J8 -> 700
A9: =+MRS!A8 -> 3 | B9: =MRS!B9 -> Fuel Efficiency | D9: =MRS!D9 -> 0 | G9: =MRS!G9 -> EA | H9: =MRS!H9 -> 1 | I9: =MRS!I9 -> 150 | J9: =MRS!J9 -> 150
A10: =+MRS!A9 -> 4
A11: =+MRS!A10 -> 5
A12: =+MRS!A11 -> 6
A13: =+MRS!A12 -> 7
A14: =+MRS!A13 -> 8
A15: =+MRS!A15 -> 10
A16: =+MRS!#REF! -> #REF!
A17: =+MRS!#REF! -> #REF!

Sheet PO 1st page
M2: BRANCH OF HYUNDAI ENG. & CONST. CO., LTD.
M3: P. O. Box 77249, Al Khobar 31952
M4: kingdom of Saudi Arabia
B5: C.R. 2051041774 & VAT No.: 300000504500003 | M5: Tel: +966-13-845-1088
M6: Fax: +966-13-845-1099
B9: TO: | C9: ATCC(Alesayi Motors)
C10: CR No. : | D10: 1001975695 | J10: P/O Date: | K10: =MRS!L3 -> 45941
C11: VAT No. : | D11: 300208467100003 | J11: P/O No.: | K11: =SUBSTITUTE(SUBSTITUTE(+MRS!A3," MRS No : ",""),"-MRS","-PO") -> SAC2-DS-PO-0140
C12: In Charge : | D12: Tarek Joseph Abi Chedid | J12: (Please mention this No. in
D13: 012 6691232 | J13: All future correspondence)
C14: P.O. Box 1342 Jeddah 21431 - KSA | J14: Quote Ref. : | K14: 5788
C15: LandLine : 012 6691232 | J15: Date- | K15: 45936
B17: PURCHASE ORDER
B19: WE ARE PLEASED TO PLACE AN ORDER WITH YOU FOR THE GOODS DESCRIBED BELOW. THE ORDER SHALL BE SUBJECT TO THE TERMS AND CONDITIONS SET OUR
B20: BELOW AND ATTACHED. PLEASE SIGN AND RETURN THE ENCLOSED COPY OF THIS ORDER AS CONFIRMATION OF YOUR ACCEPTANCE OF IT WITHIN A WEEK
B21: OTHERWISE THIS ORDER SHALL BE REGARDED AS BEING ACCEPTED BY YOU.
B24: 1 | C24: GOODS
C25: Mitsubishi Pick-up L24D-DC4-D07 (2024) | M25: [Please refer to attached Scope of supply & Quotation for more details]
B27: 2 | C27: P/O AMOUNT
C28: Material Value | E28: : | F28: =+'PO 2nd page'!G18 -> 84840 | H28: [Excludes Vat]
C29: VAT 15% | E29: : | F29: =+F28*0.15 -> 12726
C30: Registration Fee | E30: : | F30: 700 | H30: [VAT not applicable)
C31: New Fuel Efficiency Tax | F31: 150 | H31: [VAT not applicable)
C32: Total Amount | E32: : | F32: =F28+F29+F30+F31 -> 98416
B34: 3 | C34: PAYMENT TERMS
C35: 100% Payment after Delivery within 35 days with submission of the following Documents.
C36: a) Tax E-Invoice (From Zakat, Tax and Customs Authority)
C37: b) Delivery/Dispatch Note [Counter signed by Site Representative]
B39: 4 | C39: DELIVERY TERMS
C40: Delivery by Seller to Jafurah HYUNDAI Laydown within a Week after receipt of PO.
B42: 5 | C42: OTHER TERMS AND CONDITIONS
C43: a) Any quantity rejected by the Buyer owing to its poor quality and non conformity of specification shall be replaced and re-delivered
C44: by Seller to Buyer at no extra costs
C45: b) Material Certificate, Data Sheet, Safety Data Sheet and other documents which may required by ARAMCO in material receiving
C46: inspection should be submitted to Buyer
C47: c) MTC / MSDS, Others, If required by Client
B49: 6 | C49: CONTACT POINT:
B50: - | C50: Delivery & Payment : Dong Chang Kim / Daeshin Admin. [ Mobile No. : +966 53 748 5762 / Email : kdchjs@daeshinplant.com ]
B51: - | C51: Commercial (Purchaser) : Youngkyu Choi / Daeshin Planning [ Mobile No. : +966 53 952 0931 / Email : ykchoi@daeshinplant.com ]
B52: - | C52: Invoicing : Nehal Kauser / HDEC Purchase PIC [ Mobile No. : +966 50 610 2363 / Email : nehal_kauser@hdec.co.kr ]
...

Sheet PO 2nd page
A2: PO NO. : | B2: =+'PO 1st page'!K11 -> SAC2-DS-PO-0140 | C2: Scope of Supply
A3: DATE : | B3: =+'PO 1st page'!K10 -> 45941 | E3: Jafurah Utilities, Sulfur and Interconnecting Systems(Pkg-2)
A4: S. NO | B4: DESCRIPTION | D4: QTY | E4: UNIT | F4: ='PO 1st page'!C9 -> ATCC(Alesayi Motors) | H4: Remarks (Details)
F5: Unit Price | G5: Total Amount
A6: =ROW(A1) -> 1 | B6: =CONCATENATE(MRS!B6," ",MRS!D6) -> Mitsubishi Pick-up L24D-DC4-D07 (2024) | D6: =MRS!G6 -> EA | E6: =MRS!H6 -> 1 | F6: =MRS!I6 -> 96000 | G6: =MRS!J6 -> 96000 | H6: =MRS!L6 -> One time
A7: =ROW(A2) -> 2 | B7: =CONCATENATE(MRS!B7," ",MRS!D7) -> Administrative Expenses | D7: =MRS!G7 -> EA | E7: =MRS!H7 -> 1 | F7: =MRS!I7 -> 440 | G7: =MRS!J7 -> 440
A8: =ROW(A3) -> 3 | B8: =CONCATENATE(MRS!B8," ",MRS!D8) -> Registration Fee | D8: =MRS!G8 -> EA | E8: =MRS!H8 -> 1 | F8: =MRS!I8 -> 700 | G8: =MRS!J8 -> 700 | H8: =MRS!L8 -> VAT not Applicable
A9: =ROW(A4) -> 4 | B9: =CONCATENATE(MRS!B9," ",MRS!D9) -> Fuel Efficiency | D9: =MRS!G9 -> EA | E9: =MRS!H9 -> 1 | F9: =MRS!I9 -> 150 | G9: =MRS!J9 -> 150 | H9: =MRS!L9 -> VAT not Applicable
A10: =ROW(A5) -> 5 | B10: =CONCATENATE(MRS!B10," ",MRS!D10) -> Special Discount for Companies | E10: =MRS!H10 -> 1 | F10: =MRS!I10 -> -11600 | G10: =MRS!J10 -> -11600
A11: =ROW(A6) -> 6 | B11: =CONCATENATE(MRS!B11," ",MRS!D11)
A12: =ROW(A7) -> 7
A13: =ROW(A8) -> 8
A14: =ROW(A9) -> 9
A15: =ROW(A10) -> 10
A16: =ROW(A11) -> 11
A17: =ROW(A12) -> 12
A18: Sub Total Amount | G18: =SUM(G6+G7+G10) -> 84840
A19: VAT 15% | G19: =+G18*0.15 -> 12726
A20: Registration Fee | G20: 700 | H20: VAT not applicable
A21: New Fuel Efficiency Tax | G21: 150 | H21: VAT not applicable
A22: Grand Total in SAR | G22: =SUM(G18:G21) -> 98416
A23: =" 1) Above Price are as per your quotation with ref "&'PO 1st page'!K14 -> 1) Above Price are as per your quotation with ref 5788
A24: 2) Details of each item are attached separately.
A26: Page 2/2
