Workbook

Sheet MRS
A1: ■ Purchase Requisition of Material / Manpower / Equipment Rental / ETC. | J1: DAESHIN PLANT
A2: PJT : SACE2 | D2: Division (In charge Name) : ADMIN MANAGER (Dong Chang Kim) | J2: Subcontract name (SAC2-SC-IK-SMP-01)
A3: MRS No : SAC2-DS-MRS-0390 | E3: =+L3+3 -> 46240 | L3: 46237
A4: No | B4: Item | D4: Specification (Model / Manufacturer / Size) | G4: Unit | H4: Qty | I4: Unit Price (SAR) (Exclude VAT) | J4: Total Price (SAR) (Exclude VAT) | K4: Vendor Name | L4: Remarks
A6: =ROW(A1) -> 1 | B6: Measuring Cup | D6: 1000ml (Set of 3) | G6: Nos | H6: 4 | I6: 16 | J6: =+H6*I6 -> 64 | K6: JSAJ | L6: One Time
A7: =ROW(A2) -> 2 | B7: Ceramic Backing Tape | D7: 10x27x600mm CBS-W600 | G7: Nos | H7: 40 | I7: 20 | J7: =+H7*I7 -> 800
A8: =ROW(A3) -> 3 | B8: Cutting Disc C/S | D8: 5"x1mm Maks | G8: Nos | H8: 700 | I8: 1.35 | J8: =+H8*I8 -> 945
A9: =ROW(A4) -> 4 | B9: Electric Concrete Mixing Machine | G9: Nos | H9: 2 | I9: 345 | J9: =+H9*I9 -> 690
A10: =ROW(A5) -> 5 | B10: PVC Bucket with Lid | D10: Heavy Duty 20Ltr White | G10: Nos | H10: 40 | I10: 10 | J10: =+H10*I10 -> 400
A11: =ROW(A6) -> 6 | B11: Plastic Storage Drum | D11: Blue 300Ltr | G11: Nos | H11: 3 | I11: 85 | J11: =+H11*I11 -> 255
A12: =ROW(A7) -> 7 | B12: PE Water Tank Vertical | D12: 500Ltr | G12: Nos | H12: 2 | I12: 330 | J12: =+H12*I12 -> 660
A13: =ROW(A8) -> 8 | B13: Window A/C | D13: 2Ton Super General | G13: Nos | H13: 1 | I13: 1784 | J13: =+H13*I13 -> 1784
A14: =ROW(A9) -> 9 | B14: Measuring Cup | D14: 5000ml | G14: Nos | H14: 4 | I14: 37 | J14: =+H14*I14 -> 148
A15: =ROW(A10) -> 10 | B15: Flap Disc S/S | D15: 4" 80 Grit | G15: Nos | H15: 4400 | I15: 3.1 | J15: =+H15*I15 -> 13640
A16: =ROW(A11) -> 11 | B16: Flap Wheel S/S | D16: 25x20x6mm | G16: Nos | H16: 300 | I16: 4 | J16: =+H16*I16 -> 1200
A17: =ROW(A12) -> 12 | B17: Cup Brush C/S Crimped | D17: M10x75mm | G17: Nos | H17: 300 | I17: 9 | J17: =+H17*I17 -> 2700
A18: =ROW(A13) -> 13 | B18: Teflon Tape | D18: 19mm x 40yard | G18: Nos | H18: 1000 | I18: 1.6 | J18: =+H18*I18 -> 1600
A19: =ROW(A14) -> 14 | B19: Ear Plug with Corded | G19: Pair | H19: 1000 | I19: 0.55 | J19: =+H19*I19 -> 550
A20: =ROW(A15) -> 15 | B20: Wrapping Film Roll 50cm 50mtr 3Kg | D20: 19mm x 40yard | G20: Roll | H20: 25 | I20: 21 | J20: =+H20*I20 -> 525
A21: =ROW(A16) -> 16 | B21: Welding Cable Connector | D21: 35-50mm2 Male & Female | G21: Set | H21: 25 | I21: 13 | J21: =+H21*I21 -> 325
A22: =ROW(A17) -> 17 | B22: Welding Cable Connector | D22: 50-70mm2 Male & Female | G22: Set | H22: 75 | I22: 15 | J22: =+H22*I22 -> 1125
A23: =ROW(A18) -> 18 | B23: Tig Collet Body | D23: 350A 2.4mm | G23: Nos | H23: 100 | I23: 12 | J23: =+H23*I23 -> 1200
A24: =ROW(A19) -> 19 | B24: Tig Collet Pin | D24: 350A 2.4mm | G24: Nos | H24: 100 | I24: 5.7 | J24: =+H24*I24 -> 570
A25: =ROW(A20) -> 20 | B25: Tungsten Electrode | D25: 2.4mm | G25: Nos | H25: 600 | I25: 21 | J25: =+H25*I25 -> 12600
A26: =ROW(A21) -> 21 | B26: Ceramic Nozzle | D26: 250A #7 10N47 | G26: Nos | H26: 200 | I26: 2.2 | J26: =+H26*I26 -> 440
A27: =ROW(A22) -> 22 | B27: Ceramic Nozzle | D27: 350A #5 | G27: Nos | H27: 100 | I27: 12 | J27: =+H27*I27 -> 1200
A28: =ROW(A23) -> 23 | B28: Ceramic Nozzle | D28: 350A #6 | G28: Nos | H28: 200 | I28: 12 | J28: =+H28*I28 -> 2400
A29: =ROW(A24) -> 24 | B29: Ceramic Nozzle | D29: 350A #8 | G29: Nos | H29: 200 | I29: 12 | J29: =+H29*I29 -> 2400
A30: =ROW(A25) -> 25 | B30: Double Ear Clamp S/S 11-13mm | D30: 350A #8 | G30: Nos | H30: 300 | I30: 4.8 | J30: =+H30*I30 -> 1440
A31: =ROW(A26) -> 26 | B31: Double Ear Clamp S/S | D31: 13-15mm | G31: Nos | H31: 300 | I31: 4.8 | J31: =+H31*I31 -> 1440
... A33: =ROW(A28) -> 28 | B33: Right Angle | D33: 24" | G33: Nos | H33: 25 | I33: 12 | J33: =+H33*I33 -> 300
A34: =ROW(A29) -> 29 | B34: Concrete Mixing Paddle | G34: Nos | H34: 4 | I34: 42 | J34: =+H34*I34 -> 168
A35: =ROW(A30) -> 30 | B35: Plastic Sandbag Heavy Duty | D35: (Gunny Sack) 50kg | G35: Nos | H35: 500 | I35: 2.3 | J35: =+H35*I35 -> 1150
A36: =ROW(A31) -> 31 | B36: Dust Mask | D36: N95 Venus | G36: Nos | H36: 2000 | I36: 1.35 | J36: =+H36*I36 -> 2700
A37: =ROW(A32) -> 32 | B37: Power Cable | D37: CU/XLPE/PVC 4Cx35mm2 | G37: Mtr | H37: 20 | I37: 92 | J37: =+H37*I37 -> 1840
A38: =ROW(A33) -> 33 | B38: Spiral Screw Extractor | D38: (3/8", 3/16", 1/8", 1/4", 1/2", 1") | G38: Set | H38: 1 | I38: 46 | J38: =+H38*I38 -> 46
A39: =ROW(A34) -> 34 | B39: Handsaw | D39: 18" | G39: Nos | H39: 8 | I39: 16 | J39: =+H39*I39 -> 128
A40: =ROW(A35) -> 35 | B40: Measuring Tape | D40: 15mtr | G40: Nos | H40: 2 | I40: 16 | J40: =+H40*I40 -> 32
A41: =ROW(A36) -> 36 | B41: Paint Scraper | D41: 2" | G41: Nos | H41: 48 | I41: 1.6 | J41: =+H41*I41 -> 76.8
A42: =ROW(A37) -> 37 | B42: Paint Scraper | D42: 3" | G42: Nos | H42: 48 | I42: 1.8 | J42: =+H42*I42 -> 86.4
...

Sheet MRS LIST
A1: ■ Purchase Requisition of Material / Manpower / Equipment Rental / ETC. | J1: =+MRS!J1 -> DAESHIN PLANT
A2: =+MRS!A2 -> PJT : SACE2 | D2: =+MRS!D2 -> Division (In charge Name) : ADMIN MANAGER (Dong Chang Kim) | J2: =+MRS!J2 -> Subcontract name (SAC2-SC-IK-SMP-01)
A3: =+MRS!A3 -> MRS No : SAC2-DS-MRS-0390 | K3: =+MRS!L3 -> 46237
A4: No | B4: Item | D4: Specification (Model / Manufacturer / Size) | G4: Unit | H4: Qty (Liter) | I4: Unit Price | J4: Total Price | K4: Remarks
A6: =+MRS!A6 -> 1 | B6: =MRS!B6 -> Measuring Cup | D6: =MRS!D6 -> 1000ml (Set of 3) | G6: =MRS!G6 -> Nos | H6: =MRS!H6 -> 4 | I6: =MRS!I6 -> 16 | J6: =+H6*I6 -> 64
A7: =+MRS!A7 -> 2 | B7: =MRS!B7 -> Ceramic Backing Tape | D7: =MRS!D7 -> 10x27x600mm CBS-W600 | G7: =MRS!G7 -> Nos | H7: =MRS!H7 -> 40 | I7: =MRS!I7 -> 20 | J7: =+H7*I7 -> 800
A8: =+MRS!A8 -> 3 | B8: =MRS!B8 -> Cutting Disc C/S | D8: =MRS!D8 -> 5"x1mm Maks | G8: =MRS!G8 -> Nos | H8: =MRS!H8 -> 700 | I8: =MRS!I8 -> 1.35 | J8: =+H8*I8 -> 945
A9: =+MRS!A9 -> 4 | B9: =MRS!B9 -> Electric Concrete Mixing Machine | D9: =MRS!D9 -> 0 | G9: =MRS!G9 -> Nos | H9: =MRS!H9 -> 2 | I9: =MRS!I9 -> 345 | J9: =+H9*I9 -> 690
A10: =+MRS!A10 -> 5 | B10: =MRS!B10 -> PVC Bucket with Lid | D10: =MRS!D10 -> Heavy Duty 20Ltr White | G10: =MRS!G10 -> Nos | H10: =MRS!H10 -> 40 | I10: =MRS!I10 -> 10 | J10: =+H10*I10 -> 400
A11: =+MRS!A11 -> 6 | B11: =MRS!B11 -> Plastic Storage Drum | D11: =MRS!D11 -> Blue 300Ltr | G11: =MRS!G11 -> Nos | H11: =MRS!H11 -> 3 | I11: =MRS!I11 -> 85 | J11: =+H11*I11 -> 255
A12: =+MRS!A12 -> 7 | B12: =MRS!B12 -> PE Water Tank Vertical | D12: =MRS!D12 -> 500Ltr | G12: =MRS!G12 -> Nos | H12: =MRS!H12 -> 2 | I12: =MRS!I12 -> 330 | J12: =+H12*I12 -> 660
A13: =+MRS!A13 -> 8 | B13: =MRS!B13 -> Window A/C | D13: =MRS!D13 -> 2Ton Super General | G13: =MRS!G13 -> Nos | H13: =MRS!H13 -> 1 | I13: =MRS!I13 -> 1784 | J13: =+H13*I13 -> 1784
A14: =+MRS!A14 -> 9 | B14: =MRS!B14 -> Measuring Cup | D14: =MRS!D14 -> 5000ml | G14: =MRS!G14 -> Nos | H14: =MRS!H14 -> 4 | I14: =MRS!I14 -> 37 | J14: =+H14*I14 -> 148
A15: =+MRS!A15 -> 10 | B15: =MRS!B15 -> Flap Disc S/S | D15: =MRS!D15 -> 4" 80 Grit | G15: =MRS!G15 -> Nos | H15: =MRS!H15 -> 4400 | I15: =MRS!I15 -> 3.1 | J15: =+H15*I15 -> 13640
A16: =+MRS!A16 -> 11 | B16: =MRS!B16 -> Flap Wheel S/S | D16: =MRS!D16 -> 25x20x6mm | G16: =MRS!G16 -> Nos | H16: =MRS!H16 -> 300 | I16: =MRS!I16 -> 4 | J16: =+H16*I16 -> 1200
A17: =+MRS!A17 -> 12 | B17: =MRS!B17 -> Cup Brush C/S Crimped | D17: =MRS!D17 -> M10x75mm | G17: =MRS!G17 -> Nos | H17: =MRS!H17 -> 300 | I17: =MRS!I17 -> 9 | J17: =+H17*I17 -> 2700
... A93: =+MRS!A93 -> 88 | B93: =MRS!B93 -> Tungsten Electrode | D93: =MRS!D93 -> 3.2mm | G93: =MRS!G93 -> Nos | H93: =MRS!H93 -> 200 | I93: =MRS!I93 -> 25 | J93: =+H93*I93 -> 5000

Sheet PO 1st page
M2: BRANCH OF HYUNDAI ENG. & CONST. CO., LTD.
M3: P. O. Box 77249, Al Khobar 31952
M4: kingdom of Saudi Arabia
B5: C.R. 2051041774 & VAT No.: 300000504500003 | M5: Tel: +966-13-845-1088
M6: Fax: +966-13-845-1099
B9: TO: | C9: JSAJ(Jassim Saif Amer Aljaberi Trading Est.)
C10: CR No. : | D10: 2051247436 | J10: P/O Date: | K10: =MRS!L3 -> 46237
C11: VAT No. : | D11: 311625046900003 | J11: P/O No.: | K11: =SUBSTITUTE(SUBSTITUTE(+MRS!A3," MRS No : ",""),"-MRS","-PO") -> SAC2-DS-PO-0390
C12: In Charge : | D12: Shashank Kamra | J12: (Please mention this No. in
D13: Mobile No. +966 539222074 | J13: All future correspondence)
C14: Building No. 6634, Al Khobar 34423, KSA | J14: Quote Ref. : | K14: Q-20263219
C15: Mobile: +966 539222074 | J15: Date- | K15: 46235
B17: PURCHASE ORDER
B19: WE ARE PLEASED TO PLACE AN ORDER WITH YOU FOR THE GOODS DESCRIBED BELOW. THE ORDER SHALL BE SUBJECT TO THE TERMS AND CONDITIONS SET OUR
B20: BELOW AND ATTACHED. PLEASE SIGN AND RETURN THE ENCLOSED COPY OF THIS ORDER AS CONFIRMATION OF YOUR ACCEPTANCE OF IT WITHIN A WEEK
B21: OTHERWISE THIS ORDER SHALL BE REGARDED AS BEING ACCEPTED BY YOU.
B24: 1 | C24: GOODS
C25: Site Materials | M25: [Please refer to attached Scope of supply & Quotation for more details]
B27: 2 | C27: P/O AMOUNT
C28: Material Value | E28: : | F28: =+'PO 2nd page'!G94 -> 150657.2 | H28: [Excludes Vat]
C29: VAT 15% | E29: : | F29: =+F28*0.15 -> 22598.58
C30: Total Amount | E30: : | F30: =F28 -> 150657.2
B32: 3 | C32: PAYMENT TERMS
C33: 100% Payment after Delivery within 35 days with submission of the following Documents.
C34: a) Tax E-Invoice (From Zakat, Tax and Customs Authority)
C35: b) Delivery/Dispatch Note [Counter signed by Site Representative]
B37: 4 | C37: DELIVERY TERMS
C38: Delivery by Seller to Jafurah HYUNDAI Laydown within a Week after receipt of PO.
B40: 5 | C40: OTHER TERMS AND CONDITIONS
C41: a) Any quantity rejected by the Buyer owing to its poor quality and non conformity of specification shall be replaced and re-delivered
C42: by Seller to Buyer at no extra costs
C43: b) Material Certificate, Data Sheet, Safety Data Sheet and other documents which may required by ARAMCO in material receiving
C44: inspection should be submitted to Buyer
C45: c) MTC / MSDS, Others, If required by Client
B47: 6 | C47: CONTACT POINT:
B48: - | C48: Delivery & Payment : Dong Chang Kim / Daeshin Admin. [ Mobile No. : +966 53 748 5762 / Email : kdchjs@daeshinplant.com ]
B49: - | C49: Commercial (Purchaser) : Youngkyu Choi / Daeshin Planning [ Mobile No. : +966 53 952 0931 / Email : ykchoi@daeshinplant.com ]
B50: - | C50: Invoicing : Nehal Kauser / HDEC Purchase PIC [ Mobile No. : +966 50 610 2363 / Email : nehal_kauser@hdec.co.kr ]
B52: 7 | C52: Bank Account Details:
B53: - | C53: ACCOUNT NAME | F53: JASSIM SAIF AMER ALJABERI TRADING EST.
...

Sheet PO 2nd page
A2: PO NO. : | B2: =+'PO 1st page'!K11 -> SAC2-DS-PO-0390 | C2: Scope of Supply
A3: DATE : | B3: =+'PO 1st page'!K10 -> 46237 | E3: Jafurah Utilities, Sulfur and Interconnecting Systems(Pkg-2)
A4: S. NO | B4: DESCRIPTION | D4: QTY | E4: UNIT | F4: ='PO 1st page'!C9 -> JSAJ(Jassim Saif Amer Aljaberi Trading Est.) | H4: Remarks (Details)
F5: Unit Price | G5: Total Amount
A6: =ROW(A1) -> 1 | B6: =+'MRS LIST'!B6 -> Measuring Cup | D6: =+'MRS LIST'!G6 -> Nos | E6: =+'MRS LIST'!H6 -> 4 | F6: =+'MRS LIST'!I6 -> 16 | G6: =+'MRS LIST'!J6 -> 64 | H6: =MRS!L6 -> One Time
A7: =ROW(A2) -> 2 | B7: =+'MRS LIST'!B7 -> Ceramic Backing Tape | D7: =+'MRS LIST'!G7 -> Nos | E7: =+'MRS LIST'!H7 -> 40 | F7: =+'MRS LIST'!I7 -> 20 | G7: =+'MRS LIST'!J7 -> 800
A8: =ROW(A3) -> 3 | B8: =+'MRS LIST'!B8 -> Cutting Disc C/S | D8: =+'MRS LIST'!G8 -> Nos | E8: =+'MRS LIST'!H8 -> 700 | F8: =+'MRS LIST'!I8 -> 1.35 | G8: =+'MRS LIST'!J8 -> 945
A9: =ROW(A4) -> 4 | B9: =+'MRS LIST'!B9 -> Electric Concrete Mixing Machine | D9: =+'MRS LIST'!G9 -> Nos | E9: =+'MRS LIST'!H9 -> 2 | F9: =+'MRS LIST'!I9 -> 345 | G9: =+'MRS LIST'!J9 -> 690
A10: =ROW(A5) -> 5 | B10: =+'MRS LIST'!B10 -> PVC Bucket with Lid | D10: =+'MRS LIST'!G10 -> Nos | E10: =+'MRS LIST'!H10 -> 40 | F10: =+'MRS LIST'!I10 -> 10 | G10: =+'MRS LIST'!J10 -> 400
A11: =ROW(A6) -> 6 | B11: =+'MRS LIST'!B11 -> Plastic Storage Drum | D11: =+'MRS LIST'!G11 -> Nos | E11: =+'MRS LIST'!H11 -> 3 | F11: =+'MRS LIST'!I11 -> 85 | G11: =+'MRS LIST'!J11 -> 255
A12: =ROW(A7) -> 7 | B12: =+'MRS LIST'!B12 -> PE Water Tank Vertical | D12: =+'MRS LIST'!G12 -> Nos | E12: =+'MRS LIST'!H12 -> 2 | F12: =+'MRS LIST'!I12 -> 330 | G12: =+'MRS LIST'!J12 -> 660
A13: =ROW(A8) -> 8 | B13: =+'MRS LIST'!B13 -> Window A/C | D13: =+'MRS LIST'!G13 -> Nos | E13: =+'MRS LIST'!H13 -> 1 | F13: =+'MRS LIST'!I13 -> 1784 | G13: =+'MRS LIST'!J13 -> 1784
A14: =ROW(A9) -> 9 | B14: =+'MRS LIST'!B14 -> Measuring Cup | D14: =+'MRS LIST'!G14 -> Nos | E14: =+'MRS LIST'!H14 -> 4 | F14: =+'MRS LIST'!I14 -> 37 | G14: =+'MRS LIST'!J14 -> 148
A15: =ROW(A10) -> 10 | B15: =+'MRS LIST'!B15 -> Flap Disc S/S | D15: =+'MRS LIST'!G15 -> Nos | E15: =+'MRS LIST'!H15 -> 4400 | F15: =+'MRS LIST'!I15 -> 3.1 | G15: =+'MRS LIST'!J15 -> 13640
A16: =ROW(A11) -> 11 | B16: =+'MRS LIST'!B16 -> Flap Wheel S/S | D16: =+'MRS LIST'!G16 -> Nos | E16: =+'MRS LIST'!H16 -> 300 | F16: =+'MRS LIST'!I16 -> 4 | G16: =+'MRS LIST'!J16 -> 1200
A17: =ROW(A12) -> 12 | B17: =+'MRS LIST'!B17 -> Cup Brush C/S Crimped | D17: =+'MRS LIST'!G17 -> Nos | E17: =+'MRS LIST'!H17 -> 300 | F17: =+'MRS LIST'!I17 -> 9 | G17: =+'MRS LIST'!J17 -> 2700
A18: =ROW(A13) -> 13 | B18: =+'MRS LIST'!B18 -> Teflon Tape | D18: =+'MRS LIST'!G18 -> Nos | E18: =+'MRS LIST'!H18 -> 1000 | F18: =+'MRS LIST'!I18 -> 1.6 | G18: =+'MRS LIST'!J18 -> 1600
... A93: =ROW(A88) -> 88 | B93: =+'MRS LIST'!B93 -> Tungsten Electrode | D93: =+'MRS LIST'!G93 -> Nos | E93: =+'MRS LIST'!H93 -> 200 | F93: =+'MRS LIST'!I93 -> 25 | G93: =+'MRS LIST'!J93 -> 5000
A94: Sub Total Amount | G94: =SUM(G6:G93) -> 150657.2
A95: VAT 15% | G95: =+G94*0.15 -> 22598.58
A96: Grand Total in SAR | G96: =G95+G94 -> 173255.78
A97: =" 1) Above Price are as per your quotation with ref "&'PO 1st page'!K14 -> 1) Above Price are as per your quotation with ref Q-20263219
A98: 2) Details of each item are attached separately.
A100: Page 2/2
