Workbook

Sheet MRS
A1: ■ Purchase Requisition of Material / Manpower / Equipment Rental / ETC. | J1: DAESHIN PLANT
A2: PJT : SACE2 | D2: Division (In charge Name) : ADMIN MANAGER (Dong Chang Kim) | J2: Subcontract name (SAC2-SC-IK-SMP-01)
A3: MRS No : SAC2-DS-MRS-0341 | E3: =+L3 -> 46204 | L3: 46204
A4: No | B4: Item | D4: Specification (Model / Manufacturer / Size) | G4: Unit | H4: Qty | I4: Unit Price (SAR) (Exclude VAT) | J4: Total Price (SAR) (Exclude VAT) | K4: Vendor Name | L4: Remarks
A6: =ROW(A1) -> 1 | B6: Visual Inspection for Cross Arm Strap | G6: EA | H6: 10 | I6: 15 | J6: =H6*I6 -> 150 | K6: ECI | L6: One time
A7: =ROW(A2) -> 2 | B7: Visual Inspection for Gin Wheel | G7: EA | H7: 10 | I7: 40 | J7: =H7*I7 -> 400 | K7: "
A8: =ROW(A3) -> 3 | B8: Visual Inspection for Bow Shackles | G8: EA | H8: 4 | I8: 15 | J8: =H8*I8 -> 60
A9: =ROW(A4) -> 4 | B9: Visual Inspection for Webbing Sling | G9: EA | H9: 9 | I9: 15 | J9: =H9*I9 -> 135
A10: =ROW(A5) -> 5 | B10: Visual Inspection for Chain Blocks | G10: EA | H10: 7 | I10: 40 | J10: =H10*I10 -> 280
A11: =ROW(A6) -> 6 | B11: Visual Inspection for Lever Block | G11: EA | H11: 26 | I11: 40 | J11: =H11*I11 -> 1040
A12: =ROW(A7) -> 7 | B12: Visual Inspection for Bow Shackles | G12: EA | H12: 50 | I12: 15 | J12: =H12*I12 -> 750
A13: =ROW(A8) -> 8
A14: =ROW(A9) -> 9
A15: =ROW(A10) -> 10
A16: Purpose | I16: Sum | J16: =SUM(J6:J15) -> 2815
A17: * There will be an additional administration expense and financial expense (Depend on contract) deduction of total provision cost price.
R18: HEC | S18: ADM
S20: /
O21: Requesting | P21: JV Area PIC
O22: Company | R22: HDEC | S22: ADM
O24: / | P24: / | S24: /
O46: PROJECT MANAGER | P46: PROJECT MANAGER | S46: ADM
O50: PROJECT MANAGER | P50: PROJECT MANAGER | S50: PCM

Sheet MRS LIST
A1: ■ Purchase Requisition of Equipment Rental | J1: =+MRS!J1 -> DAESHIN PLANT
A2: =+MRS!A2 -> PJT : SACE2 | D2: =+MRS!D2 -> Division (In charge Name) : ADMIN MANAGER (Dong Chang Kim) | J2: =+MRS!J2 -> Subcontract name (SAC2-SC-IK-SMP-01)
A3: =+MRS!A3 -> MRS No : SAC2-DS-MRS-0341 | K3: =+MRS!L3 -> 46204
A4: No | B4: Item | D4: Specification (Model / Manufacturer / Size) | G4: Unit | H4: Q'ty | I4: Unit Price | J4: Total Price | K4: Remarks
A6: =+MRS!A6 -> 1 | B6: =MRS!B6 -> Visual Inspection for Cross Arm Strap | D6: =MRS!D6 -> 0 | G6: =MRS!G6 -> EA | H6: =MRS!H6 -> 10 | I6: =MRS!I6 -> 15 | J6: =MRS!J6 -> 150
A7: =+MRS!A7 -> 2 | B7: =MRS!B7 -> Visual Inspection for Gin Wheel | D7: =MRS!D7 -> 0 | G7: =MRS!G7 -> EA | H7: =MRS!H7 -> 10 | I7: =MRS!I7 -> 40 | J7: =MRS!J7 -> 400
A8: =+MRS!A8 -> 3 | B8: =MRS!B8 -> Visual Inspection for Bow Shackles | D8: =MRS!D8 -> 0 | G8: =MRS!G8 -> EA | H8: =MRS!H8 -> 4 | I8: =MRS!I8 -> 15 | J8: =MRS!J8 -> 60
A9: =+MRS!A9 -> 4 | B9: =MRS!B9 -> Visual Inspection for Webbing Sling | D9: =MRS!D9 -> 0 | G9: =MRS!G9 -> EA | H9: =MRS!H9 -> 9 | I9: =MRS!I9 -> 15 | J9: =MRS!J9 -> 135
A10: =+MRS!A10 -> 5 | B10: =MRS!B10 -> Visual Inspection for Chain Blocks | D10: =MRS!D10 -> 0 | G10: =MRS!G10 -> EA | H10: =MRS!H10 -> 7 | I10: =MRS!I10 -> 40 | J10: =MRS!J10 -> 280
A11: =+MRS!A11 -> 6 | B11: =MRS!B11 -> Visual Inspection for Lever Block | D11: =MRS!D11 -> 0 | G11: =MRS!G11 -> EA | H11: =MRS!H11 -> 26 | I11: =MRS!I11 -> 40 | J11: =MRS!J11 -> 1040
A12: =+MRS!A12 -> 7
A13: =+MRS!A13 -> 8
A14: =+MRS!A14 -> 9
A15: =+MRS!A15 -> 10
A16: =+MRS!#REF! -> #REF!
A17: =+MRS!#REF! -> #REF!

Sheet PO 1st page
M2: BRANCH OF HYUNDAI ENG. & CONST. CO., LTD.
M3: P. O. Box 77249, Al Khobar 31952
M4: kingdom of Saudi Arabia
B5: C.R. 2051041774 & VAT No.: 300000504500003 | M5: Tel: +966-13-845-1088
M6: Fax: +966-13-845-1099
B9: TO: | C9: ECI (Engineering Corner for Inspection Co. Ltd.)
C10: CR No. : | D10: 2066002674 | J10: P/O Date: | K10: =MRS!L3 -> 46204
C11: VAT No. : | D11: 310237629500003 | J11: P/O No.: | K11: =SUBSTITUTE(SUBSTITUTE(+MRS!A3," MRS No : ",""),"-MRS","-PO") -> SAC2-DS-PO-0341
C12: In Charge : | D12: Ahmad Salih | J12: (Please mention this No. in
D13: Email:eci@eccgroupksa.com | J13: All future correspondence)
C14: Building No. 3193, Al Fayha Dist. Ras Tannurah 32817, KSA | J14: Quote Ref. : | K14: YRD-SO-2026/519 & 520
C15: Landline : +99 13 667 6999 / 667 6895 | J15: Date- | K15: 46195
B18: PURCHASE ORDER
B20: WE ARE PLEASED TO PLACE AN ORDER WITH YOU FOR THE GOODS DESCRIBED BELOW. THE ORDER SHALL BE SUBJECT TO THE TERMS AND CONDITIONS SET OUR
B21: BELOW AND ATTACHED. PLEASE SIGN AND RETURN THE ENCLOSED COPY OF THIS ORDER AS CONFIRMATION OF YOUR ACCEPTANCE OF IT WITHIN A WEEK
B22: OTHERWISE THIS ORDER SHALL BE REGARDED AS BEING ACCEPTED BY YOU.
B25: 1 | C25: GOODS
C26: Visual Inspection of Materials | M26: [Please refer to attached Scope of supply & Quotation for more details]
B28: 2 | C28: P/O AMOUNT
C29: Material Value | E29: : | F29: ='PO 2nd page'!G18 -> 2815
C30: VAT 15% | E30: : | F30: ='PO 2nd page'!G19 -> 422.25
C31: Total Amount | E31: : | F31: ='PO 2nd page'!G20 -> 3237.25
B33: 3 | C33: PAYMENT TERMS
C34: 100% Payment after Delivery within 35 days with submission of the following Documents.
C35: a) Tax E-Invoice (From Zakat, Tax and Customs Authority)
C36: b) Delivery/Dispatch Note [Counter signed by Site Representative]
B38: 4 | C38: DELIVERY TERMS
C39: Delivery by Seller to Jafurah HYUNDAI Laydown within a Week after receipt of PO.
B41: 5 | C41: OTHER TERMS AND CONDITIONS
C42: a) Any quantity rejected by the Buyer owing to its poor quality and non conformity of specification shall be replaced and re-delivered
C43: by Seller to Buyer at no extra costs
C44: b) Material Certificate, Data Sheet, Safety Data Sheet and other documents which may required by ARAMCO in material receiving
C45: inspection should be submitted to Buyer
C46: c) MTC / MSDS, Others, If required by Client
B48: 6 | C48: CONTACT POINT:
B49: - | C49: Delivery & Payment : Dong Chang Kim / Daeshin Admin. [ Mobile No. : +966 53 748 5762 / Email : kdchjs@daeshinplant.com ]
B50: - | C50: Commercial (Purchaser) : Youngkyu Choi / Daeshin Planning [ Mobile No. : +966 53 952 0931 / Email : ykchoi@daeshinplant.com ]
B51: - | C51: Invoicing : Nehal Kauser / HDEC Purchase PIC [ Mobile No. : +966 50 610 2363 / Email : nehal_kauser@hdec.co.kr ]
B53: 7 | C53: Bank Account Details:
B54: - | C54: ACCOUNT NAME | F54: ENGINEERING CORNER FOR INSPECTION | P54: =UPPER(F54) -> ENGINEERING CORNER FOR INSPECTION
...

Sheet PO 2nd page
A2: PO NO. : | B2: =+'PO 1st page'!K11 -> SAC2-DS-PO-0341 | C2: Scope of Supply
A3: DATE : | B3: =+'PO 1st page'!K10 -> 46204 | E3: Jafurah Utilities, Sulfur and Interconnecting Systems(Pkg-2)
A4: S. NO | B4: DESCRIPTION | D4: QTY | E4: UNIT | F4: ='PO 1st page'!C9 -> ECI (Engineering Corner for Inspection Co. Ltd.) | H4: Remarks (Details)
F5: Unit Price | G5: Total Amount
A6: =ROW(A1) -> 1 | B6: =_xlfn.CONCAT(MRS!B6) -> Visual Inspection for Cross Arm Strap | D6: =_xlfn.CONCAT(MRS!G6) -> EA | E6: =_xlfn.CONCAT(MRS!H6) -> 10 | F6: =+'MRS LIST'!I6 -> 15 | G6: =+'MRS LIST'!J6 -> 150 | H6: =MRS!L6 -> One time
A7: =ROW(A2) -> 2 | B7: =_xlfn.CONCAT(MRS!B7) -> Visual Inspection for Gin Wheel | D7: =_xlfn.CONCAT(MRS!G7) -> EA | E7: =_xlfn.CONCAT(MRS!H7) -> 10 | F7: =+'MRS LIST'!I7 -> 40 | G7: =+'MRS LIST'!J7 -> 400
A8: =ROW(A3) -> 3 | B8: =_xlfn.CONCAT(MRS!B8) -> Visual Inspection for Bow Shackles | D8: =_xlfn.CONCAT(MRS!G8) -> EA | E8: =_xlfn.CONCAT(MRS!H8) -> 4 | F8: =+'MRS LIST'!I8 -> 15 | G8: =+'MRS LIST'!J8 -> 60
A9: =ROW(A4) -> 4 | B9: =_xlfn.CONCAT(MRS!B9) -> Visual Inspection for Webbing Sling | D9: =_xlfn.CONCAT(MRS!G9) -> EA | E9: =_xlfn.CONCAT(MRS!H9) -> 9 | F9: =+'MRS LIST'!I9 -> 15 | G9: =+'MRS LIST'!J9 -> 135
A10: =ROW(A5) -> 5 | B10: =_xlfn.CONCAT(MRS!B10) -> Visual Inspection for Chain Blocks | D10: =_xlfn.CONCAT(MRS!G10) -> EA | E10: =_xlfn.CONCAT(MRS!H10) -> 7 | F10: =+'MRS LIST'!I10 -> 40 | G10: =+'MRS LIST'!J10 -> 280
A11: =ROW(A6) -> 6 | B11: =_xlfn.CONCAT(MRS!B11) -> Visual Inspection for Lever Block | D11: =_xlfn.CONCAT(MRS!G11) -> EA | E11: =_xlfn.CONCAT(MRS!H11) -> 26 | F11: =+'MRS LIST'!I11 -> 40 | G11: =+'MRS LIST'!J11 -> 1040
A12: =ROW(A7) -> 7 | B12: =_xlfn.CONCAT(MRS!B12) -> Visual Inspection for Bow Shackles | D12: =_xlfn.CONCAT(MRS!G12) -> EA | E12: =_xlfn.CONCAT(MRS!H12) -> 50 | F12: =MRS!I12 -> 15 | G12: =MRS!J12 -> 750
A13: =ROW(A8) -> 8
A14: =ROW(A9) -> 9
A15: =ROW(A10) -> 10
A16: =ROW(A11) -> 11 | J16: s
A17: =ROW(A12) -> 12
A18: Sub Total Amount | G18: =SUM(G6:G17) -> 2815
A19: VAT 15% | G19: =+G18*0.15 -> 422.25
A20: Grand Total in SAR | G20: =G19+G18 -> 3237.25
A21: =" 1) Above Price are as per your quotation with ref "&'PO 1st page'!K14 -> 1) Above Price are as per your quotation with ref YRD-SO-2026/519 & 520
A22: 2) Details of each item are attached separately.
A24: Page 2/2
